Workbook
Name g_v__dane: Podsumowanie!#REF!
Name g_v__dane_1: Podsumowanie!#REF!
Name Iskra_Vmin: Podsumowanie!#REF!
Name V_Iksra: Podsumowanie!$AD$3:$AE$87
Name V_Iksra_1: Podsumowanie!#REF!
Name V_minmax: Podsumowanie!#REF!
Name V2_Iksra: Podsumowanie!$AJ$43:$AK$152
Name w_V__dane: Podsumowanie!#REF!

Sheet Podsumowanie
A1: g | B1: 9.81 | C1: m/s2 | AD1: ciągu | AE1: m zmienna | AF1: ciągu | AG1: mśr | AH1: mocy | AI1: mśr | AJ1: bez ściśli | AL1: ciągu | AM1: mmax | AN1: mocy | AO1: mmax
A2: ρ0 | B2: 1.2255 | C2: kg/m3 | AD2: Vmin
A3: S | B3: 17.5 | C3: m2 | N3: h [m] | O3: Vmin [m/s] | P3: Vmin [km/h] | Q3: Vmax [m/s] | R3: Vmax [km/h] | S3: wmax [m/s] | T3: 10·wmax [m/s] | U3: Vw [m/s] | V3: Vw [km/h] | W3: γmax [°] | X3: 10·γmax [°] | Y3: Vγ [m/s] | Z3: Vγ [km/h] | AA3: 1/wmax | AB3: 10th [min] | AD3: 49.966777 | AE3: 7.3582677 | AF3: 45.966514 | AG3: 8.9477612 | AH3: 45.966514 | AI3: 8.5373134 | AJ3: 49.969183 | AK3: 7.394958 | AL3: 49.966777 | AM3: 7.3582677 | AN3: 50.166113 | AO3: 6.9862205
A4: mmax | B4: 3840 | C4: kg | N4: 0 | O4: =AD3 -> 49.966777 | P4: =O4*3.6 -> 179.8804 | Q4: =AD12 -> 204.98982 | R4: =Q4*3.6 -> 737.96334 | S4: =AE21 -> 20.545276 | T4: =10*S4 -> 205.45276 | U4: =AD21 -> 134.68439 | V4: =U4*3.6 -> 484.86379 | W4: =AE30 -> 10.614754 | X4: =10*W4 -> 106.14754 | Y4: =AD30 -> 85.608108 | Z4: =Y4*3.6 -> 308.18919 | AA4: =1/S4 -> 0.04867299 | AB4: 0 | AD4: 55.149502 | AE4: 5.9527559 | AF4: 50.65449 | AG4: 7.4701493 | AH4: 50.65449 | AI4: 7.0597015 | AJ4: 54.776579 | AK4: 5.989916 | AL4: 55.149502 | AM4: 5.5807087 | AN4: 55.149502 | AO4: 5.5807087
A5: mpal | B5: 996 | C5: kg | N5: 2000 | O5: =AD4 -> 55.149502 | P5: =O5*3.6 -> 198.53821 | Q5: =AD13 -> 206.15071 | R5: =Q5*3.6 -> 742.14257 | S5: =AE22 -> 17.072835 | T5: =10*S5 -> 170.72835 | U5: =AD22 -> 138.27243 | V5: =U5*3.6 -> 497.78073 | W5: =AE31 -> 8.3811475 | X5: =10*W5 -> 83.811475 | Y5: =AD31 -> 98.175676 | Z5: =Y5*3.6 -> 353.43243 | AA5: =1/S5 -> 0.058572582 | AB5: =(AA5+AA4)/2*(N5-N4)/6 -> 17.874262 | AD5: 60.930233 | AE5: 4.5059055 | AF5: 56.194825 | AG5: 5.9104478 | AH5: 56.194825 | AI5: 5.5410448 | AJ5: 60.693374 | AK5: 4.6218487 | AL5: 61.328904 | AM5: 4.4232283 | AN5: 61.328904 | AO5: 4.0925197
A6: mk | B6: 2640 | C6: kg | N6: 4000 | O6: =AD5 -> 60.930233 | P6: =O6*3.6 -> 219.34884 | Q6: =AD14 -> 207.18941 | R6: =Q6*3.6 -> 745.88187 | S6: =AE23 -> 13.807087 | T6: =10*S6 -> 138.07087 | U6: =AD23 -> 142.65781 | V6: =U6*3.6 -> 513.56811 | W6: =AE32 -> 6.4959016 | X6: =10*W6 -> 64.959016 | Y6: =AD32 -> 107.2973 | Z6: =Y6*3.6 -> 386.27027 | AA6: =1/S6 -> 0.072426575 | AB6: =(AA6+AA5)/2*(N6-N5)/6+AB5 -> 39.707455 | AD6: 67.508306 | AE6: 2.9350394 | AF6: 62.587519 | AG6: 4.2686567 | AH6: 62.587519 | AI6: 3.9813433 | AJ6: 67.349769 | AK6: 3.1058824 | AL6: 68.305648 | AM6: 2.769685 | AN6: 68.305648 | AO6: 2.480315
A7: mobl | B7: =(B4+B6)/2 -> 3240 | C7: kg | N7: 6000 | O7: =AD6 -> 67.508306 | P7: =O7*3.6 -> 243.0299 | Q7: =AD15 -> 206.96538 | R7: =Q7*3.6 -> 745.07536 | S7: =AE24 -> 10.748031 | T7: =10*S7 -> 107.48031 | U7: =AD24 -> 147.04319 | V7: =U7*3.6 -> 529.35548 | W7: =AE33 -> 4.795082 | X7: =10*W7 -> 47.95082 | Y7: =AD33 -> 119.05405 | Z7: =Y7*3.6 -> 428.59459 | AA7: =1/S7 -> 0.093040293 | AB7: =(AA7+AA6)/2*(N7-N6)/6+AB6 -> 67.285266 | AD7: 75.481728 | AE7: 1.2814961 | AF7: 70.045662 | AG7: 2.5858209 | AH7: 69.832572 | AI7: 2.2985075 | AJ7: 75.855162 | AK7: 1.5159664 | AL7: 76.478405 | AM7: 1.0334646 | AN7: 76.478405 | AO7: 0.78543307
A8: Q | B8: =B7*B1 -> 31784.4 | C8: N | N8: 8000 | O8: =AD7 -> 75.481728 | P8: =O8*3.6 -> 271.73422 | Q8: =AD16 -> 206.33401 | R8: =Q8*3.6 -> 742.80244 | S8: =AE25 -> 7.8956693 | T8: =10*S8 -> 78.956693 | U8: =AD25 -> 152.62458 | V8: =U8*3.6 -> 549.4485 | W8: =AE34 -> 3.2581967 | X8: =10*W8 -> 32.581967 | Y8: =AD34 -> 129.39189 | Z8: =Y8*3.6 -> 465.81081 | AA8: =1/S8 -> 0.12665171 | AB8: =(AA8+AA7)/2*(N8-N7)/6+AB7 -> 103.9006 | AD8: 87.641196 | AE8: 0 | AF8: 79.421613 | AG8: 0.73880597 | AH8: 79.208524 | AI8: 0.41044776 | AJ8: 86.579353 | AK8: 0 | AL8: 93.023256 | AM8: 0 | AN8: 95.813953 | AO8: 0
A9: Qmax | B9: =B4*B1 -> 37670.4 | C9: N | N9: 10000 | O9: =AD8 -> 87.641196 | P9: =O9*3.6 -> 315.50831 | Q9: =AD17 -> 203.64562 | R9: =Q9*3.6 -> 733.12424 | S9: =AE26 -> 5.0846457 | T9: =10*S9 -> 50.846457 | U9: =AD26 -> 159.60133 | V9: =U9*3.6 -> 574.56478 | W9: =AE35 -> 1.9262295 | X9: =10*W9 -> 19.262295 | Y9: =AD35 -> 144.39189 | Z9: =Y9*3.6 -> 519.81081 | AA9: =1/S9 -> 0.19667054 | AB9: =(AA9+AA8)/2*(N9-N8)/6+AB8 -> 157.78764 | AD9: 116.14618 | AE9: 0 | AF9: 102.00913 | AG9: 0 | AH9: 106.27093 | AI9: 0.041044776 | AJ9: 112.09553 | AK9: 0 | AL9: 146.24585 | AM9: 0
A10: Pr-0 | B10: 9800 | C10: N | N10: 12000 | O10: =AD9 -> 116.14618 | P10: =O10*3.6 -> 418.12625 | Q10: =AD18 -> 197.16904 | R10: =Q10*3.6 -> 709.80855 | S10: =AE27 -> 2.3976378 | T10: =10*S10 -> 23.976378 | U10: =AD27 -> 167.37542 | V10: =U10*3.6 -> 602.5515 | W10: =AE36 -> 0.84016393 | X10: =10*W10 -> 8.4016393 | Y10: =AD36 -> 160.81081 | Z10: =Y10*3.6 -> 578.91892 | AA10: =1/S10 -> 0.41707718 | AB10: =(AA10+AA9)/2*(N10-N9)/6+AB9 -> 260.07893 | AJ10: 152.0339 | AK10: 0
A11: Pnom | B11: 8200 | C11: N | N11: =AD40 -> 13600 | P11: 620 | R11: =P11 -> 620 | T11: 0 | V11: =R11 -> 620 | X11: 0 | Z11: =R11 -> 620 | AB11: 1100 | AD11: Vmax
A12: ns | B12: =14600/60 -> 243.33333 | C12: 1/s | AD12: 204.98982 | AE12: 4.9377161e-05 | AF12: 204.78759 | AG12: -9.6129115e-05 | AH12: 205.59478 | AI12: -9.6129115e-05 | AJ12: 233.75963 | AK12: 0 | AL12: 203.84 | AM12: 0 | AN12: 205.1896 | AO12: 0.00405
A13: a0 | B13: 340.3 | C13: m/s | N13: h [m] | O13: Vmin [m/s] | P13: Vmin [km/h] | Q13: Vmax [m/s] | R13: Vmax [km/h] | S13: wmax [m/s] | T13: 10·wmax [m/s] | U13: Vw [m/s] | V13: Vw [km/h] | W13: γmax [°] | X13: 10·γmax [°] | Y13: Vγ [m/s] | Z13: Vγ [km/h] | AA13: 1/wmax | AB13: 10th [min] | AD13: 206.15071 | AE13: 8.1821626e-05 | AF13: 205.76652 | AG13: -9.6129115e-05 | AH13: 206.95154 | AI13: -9.6129115e-05 | AJ13: 238.56703 | AK13: 0 | AL13: 204.70468 | AM13: 7.7618055e-05 | AN13: 205.35804 | AO13: 0.00415
A14: Λe | B14: 5.134 | C14: - | N14: 0 | O14: =AF3 -> 45.966514 | P14: =O14*3.6 -> 165.47945 | Q14: =AF12 -> 204.78759 | R14: =Q14*3.6 -> 737.23532 | S14: =AG21 -> 21.384328 | T14: =10*S14 -> 213.84328 | U14: =AF21 -> 124.17047 | V14: =U14*3.6 -> 447.0137 | W14: =AG30 -> 12.642857 | X14: =10*W14 -> 126.42857 | Y14: =AF30 -> 67.269939 | Z14: =Y14*3.6 -> 242.17178 | AA14: =1/S14 -> 0.046763218 | AB14: 0 | AD14: 207.18941 | AE14: 5.5771326e-05 | AF14: 206.3161 | AG14: 0.00010480967 | AH14: 207.07176 | AI14: -9.6129115e-05 | AJ14: 243.74422 | AK14: 0 | AL14: 204.62322 | AM14: 7.7381234e-05 | AN14: 205.82723 | AO14: 0.0041
A15: (Cx)min | B15: 0.01533 | C15: - | N15: 2000 | O15: =AF4 -> 50.65449 | P15: =O15*3.6 -> 182.35616 | Q15: =AF13 -> 205.76652 | R15: =Q15*3.6 -> 740.75948 | S15: =AG22 -> 17.731343 | T15: =10*S15 -> 177.31343 | U15: =AF22 -> 125.87519 | V15: =U15*3.6 -> 453.15068 | W15: =AG31 -> 9.9047619 | X15: =10*W15 -> 99.047619 | Y15: =AF31 -> 75 | Z15: =Y15*3.6 -> 270 | AA15: =1/S15 -> 0.056397306 | AB15: =(AA15+AA14)/2*(N15-N14)/6 -> 17.193421 | AD15: 206.96538 | AE15: 5.5120068e-05 | AF15: 206.11001 | AG15: -9.6129115e-05 | AH15: 207.60417 | AI15: -0.0002970679 | AJ15: 248.92142 | AK15: 0 | AL15: 204.41955 | AM15: 4.7719415e-05 | AN15: 206.30366 | AO15: 0.0041
A16: Czmax | B16: 1.405 | C16: - | N16: 4000 | O16: =AF5 -> 56.194825 | P16: =O16*3.6 -> 202.30137 | Q16: =AF14 -> 206.3161 | R16: =Q16*3.6 -> 742.73795 | S16: =AG23 -> 14.406716 | T16: =10*S16 -> 144.06716 | U16: =AF23 -> 129.49772 | V16: =U16*3.6 -> 466.19178 | W16: =AG32 -> 7.5714286 | X16: =10*W16 -> 75.714286 | Y16: =AF32 -> 84.018405 | Z16: =Y16*3.6 -> 302.46626 | AA16: =1/S16 -> 0.069412069 | AB16: =(AA16+AA15)/2*(N16-N15)/6+AB15 -> 38.16165 | AD16: 206.33401 | AE16: 5.3284706e-05 | AF16: 204.59867 | AG16: 0.00010480967 | AH16: 207.22633 | AI16: -9.6129115e-05 | AJ16: 254.83821 | AK16: 0 | AL16: 203.31976 | AM16: 7.35921e-05 | AN16: 202.32356 | AO16: 0.0041
A17: a∞ | B17: 6.231 | C17: 1/rad | N17: 6000 | O17: =AF6 -> 62.587519 | P17: =O17*3.6 -> 225.31507 | Q17: =AF15 -> 206.11001 | R17: =Q17*3.6 -> 741.99602 | S17: =AG24 -> 11.164179 | T17: =10*S17 -> 111.64179 | U17: =AF24 -> 132.48097 | V17: =U17*3.6 -> 476.93151 | W17: =AG33 -> 5.5238095 | X17: =10*W17 -> 55.238095 | Y17: =AF33 -> 93.680982 | Z17: =Y17*3.6 -> 337.25153 | AA17: =1/S17 -> 0.089572193 | AB17: =(AA17+AA16)/2*(N17-N16)/6+AB16 -> 64.659027 | AD17: 203.64562 | AE17: 7.4539383e-05 | AF17: 200.40815 | AG17: -9.6129115e-05 | AH17: 203.22473 | AI17: -9.6129115e-05 | AJ17: 260.75501 | AK17: 0 | AL17: 200.4277 | AM17: 3.611519e-05 | AN17: 190.40541 | AO17: 0
A18: T0 | B18: 288.15 | C18: K | N18: 8000 | O18: =AF7 -> 70.045662 | P18: =O18*3.6 -> 252.16438 | Q18: =AF16 -> 204.59867 | R18: =Q18*3.6 -> 736.55522 | S18: =AG25 -> 8.1679104 | T18: =10*S18 -> 81.679104 | U18: =AF25 -> 136.1035 | V18: =U18*3.6 -> 489.9726 | W18: =AG34 -> 3.7619048 | X18: =10*W18 -> 37.619048 | Y18: =AF34 -> 104.41718 | Z18: =Y18*3.6 -> 375.90184 | AA18: =1/S18 -> 0.12243033 | AB18: =(AA18+AA17)/2*(N18-N17)/6+AB17 -> 99.992781 | AD18: 197.16904 | AE18: 2.6642353e-05 | AF18: 189.60555 | AG18: -9.6129115e-05 | AH18: 184.12696 | AI18: -9.6129115e-05 | AJ18: 266.302 | AK18: 0 | AL18: 170 | AM18: 4.1976507e-05
A19: φ | B19: 1 | C19: ° | N19: 10000 | O19: =AF8 -> 79.421613 | P19: =O19*3.6 -> 285.91781 | Q19: =AF17 -> 200.40815 | R19: =Q19*3.6 -> 721.46935 | S19: =AG26 -> 5.2126866 | T19: =10*S19 -> 52.126866 | U19: =AF26 -> 139.51294 | V19: =U19*3.6 -> 502.24658 | W19: =AG35 -> 2.2380952 | X19: =10*W19 -> 22.380952 | Y19: =AF35 -> 118.37423 | Z19: =Y19*3.6 -> 426.14724 | AA19: =1/S19 -> 0.19183966 | AB19: =(AA19+AA18)/2*(N19-N18)/6+AB18 -> 152.37111 | AJ19: 267.7812 | AK19: 0
A20: α0 | B20: -1.42 | C20: ° | N20: 12000 | O20: =AF9 -> 102.00913 | P20: =O20*3.6 -> 367.23288 | Q20: =AF18 -> 189.60555 | R20: =Q20*3.6 -> 682.57997 | S20: =AG27 -> 2.2164179 | T20: =10*S20 -> 22.164179 | U20: =AF27 -> 145.69254 | V20: =U20*3.6 -> 524.49315 | W20: =AG36 -> 0.88095238 | X20: =10*W20 -> 8.8095238 | Y20: =AF36 -> 135.9816 | Z20: =Y20*3.6 -> 489.53374 | AA20: =1/S20 -> 0.45117845 | AB20: =(AA20+AA19)/2*(N20-N19)/6+AB19 -> 259.5408 | AD20: Vw
N21: =AF40 -> 13390 | P21: 550 | R21: =P21 -> 550 | T21: 0 | V21: =R21 -> 550 | X21: 0 | Z21: =R21 -> 550 | AB21: =AB11 -> 1100 | AD21: 134.68439 | AE21: 20.545276 | AF21: 124.17047 | AG21: 21.384328 | AH21: 129.07154 | AI21: 21.548507 | AJ21: 142.78891 | AK21: 21.334454 | AL21: 125.91362 | AM21: 17.444882 | AN21: 129.10299 | AO21: 17.734252
A22: qN | B22: =B4/(B10/1000) -> 391.83673 | AD22: 138.27243 | AE22: 17.072835 | AF22: 125.87519 | AG22: 17.731343 | AH22: 131.41553 | AI22: 17.977612 | AJ22: 149.4453 | AK22: 17.858824 | AL22: 128.30565 | AM22: 14.344488 | AN22: 134.48505 | AO22: 14.509843
A23: qt | B23: =0.022*B25 -> 18.48 | N23: h [m] | O23: Vmin [m/s] | P23: Vmin [km/h] | Q23: Vmax [m/s] | R23: Vmax [km/h] | S23: wmax [m/s] | T23: 10·wmax [m/s] | U23: Vw [m/s] | V23: Vw [km/h] | W23: γmax [°] | X23: 10·γmax [°] | Y23: Vγ [m/s] | Z23: Vγ [km/h] | AA23: 1/wmax | AB23: 10th [min] | AD23: 142.65781 | AE23: 13.807087 | AF23: 129.49772 | AG23: 14.406716 | AH23: 135.25114 | AI23: 14.570896 | AJ23: 156.84129 | AK23: 14.678992 | AL23: 132.69103 | AM23: 11.326772 | AN23: 138.87043 | AO23: 11.161417
A24: qe | B24: =B23/B11 -> 0.0022536585 | N24: 0 | O24: =AH3 -> 45.966514 | P24: =O24*3.6 -> 165.47945 | Q24: =AH12 -> 205.59478 | R24: =Q24*3.6 -> 740.1412 | S24: =AI21 -> 21.548507 | T24: =10*S24 -> 215.48507 | U24: =AH21 -> 129.07154 | V24: =U24*3.6 -> 464.65753 | W24: =AI30 -> 12.238095 | X24: =10*W24 -> 122.38095 | Y24: =AH30 -> 72.423313 | Z24: =Y24*3.6 -> 260.72393 | AA24: =1/S24 -> 0.046406926 | AB24: 0 | AD24: 147.04319 | AE24: 10.748031 | AF24: 132.48097 | AG24: 11.164179 | AH24: 138.2344 | AI24: 11.041045 | AJ24: 164.60709 | AK24: 11.684034 | AL24: 137.47508 | AM24: 8.515748 | AN24: 144.65116 | AO24: 8.1023622
A25: ρpal | B25: 840 | C25: kg/m3 | N25: 2000 | O25: =AH4 -> 50.65449 | P25: =O25*3.6 -> 182.35616 | Q25: =AH13 -> 206.95154 | R25: =Q25*3.6 -> 745.02556 | S25: =AI22 -> 17.977612 | T25: =10*S25 -> 179.77612 | U25: =AH22 -> 131.41553 | V25: =U25*3.6 -> 473.09589 | W25: =AI31 -> 9.6190476 | X25: =10*W25 -> 96.190476 | Y25: =AH31 -> 81.226994 | Z25: =Y25*3.6 -> 292.41718 | AA25: =1/S25 -> 0.055624741 | AB25: =(AA25+AA24)/2*(N25-N24)/6 -> 17.005278 | AD25: 152.62458 | AE25: 7.8956693 | AF25: 136.1035 | AG25: 8.1679104 | AH25: 142.92237 | AI25: 7.9216418 | AJ25: 171.63328 | AK25: 9.0588235 | AL25: 142.45847 | AM25: 5.746063 | AN25: 148.2392 | AO25: 5.3740157
A26: thp | B26: 45.4 | C26: min | N26: 4000 | O26: =AH5 -> 56.194825 | P26: =O26*3.6 -> 202.30137 | Q26: =AH14 -> 207.07176 | R26: =Q26*3.6 -> 745.45835 | S26: =AI23 -> 14.570896 | T26: =10*S26 -> 145.70896 | U26: =AH23 -> 135.25114 | V26: =U26*3.6 -> 486.90411 | W26: =AI32 -> 7.2857143 | X26: =10*W26 -> 72.857143 | Y26: =AH32 -> 90.460123 | Z26: =Y26*3.6 -> 325.65644 | AA26: =1/S26 -> 0.068629962 | AB26: =(AA26+AA25)/2*(N26-N25)/6+AB25 -> 37.714395 | AD26: 159.60133 | AE26: 5.0846457 | AF26: 139.51294 | AG26: 5.2126866 | AH26: 146.5449 | AI26: 5.0895522 | AJ26: 182.35747 | AK26: 6.507563 | AL26: 148.2392 | AM26: 3.0590551 | AN26: 154.81728 | AO26: 2.5629921
A27: Δt | B27: 1.25 | C27: h | N27: 6000 | O27: =AH6 -> 62.587519 | P27: =O27*3.6 -> 225.31507 | Q27: =AH15 -> 207.60417 | R27: =Q27*3.6 -> 747.375 | S27: =AI24 -> 11.041045 | T27: =10*S27 -> 110.41045 | U27: =AH24 -> 138.2344 | V27: =U27*3.6 -> 497.64384 | W27: =AI33 -> 5.2857143 | X27: =10*W27 -> 52.857143 | Y27: =AH33 -> 100.76687 | Z27: =Y27*3.6 -> 362.76074 | AA27: =1/S27 -> 0.090571139 | AB27: =(AA27+AA26)/2*(N27-N26)/6+AB26 -> 64.247912 | AD27: 167.37542 | AE27: 2.3976378 | AF27: 145.69254 | AG27: 2.2164179 | AH27: 154.00304 | AI27: 1.7649254 | AJ27: 196.04006 | AK27: 4.0672269 | AL27: 153.42193 | AM27: 0.2
A28: ht | B28: 4550 | C28: m | N28: 8000 | O28: =AH7 -> 69.832572 | P28: =O28*3.6 -> 251.39726 | Q28: =AH16 -> 207.22633 | R28: =Q28*3.6 -> 746.0148 | S28: =AI25 -> 7.9216418 | T28: =10*S28 -> 79.216418 | U28: =AH25 -> 142.92237 | V28: =U28*3.6 -> 514.52055 | W28: =AI34 -> 3.5714286 | X28: =10*W28 -> 35.714286 | Y28: =AH34 -> 112.14724 | Z28: =Y28*3.6 -> 403.73006 | AA28: =1/S28 -> 0.12623646 | AB28: =(AA28+AA27)/2*(N28-N27)/6+AB27 -> 100.38251 | AJ28: 214.89985 | AK28: 1.8487395
A29: hp | B29: 3700 | C29: m | N29: 10000 | O29: =AH8 -> 79.208524 | P29: =O29*3.6 -> 285.15068 | Q29: =AH17 -> 203.22473 | R29: =Q29*3.6 -> 731.60903 | S29: =AI26 -> 5.0895522 | T29: =10*S29 -> 50.895522 | U29: =AH26 -> 146.5449 | V29: =U29*3.6 -> 527.56164 | W29: =AI35 -> 1.9761905 | X29: =10*W29 -> 19.761905 | Y29: =AH35 -> 127.17791 | Z29: =Y29*3.6 -> 457.84049 | AA29: =1/S29 -> 0.19648094 | AB29: =(AA29+AA28)/2*(N29-N28)/6+AB28 -> 154.16874 | AD29: Vy
A30: φ | B30: =RADIANS(B19) -> 0.017453293 | C30: rad | N30: 12000 | O30: =AH9 -> 106.27093 | P30: =O30*3.6 -> 382.57534 | Q30: =AH18 -> 184.12696 | R30: =Q30*3.6 -> 662.85706 | S30: =AI27 -> 1.7649254 | T30: =10*S30 -> 17.649254 | U30: =AH27 -> 154.00304 | V30: =U30*3.6 -> 554.41096 | W30: =AI36 -> 0.64285714 | X30: =10*W30 -> 6.4285714 | Y30: =AH36 -> 146.71779 | Z30: =Y30*3.6 -> 528.18405 | AA30: =1/S30 -> 0.56659619 | AB30: =(AA30+AA29)/2*(N30-N29)/6+AB29 -> 281.34827 | AD30: 85.608108 | AE30: 10.614754 | AF30: 67.269939 | AG30: 12.642857 | AH30: 72.423313 | AI30: 12.238095 | AJ30: 85.566502 | AK30: 10.600638 | AL30: 75.675676 | AM30: 9.9180328 | AN30: 80.540541 | AO30: 9.5901639
A31: α0 | B31: =RADIANS(B20) -> -0.024783675 | C31: rad | N31: =AH40 -> 13070 | P31: 560 | R31: =P31 -> 560 | T31: 0 | V31: =R31 -> 560 | X31: 0 | Z31: =R31 -> 560 | AB31: =AB21 -> 1100 | AD31: 98.175676 | AE31: 8.3811475 | AF31: 75 | AG31: 9.9047619 | AH31: 81.226994 | AI31: 9.6190476 | AJ31: 95.812808 | AK31: 8.4091512 | AL31: 83.175676 | AM31: 7.6434426 | AN31: 89.459459 | AO31: 7.397541
A32: qe | B32: 0.0296 | C32: kg/kNs | AD32: 107.2973 | AE32: 6.4959016 | AF32: 84.018405 | AG32: 7.5714286 | AH32: 90.460123 | AI32: 7.2857143 | AJ32: 108.42365 | AK32: 6.5063155 | AL32: 93.716216 | AM32: 5.6762295 | AN32: 99.391892 | AO32: 5.4508197
B33: =3600*B32 -> 106.56 | AD33: 119.05405 | AE33: 4.795082 | AF33: 93.680982 | AG33: 5.5238095 | AH33: 100.76687 | AI33: 5.2857143 | AJ33: 121.82266 | AK33: 4.8727738 | AL33: 106.28378 | AM33: 3.9959016 | AN33: 112.56757 | AO33: 3.7704918
N34: h [m] | O34: Vmin [m/s] | P34: Vmin [km/h] | Q34: Vmax [m/s] | R34: Vmax [km/h] | S34: wmax [m/s] | T34: 10·wmax [m/s] | U34: Vw [m/s] | V34: Vw [km/h] | W34: γmax [°] | X34: 10·γmax [°] | Y34: Vγ [m/s] | Z34: Vγ [km/h] | AA34: 1/wmax | AB34: 10th [min] | AD34: 129.39189 | AE34: 3.2581967 | AF34: 104.41718 | AG34: 3.7619048 | AH34: 112.14724 | AI34: 3.5714286 | AJ34: 136.00985 | AK34: 3.4700644 | AL34: 119.86486 | AM34: 2.4795082 | AN34: 127.56757 | AO34: 2.2540984
N35: 0 | O35: =AJ3 -> 49.969183 | P35: =O35*3.6 -> 179.88906 | Q35: =AJ12 -> 233.75963 | R35: =Q35*3.6 -> 841.53467 | S35: =AK21 -> 21.334454 | T35: =10*S35 -> 213.34454 | U35: =AJ21 -> 142.78891 | V35: =U35*3.6 -> 514.04006 | W35: =AK30 -> 10.600638 | X35: =10*W35 -> 106.00638 | Y35: =AJ30 -> 85.566502 | Z35: =Y35*3.6 -> 308.03941 | AA35: =1/S35 -> 0.046872538 | AB35: 0 | AD35: 144.39189 | AE35: 1.9262295 | AF35: 118.37423 | AG35: 2.2380952 | AH35: 127.17791 | AI35: 1.9761905 | AJ35: 153.74384 | AK35: 2.2791777 | AL35: 135.47297 | AM35: 1.1885246 | AN35: 143.17568 | AO35: 0.98360656
N36: 2000 | O36: =AJ4 -> 54.776579 | P36: =O36*3.6 -> 197.19569 | Q36: =AJ13 -> 238.56703 | R36: =Q36*3.6 -> 858.84129 | S36: =AK22 -> 17.858824 | T36: =10*S36 -> 178.58824 | U36: =AJ22 -> 149.4453 | V36: =U36*3.6 -> 538.00308 | W36: =AK31 -> 8.4091512 | X36: =10*W36 -> 84.091512 | Y36: =AJ31 -> 95.812808 | Z36: =Y36*3.6 -> 344.92611 | AA36: =1/S36 -> 0.05599473 | AB36: =(AA36+AA35)/2*(N36-N35)/6 -> 17.144545 | AD36: 160.81081 | AE36: 0.84016393 | AF36: 135.9816 | AG36: 0.88095238 | AH36: 146.71779 | AI36: 0.64285714 | AJ36: 178.17734 | AK36: 1.3003663 | AL36: 153.51351 | AM36: 0.020491803
N37: 4000 | O37: =AJ5 -> 60.693374 | P37: =O37*3.6 -> 218.49615 | Q37: =AJ14 -> 243.74422 | R37: =Q37*3.6 -> 877.4792 | S37: =AK23 -> 14.678992 | T37: =10*S37 -> 146.78992 | U37: =AJ23 -> 156.84129 | V37: =U37*3.6 -> 564.62866 | W37: =AK32 -> 6.5063155 | X37: =10*W37 -> 65.063155 | Y37: =AJ32 -> 108.42365 | Z37: =Y37*3.6 -> 390.32512 | AA37: =1/S37 -> 0.068124571 | AB37: =(AA37+AA36)/2*(N37-N36)/6+AB36 -> 37.831095 | AJ37: 208.91626 | AK37: 0.51436782
N38: 6000 | O38: =AJ6 -> 67.349769 | P38: =O38*3.6 -> 242.45917 | Q38: =AJ15 -> 248.92142 | R38: =Q38*3.6 -> 896.1171 | S38: =AK24 -> 11.684034 | T38: =10*S38 -> 116.84034 | U38: =AJ24 -> 164.60709 | V38: =U38*3.6 -> 592.58552 | W38: =AK33 -> 4.8727738 | X38: =10*W38 -> 48.727738 | Y38: =AJ33 -> 121.82266 | Z38: =Y38*3.6 -> 438.56158 | AA38: =1/S38 -> 0.085586881 | AB38: =(AA38+AA37)/2*(N38-N37)/6+AB37 -> 63.44967
N39: 8000 | O39: =AJ7 -> 75.855162 | P39: =O39*3.6 -> 273.07858 | Q39: =AJ16 -> 254.83821 | R39: =Q39*3.6 -> 917.41757 | S39: =AK25 -> 9.0588235 | T39: =10*S39 -> 90.588235 | U39: =AJ25 -> 171.63328 | V39: =U39*3.6 -> 617.87982 | W39: =AK34 -> 3.4700644 | X39: =10*W39 -> 34.700644 | Y39: =AJ34 -> 136.00985 | Z39: =Y39*3.6 -> 489.63547 | AA39: =1/S39 -> 0.11038961 | AB39: =(AA39+AA38)/2*(N39-N38)/6+AB38 -> 96.112419 | AD39: ht1 | AE39: hp1 | AF39: ht2 | AG39: hp2 | AH39: ht3 | AI39: hp3 | AJ39: ht4 | AK39: hp4 | AL39: ht5 | AM39: hp5 | AN39: ht6 | AO39: hp6
N40: 10000 | O40: =AJ8 -> 86.579353 | P40: =O40*3.6 -> 311.68567 | Q40: =AJ17 -> 260.75501 | R40: =Q40*3.6 -> 938.71803 | S40: =AK26 -> 6.507563 | T40: =10*S40 -> 65.07563 | U40: =AJ26 -> 182.35747 | V40: =U40*3.6 -> 656.4869 | W40: =AK35 -> 2.2791777 | X40: =10*W40 -> 22.791777 | Y40: =AJ35 -> 153.74384 | Z40: =Y40*3.6 -> 553.47783 | AA40: =1/S40 -> 0.15366736 | AB40: =(AA40+AA39)/2*(N40-N39)/6+AB39 -> 140.12191 | AD40: 13600 | AE40: =-661.24*AE$44+AD40 -> 13269.38 | AF40: 13390 | AG40: =-626.05*AE$44+AF40 -> 13076.975 | AH40: 13070 | AI40: =-606.56*AE$44+AH40 -> 12766.72 | AJ40: 15330 | AK40: =-718.48*AE44+AJ40 -> 14970.76 | AL40: 12140 | AM40: =-695.86*AE44+AL40 -> 11792.07 | AN40: 11670 | AO40: =-659.14*AE44+AN40 -> 11340.43
...

Sheet Metoda CIągu, zmienna masa
A1: kąt pochylenia osi silnika fi | B1: φ | C1: =Podsumowanie!B30 -> 0.017453293 | D1: rad
A2: Współczynnik kierunkowy prostej Cz(a) | B2: a∞ | C2: =Podsumowanie!B17 -> 6.231 | D2: 1/rad | E2: =DEGREES(C5) -> -1.42 | J2: Metoda ciągu, zmienna masa, h=0m, ściśliwość
A3: Ciąg silnika przy ziemii | B3: Pr-0 | C3: =Podsumowanie!B10 -> 9800 | D3: N | J3: V [m/s] | K3: Ma | L3: Ps [N] | M3: α [°] | N3: γ [°] | O3: w [m/s] | P3: Ps/w | R3: γ | S3: [°] | T3: [rad] | U3: [rad] | V3: [°] | W3: α
A4: Powierzchnia nośna | B4: S | C4: =Podsumowanie!B3 -> 17.5 | D4: m2 | J4: =SQRT(2*(C$14+G12)*C$10/C$4/C$15/G8) -> 50.0036 | K4: =J4/G$11 -> 0.14693976 | L4: =G$9*(1-0.605*K4+0.725*K4^2) -> 9082.2003 | M4: =V4 -> 10.826661 | N4: =S4 -> 8.4759584 | O4: =J4*SIN(RADIANS(N4)) -> 7.3702507 | P4: =L4/1000/O4 -> 1.2322783 | Q4: 1 | R4: =0.5*G$8*C$4*C$2*(U4-C$5)*J4^2+L4*SIN(U4-C$1)-C$10*(C$14+G$12*(J$18-J4)/(J$18-J$4))*COS(T4) -> 0.0046671114 | S4: =DEGREES(T4) -> 8.4759584 | T4: 0.14793338 | U4: 0.18896088 | V4: =DEGREES(U4) -> 10.826661 | W4: =-0.5*G$8*C$4*J4^2*((C$7+(C$2^2)*(U4-C$5)^2/(PI()*C$6))/SQRT(1-(J4/G$11)^2))+L4*COS(U4-C$1)-C$10*(C$14+G$12*(J$18-J4)/(J$18-J$4))*SIN(T4) -> 0.00079383864 | X4: =Q4 -> 1
A5: Kąt zerowej siły nośnej | B5: α0 | C5: =Podsumowanie!B31 -> -0.024783675 | D5: rad | J5: =J$4+Q4*G$14 -> 61.431914 | K5: =J5/G$11 -> 0.18052282 | L5: =G$9*(1-0.605*K5+0.725*K5^2) -> 8961.2214 | M5: =V5 -> 6.6567537 | N5: =S5 -> 9.8404246 | O5: =J5*SIN(RADIANS(N5)) -> 10.499003 | P5: =L5/1000/O5 -> 0.8535307 | Q5: 2 | R5: =0.5*G$8*C$4*C$2*(U5-C$5)*J5^2+L5*SIN(U5-C$1)-C$10*(C$14+G$12*(J$18-J5)/(J$18-J$4))*COS(T5) -> -2.6983806e-05 | S5: =DEGREES(T5) -> 9.8404246 | T5: 0.17174781 | U5: 0.11618227 | V5: =DEGREES(U5) -> 6.6567537 | W5: =-0.5*G$8*C$4*J5^2*((C$7+(C$2^2)*(U5-C$5)^2/(PI()*C$6))/SQRT(1-(J5/G$11)^2))+L5*COS(U5-C$1)-C$10*(C$14+G$12*(J$18-J5)/(J$18-J$4))*SIN(T5) -> -7.2510211e-06 | X5: =Q5 -> 2
A6: wydłużenie Oswalda | B6: Λe | C6: =Podsumowanie!B14 -> 5.134 | D6: - | J6: =J$4+Q5*G$14 -> 72.860228 | K6: =J6/G$11 -> 0.21410587 | L6: =G$9*(1-0.605*K6+0.725*K6^2) -> 8856.2689 | M6: =V6 -> 4.2612842 | N6: =S6 -> 10.433763 | O6: =J6*SIN(RADIANS(N6)) -> 13.194894 | P6: =L6/1000/O6 -> 0.67118911 | Q6: 3 | R6: =0.5*G$8*C$4*C$2*(U6-C$5)*J6^2+L6*SIN(U6-C$1)-C$10*(C$14+G$12*(J$18-J6)/(J$18-J$4))*COS(T6) -> 7.1416034e-05 | S6: =DEGREES(T6) -> 10.433763 | T6: 0.18210352 | U6: 0.074373439 | V6: =DEGREES(U6) -> 4.2612842 | W6: =-0.5*G$8*C$4*J6^2*((C$7+(C$2^2)*(U6-C$5)^2/(PI()*C$6))/SQRT(1-(J6/G$11)^2))+L6*COS(U6-C$1)-C$10*(C$14+G$12*(J$18-J6)/(J$18-J$4))*SIN(T6) -> -0.00037409974 | X6: =Q6 -> 3
A7: Minimalny współczynnik Cx z danych | B7: (Cx)min | C7: =Podsumowanie!B15 -> 0.01533 | D7: - | F7: h | G7: 0 | H7: m | J7: =J$4+Q6*G$14 -> 84.288543 | K7: =J7/G$11 -> 0.24768893 | L7: =G$9*(1-0.605*K7+0.725*K7^2) -> 8767.3427 | M7: =V7 -> 2.7681224 | N7: =S7 -> 10.603235 | O7: =J7*SIN(RADIANS(N7)) -> 15.50967 | P7: =L7/1000/O7 -> 0.56528236 | Q7: 4 | R7: =0.5*G$8*C$4*C$2*(U7-C$5)*J7^2+L7*SIN(U7-C$1)-C$10*(C$14+G$12*(J$18-J7)/(J$18-J$4))*COS(T7) -> 1.1682983e-05 | S7: =DEGREES(T7) -> 10.603235 | T7: 0.18506137 | U7: 0.048312851 | V7: =DEGREES(U7) -> 2.7681224 | W7: =-0.5*G$8*C$4*J7^2*((C$7+(C$2^2)*(U7-C$5)^2/(PI()*C$6))/SQRT(1-(J7/G$11)^2))+L7*COS(U7-C$1)-C$10*(C$14+G$12*(J$18-J7)/(J$18-J$4))*SIN(T7) -> -8.1873212e-05 | X7: =Q7 -> 4
A8: Obroty silnika | B8: ns | C8: =Podsumowanie!B12 -> 243.33333 | D8: 1/s | F8: ρh | G8: =C$9*(1-G7/44300)^4.256 -> 1.2255 | H8: kg/m3 | J8: =J$4+Q7*G$14 -> 95.716857 | K8: =J8/G$11 -> 0.28127199 | L8: =G$9*(1-0.605*K8+0.725*K8^2) -> 8694.4429 | M8: =V8 -> 1.778856 | N8: =S8 -> 10.49987 | O8: =J8*SIN(RADIANS(N8)) -> 17.442798 | P8: =L8/1000/O8 -> 0.49845459 | Q8: 5 | R8: =0.5*G$8*C$4*C$2*(U8-C$5)*J8^2+L8*SIN(U8-C$1)-C$10*(C$14+G$12*(J$18-J8)/(J$18-J$4))*COS(T8) -> 1.9264044e-06 | S8: =DEGREES(T8) -> 10.49987 | T8: 0.18325731 | U8: 0.031046894 | V8: =DEGREES(U8) -> 1.778856 | W8: =-0.5*G$8*C$4*J8^2*((C$7+(C$2^2)*(U8-C$5)^2/(PI()*C$6))/SQRT(1-(J8/G$11)^2))+L8*COS(U8-C$1)-C$10*(C$14+G$12*(J$18-J8)/(J$18-J$4))*SIN(T8) -> -1.7377821e-05 | X8: =Q8 -> 5
A9: gęstość powietrza przy ziemii | B9: ρ | C9: =Podsumowanie!B2 -> 1.2255 | D9: kg/m3 | F9: Ph | G9: =C$3*(G8/C$9)^0.85 -> 9800 | H9: N | J9: =J$4+Q8*G$14 -> 107.14517 | K9: =J9/G$11 -> 0.31485504 | L9: =G$9*(1-0.605*K9+0.725*K9^2) -> 8637.5694 | M9: =V9 -> 1.0918418 | N9: =S9 -> 10.193733 | O9: =J9*SIN(RADIANS(N9)) -> 18.962241 | P9: =L9/1000/O9 -> 0.45551416 | Q9: 6 | R9: =0.5*G$8*C$4*C$2*(U9-C$5)*J9^2+L9*SIN(U9-C$1)-C$10*(C$14+G$12*(J$18-J9)/(J$18-J$4))*COS(T9) -> 0.001221388 | S9: =DEGREES(T9) -> 10.193733 | T9: 0.17791421 | U9: 0.019056234 | V9: =DEGREES(U9) -> 1.0918418 | W9: =-0.5*G$8*C$4*J9^2*((C$7+(C$2^2)*(U9-C$5)^2/(PI()*C$6))/SQRT(1-(J9/G$11)^2))+L9*COS(U9-C$1)-C$10*(C$14+G$12*(J$18-J9)/(J$18-J$4))*SIN(T9) -> 5.9513782e-05 | X9: =Q9 -> 6
A10: Przyspieszenie grawitacyjne | B10: g | C10: =Podsumowanie!B1 -> 9.81 | D10: m/s2 | F10: Th | G10: =C$12-6.5*G7/1000 -> 288.15 | H10: K | J10: =J$4+Q9*G$14 -> 118.57349 | K10: =J10/G$11 -> 0.3484381 | L10: =G$9*(1-0.605*K10+0.725*K10^2) -> 8596.7222 | M10: =V10 -> 0.59656492 | N10: =S10 -> 9.7167485 | O10: =J10*SIN(RADIANS(N10)) -> 20.012538 | P10: =L10/1000/O10 -> 0.42956682 | Q10: 7 | R10: =0.5*G$8*C$4*C$2*(U10-C$5)*J10^2+L10*SIN(U10-C$1)-C$10*(C$14+G$12*(J$18-J10)/(J$18-J$4))*COS(T10) -> 0.00020676825 | S10: =DEGREES(T10) -> 9.7167485 | T10: 0.16958925 | U10: 0.010412022 | V10: =DEGREES(U10) -> 0.59656492 | W10: =-0.5*G$8*C$4*J10^2*((C$7+(C$2^2)*(U10-C$5)^2/(PI()*C$6))/SQRT(1-(J10/G$11)^2))+L10*COS(U10-C$1)-C$10*(C$14+G$12*(J$18-J10)/(J$18-J$4))*SIN(T10) -> 1.1551164e-05 | X10: =Q10 -> 7
A11: Prędkość dźwięku na poziomie morza | B11: a0 | C11: =Podsumowanie!B13 -> 340.3 | D11: m/s | F11: ah | G11: =C$11*SQRT(G10/C$12) -> 340.3 | H11: m/s | J11: =J$4+Q10*G$14 -> 130.0018 | K11: =J11/G$11 -> 0.38202116 | L11: =G$9*(1-0.605*K11+0.725*K11^2) -> 8571.9014 | M11: =V11 -> 0.22849923 | N11: =S11 -> 9.0804259 | O11: =J11*SIN(RADIANS(N11)) -> 20.516978 | P11: =L11/1000/O11 -> 0.41779551 | Q11: 8 | R11: =0.5*G$8*C$4*C$2*(U11-C$5)*J11^2+L11*SIN(U11-C$1)-C$10*(C$14+G$12*(J$18-J11)/(J$18-J$4))*COS(T11) -> 0.0001826776 | S11: =DEGREES(T11) -> 9.0804259 | T11: 0.15848333 | U11: 0.003988064 | V11: =DEGREES(U11) -> 0.22849923 | W11: =-0.5*G$8*C$4*J11^2*((C$7+(C$2^2)*(U11-C$5)^2/(PI()*C$6))/SQRT(1-(J11/G$11)^2))+L11*COS(U11-C$1)-C$10*(C$14+G$12*(J$18-J11)/(J$18-J$4))*SIN(T11) -> 7.3295168e-06 | X11: =Q11 -> 8
A12: Tempratura na poziomie morza | B12: T0 | C12: =Podsumowanie!B18 -> 288.15 | D12: K | F12: mp | G12: =C13 -> 996 | H12: kg | J12: =J$4+Q11*G$14 -> 141.43011 | K12: =J12/G$11 -> 0.41560421 | L12: =G$9*(1-0.605*K12+0.725*K12^2) -> 8563.107 | M12: =V12 -> -0.052017611 | N12: =S12 -> 8.2837074 | O12: =J12*SIN(RADIANS(N12)) -> 20.376517 | P12: =L12/1000/O12 -> 0.42024389 | Q12: 9 | R12: =0.5*G$8*C$4*C$2*(U12-C$5)*J12^2+L12*SIN(U12-C$1)-C$10*(C$14+G$12*(J$18-J12)/(J$18-J$4))*COS(T12) -> 6.0660266e-05 | S12: =DEGREES(T12) -> 8.2837074 | T12: 0.14457797 | U12: -0.00090787859 | V12: =DEGREES(U12) -> -0.052017611 | W12: =-0.5*G$8*C$4*J12^2*((C$7+(C$2^2)*(U12-C$5)^2/(PI()*C$6))/SQRT(1-(J12/G$11)^2))+L12*COS(U12-C$1)-C$10*(C$14+G$12*(J$18-J12)/(J$18-J$4))*SIN(T12) -> 2.5843001e-06 | X12: =Q12 -> 9
A13: Masa paliwa | B13: mp | C13: =Podsumowanie!B5 -> 996 | D13: kg | F13: dmp | G13: {=C$16*(G25-G7)*MIN(IF(P4:P18>0,P4:P18))} -> 24.733494 | H13: kg | J13: =J$4+Q12*G$14 -> 152.85843 | K13: =J13/G$11 -> 0.44918727 | L13: =G$9*(1-0.605*K13+0.725*K13^2) -> 8570.3389 | M13: =V13 -> -0.27042586 | N13: =S13 -> 7.3164116 | O13: =J13*SIN(RADIANS(N13)) -> 19.466325 | P13: =L13/1000/O13 -> 0.44026486 | Q13: 10 | R13: =0.5*G$8*C$4*C$2*(U13-C$5)*J13^2+L13*SIN(U13-C$1)-C$10*(C$14+G$12*(J$18-J13)/(J$18-J$4))*COS(T13) -> 1.5323822e-05 | S13: =DEGREES(T13) -> 7.3164116 | T13: 0.12769547 | U13: -0.0047198217 | V13: =DEGREES(U13) -> -0.27042586 | W13: =-0.5*G$8*C$4*J13^2*((C$7+(C$2^2)*(U13-C$5)^2/(PI()*C$6))/SQRT(1-(J13/G$11)^2))+L13*COS(U13-C$1)-C$10*(C$14+G$12*(J$18-J13)/(J$18-J$4))*SIN(T13) -> 8.4160047e-07 | X13: =Q13 -> 10
A14: Masa pełnego samolotu bez paliwa | B14: mmin | C14: =Podsumowanie!B4-Podsumowanie!B5 -> 2844 | D14: kg | F14: v | G14: =(J18-J4)/Q17 -> 11.428314 | H14: m/s | J14: =J$4+Q13*G$14 -> 164.28674 | K14: =J14/G$11 -> 0.48277033 | L14: =G$9*(1-0.605*K14+0.725*K14^2) -> 8593.5971 | M14: =V14 -> -0.44364242 | N14: =S14 -> 6.1604402 | O14: =J14*SIN(RADIANS(N14)) -> 17.63009 | P14: =L14/1000/O14 -> 0.48743921 | Q14: 11 | R14: =0.5*G$8*C$4*C$2*(U14-C$5)*J14^2+L14*SIN(U14-C$1)-C$10*(C$14+G$12*(J$18-J14)/(J$18-J$4))*COS(T14) -> 4.6889218e-06 | S14: =DEGREES(T14) -> 6.1604402 | T14: 0.10751996 | U14: -0.007743021 | V14: =DEGREES(U14) -> -0.44364242 | W14: =-0.5*G$8*C$4*J14^2*((C$7+(C$2^2)*(U14-C$5)^2/(PI()*C$6))/SQRT(1-(J14/G$11)^2))+L14*COS(U14-C$1)-C$10*(C$14+G$12*(J$18-J14)/(J$18-J$4))*SIN(T14) -> 1.9493154e-07 | X14: =Q14 -> 11
A15: maksymalny współczynnik siły nośnej | B15: Czmax | C15: =Podsumowanie!B16 -> 1.405 | D15: - | J15: =J$4+Q14*G$14 -> 175.71506 | K15: =J15/G$11 -> 0.51635339 | L15: =G$9*(1-0.605*K15+0.725*K15^2) -> 8632.8817 | M15: =V15 -> -0.58327296 | N15: =S15 -> 4.7895935 | O15: =J15*SIN(RADIANS(N15)) -> 14.671654 | P15: =L15/1000/O15 -> 0.58840549 | Q15: 12 | R15: =0.5*G$8*C$4*C$2*(U15-C$5)*J15^2+L15*SIN(U15-C$1)-C$10*(C$14+G$12*(J$18-J15)/(J$18-J$4))*COS(T15) -> 1.6487709e-05 | S15: =DEGREES(T15) -> 4.7895935 | T15: 0.083594176 | U15: -0.010180034 | V15: =DEGREES(U15) -> -0.58327296 | W15: =-0.5*G$8*C$4*J15^2*((C$7+(C$2^2)*(U15-C$5)^2/(PI()*C$6))/SQRT(1-(J15/G$11)^2))+L15*COS(U15-C$1)-C$10*(C$14+G$12*(J$18-J15)/(J$18-J$4))*SIN(T15) -> 1.2109554e-06 | X15: =Q15 -> 12
A16: Jednostkowe zużycie paliwa | B16: qe | C16: =Podsumowanie!B32 -> 0.0296 | D16: kg/kNs | J16: =J$4+Q15*G$14 -> 187.14337 | K16: =J16/G$11 -> 0.54993644 | L16: =G$9*(1-0.605*K16+0.725*K16^2) -> 8688.1926 | M16: =V16 -> -0.69750444 | N16: =S16 -> 3.1682435 | O16: =J16*SIN(RADIANS(N16)) -> 10.343059 | P16: =L16/1000/O16 -> 0.84000219 | Q16: 13 | R16: =0.5*G$8*C$4*C$2*(U16-C$5)*J16^2+L16*SIN(U16-C$1)-C$10*(C$14+G$12*(J$18-J16)/(J$18-J$4))*COS(T16) -> 1.4688812e-06 | S16: =DEGREES(T16) -> 3.1682435 | T16: 0.05529628 | U16: -0.012173749 | V16: =DEGREES(U16) -> -0.69750444 | W16: =-0.5*G$8*C$4*J16^2*((C$7+(C$2^2)*(U16-C$5)^2/(PI()*C$6))/SQRT(1-(J16/G$11)^2))+L16*COS(U16-C$1)-C$10*(C$14+G$12*(J$18-J16)/(J$18-J$4))*SIN(T16) -> 6.6968141e-08 | X16: =Q16 -> 13
J17: =J$4+Q16*G$14 -> 198.57169 | K17: =J17/G$11 -> 0.5835195 | L17: =G$9*(1-0.605*K17+0.725*K17^2) -> 8759.5299 | M17: =V17 -> -0.79226516 | N17: =S17 -> 1.2487325 | O17: =J17*SIN(RADIANS(N17)) -> 4.3274266 | P17: =L17/1000/O17 -> 2.0241891 | Q17: 14 | R17: =0.5*G$8*C$4*C$2*(U17-C$5)*J17^2+L17*SIN(U17-C$1)-C$10*(C$14+G$12*(J$18-J17)/(J$18-J$4))*COS(T17) -> 1.6044214e-07 | S17: =DEGREES(T17) -> 1.2487325 | T17: 0.021794493 | U17: -0.013827636 | V17: =DEGREES(U17) -> -0.79226516 | W17: =-0.5*G$8*C$4*J17^2*((C$7+(C$2^2)*(U17-C$5)^2/(PI()*C$6))/SQRT(1-(J17/G$11)^2))+L17*COS(U17-C$1)-C$10*(C$14+G$12*(J$18-J17)/(J$18-J$4))*SIN(T17) -> 1.9676918e-09 | X17: =Q17 -> 14
J18: 210 | K18: =J18/G$11 -> 0.61710256 | L18: =G$9*(1-0.605*K18+0.725*K18^2) -> 8846.8935 | M18: =V18 -> -0.871964 | N18: =S18 -> -1.0330159 | O18: =J18*SIN(RADIANS(N18)) -> -3.7859961 | P18: =L18/1000/O18 -> -2.3367413 | Q18: 15 | R18: =0.5*G$8*C$4*C$2*(U18-C$5)*J18^2+L18*SIN(U18-C$1)-C$10*(C$14+G$12*(J$18-J18)/(J$18-J$4))*COS(T18) -> 0.00034585471 | S18: =DEGREES(T18) -> -1.0330159 | T18: -0.018029529 | U18: -0.015218643 | V18: =DEGREES(U18) -> -0.871964 | W18: =-0.5*G$8*C$4*J18^2*((C$7+(C$2^2)*(U18-C$5)^2/(PI()*C$6))/SQRT(1-(J18/G$11)^2))+L18*COS(U18-C$1)-C$10*(C$14+G$12*(J$18-J18)/(J$18-J$4))*SIN(T18) -> -3.5284632e-05 | X18: =Q18 -> 15
J20: Metoda ciągu, zmienna masa, h=2km, ściśliwość
J21: V [m/s] | K21: Ma | L21: Ps [N] | M21: α [°] | N21: γ [°] | O21: w [m/s] | P21: Ps/w | R21: γ | S21: [°] | T21: [rad] | U21: [rad] | V21: [°] | W21: α
J22: =SQRT(2*(C$14+G30)*C$10/C$4/C$15/G26) -> 54.991166 | K22: =J22/G$29 -> 0.16536954 | L22: =G$27*(1-0.605*K22+0.725*K22^2) -> 7626.5464 | M22: =V22 -> 10.967536 | N22: =S22 -> 6.2244595 | O22: =J22*SIN(RADIANS(N22)) -> 5.9623483 | P22: =L22/1000/O22 -> 1.2791179 | Q22: 1 | R22: =0.5*G$26*C$4*C$2*(U22-C$5)*J22^2+L22*SIN(U22-C$1)-C$10*(C$14+G$30*(J$36-J22)/(J$36-J$22))*COS(T22) -> -0.00011439241 | S22: =DEGREES(T22) -> 6.2244595 | T22: 0.10863731 | U22: 0.19141962 | V22: =DEGREES(U22) -> 10.967536 | W22: =-0.5*G$26*C$4*J22^2*((C$7+(C$2^2)*(U22-C$5)^2/(PI()*C$6))/SQRT(1-(J22/G$29)^2))+L22*COS(U22-C$1)-C$10*(C$14+G$30*(J$36-J22)/(J$36-J$22))*SIN(T22) -> -4.6534722e-05 | X22: =Q22 -> 1
J23: =J$22+Q22*G$32 -> 66.063225 | K23: =J23/G$29 -> 0.19866546 | L23: =G$27*(1-0.605*K23+0.725*K23^2) -> 7532.3823 | M23: =V23 -> 7.1021783 | N23: =S23 -> 7.5043408 | O23: =J23*SIN(RADIANS(N23)) -> 8.6279434 | P23: =L23/1000/O23 -> 0.87302176 | Q23: 2 | R23: =0.5*G$26*C$4*C$2*(U23-C$5)*J23^2+L23*SIN(U23-C$1)-C$10*(C$14+G$30*(J$36-J23)/(J$36-J$22))*COS(T23) -> -1.5690755e-05 | S23: =DEGREES(T23) -> 7.5043408 | T23: 0.13097545 | U23: 0.1239564 | V23: =DEGREES(U23) -> 7.1021783 | W23: =-0.5*G$26*C$4*J23^2*((C$7+(C$2^2)*(U23-C$5)^2/(PI()*C$6))/SQRT(1-(J23/G$29)^2))+L23*COS(U23-C$1)-C$10*(C$14+G$30*(J$36-J23)/(J$36-J$22))*SIN(T23) -> -4.2300762e-06 | X23: =Q23 -> 2
J24: =J$22+Q23*G$32 -> 77.135285 | K24: =J24/G$29 -> 0.23196138 | L24: =G$27*(1-0.605*K24+0.725*K24^2) -> 7451.5471 | M24: =V24 -> 4.7581989 | N24: =S24 -> 8.1313793 | O24: =J24*SIN(RADIANS(N24)) -> 10.910278 | P24: =L24/1000/O24 -> 0.68298415 | Q24: 3 | R24: =0.5*G$26*C$4*C$2*(U24-C$5)*J24^2+L24*SIN(U24-C$1)-C$10*(C$14+G$30*(J$36-J24)/(J$36-J$22))*COS(T24) -> 5.3297867e-05 | S24: =DEGREES(T24) -> 8.1313793 | T24: 0.14191934 | U24: 0.083046238 | V24: =DEGREES(U24) -> 4.7581989 | W24: =-0.5*G$26*C$4*J24^2*((C$7+(C$2^2)*(U24-C$5)^2/(PI()*C$6))/SQRT(1-(J24/G$29)^2))+L24*COS(U24-C$1)-C$10*(C$14+G$30*(J$36-J24)/(J$36-J$22))*SIN(T24) -> -0.00027104005 | X24: =Q24 -> 3
F25: h | G25: 2000 | H25: m | J25: =J$22+Q24*G$32 -> 88.207344 | K25: =J25/G$29 -> 0.2652573 | L25: =G$27*(1-0.605*K25+0.725*K25^2) -> 7384.0409 | M25: =V25 -> 3.2380115 | N25: =S25 -> 8.3810081 | O25: =J25*SIN(RADIANS(N25)) -> 12.856671 | P25: =L25/1000/O25 -> 0.57433538 | Q25: 4 | R25: =0.5*G$26*C$4*C$2*(U25-C$5)*J25^2+L25*SIN(U25-C$1)-C$10*(C$14+G$30*(J$36-J25)/(J$36-J$22))*COS(T25) -> 1.2606892e-05 | S25: =DEGREES(T25) -> 8.3810081 | T25: 0.14627619 | U25: 0.056513962 | V25: =DEGREES(U25) -> 3.2380115 | W25: =-0.5*G$26*C$4*J25^2*((C$7+(C$2^2)*(U25-C$5)^2/(PI()*C$6))/SQRT(1-(J25/G$29)^2))+L25*COS(U25-C$1)-C$10*(C$14+G$30*(J$36-J25)/(J$36-J$22))*SIN(T25) -> -8.3095101e-05 | X25: =Q25 -> 4
F26: ρh | G26: =C$9*(1-G25/44300)^4.256 -> 1.0067547 | H26: kg/m3 | J26: =J$22+Q25*G$32 -> 99.279404 | K26: =J26/G$29 -> 0.29855322 | L26: =G$27*(1-0.605*K26+0.725*K26^2) -> 7329.8636 | M26: =V26 -> 2.1999439 | N26: =S26 -> 8.3825959 | O26: =J26*SIN(RADIANS(N26)) -> 14.473202 | P26: =L26/1000/O26 -> 0.50644382 | Q26: 5 | R26: =0.5*G$26*C$4*C$2*(U26-C$5)*J26^2+L26*SIN(U26-C$1)-C$10*(C$14+G$30*(J$36-J26)/(J$36-J$22))*COS(T26) -> 2.6576017e-06 | S26: =DEGREES(T26) -> 8.3825959 | T26: 0.1463039 | U26: 0.038396264 | V26: =DEGREES(U26) -> 2.1999439 | W26: =-0.5*G$26*C$4*J26^2*((C$7+(C$2^2)*(U26-C$5)^2/(PI()*C$6))/SQRT(1-(J26/G$29)^2))+L26*COS(U26-C$1)-C$10*(C$14+G$30*(J$36-J26)/(J$36-J$22))*SIN(T26) -> -2.2083884e-05 | X26: =Q26 -> 5
F27: Ph | G27: =C$3*(G26/C$9)^0.85 -> 8291.7246 | H27: N | J27: =J$22+Q26*G$32 -> 110.35146 | K27: =J27/G$29 -> 0.33184914 | L27: =G$27*(1-0.605*K27+0.725*K27^2) -> 7289.0151 | M27: =V27 -> 1.4617217 | N27: =S27 -> 8.2002055 | O27: =J27*SIN(RADIANS(N27)) -> 15.739703 | P27: =L27/1000/O27 -> 0.46309737 | Q27: 6 | R27: =0.5*G$26*C$4*C$2*(U27-C$5)*J27^2+L27*SIN(U27-C$1)-C$10*(C$14+G$30*(J$36-J27)/(J$36-J$22))*COS(T27) -> 0.0017719482 | S27: =DEGREES(T27) -> 8.2002055 | T27: 0.14312058 | U27: 0.025511856 | V27: =DEGREES(U27) -> 1.4617217 | W27: =-0.5*G$26*C$4*J27^2*((C$7+(C$2^2)*(U27-C$5)^2/(PI()*C$6))/SQRT(1-(J27/G$29)^2))+L27*COS(U27-C$1)-C$10*(C$14+G$30*(J$36-J27)/(J$36-J$22))*SIN(T27) -> 8.9538288e-05 | X27: =Q27 -> 6
F28: Th | G28: =C$12-6.5*G25/1000 -> 275.15 | H28: K | J28: =J$22+Q27*G$32 -> 121.42352 | K28: =J28/G$29 -> 0.36514506 | L28: =G$27*(1-0.605*K28+0.725*K28^2) -> 7261.4957 | M28: =V28 -> 0.91925993 | N28: =S28 -> 7.8652795 | O28: =J28*SIN(RADIANS(N28)) -> 16.616115 | P28: =L28/1000/O28 -> 0.43701524 | Q28: 7 | R28: =0.5*G$26*C$4*C$2*(U28-C$5)*J28^2+L28*SIN(U28-C$1)-C$10*(C$14+G$30*(J$36-J28)/(J$36-J$22))*COS(T28) -> 0.0006650173 | S28: =DEGREES(T28) -> 7.8652795 | T28: 0.13727502 | U28: 0.016044112 | V28: =DEGREES(U28) -> 0.91925993 | W28: =-0.5*G$26*C$4*J28^2*((C$7+(C$2^2)*(U28-C$5)^2/(PI()*C$6))/SQRT(1-(J28/G$29)^2))+L28*COS(U28-C$1)-C$10*(C$14+G$30*(J$36-J28)/(J$36-J$22))*SIN(T28) -> 3.0213223e-05 | X28: =Q28 -> 7
F29: ah | G29: =C$11*SQRT(G28/C$12) -> 332.53503 | H29: m/s | J29: =J$22+Q28*G$32 -> 132.49558 | K29: =J29/G$29 -> 0.39844098 | L29: =G$27*(1-0.605*K29+0.725*K29^2) -> 7247.3051 | M29: =V29 -> 0.50975789 | N29: =S29 -> 7.3910823 | O29: =J29*SIN(RADIANS(N29)) -> 17.044397 | P29: =L29/1000/O29 -> 0.42520161 | Q29: 8 | R29: =0.5*G$26*C$4*C$2*(U29-C$5)*J29^2+L29*SIN(U29-C$1)-C$10*(C$14+G$30*(J$36-J29)/(J$36-J$22))*COS(T29) -> 0.000167055 | S29: =DEGREES(T29) -> 7.3910823 | T29: 0.12899872 | U29: 0.0088969536 | V29: =DEGREES(U29) -> 0.50975789 | W29: =-0.5*G$26*C$4*J29^2*((C$7+(C$2^2)*(U29-C$5)^2/(PI()*C$6))/SQRT(1-(J29/G$29)^2))+L29*COS(U29-C$1)-C$10*(C$14+G$30*(J$36-J29)/(J$36-J$22))*SIN(T29) -> 8.2163397e-06 | X29: =Q29 -> 8
F30: mp | G30: =G12-G13 -> 971.26651 | H30: kg | J30: =J$22+Q29*G$32 -> 143.56764 | K30: =J30/G$29 -> 0.4317369 | L30: =G$27*(1-0.605*K30+0.725*K30^2) -> 7246.4434 | M30: =V30 -> 0.1935634 | N30: =S30 -> 6.7794358 | O30: =J30*SIN(RADIANS(N30)) -> 16.947812 | P30: =L30/1000/O30 -> 0.42757399 | Q30: 9 | R30: =0.5*G$26*C$4*C$2*(U30-C$5)*J30^2+L30*SIN(U30-C$1)-C$10*(C$14+G$30*(J$36-J30)/(J$36-J$22))*COS(T30) -> 0.00010283557 | S30: =DEGREES(T30) -> 6.7794358 | T30: 0.11832348 | U30: 0.0033783186 | V30: =DEGREES(U30) -> 0.1935634 | W30: =-0.5*G$26*C$4*J30^2*((C$7+(C$2^2)*(U30-C$5)^2/(PI()*C$6))/SQRT(1-(J30/G$29)^2))+L30*COS(U30-C$1)-C$10*(C$14+G$30*(J$36-J30)/(J$36-J$22))*SIN(T30) -> 4.251594e-06 | X30: =Q30 -> 9
F31: dmp | G31: {=C$16*(G43-G25)*MIN(IF(P22:P36>0,P22:P36))} -> 25.171935 | H31: kg | J31: =J$22+Q30*G$32 -> 154.6397 | K31: =J31/G$29 -> 0.46503282 | L31: =G$27*(1-0.605*K31+0.725*K31^2) -> 7258.9107 | M31: =V31 -> -0.055331161 | N31: =S31 -> 6.0238367 | O31: =J31*SIN(RADIANS(N31)) -> 16.228231 | P31: =L31/1000/O31 -> 0.44730141 | Q31: 10 | R31: =0.5*G$26*C$4*C$2*(U31-C$5)*J31^2+L31*SIN(U31-C$1)-C$10*(C$14+G$30*(J$36-J31)/(J$36-J$22))*COS(T31) -> 2.6008747e-06 | S31: =DEGREES(T31) -> 6.0238367 | T31: 0.10513578 | U31: -0.00096571094 | V31: =DEGREES(U31) -> -0.055331161 | W31: =-0.5*G$26*C$4*J31^2*((C$7+(C$2^2)*(U31-C$5)^2/(PI()*C$6))/SQRT(1-(J31/G$29)^2))+L31*COS(U31-C$1)-C$10*(C$14+G$30*(J$36-J31)/(J$36-J$22))*SIN(T31) -> 8.7025683e-07 | X31: =Q31 -> 10
F32: v | G32: =(J36-J22)/Q35 -> 11.07206 | H32: m/s | J32: =J$22+Q31*G$32 -> 165.71176 | K32: =J32/G$29 -> 0.49832874 | L32: =G$27*(1-0.605*K32+0.725*K32^2) -> 7284.7069 | M32: =V32 -> -0.25454732 | N32: =S32 -> 5.1106552 | O32: =J32*SIN(RADIANS(N32)) -> 14.761525 | P32: =L32/1000/O32 -> 0.49349283 | Q32: 11 | R32: =0.5*G$26*C$4*C$2*(U32-C$5)*J32^2+L32*SIN(U32-C$1)-C$10*(C$14+G$30*(J$36-J32)/(J$36-J$22))*COS(T32) -> 6.0056263e-06 | S32: =DEGREES(T32) -> 5.1106552 | T32: 0.08919776 | U32: -0.0044426888 | V32: =DEGREES(U32) -> -0.25454732 | W32: =-0.5*G$26*C$4*J32^2*((C$7+(C$2^2)*(U32-C$5)^2/(PI()*C$6))/SQRT(1-(J32/G$29)^2))+L32*COS(U32-C$1)-C$10*(C$14+G$30*(J$36-J32)/(J$36-J$22))*SIN(T32) -> 4.458193e-07 | X32: =Q32 -> 11
J33: =J$22+Q32*G$32 -> 176.78382 | K33: =J33/G$29 -> 0.53162466 | L33: =G$27*(1-0.605*K33+0.725*K33^2) -> 7323.832 | M33: =V33 -> -0.41636705 | N33: =S33 -> 4.0191204 | O33: =J33*SIN(RADIANS(N33)) -> 12.390667 | P33: =L33/1000/O33 -> 0.59107649 | Q33: 12 | R33: =0.5*G$26*C$4*C$2*(U33-C$5)*J33^2+L33*SIN(U33-C$1)-C$10*(C$14+G$30*(J$36-J33)/(J$36-J$22))*COS(T33) -> 2.9718285e-07 | S33: =DEGREES(T33) -> 4.0191204 | T33: 0.070146885 | U33: -0.007266976 | V33: =DEGREES(U33) -> -0.41636705 | W33: =-0.5*G$26*C$4*J33^2*((C$7+(C$2^2)*(U33-C$5)^2/(PI()*C$6))/SQRT(1-(J33/G$29)^2))+L33*COS(U33-C$1)-C$10*(C$14+G$30*(J$36-J33)/(J$36-J$22))*SIN(T33) -> 1.6730155e-08 | X33: =Q33 -> 12
J34: =J$22+Q33*G$32 -> 187.85588 | K34: =J34/G$29 -> 0.56492058 | L34: =G$27*(1-0.605*K34+0.725*K34^2) -> 7376.286 | M34: =V34 -> -0.54956986 | N34: =S34 -> 2.7203154 | O34: =J34*SIN(RADIANS(N34)) -> 8.9157574 | P34: =L34/1000/O34 -> 0.82733139 | Q34: 13 | R34: =0.5*G$26*C$4*C$2*(U34-C$5)*J34^2+L34*SIN(U34-C$1)-C$10*(C$14+G$30*(J$36-J34)/(J$36-J$22))*COS(T34) -> 1.1040393e-06 | S34: =DEGREES(T34) -> 2.7203154 | T34: 0.04747846 | U34: -0.0095918036 | V34: =DEGREES(U34) -> -0.54956986 | W34: =-0.5*G$26*C$4*J34^2*((C$7+(C$2^2)*(U34-C$5)^2/(PI()*C$6))/SQRT(1-(J34/G$29)^2))+L34*COS(U34-C$1)-C$10*(C$14+G$30*(J$36-J34)/(J$36-J$22))*SIN(T34) -> 3.9735596e-08 | X34: =Q34 -> 13
J35: =J$22+Q34*G$32 -> 198.92794 | K35: =J35/G$29 -> 0.5982165 | L35: =G$27*(1-0.605*K35+0.725*K35^2) -> 7442.0689 | M35: =V35 -> -0.66058128 | N35: =S35 -> 1.1750941 | O35: =J35*SIN(RADIANS(N35)) -> 4.0795791 | P35: =L35/1000/O35 -> 1.8242247 | Q35: 14 | R35: =0.5*G$26*C$4*C$2*(U35-C$5)*J35^2+L35*SIN(U35-C$1)-C$10*(C$14+G$30*(J$36-J35)/(J$36-J$22))*COS(T35) -> 1.1533848e-07 | S35: =DEGREES(T35) -> 1.1750941 | T35: 0.020509261 | U35: -0.011529318 | V35: =DEGREES(U35) -> -0.66058128 | W35: =-0.5*G$26*C$4*J35^2*((C$7+(C$2^2)*(U35-C$5)^2/(PI()*C$6))/SQRT(1-(J35/G$29)^2))+L35*COS(U35-C$1)-C$10*(C$14+G$30*(J$36-J35)/(J$36-J$22))*SIN(T35) -> 1.0383019e-09 | X35: =Q35 -> 14
J36: 210 | K36: =J36/G$29 -> 0.63151242 | L36: =G$27*(1-0.605*K36+0.725*K36^2) -> 7521.1808 | M36: =V36 -> -0.75421648 | N36: =S36 -> -0.66947191 | O36: =J36*SIN(RADIANS(N36)) -> -2.4536869 | P36: =L36/1000/O36 -> -3.065257 | Q36: 15 | R36: =0.5*G$26*C$4*C$2*(U36-C$5)*J36^2+L36*SIN(U36-C$1)-C$10*(C$14+G$30*(J$36-J36)/(J$36-J$22))*COS(T36) -> 0.00012844438 | S36: =DEGREES(T36) -> -0.66947191 | T36: -0.011684489 | U36: -0.013163561 | V36: =DEGREES(U36) -> -0.75421648 | W36: =-0.5*G$26*C$4*J36^2*((C$7+(C$2^2)*(U36-C$5)^2/(PI()*C$6))/SQRT(1-(J36/G$29)^2))+L36*COS(U36-C$1)-C$10*(C$14+G$30*(J$36-J36)/(J$36-J$22))*SIN(T36) -> -1.2168876e-05 | X36: =Q36 -> 15
J38: Metoda ciągu, zmienna masa, h=4km, ściśliwość
J39: V [m/s] | K39: Ma | L39: Ps [N] | M39: α [°] | N39: γ [°] | O39: w [m/s] | P39: Ps/w | R39: γ | S39: [°] | T39: [rad] | U39: [rad] | V39: [°] | W39: α
J40: =SQRT(2*(C$14+G48)*C$10/C$4/C$15/G44) -> 60.760127 | K40: =J40/G$47 -> 0.18719365 | L40: =G$45*(1-0.605*K40+0.725*K40^2) -> 6347.6816 | M40: =V40 -> 11.077985 | N40: =S40 -> 4.2434963 | O40: =J40*SIN(RADIANS(N40)) -> 4.4959633 | P40: =L40/1000/O40 -> 1.4118624 | Q40: 1 | R40: =0.5*G$44*C$4*C$2*(U40-C$5)*J40^2+L40*SIN(U40-C$1)-C$10*(C$14+G$48*(J$54-J40)/(J$54-J$40))*COS(T40) -> 0.00022519968 | S40: =DEGREES(T40) -> 4.2434963 | T40: 0.074062983 | U40: 0.19334731 | V40: =DEGREES(U40) -> 11.077985 | W40: =-0.5*G$44*C$4*J40^2*((C$7+(C$2^2)*(U40-C$5)^2/(PI()*C$6))/SQRT(1-(J40/G$47)^2))+L40*COS(U40-C$1)-C$10*(C$14+G$48*(J$54-J40)/(J$54-J$40))*SIN(T40) -> 7.9344208e-05 | X40: =Q40 -> 1
J41: =J$40+Q40*G$50 -> 71.420118 | K41: =J41/G$47 -> 0.22003562 | L41: =G$45*(1-0.605*K41+0.725*K41^2) -> 6276.887 | M41: =V41 -> 7.5428023 | N41: =S41 -> 5.4266228 | O41: =J41*SIN(RADIANS(N41)) -> 6.7542646 | P41: =L41/1000/O41 -> 0.92932204 | Q41: 2 | R41: =0.5*G$44*C$4*C$2*(U41-C$5)*J41^2+L41*SIN(U41-C$1)-C$10*(C$14+G$48*(J$54-J41)/(J$54-J$40))*COS(T41) -> 0.00012027436 | S41: =DEGREES(T41) -> 5.4266228 | T41: 0.094712436 | U41: 0.13164674 | V41: =DEGREES(U41) -> 7.5428023 | W41: =-0.5*G$44*C$4*J41^2*((C$7+(C$2^2)*(U41-C$5)^2/(PI()*C$6))/SQRT(1-(J41/G$47)^2))+L41*COS(U41-C$1)-C$10*(C$14+G$48*(J$54-J41)/(J$54-J$40))*SIN(T41) -> -0.0004270306 | X41: =Q41 -> 2
J42: =J$40+Q41*G$50 -> 82.080109 | K42: =J42/G$47 -> 0.2528776 | L42: =G$45*(1-0.605*K42+0.725*K42^2) -> 6216.976 | M42: =V42 -> 5.2804193 | N42: =S42 -> 6.0696449 | O42: =J42*SIN(RADIANS(N42)) -> 8.6789258 | P42: =L42/1000/O42 -> 0.71633012 | Q42: 3 | R42: =0.5*G$44*C$4*C$2*(U42-C$5)*J42^2+L42*SIN(U42-C$1)-C$10*(C$14+G$48*(J$54-J42)/(J$54-J$40))*COS(T42) -> 0.0019949765 | S42: =DEGREES(T42) -> 6.0696449 | T42: 0.10593529 | U42: 0.092160703 | V42: =DEGREES(U42) -> 5.2804193 | W42: =-0.5*G$44*C$4*J42^2*((C$7+(C$2^2)*(U42-C$5)^2/(PI()*C$6))/SQRT(1-(J42/G$47)^2))+L42*COS(U42-C$1)-C$10*(C$14+G$48*(J$54-J42)/(J$54-J$40))*SIN(T42) -> 0.00026220302 | X42: =Q42 -> 3
...

Sheet h=0km
A1: wysokość lotu | B1: h | C1: 0 | D1: m | G1: Metoda ciągu, m=mśr, h=0km
A2: Współczynnik kierunkowy prostej Cz(a) | B2: a∞ | C2: =Podsumowanie!B17 -> 6.231 | D2: 1/rad | G2: V [m/s] | H2: Ma | I2: Ps [N] | J2: α [°] | K2: γ [°] | L2: w [m/s]
A3: Ciąg silnika przy ziemii | B3: Pr-0 | C3: =Podsumowanie!B10 -> 9800 | D3: N | G3: =SQRT(2*C$11/C$4/C$16/C$15) -> 45.931239 | H3: =G3/C$19 -> 0.13497279 | I3: =C$17*(1-0.605*H3+0.725*H3^2) -> 9129.1828 | J3: =OFFSET(D22,A22-2,0,1,1) -> 10.628885 | K3: =OFFSET(D21,A22-2,0,1,1) -> 11.285434 | L3: =G3*SIN(RADIANS(K3)) -> 8.9885985
A4: Powierzchnia nośna | B4: S | C4: =Podsumowanie!B3 -> 17.5 | D4: m2 | G4: 63 | H4: =G4/C$19 -> 0.18513077 | I4: =C$17*(1-0.605*H4+0.725*H4^2) -> 8945.8722 | J4: =OFFSET(D23,A23-2,0,1,1) -> 5.144176 | K4: =OFFSET(D22,A23-2,0,1,1) -> 12.519935 | L4: =G4*SIN(RADIANS(K4)) -> 13.657095
A5: Kąt zerowej siły nośnej | B5: α0 | C5: =Podsumowanie!B31 -> -0.024783675 | D5: rad | G5: 77 | H5: =G5/C$19 -> 0.22627094 | I5: =C$17*(1-0.605*H5+0.725*H5^2) -> 8822.2052 | J5: =OFFSET(D24,A24-2,0,1,1) -> 3.023263 | K5: =OFFSET(D23,A24-2,0,1,1) -> 12.484886 | L5: =G5*SIN(RADIANS(K5)) -> 16.646019
A6: masa samolotu | B6: m | C6: =Podsumowanie!B7 -> 3240 | D6: kg | G6: 90 | H6: =G6/C$19 -> 0.26447252 | I6: =C$17*(1-0.605*H6+0.725*H6^2) -> 8728.9067 | J6: =OFFSET(D25,A25-2,0,1,1) -> 1.8568808 | K6: =OFFSET(D24,A25-2,0,1,1) -> 12.054829 | L6: =G6*SIN(RADIANS(K6)) -> 18.796286
A7: wydłużenie Oswalda | B7: Λe | C7: =Podsumowanie!B14 -> 5.134 | D7: - | G7: 104 | H7: =G7/C$19 -> 0.30561269 | I7: =C$17*(1-0.605*H7+0.725*H7^2) -> 8651.6231 | J7: =OFFSET(D26,A26-2,0,1,1) -> 1.050314 | K7: =OFFSET(D25,A26-2,0,1,1) -> 11.320569 | L7: =G7*SIN(RADIANS(K7)) -> 20.41501
A8: Minimalny współczynnik Cx z danych | B8: (Cx)min | C8: =Podsumowanie!B15 -> 0.01533 | D8: - | G8: 117 | H8: =G8/C$19 -> 0.34381428 | I8: =C$17*(1-0.605*H8+0.725*H8^2) -> 8601.3948 | J8: =OFFSET(D27,A27-2,0,1,1) -> 0.54236425 | K8: =OFFSET(D26,A27-2,0,1,1) -> 10.447041 | L8: =G8*SIN(RADIANS(K8)) -> 21.215215
A9: Obroty silnika | B9: ns | C9: =Podsumowanie!B12 -> 243.33333 | D9: 1/s | G9: 130 | H9: =G9/C$19 -> 0.38201587 | I9: =C$17*(1-0.605*H9+0.725*H9^2) -> 8571.9041 | J9: =OFFSET(D28,A28-2,0,1,1) -> 0.17729576 | K9: =OFFSET(D27,A28-2,0,1,1) -> 9.412486 | L9: =G9*SIN(RADIANS(K9)) -> 21.260324
A10: gęstość powietrza przy ziemii | B10: ρ | C10: =Podsumowanie!B2 -> 1.2255 | D10: kg/m3 | G10: 144 | H10: =G10/C$19 -> 0.42315604 | I10: =C$17*(1-0.605*H10+0.725*H10^2) -> 8563.3365 | J10: =OFFSET(D29,A29-2,0,1,1) -> -0.11190394 | K10: =OFFSET(D28,A29-2,0,1,1) -> 8.1240744 | L10: =G10*SIN(RADIANS(K10)) -> 20.349678
A11: Ciężar samolotu | B11: Q | C11: =Podsumowanie!B8 -> 31784.4 | D11: N | G11: 158 | H11: =G11/C$19 -> 0.46429621 | I11: =C$17*(1-0.605*H11+0.725*H11^2) -> 8578.8195 | J11: =OFFSET(D30,A30-2,0,1,1) -> -0.32870527 | K11: =OFFSET(D29,A30-2,0,1,1) -> 6.6470959 | L11: =G11*SIN(RADIANS(K11)) -> 18.289075
A12: Prędkość dźwięku na poziomie morza | B12: a0 | C12: =Podsumowanie!B13 -> 340.3 | D12: m/s | G12: 171 | H12: =G12/C$19 -> 0.5024978 | I12: =C$17*(1-0.605*H12+0.725*H12^2) -> 8614.7317 | J12: =OFFSET(D31,A31-2,0,1,1) -> -0.48502182 | K12: =OFFSET(D30,A31-2,0,1,1) -> 5.0895245 | L12: =G12*SIN(RADIANS(K12)) -> 15.169784
A13: Tempratura na poziomie morza | B13: T0 | C13: =Podsumowanie!B18 -> 288.15 | D13: K | G13: 185 | H13: =G13/C$19 -> 0.54363797 | I13: =C$17*(1-0.605*H13+0.725*H13^2) -> 8676.5981 | J13: =OFFSET(D32,A32-2,0,1,1) -> -0.61871805 | K13: =OFFSET(D31,A32-2,0,1,1) -> 3.1816993 | L13: =G13*SIN(RADIANS(K13)) -> 10.26798
A14: kąt pochylenia osi silnika fi | B14: φ | C14: =Podsumowanie!B30 -> 0.017453293 | D14: rad | G14: 200 | H14: =G14/C$19 -> 0.58771672 | I14: =C$17*(1-0.605*H14+0.725*H14^2) -> 8769.5723 | J14: =OFFSET(D33,A33-2,0,1,1) -> -0.73299149 | K14: =OFFSET(D32,A33-2,0,1,1) -> 0.82007733 | L14: =G14*SIN(RADIANS(K14)) -> 2.8625122
A15: maksymalny współczynnik siły nośnej | B15: Czmax | C15: =Podsumowanie!B16 -> 1.405 | D15: - | G15: 213 | H15: =G15/C$19 -> 0.62591831 | I15: =C$17*(1-0.605*H15+0.725*H15^2) -> 8872.4827 | J15: =OFFSET(D34,A34-2,0,1,1) -> -0.81415613 | K15: =OFFSET(D33,A34-2,0,1,1) -> -1.5554526 | L15: =G15*SIN(RADIANS(K15)) -> -5.7817646
A16: gęstość powietrza na wysokości h | B16: ρh | C16: =C10*(1-C1/44300)^4.256 -> 1.2255 | D16: kg/m3 | G16: 227 | H16: =G16/C$19 -> 0.66705848 | I16: =C$17*(1-0.605*H16+0.725*H16^2) -> 9006.5009 | J16: =OFFSET(D35,A35-2,0,1,1) -> -0.88779143 | K16: =OFFSET(D34,A35-2,0,1,1) -> -4.5515949 | L16: =G16*SIN(RADIANS(K16)) -> -18.013991
A17: Moc na wysokości przelotowej | B17: Ph | C17: =C3*(C16/C10)^0.85 -> 9800 | D17: N | G17: 240 | H17: =G17/C$19 -> 0.70526006 | I17: =C$17*(1-0.605*H17+0.725*H17^2) -> 9152.4815 | J17: =OFFSET(D36,A36-2,0,1,1) -> -0.94663824 | K17: =OFFSET(D35,A36-2,0,1,1) -> -7.8694159 | L17: =G17*SIN(RADIANS(K17)) -> -32.859792
A18: Temperatura na wysokości h | B18: Th | C18: =C13-6.5*C1/1000 -> 288.15 | D18: K
A19: Prędkość dźwięku na wysokości h | B19: ah | C19: =C12*SQRT(C18/C13) -> 340.3 | D19: m/s
A20: Maksymalny ciężar samolotu | B20: Qmax | C20: =Podsumowanie!B9 -> 37670.4 | D20: N
A21: 1 | B21: =-I3*COS(C21+C22-C$14)+0.5*C$16*C$4*C$2*(C22-C$5)*G3^2*SIN(C21)+0.5*C$16*C$4*((C$8+1/PI()/C$7*C$2^2*(C22-C$5)^2)/SQRT(1-H3^2))*G3^2*COS(C21) -> -0.00019383592 | C21: 0.19696798 | D21: =DEGREES(C21) -> 11.285434 | F21: Metoda mocy, m=mśr, h=0km
A22: 2 | B22: =I3*SIN(C21+C22-C$14)+0.5*C$16*C$4*C$2*(C22-C$5)*G3^2*COS(C21)-0.5*C$16*C$4*(C$8+1/PI()/C$7*C$2^2*(C22-C$5)^2)/SQRT(1-H3^2)*G3^2*SIN(C21)-C$11 -> 3.4022378e-08 | C22: 0.18550904 | D22: =DEGREES(C22) -> 10.628885 | F22: Cz | G22: Cx | H22: Cx~ | I22: E | J22: V [m/s] | K22: Ma | L22: Pn [N] | M22: Ps [N] | N22: ΔP [N] | O22: w [m/s] | P22: γ [°] | Q22: α [°]
A23: 3 | B23: =-I4*COS(C23+C24-C$14)+0.5*C$16*C$4*C$2*(C24-C$5)*G4^2*SIN(C23)+0.5*C$16*C$4*(C$8+1/PI()/C$7*C$2^2*(C24-C$5)^2)/SQRT(1-H4^2)*G4^2*COS(C23) -> -9.4564712e-10 | C23: 0.21851409 | D23: =DEGREES(C23) -> 12.519935 | F23: 1.405 | G23: 0.1406 | H23: =G23/SQRT(1-K23^2) -> 0.14189847 | I23: =F23^3/H23^2 -> 137.74427 | J23: =SQRT((2*C$11)/(C$4*C$16*F23)) -> 45.931239 | K23: =J23/C$19 -> 0.13497279 | L23: =C$11*SQRT((2*C$11)/(C$16*C$4*I23))/J23 -> 3210.0767 | M23: =C$17*(1-0.605*K23+0.725*K23^2) -> 9129.1828 | N23: =(M23-L23) -> 5919.1061 | O23: =N23/C$11*J23 -> 8.5536263 | P23: =DEGREES(ASIN(O23/J23)) -> 10.732664 | Q23: 12.989
A24: 4 | B24: =I4*SIN(C23+C24-C$14)+0.5*C$16*C$4*C$2*(C24-C$5)*G4^2*COS(C23)-0.5*C$16*C$4*(C$8+1/PI()/C$7*C$2^2*(C24-C$5)^2)/SQRT(1-H4^2)*G4^2*SIN(C23)-C$11 -> -2.3764005e-07 | C24: 0.089782808 | D24: =DEGREES(C24) -> 5.144176 | F24: 1.356 | G24: 0.1324 | H24: =G24/SQRT(1-K24^2) -> 0.13366756 | I24: =F24^3/H24^2 -> 139.54909 | J24: =SQRT((2*C$11)/(C$4*C$16*F24)) -> 46.753753 | K24: =J24/C$19 -> 0.13738981 | L24: =C$11*SQRT((2*C$11)/(C$16*C$4*I24))/J24 -> 3133.144 | M24: =C$17*(1-0.605*K24+0.725*K24^2) -> 9119.5295 | N24: =(M24-L24) -> 5986.3855 | O24: =N24/C$11*J24 -> 8.8057661 | P24: =DEGREES(ASIN(O24/J24)) -> 10.856129 | Q24: 11.238
A25: 5 | B25: =-I5*COS(C25+C26-C$14)+0.5*C$16*C$4*C$2*(C26-C$5)*G5^2*SIN(C25)+0.5*C$16*C$4*(C$8+1/PI()/C$7*C$2^2*(C26-C$5)^2)/SQRT(1-H5^2)*G5^2*COS(C25) -> -1.6575541e-09 | C25: 0.21790236 | D25: =DEGREES(C25) -> 12.484886 | F25: 1.302 | G25: 0.1231 | H25: =G25/SQRT(1-K25^2) -> 0.12432814 | I25: =F25^3/H25^2 -> 142.78878 | J25: =SQRT((2*C$11)/(C$4*C$16*F25)) -> 47.713451 | K25: =J25/C$19 -> 0.14020997 | L25: =C$11*SQRT((2*C$11)/(C$16*C$4*I25))/J25 -> 3035.0962 | M25: =C$17*(1-0.605*K25+0.725*K25^2) -> 9108.3711 | N25: =(M25-L25) -> 6073.2749 | O25: =N25/C$11*J25 -> 9.1169538 | P25: =DEGREES(ASIN(O25/J25)) -> 11.015656 | Q25: 10.575
A26: 6 | B26: =I5*SIN(C25+C26-C$14)+0.5*C$16*C$4*C$2*(C26-C$5)*G5^2*COS(C25)-0.5*C$16*C$4*(C$8+1/PI()/C$7*C$2^2*(C26-C$5)^2)/SQRT(1-H5^2)*G5^2*SIN(C25)-C$11 -> -6.5301356e-07 | C26: 0.052765894 | D26: =DEGREES(C26) -> 3.023263 | F26: 1.193 | G26: 0.1061 | H26: =G26/SQRT(1-K26^2) -> 0.10725684 | I26: =F26^3/H26^2 -> 147.59491 | J26: =SQRT((2*C$11)/(C$4*C$16*F26)) -> 49.845517 | K26: =J26/C$19 -> 0.14647522 | L26: =C$11*SQRT((2*C$11)/(C$16*C$4*I26))/J26 -> 2857.581 | M26: =C$17*(1-0.605*K26+0.725*K26^2) -> 9083.9861 | N26: =(M26-L26) -> 6226.4051 | O26: =N26/C$11*J26 -> 9.7644876 | P26: =DEGREES(ASIN(O26/J26)) -> 11.297012 | Q26: 9.576
A27: 7 | B27: =-I6*COS(C27+C28-C$14)+0.5*C$16*C$4*C$2*(C28-C$5)*G6^2*SIN(C27)+0.5*C$16*C$4*(C$8+1/PI()/C$7*C$2^2*(C28-C$5)^2)/SQRT(1-H6^2)*G6^2*COS(C27) -> -1.4256329e-10 | C27: 0.21039645 | D27: =DEGREES(C27) -> 12.054829 | F27: 1.095 | G27: 0.0919 | H27: =G27/SQRT(1-K27^2) -> 0.092993293 | I27: =F27^3/H27^2 -> 151.82354 | J27: =SQRT((2*C$11)/(C$4*C$16*F27)) -> 52.028256 | K27: =J27/C$19 -> 0.15288938 | L27: =C$11*SQRT((2*C$11)/(C$16*C$4*I27))/J27 -> 2699.3023 | M27: =C$17*(1-0.605*K27+0.725*K27^2) -> 9059.5994 | N27: =(M27-L27) -> 6360.2971 | O27: =N27/C$11*J27 -> 10.411245 | P27: =DEGREES(ASIN(O27/J27)) -> 11.543246 | Q27: 8.687
A28: 8 | B28: =I6*SIN(C27+C28-C$14)+0.5*C$16*C$4*C$2*(C28-C$5)*G6^2*COS(C27)-0.5*C$16*C$4*(C$8+1/PI()/C$7*C$2^2*(C28-C$5)^2)/SQRT(1-H6^2)*G6^2*SIN(C27)-C$11 -> -1.8103747e-06 | C28: 0.032408683 | D28: =DEGREES(C28) -> 1.8568808 | F28: 0.997 | G28: 0.0794 | H28: =G28/SQRT(1-K28^2) -> 0.080439265 | I28: =F28^3/H28^2 -> 153.16139 | J28: =SQRT((2*C$11)/(C$4*C$16*F28)) -> 54.525386 | K28: =J28/C$19 -> 0.1602274 | L28: =C$11*SQRT((2*C$11)/(C$16*C$4*I28))/J28 -> 2564.407 | M28: =C$17*(1-0.605*K28+0.725*K28^2) -> 9032.4171 | N28: =(M28-L28) -> 6468.0101 | O28: =N28/C$11*J28 -> 11.095718 | P28: =DEGREES(ASIN(O28/J28)) -> 11.741492 | Q28: 8.017
A29: 9 | B29: =-I7*COS(C29+C30-C$14)+0.5*C$16*C$4*C$2*(C30-C$5)*G7^2*SIN(C29)+0.5*C$16*C$4*(C$8+1/PI()/C$7*C$2^2*(C30-C$5)^2)/SQRT(1-H7^2)*G7^2*COS(C29) -> 2.0840162e-08 | C29: 0.1975812 | D29: =DEGREES(C29) -> 11.320569 | F29: 0.801 | G29: 0.0576 | H29: =G29/SQRT(1-K29^2) -> 0.058542959 | I29: =F29^3/H29^2 -> 149.9506 | J29: =SQRT((2*C$11)/(C$4*C$16*F29)) -> 60.831716 | K29: =J29/C$19 -> 0.17875908 | L29: =C$11*SQRT((2*C$11)/(C$16*C$4*I29))/J29 -> 2323.0372 | M29: =C$17*(1-0.605*K29+0.725*K29^2) -> 8967.1763 | N29: =(M29-L29) -> 6644.1391 | O29: =N29/C$11*J29 -> 12.716124 | P29: =DEGREES(ASIN(O29/J29)) -> 12.065967 | Q29: 6.131
A30: 10 | B30: =I7*SIN(C29+C30-C$14)+0.5*C$16*C$4*C$2*(C30-C$5)*G7^2*COS(C29)-0.5*C$16*C$4*(C$8+1/PI()/C$7*C$2^2*(C30-C$5)^2)/SQRT(1-H7^2)*G7^2*SIN(C29)-C$11 -> -5.0979761e-06 | C30: 0.018331438 | D30: =DEGREES(C30) -> 1.050314 | F30: 0.611 | G30: 0.0406 | H30: =G30/SQRT(1-K30^2) -> 0.041478087 | I30: =F30^3/H30^2 -> 132.58249 | J30: =SQRT((2*C$11)/(C$4*C$16*F30)) -> 69.650738 | K30: =J30/C$19 -> 0.20467452 | L30: =C$11*SQRT((2*C$11)/(C$16*C$4*I30))/J30 -> 2157.7023 | M30: =C$17*(1-0.605*K30+0.725*K30^2) -> 8884.125 | N30: =(M30-L30) -> 6726.4227 | O30: =N30/C$11*J30 -> 14.739945 | P30: =DEGREES(ASIN(O30/J30)) -> 12.217689 | Q30: 4.573
A31: 11 | B31: =-I8*COS(C31+C32-C$14)+0.5*C$16*C$4*C$2*(C32-C$5)*G8^2*SIN(C31)+0.5*C$16*C$4*(C$8+1/PI()/C$7*C$2^2*(C32-C$5)^2)/SQRT(1-H8^2)*G8^2*COS(C31) -> 9.9874796e-08 | C31: 0.18233527 | D31: =DEGREES(C31) -> 10.447041 | F31: 0.491 | G31: 0.0317 | H31: =G31/SQRT(1-K31^2) -> 0.032560035 | I31: =F31^3/H31^2 -> 111.65412 | J31: =SQRT((2*C$11)/(C$4*C$16*F31)) -> 77.697238 | K31: =J31/C$19 -> 0.22831983 | L31: =C$11*SQRT((2*C$11)/(C$16*C$4*I31))/J31 -> 2107.7417 | M31: =C$17*(1-0.605*K31+0.725*K31^2) -> 8816.675 | N31: =(M31-L31) -> 6708.9333 | O31: =N31/C$11*J31 -> 16.400045 | P31: =DEGREES(ASIN(O31/J31)) -> 12.185433 | Q31: 3.354
A32: 12 | B32: =I8*SIN(C31+C32-C$14)+0.5*C$16*C$4*C$2*(C32-C$5)*G8^2*COS(C31)-0.5*C$16*C$4*(C$8+1/PI()/C$7*C$2^2*(C32-C$5)^2)/SQRT(1-H8^2)*G8^2*SIN(C31)-C$11 -> -1.0193486e-05 | C32: 0.0094660419 | D32: =DEGREES(C32) -> 0.54236425 | F32: 0.388 | G32: 0.0252 | H32: =G32/SQRT(1-K32^2) -> 0.026074728 | I32: =F32^3/H32^2 -> 85.912348 | J32: =SQRT((2*C$11)/(C$4*C$16*F32)) -> 87.40383 | K32: =J32/C$19 -> 0.25684346 | L32: =C$11*SQRT((2*C$11)/(C$16*C$4*I32))/J32 -> 2136.0041 | M32: =C$17*(1-0.605*K32+0.725*K32^2) -> 8745.8818 | N32: =(M32-L32) -> 6609.8776 | O32: =N32/C$11*J32 -> 18.176483 | P32: =DEGREES(ASIN(O32/J32)) -> 12.002818 | Q32: 2.574
A33: 13 | B33: =-I9*COS(C33+C34-C$14)+0.5*C$16*C$4*C$2*(C34-C$5)*G9^2*SIN(C33)+0.5*C$16*C$4*(C$8+1/PI()/C$7*C$2^2*(C34-C$5)^2)/SQRT(1-H9^2)*G9^2*COS(C33) -> 1.3112412e-07 | C33: 0.16427887 | D33: =DEGREES(C33) -> 9.412486 | F33: 0.246 | G33: 0.0188 | H33: =G33/SQRT(1-K33^2) -> 0.019861657 | I33: =F33^3/H33^2 -> 37.737609 | J33: =SQRT((2*C$11)/(C$4*C$16*F33)) -> 109.76876 | K33: =J33/C$19 -> 0.32256469 | L33: =C$11*SQRT((2*C$11)/(C$16*C$4*I33))/J33 -> 2566.2229 | M33: =C$17*(1-0.605*K33+0.725*K33^2) -> 8626.7748 | N33: =(M33-L33) -> 6060.5519 | O33: =N33/C$11*J33 -> 20.930371 | P33: =DEGREES(ASIN(O33/J33)) -> 10.992292 | Q33: 1.242
A34: 14 | B34: =I9*SIN(C33+C34-C$14)+0.5*C$16*C$4*C$2*(C34-C$5)*G9^2*COS(C33)-0.5*C$16*C$4*(C$8+1/PI()/C$7*C$2^2*(C34-C$5)^2)/SQRT(1-H9^2)*G9^2*SIN(C33)-C$11 -> -7.4457712e-06 | C34: 0.0030943947 | D34: =DEGREES(C34) -> 0.17729576 | F34: 0.2 | G34: 0.0175 | H34: =G34/SQRT(1-K34^2) -> 0.018740215 | I34: =F34^3/H34^2 -> 22.779324 | J34: =SQRT((2*C$11)/(C$4*C$16*F34)) -> 121.73945 | K34: =J34/C$19 -> 0.35774154 | L34: =C$11*SQRT((2*C$11)/(C$16*C$4*I34))/J34 -> 2978.2325 | M34: =C$17*(1-0.605*K34+0.725*K34^2) -> 8588.2413 | N34: =(M34-L34) -> 5610.0087 | O34: =N34/C$11*J34 -> 21.487251 | P34: =DEGREES(ASIN(O34/J34)) -> 10.166074 | Q34: 0.688
A35: 15 | B35: =-I10*COS(C35+C36-C$14)+0.5*C$16*C$4*C$2*(C36-C$5)*G10^2*SIN(C35)+0.5*C$16*C$4*(C$8+1/PI()/C$7*C$2^2*(C36-C$5)^2)/SQRT(1-H10^2)*G10^2*COS(C35) -> 5.2766563e-07 | C35: 0.14179185 | D35: =DEGREES(C35) -> 8.1240744 | F35: 0.151 | G35: 0.0163 | H35: =G35/SQRT(1-K35^2) -> 0.017886281 | I35: =F35^3/H35^2 -> 10.761945 | J35: =SQRT((2*C$11)/(C$4*C$16*F35)) -> 140.10636 | K35: =J35/C$19 -> 0.41171425 | L35: =C$11*SQRT((2*C$11)/(C$16*C$4*I35))/J35 -> 3764.9318 | M35: =C$17*(1-0.605*K35+0.725*K35^2) -> 8563.305 | N35: =(M35-L35) -> 4798.3732 | O35: =N35/C$11*J35 -> 21.151339 | P35: =DEGREES(ASIN(O35/J35)) -> 8.6829291 | Q35: 0.237
