Workbook
Name Cx_Cz: 'projekty 2 i 3'!$E$2:$F$115
Name Cx_Cz_1: 'projekty 2 i 3'!$C$3:$C$111
Name Cx_Cz_2: 'projekty 2 i 3'!#REF!
Name Cx_Cz_3: 'projekty 2 i 3'!#REF!
Name Cz_a: 'projekty 2 i 3'!$A$3:$B$229
Name Cz_a_1: 'projekty 2 i 3'!$F$3:$G$229
Name Cz_a_2: 'projekty 2 i 3'!$A$3:$B$128
Name Cz_a_3: 'projekty 2 i 3'!#REF!

Sheet Arkusz1
A1: Dana | B1: Symbol | C1: Wartość | D1: Jednostka
A2: Rozpiętość płata | B2: b | C2: 10.07 | D2: m
A3: Wysokość samolotu | B3: hs | C3: 3.6 | D3: m
A4: Długość kadłuba | B4: lk | C4: 11.25 | D4: m
A5: Powierzchnia nośna | B5: S | C5: 17.5 | D5: m2
A6: Masa pustego samolotu | B6: m0 | C6: 2560 | D6: kg
A7: Masa maksymalna samolotu | B7: mk | C7: 3840 | D7: kg
A8: Masa paliwa | B8: mp | C8: 996 | D8: kg
A9: ciąg statyczny silnika uzyskiwany na ziemii przy zerowej prędkości lotu | B9: Pr-0 | C9: 9800 | D9: N
A10: obroty startowe | B10: nso | C10: 14600 | D10: obr/min
A11: ciąg silnika nominalny | B11: Pnom | C11: 8200 | D11: N
A12: obroty nominalne | B12: nnom | C12: 13600 | D12: obr/min
A13: Zużycie paliwa | B13: q | C13: 0.001 | D13: m3/h
A14: Prędkość maksymalna | B14: Vmax | C14: =720*1000/3600 -> 200 | D14: m/s
A15: Maksymalna prędkość wznoszenia | B15: wmax | C15: 16 | D15: m/s
A16: Przyspieszenie grawitacyjne | B16: g | C16: 9.81 | D16: m/s2
A17: Pułap praktyczny | B17: pułapp | C17: 12500 | D17: m
A18: Pułap teoretyczny | B18: pulap | C18: 13100 | D18: m
A19: cięciwa na osi symetrii samolotu | B19: c0 | C19: 2.49 | D19: m
A20: cięcika końcowa | B20: ck | C20: 1.14 | D20: m
A21: kąt skosu krawędzi natarcia płata | B21: νx0 | C21: =DEGREES(ATAN(23/115)) -> 11.309932 | D21: °
A22: zbieżność płata | B22: λ | C22: =C20/C19 -> 0.45783133 | D22: -
A23: wydłużenie geometryczne płata | B23: Λ | C23: =C2*C2/C5 -> 5.7945657 | D23: -
A24: średnia cięciwa aerodynamiczna | B24: ca | C24: =2*C19*(1+C22+C22^2)/(3+3*C22) -> 1.8986777 | D24: m
A25: położenie noska ca względem początku cięciwy przykadłubowej | B25: xN | C25: =C2*TAN(RADIANS(C21))*(1+2*C22)/(6+6*C22) -> 0.44108264 | D25: m
A26: gęstość powietrza przy ziemii | B26: ρ | C26: 1.2255 | D26: kg/m3
A27: Liczba Reynoldsa 3M | B27: Re3M | C27: =2*10^6 -> 2000000 | D27: -
A28: Czmax dla Reynoldsa 3M | B28: Czmax re | C28: 1.36 | D28: -
A29: lepkość kinematyczna powietrzna na poziomie morza | B29: ν | C29: =1.4607*10^-5 -> 1.4607e-05 | D29: m2/s
A30: Prędkość przeciągnięcia | B30: VS1 | C30: =SQRT(2*C7*C16/C26/C5/C28) -> 50.824133 | D30: m/s
A31: Obliczona liczba Reynoldsa | B31: Re | C31: =C30*C24/C29 -> 6606328.9 | D31: -
A32: środek aerodynamiczny na x | B32: xsa kreska | C32: 0.263 | D32: -
A33: środek aerodynamiczny na z | B33: zsa kreska | C33: -0.026 | D33: -
A34: Współczynnik momentu podłużnego względem środka aerodynamicznego | B34: Cmsa | C34: -0.03364 | D34: -
A35: Współczynnik kierunkowy prostej Cz(a) | B35: a∞ | C35: 6.2313 | D35: 1/rad
A36: minimalna wartość Cx | B36: Cx∞ min1 | C36: =MIN('projekty 2 i 3'!H3:H20) -> 0.0046487465 | D36: -
A37: Cz odpowiadające minimalnej wartości Cx | B37: Cz∞1 | C37: ='projekty 2 i 3'!G25 -> 0.25823453 | D37: -
A38: Korekta dottycząca liczby reynoldsa | B38: Cx∞ min2 | C38: =C36*(C31/10^7)^0.11 -> 0.0044415187 | D38: -
A39: maksymalny współczynnik Cz | B39: Czmax | C39: =MAX('projekty 2 i 3'!G3:G20) -> 0.092816698 | D39: -
A40: Minimalny współczynnik Cx' | B40: Cx'∞ min | C40: =MIN('projekty 2 i 3'!J3:J20) -> 0.0048358339 | D40: -
...

Sheet projekty 2 i 3
G1: profil | K1: płat | O1: samolot
A2: a deg | B2: Cz | C2: Cx | D2: a rad | E2: dCxRe | F2: ap rad | G2: Cz | H2: Cx | I2: α [°] | J2: Cx' | K2: αi [°] | L2: αp [°] | M2: Cxi | N2: C'xp | O2: CzH | P2: CxH | Q2: Cx'szk | R2: Cx | S2: ΔCzH | T2: Cz' | U2: K | V2: E | W2: alfa | X2: Cz'2 | Y2: K/10 | Z2: E/100
A3: -10.541191 | B3: -1.09768 | C3: =0.0056*B3^2-0.0018*B3+0.0054 -> 0.014123272 | D3: =RADIANS(A3) -> -0.18397849 | E3: =(Arkusz1!C$38-Arkusz1!C$36)*(1-ABS('projekty 2 i 3'!G3/Arkusz1!C$39)) -> 0.0022435156 | F3: =RADIANS(L3) -> -0.24548503 | G3: =B3 -> -1.09768 | H3: =C3 -> 0.014123272 | I3: =A3 -> -10.541191 | J3: =H3+E3 -> 0.016366787 | K3: =DEGREES(G3*(1+Arkusz1!C$49)/Arkusz1!C$23/PI()) -> -3.5240656 | L3: =I3+K3 -> -14.065256 | M3: =G3^2*(1+Arkusz1!C$48)/Arkusz1!C$23/PI() -> 0.066486746 | N3: =J3+M3+Arkusz1!C$41 -> 0.083578908 | O3: =Arkusz1!C$34/Arkusz1!C$80+(Arkusz1!C$71-Arkusz1!C$32)/Arkusz1!C$80*'projekty 2 i 3'!G3 -> -0.10204678 | P3: =Arkusz1!C$75+Arkusz1!C$76+1/PI()/Arkusz1!C$79*'projekty 2 i 3'!O3^2 -> 0.0093508431 | Q3: =Arkusz1!C$90*(1+1/Arkusz1!C$91*ABS('projekty 2 i 3'!G3)) -> 0.0084861945 | R3: =(N3+Q3+P3*Arkusz1!C$70/Arkusz1!C$5)*(1+Arkusz1!C$92) -> 0.096029129 | S3: =O3*Arkusz1!C$70/Arkusz1!C$5 -> -0.022711296 | T3: =G3+S3 -> -1.1203913 | U3: =T3/R3 -> -11.667203 | V3: =T3^3/R3^2 -> -152.51171 | W3: =I3 -> -10.541191 | X3: =T3^2 -> 1.2552767 | Y3: =U3/10 -> -1.1667203 | Z3: =V3/100 -> -1.5251171
A4: -9.7598075 | B4: -0.98949395 | C4: =0.0056*B4^2-0.0018*B4+0.0054 -> 0.012664039 | D4: =RADIANS(A4) -> -0.17034078 | E4: =(Arkusz1!C$38-Arkusz1!C$36)*(1-ABS('projekty 2 i 3'!G4/Arkusz1!C$39)) -> 0.0020019732 | F4: =RADIANS(L4) -> -0.22578531 | G4: =B4 -> -0.98949395 | H4: =C4 -> 0.012664039 | I4: =A4 -> -9.7598075 | J4: =H4+E4 -> 0.014666013 | K4: =DEGREES(G4*(1+Arkusz1!C$49)/Arkusz1!C$23/PI()) -> -3.1767378 | L4: =I4+K4 -> -12.936545 | M4: =G4^2*(1+Arkusz1!C$48)/Arkusz1!C$23/PI() -> 0.054026876 | N4: =J4+M4+Arkusz1!C$41 -> 0.069418264 | O4: =Arkusz1!C$34/Arkusz1!C$80+(Arkusz1!C$71-Arkusz1!C$32)/Arkusz1!C$80*'projekty 2 i 3'!G4 -> -0.098458274 | P4: =Arkusz1!C$75+Arkusz1!C$76+1/PI()/Arkusz1!C$79*'projekty 2 i 3'!O4^2 -> 0.0092644174 | Q4: =Arkusz1!C$90*(1+1/Arkusz1!C$91*ABS('projekty 2 i 3'!G4)) -> 0.0083568441 | R4: =(N4+Q4+P4*Arkusz1!C$70/Arkusz1!C$5)*(1+Arkusz1!C$92) -> 0.081433715 | S4: =O4*Arkusz1!C$70/Arkusz1!C$5 -> -0.021912648 | T4: =G4+S4 -> -1.0114066 | U4: =T4/R4 -> -12.419998 | V4: =T4^3/R4^2 -> -156.0159 | W4: =I4 -> -9.7598075 | X4: =T4^2 -> 1.0229433 | Y4: =U4/10 -> -1.2419998 | Z4: =V4/100 -> -1.560159
A5: -8.9822129 | B5: -0.90304455 | C5: =0.0056*B5^2-0.0018*B5+0.0054 -> 0.011592221 | D5: =RADIANS(A5) -> -0.15676919 | E5: =(Arkusz1!C$38-Arkusz1!C$36)*(1-ABS('projekty 2 i 3'!G5/Arkusz1!C$39)) -> 0.0018089613 | F5: =RADIANS(L5) -> -0.20736969 | G5: =B5 -> -0.90304455 | H5: =C5 -> 0.011592221 | I5: =A5 -> -8.9822129 | J5: =H5+E5 -> 0.013401182 | K5: =DEGREES(G5*(1+Arkusz1!C$49)/Arkusz1!C$23/PI()) -> -2.8991949 | L5: =I5+K5 -> -11.881408 | M5: =G5^2*(1+Arkusz1!C$48)/Arkusz1!C$23/PI() -> 0.044998903 | N5: =J5+M5+Arkusz1!C$41 -> 0.05912546 | O5: =Arkusz1!C$34/Arkusz1!C$80+(Arkusz1!C$71-Arkusz1!C$32)/Arkusz1!C$80*'projekty 2 i 3'!G5 -> -0.095590771 | P5: =Arkusz1!C$75+Arkusz1!C$76+1/PI()/Arkusz1!C$79*'projekty 2 i 3'!O5^2 -> 0.00919758 | Q5: =Arkusz1!C$90*(1+1/Arkusz1!C$91*ABS('projekty 2 i 3'!G5)) -> 0.0082534827 | R5: =(N5+Q5+P5*Arkusz1!C$70/Arkusz1!C$5)*(1+Arkusz1!C$92) -> 0.070814454 | S5: =O5*Arkusz1!C$70/Arkusz1!C$5 -> -0.021274463 | T5: =G5+S5 -> -0.92431902 | U5: =T5/R5 -> -13.052689 | V5: =T5^3/R5^2 -> -157.47871 | W5: =I5 -> -8.9822129 | X5: =T5^2 -> 0.85436564 | Y5: =U5/10 -> -1.3052689 | Z5: =V5/100 -> -1.5747871
A6: -8.2017768 | B6: -0.80029266 | C6: =-0.0018*B6^4+0.003*B6^3+0.0059*B6^2-0.0032*B6+0.0055 -> 0.0095636539 | D6: =RADIANS(A6) -> -0.14314801 | E6: =(Arkusz1!C$38-Arkusz1!C$36)*(1-ABS('projekty 2 i 3'!G6/Arkusz1!C$39)) -> 0.0015795515 | F6: =RADIANS(L6) -> -0.18799099 | G6: =B6 -> -0.80029266 | H6: =C6 -> 0.0095636539 | I6: =A6 -> -8.2017768 | J6: =H6+E6 -> 0.011143205 | K6: =DEGREES(G6*(1+Arkusz1!C$49)/Arkusz1!C$23/PI()) -> -2.5693133 | L6: =I6+K6 -> -10.77109 | M6: =G6^2*(1+Arkusz1!C$48)/Arkusz1!C$23/PI() -> 0.035341196 | N6: =J6+M6+Arkusz1!C$41 -> 0.047209776 | O6: =Arkusz1!C$34/Arkusz1!C$80+(Arkusz1!C$71-Arkusz1!C$32)/Arkusz1!C$80*'projekty 2 i 3'!G6 -> -0.092182519 | P6: =Arkusz1!C$75+Arkusz1!C$76+1/PI()/Arkusz1!C$79*'projekty 2 i 3'!O6^2 -> 0.0091207077 | Q6: =Arkusz1!C$90*(1+1/Arkusz1!C$91*ABS('projekty 2 i 3'!G6)) -> 0.0081306295 | R6: =(N6+Q6+P6*Arkusz1!C$70/Arkusz1!C$5)*(1+Arkusz1!C$92) -> 0.058517696 | S6: =O6*Arkusz1!C$70/Arkusz1!C$5 -> -0.02051593 | T6: =G6+S6 -> -0.82080859 | U6: =T6/R6 -> -14.026673 | V6: =T6^3/R6^2 -> -161.49209 | W6: =I6 -> -8.2017768 | X6: =T6^2 -> 0.67372675 | Y6: =U6/10 -> -1.4026673 | Z6: =V6/100 -> -1.6149209
A7: -6.6390104 | B7: -0.58392055 | C7: =-0.0018*B7^4+0.003*B7^3+0.0059*B7^2-0.0032*B7+0.0055 -> 0.0085736818 | D7: =RADIANS(A7) -> -0.11587259 | E7: =(Arkusz1!C$38-Arkusz1!C$36)*(1-ABS('projekty 2 i 3'!G7/Arkusz1!C$39)) -> 0.0010964667 | F7: =RADIANS(L7) -> -0.14859154 | G7: =B7 -> -0.58392055 | H7: =C7 -> 0.0085736818 | I7: =A7 -> -6.6390104 | J7: =H7+E7 -> 0.0096701485 | K7: =DEGREES(G7*(1+Arkusz1!C$49)/Arkusz1!C$23/PI()) -> -1.8746578 | L7: =I7+K7 -> -8.5136682 | M7: =G7^2*(1+Arkusz1!C$48)/Arkusz1!C$23/PI() -> 0.018814431 | N7: =J7+M7+Arkusz1!C$41 -> 0.029209955 | O7: =Arkusz1!C$34/Arkusz1!C$80+(Arkusz1!C$71-Arkusz1!C$32)/Arkusz1!C$80*'projekty 2 i 3'!G7 -> -0.085005516 | P7: =Arkusz1!C$75+Arkusz1!C$76+1/PI()/Arkusz1!C$79*'projekty 2 i 3'!O7^2 -> 0.0089679575 | Q7: =Arkusz1!C$90*(1+1/Arkusz1!C$91*ABS('projekty 2 i 3'!G7)) -> 0.0078719286 | R7: =(N7+Q7+P7*Arkusz1!C$70/Arkusz1!C$5)*(1+Arkusz1!C$92) -> 0.039859327 | S7: =O7*Arkusz1!C$70/Arkusz1!C$5 -> -0.018918633 | T7: =G7+S7 -> -0.60283919 | U7: =T7/R7 -> -15.124169 | V7: =T7^3/R7^2 -> -137.89372 | W7: =I7 -> -6.6390104 | X7: =T7^2 -> 0.36341509 | Y7: =U7/10 -> -1.5124169 | Z7: =V7/100 -> -1.3789372
A8: -5.86331 | B8: -0.50833949 | C8: 0.0075602126 | D8: =RADIANS(A8) -> -0.10233407 | E8: =(Arkusz1!C$38-Arkusz1!C$36)*(1-ABS('projekty 2 i 3'!G8/Arkusz1!C$39)) -> 0.00092772008 | F8: =RADIANS(L8) -> -0.13081796 | G8: =B8 -> -0.50833949 | H8: =C8 -> 0.0075602126 | I8: =A8 -> -5.86331 | J8: =H8+E8 -> 0.0084879326 | K8: =DEGREES(G8*(1+Arkusz1!C$49)/Arkusz1!C$23/PI()) -> -1.6320072 | L8: =I8+K8 -> -7.4953173 | M8: =G8^2*(1+Arkusz1!C$48)/Arkusz1!C$23/PI() -> 0.014259072 | N8: =J8+M8+Arkusz1!C$41 -> 0.02347238 | O8: =Arkusz1!C$34/Arkusz1!C$80+(Arkusz1!C$71-Arkusz1!C$32)/Arkusz1!C$80*'projekty 2 i 3'!G8 -> -0.082498513 | P8: =Arkusz1!C$75+Arkusz1!C$76+1/PI()/Arkusz1!C$79*'projekty 2 i 3'!O8^2 -> 0.0089175164 | Q8: =Arkusz1!C$90*(1+1/Arkusz1!C$91*ABS('projekty 2 i 3'!G8)) -> 0.0077815617 | R8: =(N8+Q8+P8*Arkusz1!C$70/Arkusz1!C$5)*(1+Arkusz1!C$92) -> 0.033903376 | S8: =O8*Arkusz1!C$70/Arkusz1!C$5 -> -0.01836068 | T8: =G8+S8 -> -0.52670017 | U8: =T8/R8 -> -15.535331 | V8: =T8^3/R8^2 -> -127.11725 | W8: =I8 -> -5.86331 | X8: =T8^2 -> 0.27741307 | Y8: =U8/10 -> -1.5535331 | Z8: =V8/100 -> -1.2711725
A9: -4.0836506 | B9: -0.29754362 | C9: 0.0068250193 | D9: =RADIANS(A9) -> -0.071273149 | E9: =(Arkusz1!C$38-Arkusz1!C$36)*(1-ABS('projekty 2 i 3'!G9/Arkusz1!C$39)) -> 0.00045708509 | F9: =RADIANS(L9) -> -0.087945476 | G9: =B9 -> -0.29754362 | H9: =C9 -> 0.0068250193 | I9: =A9 -> -4.0836506 | J9: =H9+E9 -> 0.0072821044 | K9: =DEGREES(G9*(1+Arkusz1!C$49)/Arkusz1!C$23/PI()) -> -0.95525401 | L9: =I9+K9 -> -5.0389046 | M9: =G9^2*(1+Arkusz1!C$48)/Arkusz1!C$23/PI() -> 0.0048852281 | N9: =J9+M9+Arkusz1!C$41 -> 0.012892708 | O9: =Arkusz1!C$34/Arkusz1!C$80+(Arkusz1!C$71-Arkusz1!C$32)/Arkusz1!C$80*'projekty 2 i 3'!G9 -> -0.075506472 | P9: =Arkusz1!C$75+Arkusz1!C$76+1/PI()/Arkusz1!C$79*'projekty 2 i 3'!O9^2 -> 0.008784814 | Q9: =Arkusz1!C$90*(1+1/Arkusz1!C$91*ABS('projekty 2 i 3'!G9)) -> 0.007529528 | R9: =(N9+Q9+P9*Arkusz1!C$70/Arkusz1!C$5)*(1+Arkusz1!C$92) -> 0.022824911 | S9: =O9*Arkusz1!C$70/Arkusz1!C$5 -> -0.016804547 | T9: =G9+S9 -> -0.31434816 | U9: =T9/R9 -> -13.772153 | V9: =T9^3/R9^2 -> -59.623107 | W9: =I9 -> -4.0836506 | X9: =T9^2 -> 0.098814767 | Y9: =U9/10 -> -1.3772153 | Z9: =V9/100 -> -0.59623107
A10: -3.5295789 | B10: -0.24355714 | C10: 0.0066238107 | D10: =RADIANS(A10) -> -0.061602773 | E10: =(Arkusz1!C$38-Arkusz1!C$36)*(1-ABS('projekty 2 i 3'!G10/Arkusz1!C$39)) -> 0.00033655178 | F10: =RADIANS(L10) -> -0.075250065 | G10: =B10 -> -0.24355714 | H10: =C10 -> 0.0066238107 | I10: =A10 -> -3.5295789 | J10: =H10+E10 -> 0.0069603625 | K10: =DEGREES(G10*(1+Arkusz1!C$49)/Arkusz1!C$23/PI()) -> -0.7819322 | L10: =I10+K10 -> -4.3115111 | M10: =G10^2*(1+Arkusz1!C$48)/Arkusz1!C$23/PI() -> 0.0032732962 | N10: =J10+M10+Arkusz1!C$41 -> 0.010959034 | O10: =Arkusz1!C$34/Arkusz1!C$80+(Arkusz1!C$71-Arkusz1!C$32)/Arkusz1!C$80*'projekty 2 i 3'!G10 -> -0.073715755 | P10: =Arkusz1!C$75+Arkusz1!C$76+1/PI()/Arkusz1!C$79*'projekty 2 i 3'!O10^2 -> 0.0087527169 | Q10: =Arkusz1!C$90*(1+1/Arkusz1!C$91*ABS('projekty 2 i 3'!G10)) -> 0.0074649802 | R10: =(N10+Q10+P10*Arkusz1!C$70/Arkusz1!C$5)*(1+Arkusz1!C$92) -> 0.020779439 | S10: =O10*Arkusz1!C$70/Arkusz1!C$5 -> -0.016406009 | T10: =G10+S10 -> -0.25996315 | U10: =T10/R10 -> -12.510595 | V10: =T10^3/R10^2 -> -40.688132 | W10: =I10 -> -3.5295789 | X10: =T10^2 -> 0.067580839 | Y10: =U10/10 -> -1.2510595 | Z10: =V10/100 -> -0.40688132
A11: -3.1933474 | B11: -0.1894286 | C11: 0.0066208108 | D11: =RADIANS(A11) -> -0.055734425 | E11: =(Arkusz1!C$38-Arkusz1!C$36)*(1-ABS('projekty 2 i 3'!G11/Arkusz1!C$39)) -> 0.00021570128 | F11: =RADIANS(L11) -> -0.06634872 | G11: =B11 -> -0.1894286 | H11: =C11 -> 0.0066208108 | I11: =A11 -> -3.1933474 | J11: =H11+E11 -> 0.0068365121 | K11: =DEGREES(G11*(1+Arkusz1!C$49)/Arkusz1!C$23/PI()) -> -0.60815429 | L11: =I11+K11 -> -3.8015016 | M11: =G11^2*(1+Arkusz1!C$48)/Arkusz1!C$23/PI() -> 0.0019800431 | N11: =J11+M11+Arkusz1!C$41 -> 0.0095419303 | O11: =Arkusz1!C$34/Arkusz1!C$80+(Arkusz1!C$71-Arkusz1!C$32)/Arkusz1!C$80*'projekty 2 i 3'!G11 -> -0.071920326 | P11: =Arkusz1!C$75+Arkusz1!C$76+1/PI()/Arkusz1!C$79*'projekty 2 i 3'!O11^2 -> 0.0087213089 | Q11: =Arkusz1!C$90*(1+1/Arkusz1!C$91*ABS('projekty 2 i 3'!G11)) -> 0.0074002625 | R11: =(N11+Q11+P11*Arkusz1!C$70/Arkusz1!C$5)*(1+Arkusz1!C$92) -> 0.019260851 | S11: =O11*Arkusz1!C$70/Arkusz1!C$5 -> -0.016006423 | T11: =G11+S11 -> -0.20543502 | U11: =T11/R11 -> -10.665937 | V11: =T11^3/R11^2 -> -23.370741 | W11: =I11 -> -3.1933474 | X11: =T11^2 -> 0.042203547 | Y11: =U11/10 -> -1.0665937 | Z11: =V11/100 -> -0.23370741
A12: -2.8609043 | B12: -0.15703671 | C12: 0.0062880346 | D12: =RADIANS(A12) -> -0.0499322 | E12: =(Arkusz1!C$38-Arkusz1!C$36)*(1-ABS('projekty 2 i 3'!G12/Arkusz1!C$39)) -> 0.00014338129 | F12: =RADIANS(L12) -> -0.058731473 | G12: =B12 -> -0.15703671 | H12: =C12 -> 0.0062880346 | I12: =A12 -> -2.8609043 | J12: =H12+E12 -> 0.0064314159 | K12: =DEGREES(G12*(1+Arkusz1!C$49)/Arkusz1!C$23/PI()) -> -0.5041612 | L12: =I12+K12 -> -3.3650655 | M12: =G12^2*(1+Arkusz1!C$48)/Arkusz1!C$23/PI() -> 0.0013607738 | N12: =J12+M12+Arkusz1!C$41 -> 0.0085175648 | O12: =Arkusz1!C$34/Arkusz1!C$80+(Arkusz1!C$71-Arkusz1!C$32)/Arkusz1!C$80*'projekty 2 i 3'!G12 -> -0.070845896 | P12: =Arkusz1!C$75+Arkusz1!C$76+1/PI()/Arkusz1!C$79*'projekty 2 i 3'!O12^2 -> 0.0087028839 | Q12: =Arkusz1!C$90*(1+1/Arkusz1!C$91*ABS('projekty 2 i 3'!G12)) -> 0.0073615338 | R12: =(N12+Q12+P12*Arkusz1!C$70/Arkusz1!C$5)*(1+Arkusz1!C$92) -> 0.018172312 | S12: =O12*Arkusz1!C$70/Arkusz1!C$5 -> -0.0157673 | T12: =G12+S12 -> -0.17280401 | U12: =T12/R12 -> -9.5091922 | V12: =T12^3/R12^2 -> -15.625757 | W12: =I12 -> -2.8609043 | X12: =T12^2 -> 0.029861226 | Y12: =U12/10 -> -0.95091922 | Z12: =V12/100 -> -0.15625757
A13: -2.4157527 | B13: -0.1029792 | C13: 0.0060876832 | D13: =RADIANS(A13) -> -0.042162838 | E13: =(Arkusz1!C$38-Arkusz1!C$36)*(1-ABS('projekty 2 i 3'!G13/Arkusz1!C$39)) -> 2.268939e-05 | F13: =RADIANS(L13) -> -0.047933095 | G13: =B13 -> -0.1029792 | H13: =C13 -> 0.0060876832 | I13: =A13 -> -2.4157527 | J13: =H13+E13 -> 0.0061103726 | K13: =DEGREES(G13*(1+Arkusz1!C$49)/Arkusz1!C$23/PI()) -> -0.33061134 | L13: =I13+K13 -> -2.746364 | M13: =G13^2*(1+Arkusz1!C$48)/Arkusz1!C$23/PI() -> 0.00058517075 | N13: =J13+M13+Arkusz1!C$41 -> 0.0074209184 | O13: =Arkusz1!C$34/Arkusz1!C$80+(Arkusz1!C$71-Arkusz1!C$32)/Arkusz1!C$80*'projekty 2 i 3'!G13 -> -0.069052824 | P13: =Arkusz1!C$75+Arkusz1!C$76+1/PI()/Arkusz1!C$79*'projekty 2 i 3'!O13^2 -> 0.0086727527 | Q13: =Arkusz1!C$90*(1+1/Arkusz1!C$91*ABS('projekty 2 i 3'!G13)) -> 0.0072969011 | R13: =(N13+Q13+P13*Arkusz1!C$70/Arkusz1!C$5)*(1+Arkusz1!C$92) -> 0.016980968 | S13: =O13*Arkusz1!C$70/Arkusz1!C$5 -> -0.015368238 | T13: =G13+S13 -> -0.11834744 | U13: =T13/R13 -> -6.9694167 | V13: =T13^3/R13^2 -> -5.7484628 | W13: =I13 -> -2.4157527 | X13: =T13^2 -> 0.014006116 | Y13: =U13/10 -> -0.69694167 | Z13: =V13/100 -> -0.057484628
A14: -2.0823625 | B14: -0.065153151 | C14: 0.006019328 | D14: =RADIANS(A14) -> -0.036344082 | E14: =(Arkusz1!C$38-Arkusz1!C$36)*(1-ABS('projekty 2 i 3'!G14/Arkusz1!C$39)) -> -6.1763224e-05 | F14: =RADIANS(L14) -> -0.039994823 | G14: =B14 -> -0.065153151 | H14: =C14 -> 0.006019328 | I14: =A14 -> -2.0823625 | J14: =H14+E14 -> 0.0059575648 | K14: =DEGREES(G14*(1+Arkusz1!C$49)/Arkusz1!C$23/PI()) -> -0.20917205 | L14: =I14+K14 -> -2.2915346 | M14: =G14^2*(1+Arkusz1!C$48)/Arkusz1!C$23/PI() -> 0.00023423642 | N14: =J14+M14+Arkusz1!C$41 -> 0.0069171763 | O14: =Arkusz1!C$34/Arkusz1!C$80+(Arkusz1!C$71-Arkusz1!C$32)/Arkusz1!C$80*'projekty 2 i 3'!G14 -> -0.067798144 | P14: =Arkusz1!C$75+Arkusz1!C$76+1/PI()/Arkusz1!C$79*'projekty 2 i 3'!O14^2 -> 0.0086521281 | Q14: =Arkusz1!C$90*(1+1/Arkusz1!C$91*ABS('projekty 2 i 3'!G14)) -> 0.0072516751 | R14: =(N14+Q14+P14*Arkusz1!C$70/Arkusz1!C$5)*(1+Arkusz1!C$92) -> 0.016416338 | S14: =O14*Arkusz1!C$70/Arkusz1!C$5 -> -0.015088999 | T14: =G14+S14 -> -0.08024215 | U14: =T14/R14 -> -4.8879445 | V14: =T14^3/R14^2 -> -1.9171456 | W14: =I14 -> -2.0823625 | X14: =T14^2 -> 0.0064388027 | Y14: =U14/10 -> -0.48879445 | Z14: =V14/100 -> -0.019171456
A15: -1.421265 | B15: -0.022106041 | C15: 0.0057523356 | D15: =RADIANS(A15) -> -0.024805754 | E15: =(Arkusz1!C$38-Arkusz1!C$36)*(1-ABS('projekty 2 i 3'!G15/Arkusz1!C$39)) -> -0.00015787268 | F15: =RADIANS(L15) -> -0.026044426 | G15: =B15 -> -0.022106041 | H15: =C15 -> 0.0057523356 | I15: =A15 -> -1.421265 | J15: =H15+E15 -> 0.005594463 | K15: =DEGREES(G15*(1+Arkusz1!C$49)/Arkusz1!C$23/PI()) -> -0.070970718 | L15: =I15+K15 -> -1.4922357 | M15: =G15^2*(1+Arkusz1!C$48)/Arkusz1!C$23/PI() -> 2.6965315e-05 | N15: =J15+M15+Arkusz1!C$41 -> 0.0063468034 | O15: =Arkusz1!C$34/Arkusz1!C$80+(Arkusz1!C$71-Arkusz1!C$32)/Arkusz1!C$80*'projekty 2 i 3'!G15 -> -0.066370283 | P15: =Arkusz1!C$75+Arkusz1!C$76+1/PI()/Arkusz1!C$79*'projekty 2 i 3'!O15^2 -> 0.0086291169 | Q15: =Arkusz1!C$90*(1+1/Arkusz1!C$91*ABS('projekty 2 i 3'!G15)) -> 0.0072002067 | R15: =(N15+Q15+P15*Arkusz1!C$70/Arkusz1!C$5)*(1+Arkusz1!C$92) -> 0.015776836 | S15: =O15*Arkusz1!C$70/Arkusz1!C$5 -> -0.014771218 | T15: =G15+S15 -> -0.036877259 | U15: =T15/R15 -> -2.3374305 | V15: =T15^3/R15^2 -> -0.20148191 | W15: =I15 -> -1.421265 | X15: =T15^2 -> 0.0013599322 | Y15: =U15/10 -> -0.23374305 | Z15: =V15/100 -> -0.0020148191
A16: -1.4155822 | B16: 0.010498949 | C16: 0.0056856947 | D16: =RADIANS(A16) -> -0.02470657 | E16: =(Arkusz1!C$38-Arkusz1!C$36)*(1-ABS('projekty 2 i 3'!G16/Arkusz1!C$39)) -> -0.00018378734 | F16: =RADIANS(L16) -> -0.02411828 | G16: =B16 -> 0.010498949 | H16: =C16 -> 0.0056856947 | I16: =A16 -> -1.4155822 | J16: =H16+E16 -> 0.0055019074 | K16: =DEGREES(G16*(1+Arkusz1!C$49)/Arkusz1!C$23/PI()) -> 0.03370653 | L16: =I16+K16 -> -1.3818757 | M16: =G16^2*(1+Arkusz1!C$48)/Arkusz1!C$23/PI() -> 6.0824031e-06 | N16: =J16+M16+Arkusz1!C$41 -> 0.0062333648 | O16: =Arkusz1!C$34/Arkusz1!C$80+(Arkusz1!C$71-Arkusz1!C$32)/Arkusz1!C$80*'projekty 2 i 3'!G16 -> -0.065288785 | P16: =Arkusz1!C$75+Arkusz1!C$76+1/PI()/Arkusz1!C$79*'projekty 2 i 3'!O16^2 -> 0.0086120135 | Q16: =Arkusz1!C$90*(1+1/Arkusz1!C$91*ABS('projekty 2 i 3'!G16)) -> 0.0071863289 | R16: =(N16+Q16+P16*Arkusz1!C$70/Arkusz1!C$5)*(1+Arkusz1!C$92) -> 0.015643091 | S16: =O16*Arkusz1!C$70/Arkusz1!C$5 -> -0.014530522 | T16: =G16+S16 -> -0.0040315734 | U16: =T16/R16 -> -0.2577223 | V16: =T16^3/R16^2 -> -0.00026778027 | W16: =I16 -> -1.4155822 | X16: =T16^2 -> 1.6253584e-05 | Y16: =U16/10 -> -0.02577223 | Z16: =V16/100 -> -2.6778027e-06
A17: -0.75353753 | B17: 0.058980224 | C17: 0.0052213508 | D17: =RADIANS(A17) -> -0.013151711 | E17: =(Arkusz1!C$38-Arkusz1!C$36)*(1-ABS('projekty 2 i 3'!G17/Arkusz1!C$39)) -> -7.5545257e-05 | F17: =RADIANS(L17) -> -0.009846859 | G17: =B17 -> 0.058980224 | H17: =C17 -> 0.0052213508 | I17: =A17 -> -0.75353753 | J17: =H17+E17 -> 0.0051458056 | K17: =DEGREES(G17*(1+Arkusz1!C$49)/Arkusz1!C$23/PI()) -> 0.18935407 | L17: =I17+K17 -> -0.56418346 | M17: =G17^2*(1+Arkusz1!C$48)/Arkusz1!C$23/PI() -> 0.00019195366 | N17: =J17+M17+Arkusz1!C$41 -> 0.0060631343 | O17: =Arkusz1!C$34/Arkusz1!C$80+(Arkusz1!C$71-Arkusz1!C$32)/Arkusz1!C$80*'projekty 2 i 3'!G17 -> -0.063680674 | P17: =Arkusz1!C$75+Arkusz1!C$76+1/PI()/Arkusz1!C$79*'projekty 2 i 3'!O17^2 -> 0.0085871016 | Q17: =Arkusz1!C$90*(1+1/Arkusz1!C$91*ABS('projekty 2 i 3'!G17)) -> 0.0072442946 | R17: =(N17+Q17+P17*Arkusz1!C$70/Arkusz1!C$5)*(1+Arkusz1!C$92) -> 0.015522926 | S17: =O17*Arkusz1!C$70/Arkusz1!C$5 -> -0.014172625 | T17: =G17+S17 -> 0.044807599 | U17: =T17/R17 -> 2.8865434 | V17: =T17^3/R17^2 -> 0.37334288 | W17: =I17 -> -0.75353753 | X17: =T17^2 -> 0.0020077209 | Y17: =U17/10 -> 0.28865434 | Z17: =V17/100 -> 0.0037334288
A18: =DEGREES((B18-0.1382)/6.2313) -> -0.65810406 | B18: 0.066626773 | C18: 0.0048026093 | D18: =RADIANS(A18) -> -0.011486083 | E18: =(Arkusz1!C$38-Arkusz1!C$36)*(1-ABS('projekty 2 i 3'!G18/Arkusz1!C$39)) -> -5.8473131e-05 | F18: =RADIANS(L18) -> -0.0077527698 | G18: =B18 -> 0.066626773 | H18: =C18 -> 0.0048026093 | I18: =A18 -> -0.65810406 | J18: =H18+E21 -> 0.0048358339 | K18: =DEGREES(G18*(1+Arkusz1!C$49)/Arkusz1!C$23/PI()) -> 0.21390307 | L18: =I18+K18 -> -0.44420099 | M18: =G18^2*(1+Arkusz1!C$48)/Arkusz1!C$23/PI() -> 0.00024495208 | N18: =J18+M18+Arkusz1!C$41 -> 0.0058061611 | O18: =Arkusz1!C$34/Arkusz1!C$80+(Arkusz1!C$71-Arkusz1!C$32)/Arkusz1!C$80*'projekty 2 i 3'!G18 -> -0.06342704 | P18: =Arkusz1!C$75+Arkusz1!C$76+1/PI()/Arkusz1!C$79*'projekty 2 i 3'!O18^2 -> 0.0085832292 | Q18: =Arkusz1!C$90*(1+1/Arkusz1!C$91*ABS('projekty 2 i 3'!G18)) -> 0.007253437 | R18: =(N18+Q18+P18*Arkusz1!C$70/Arkusz1!C$5)*(1+Arkusz1!C$92) -> 0.015269259 | S18: =O18*Arkusz1!C$70/Arkusz1!C$5 -> -0.014116177 | T18: =G18+S18 -> 0.052510597 | U18: =T18/R18 -> 3.4389748 | V18: =T18^3/R18^2 -> 0.62101906 | W18: =I18 -> -0.65810406 | X18: =T18^2 -> 0.0027573628 | Y18: =U18/10 -> 0.34389748 | Z18: =V18/100 -> 0.0062101906
A19: =DEGREES((B19-0.1382)/6.2313) -> -0.55502835 | B19: 0.077836948 | C19: 0.0047258627 | D19: =RADIANS(A19) -> -0.0096870721 | E19: =(Arkusz1!C$38-Arkusz1!C$36)*(1-ABS('projekty 2 i 3'!G19/Arkusz1!C$39)) -> -3.3444651e-05 | F19: =RADIANS(L19) -> -0.0053256171 | G19: =B19 -> 0.077836948 | H19: =C19 -> 0.0047258627 | I19: =A19 -> -0.55502835 | J19: =H19+E23 -> 0.0048847798 | K19: =DEGREES(G19*(1+Arkusz1!C$49)/Arkusz1!C$23/PI()) -> 0.24989297 | L19: =I19+K19 -> -0.30513538 | M19: =G19^2*(1+Arkusz1!C$48)/Arkusz1!C$23/PI() -> 0.00033431446 | N19: =J19+M19+Arkusz1!C$41 -> 0.0059444693 | O19: =Arkusz1!C$34/Arkusz1!C$80+(Arkusz1!C$71-Arkusz1!C$32)/Arkusz1!C$80*'projekty 2 i 3'!G19 -> -0.063055202 | P19: =Arkusz1!C$75+Arkusz1!C$76+1/PI()/Arkusz1!C$79*'projekty 2 i 3'!O19^2 -> 0.00857758 | Q19: =Arkusz1!C$90*(1+1/Arkusz1!C$91*ABS('projekty 2 i 3'!G19)) -> 0.0072668402 | R19: =(N19+Q19+P19*Arkusz1!C$70/Arkusz1!C$5)*(1+Arkusz1!C$92) -> 0.015422722 | S19: =O19*Arkusz1!C$70/Arkusz1!C$5 -> -0.014033421 | T19: =G19+S19 -> 0.063803527 | U19: =T19/R19 -> 4.1369821 | V19: =T19^3/R19^2 -> 1.0919732 | W19: =I19 -> -0.55502835 | X19: =T19^2 -> 0.00407089 | Y19: =U19/10 -> 0.41369821 | Z19: =V19/100 -> 0.010919732
A20: =DEGREES((B20-0.1382)/6.2313) -> -0.41729201 | B20: 0.092816698 | C20: 0.0046487465 | D20: =RADIANS(A20) -> -0.0072831195 | E20: =(Arkusz1!C$38-Arkusz1!C$36)*(1-ABS('projekty 2 i 3'!G20/Arkusz1!C$39)) -> 0 | F20: =RADIANS(L20) -> -0.0020823008 | G20: =B20 -> 0.092816698 | H20: =C20 -> 0.0046487465 | I20: =A20 -> -0.41729201 | J20: =H20+E24 -> 0.0049170739 | K20: =DEGREES(G20*(1+Arkusz1!C$49)/Arkusz1!C$23/PI()) -> 0.29798496 | L20: =I20+K20 -> -0.11930705 | M20: =G20^2*(1+Arkusz1!C$48)/Arkusz1!C$23/PI() -> 0.0004753744 | N20: =J20+M20+Arkusz1!C$41 -> 0.0061178234 | O20: =Arkusz1!C$34/Arkusz1!C$80+(Arkusz1!C$71-Arkusz1!C$32)/Arkusz1!C$80*'projekty 2 i 3'!G20 -> -0.062558327 | P20: =Arkusz1!C$75+Arkusz1!C$76+1/PI()/Arkusz1!C$79*'projekty 2 i 3'!O20^2 -> 0.008570083 | Q20: =Arkusz1!C$90*(1+1/Arkusz1!C$91*ABS('projekty 2 i 3'!G20)) -> 0.0072847505 | R20: =(N20+Q20+P20*Arkusz1!C$70/Arkusz1!C$5)*(1+Arkusz1!C$92) -> 0.01561611 | S20: =O20*Arkusz1!C$70/Arkusz1!C$5 -> -0.013922838 | T20: =G20+S20 -> 0.07889386 | U20: =T20/R20 -> 5.0520814 | V20: =T20^3/R20^2 -> 2.0136495 | W20: =I20 -> -0.41729201 | X20: =T20^2 -> 0.0062242411 | Y20: =U20/10 -> 0.50520814 | Z20: =V20/100 -> 0.020136495
A21: =DEGREES((B21-0.1382)/6.2313) -> -0.28046183 | B21: 0.1076979 | C21: 0.0044959925 | D21: =RADIANS(A21) -> -0.0048949824 | E21: =(Arkusz1!C$38-Arkusz1!C$36)*(1-ABS('projekty 2 i 3'!G21/Arkusz1!C$39)) -> 3.322462e-05 | F21: =RADIANS(L21) -> 0.0011396778 | G21: =B21 -> 0.1076979 | H21: =C21 -> 0.0044959925 | I21: =A21 -> -0.28046183 | J21: =H21+E25 -> 0.0048653139 | K21: =DEGREES(G21*(1+Arkusz1!C$49)/Arkusz1!C$23/PI()) -> 0.34576056 | L21: =I21+K21 -> 0.065298729 | M21: =G21^2*(1+Arkusz1!C$48)/Arkusz1!C$23/PI() -> 0.00064002658 | N21: =J21+M21+Arkusz1!C$41 -> 0.0062307155 | O21: =Arkusz1!C$34/Arkusz1!C$80+(Arkusz1!C$71-Arkusz1!C$32)/Arkusz1!C$80*'projekty 2 i 3'!G21 -> -0.062064722 | P21: =Arkusz1!C$75+Arkusz1!C$76+1/PI()/Arkusz1!C$79*'projekty 2 i 3'!O21^2 -> 0.008562694 | Q21: =Arkusz1!C$90*(1+1/Arkusz1!C$91*ABS('projekty 2 i 3'!G21)) -> 0.0073025429 | R21: =(N21+Q21+P21*Arkusz1!C$70/Arkusz1!C$5)*(1+Arkusz1!C$92) -> 0.015747731 | S21: =O21*Arkusz1!C$70/Arkusz1!C$5 -> -0.013812982 | T21: =G21+S21 -> 0.093884914 | U21: =T21/R21 -> 5.9618058 | V21: =T21^3/R21^2 -> 3.3369636 | W21: =I21 -> -0.28046183 | X21: =T21^2 -> 0.0088143771 | Y21: =U21/10 -> 0.59618058 | Z21: =V21/100 -> 0.033369636
A22: =DEGREES((B22-0.1382)/6.2313) -> -0.038743621 | B22: 0.13398637 | C22: 0.0044177677 | D22: =RADIANS(A22) -> -0.00067620375 | E22: =(Arkusz1!C$38-Arkusz1!C$36)*(1-ABS('projekty 2 i 3'!G22/Arkusz1!C$39)) -> 9.1917782e-05 | F22: =RADIANS(L22) -> 0.0068314844 | G22: =B22 -> 0.13398637 | H22: =C22 -> 0.0044177677 | I22: =A22 -> -0.038743621 | J22: =H22+E26 -> 0.0048716908 | K22: =DEGREES(G22*(1+Arkusz1!C$49)/Arkusz1!C$23/PI()) -> 0.43015885 | L22: =I22+K22 -> 0.39141523 | M22: =G22^2*(1+Arkusz1!C$48)/Arkusz1!C$23/PI() -> 0.00099061483 | N22: =J22+M22+Arkusz1!C$41 -> 0.0065876807 | O22: =Arkusz1!C$34/Arkusz1!C$80+(Arkusz1!C$71-Arkusz1!C$32)/Arkusz1!C$80*'projekty 2 i 3'!G22 -> -0.061192741 | P22: =Arkusz1!C$75+Arkusz1!C$76+1/PI()/Arkusz1!C$79*'projekty 2 i 3'!O22^2 -> 0.0085497841 | Q22: =Arkusz1!C$90*(1+1/Arkusz1!C$91*ABS('projekty 2 i 3'!G22)) -> 0.0073339741 | R22: =(N22+Q22+P22*Arkusz1!C$70/Arkusz1!C$5)*(1+Arkusz1!C$92) -> 0.016140965 | S22: =O22*Arkusz1!C$70/Arkusz1!C$5 -> -0.013618916 | T22: =G22+S22 -> 0.12036746 | U22: =T22/R22 -> 7.4572653 | V22: =T22^3/R22^2 -> 6.6937312 | W22: =I22 -> -0.038743621 | X22: =T22^2 -> 0.014488324 | Y22: =U22/10 -> 0.74572653 | Z22: =V22/100 -> 0.066937312
A23: =DEGREES((B23-0.1382)/6.2313) -> 0.23718213 | B23: 0.16399515 | C23: 0.0043013543 | D23: =RADIANS(A23) -> 0.0041396092 | E23: =(Arkusz1!C$38-Arkusz1!C$36)*(1-ABS('projekty 2 i 3'!G23/Arkusz1!C$39)) -> 0.0001589171 | F23: =RADIANS(L23) -> 0.013328786 | G23: =B23 -> 0.16399515 | H23: =C23 -> 0.0043013543 | I23: =A23 -> 0.23718213 | J23: =H23+E23 -> 0.0044602714 | K23: =DEGREES(G23*(1+Arkusz1!C$49)/Arkusz1!C$23/PI()) -> 0.52650103 | L23: =I23+K23 -> 0.76368317 | M23: =G23^2*(1+Arkusz1!C$48)/Arkusz1!C$23/PI() -> 0.0014840398 | N23: =J23+M23+Arkusz1!C$41 -> 0.0066696864 | O23: =Arkusz1!C$34/Arkusz1!C$80+(Arkusz1!C$71-Arkusz1!C$32)/Arkusz1!C$80*'projekty 2 i 3'!G23 -> -0.060197358 | P23: =Arkusz1!C$75+Arkusz1!C$76+1/PI()/Arkusz1!C$79*'projekty 2 i 3'!O23^2 -> 0.0085352704 | Q23: =Arkusz1!C$90*(1+1/Arkusz1!C$91*ABS('projekty 2 i 3'!G23)) -> 0.0073698535 | R23: =(N23+Q23+P23*Arkusz1!C$70/Arkusz1!C$5)*(1+Arkusz1!C$92) -> 0.016257913 | S23: =O23*Arkusz1!C$70/Arkusz1!C$5 -> -0.013397386 | T23: =G23+S23 -> 0.15059776 | U23: =T23/R23 -> 9.263044 | V23: =T23^3/R23^2 -> 12.921888 | W23: =I23 -> 0.23718213 | X23: =T23^2 -> 0.022679686 | Y23: =U23/10 -> 0.9263044 | Z23: =V23/100 -> 0.12921888
A24: =DEGREES((B24-0.1382)/6.2313) -> 0.68777025 | B24: 0.21299962 | C24: 0.00429655 | D24: =RADIANS(A24) -> 0.012003855 | E24: =(Arkusz1!C$38-Arkusz1!C$36)*(1-ABS('projekty 2 i 3'!G24/Arkusz1!C$39)) -> 0.00026832731 | F24: =RADIANS(L24) -> 0.023938911 | G24: =B24 -> 0.21299962 | H24: =C24 -> 0.00429655 | I24: =A24 -> 0.68777025 | J24: =H24+E24 -> 0.0045648773 | K24: =DEGREES(G24*(1+Arkusz1!C$49)/Arkusz1!C$23/PI()) -> 0.6838283 | L24: =I24+K24 -> 1.3715985 | M24: =G24^2*(1+Arkusz1!C$48)/Arkusz1!C$23/PI() -> 0.0025034634 | N24: =J24+M24+Arkusz1!C$41 -> 0.0077937157 | O24: =Arkusz1!C$34/Arkusz1!C$80+(Arkusz1!C$71-Arkusz1!C$32)/Arkusz1!C$80*'projekty 2 i 3'!G24 -> -0.058571893 | P24: =Arkusz1!C$75+Arkusz1!C$76+1/PI()/Arkusz1!C$79*'projekty 2 i 3'!O24^2 -> 0.0085120812 | Q24: =Arkusz1!C$90*(1+1/Arkusz1!C$91*ABS('projekty 2 i 3'!G24)) -> 0.0074284447 | R24: =(N24+Q24+P24*Arkusz1!C$70/Arkusz1!C$5)*(1+Arkusz1!C$92) -> 0.017458921 | S24: =O24*Arkusz1!C$70/Arkusz1!C$5 -> -0.013035626 | T24: =G24+S24 -> 0.199964 | U24: =T24/R24 -> 11.453399 | V24: =T24^3/R24^2 -> 26.231348 | W24: =I24 -> 0.68777025 | X24: =T24^2 -> 0.0399856 | Y24: =U24/10 -> 1.1453399 | Z24: =V24/100 -> 0.26231348
A25: =DEGREES((B25-0.1382)/6.2313) -> 1.1036977 | B25: 0.25823453 | C25: 0.0042921152 | D25: =RADIANS(A25) -> 0.01926316 | E25: =(Arkusz1!C$38-Arkusz1!C$36)*(1-ABS('projekty 2 i 3'!G25/Arkusz1!C$39)) -> 0.00036932136 | F25: =RADIANS(L25) -> 0.033732872 | G25: =B25 -> 0.25823453 | H25: =C25 -> 0.0042921152 | I25: =A25 -> 1.1036977 | J25: =H25+E25 -> 0.0046614365 | K25: =DEGREES(G25*(1+Arkusz1!C$49)/Arkusz1!C$23/PI()) -> 0.82905347 | L25: =I25+K25 -> 1.9327512 | M25: =G25^2*(1+Arkusz1!C$48)/Arkusz1!C$23/PI() -> 0.0036796981 | N25: =J25+M25+Arkusz1!C$41 -> 0.0090665097 | O25: =Arkusz1!C$34/Arkusz1!C$80+(Arkusz1!C$71-Arkusz1!C$32)/Arkusz1!C$80*'projekty 2 i 3'!G25 -> -0.057071464 | P25: =Arkusz1!C$75+Arkusz1!C$76+1/PI()/Arkusz1!C$79*'projekty 2 i 3'!O25^2 -> 0.0084912391 | Q25: =Arkusz1!C$90*(1+1/Arkusz1!C$91*ABS('projekty 2 i 3'!G25)) -> 0.0074825289 | R25: =(N25+Q25+P25*Arkusz1!C$70/Arkusz1!C$5)*(1+Arkusz1!C$92) -> 0.018807606 | S25: =O25*Arkusz1!C$70/Arkusz1!C$5 -> -0.012701694 | T25: =G25+S25 -> 0.24553283 | U25: =T25/R25 -> 13.054975 | V25: =T25^3/R25^2 -> 41.846746 | W25: =I25 -> 1.1036977 | X25: =T25^2 -> 0.060286372 | Y25: =U25/10 -> 1.3054975 | Z25: =V25/100 -> 0.41846746
A26: =DEGREES((B26-0.1382)/6.2313) -> 1.4521163 | B26: 0.29612738 | C26: 0.0044396953 | D26: =RADIANS(A26) -> 0.025344211 | E26: =(Arkusz1!C$38-Arkusz1!C$36)*(1-ABS('projekty 2 i 3'!G26/Arkusz1!C$39)) -> 0.00045392312 | F26: =RADIANS(L26) -> 0.041937182 | G26: =B26 -> 0.29612738 | H26: =C26 -> 0.0044396953 | I26: =A26 -> 1.4521163 | J26: =H26+E26 -> 0.0048936184 | K26: =DEGREES(G26*(1+Arkusz1!C$49)/Arkusz1!C$23/PI()) -> 0.95070723 | L26: =I26+K26 -> 2.4028235 | M26: =G26^2*(1+Arkusz1!C$48)/Arkusz1!C$23/PI() -> 0.0048388337 | N26: =J26+M26+Arkusz1!C$41 -> 0.010457827 | O26: =Arkusz1!C$34/Arkusz1!C$80+(Arkusz1!C$71-Arkusz1!C$32)/Arkusz1!C$80*'projekty 2 i 3'!G26 -> -0.055814568 | P26: =Arkusz1!C$75+Arkusz1!C$76+1/PI()/Arkusz1!C$79*'projekty 2 i 3'!O26^2 -> 0.0084741962 | Q26: =Arkusz1!C$90*(1+1/Arkusz1!C$91*ABS('projekty 2 i 3'!G26)) -> 0.0075278347 | R26: =(N26+Q26+P26*Arkusz1!C$70/Arkusz1!C$5)*(1+Arkusz1!C$92) -> 0.020269093 | S26: =O26*Arkusz1!C$70/Arkusz1!C$5 -> -0.012421962 | T26: =G26+S26 -> 0.28370542 | U26: =T26/R26 -> 13.996947 | V26: =T26^3/R26^2 -> 55.582013 | W26: =I26 -> 1.4521163 | X26: =T26^2 -> 0.080488764 | Y26: =U26/10 -> 1.3996947 | Z26: =V26/100 -> 0.55582013
A27: =DEGREES((B27-0.1382)/6.2313) -> 2.3623541 | B27: 0.39512184 | C27: 0.0051864654 | D27: =RADIANS(A27) -> 0.041230858 | E27: =(Arkusz1!C$38-Arkusz1!C$36)*(1-ABS('projekty 2 i 3'!G27/Arkusz1!C$39)) -> 0.00067494385 | F27: =RADIANS(L27) -> 0.063370808 | G27: =B27 -> 0.39512184 | H27: =C27 -> 0.0051864654 | I27: =A27 -> 2.3623541 | J27: =H27+E27 -> 0.0058614092 | K27: =DEGREES(G27*(1+Arkusz1!C$49)/Arkusz1!C$23/PI()) -> 1.2685257 | L27: =I27+K27 -> 3.6308798 | M27: =G27^2*(1+Arkusz1!C$48)/Arkusz1!C$23/PI() -> 0.008614809 | N27: =J27+M27+Arkusz1!C$41 -> 0.015201593 | O27: =Arkusz1!C$34/Arkusz1!C$80+(Arkusz1!C$71-Arkusz1!C$32)/Arkusz1!C$80*'projekty 2 i 3'!G27 -> -0.052530949 | P27: =Arkusz1!C$75+Arkusz1!C$76+1/PI()/Arkusz1!C$79*'projekty 2 i 3'!O27^2 -> 0.0084314628 | Q27: =Arkusz1!C$90*(1+1/Arkusz1!C$91*ABS('projekty 2 i 3'!G27)) -> 0.0076461954 | R27: =(N27+Q27+P27*Arkusz1!C$70/Arkusz1!C$5)*(1+Arkusz1!C$92) -> 0.025218761 | S27: =O27*Arkusz1!C$70/Arkusz1!C$5 -> -0.011691167 | T27: =G27+S27 -> 0.38343068 | U27: =T27/R27 -> 15.204184 | V27: =T27^3/R27^2 -> 88.636597 | W27: =I27 -> 2.3623541 | X27: =T27^2 -> 0.14701908 | Y27: =U27/10 -> 1.5204184 | Z27: =V27/100 -> 0.88636597
A28: 3.3541702 | B28: 0.50195346 | C28: 0.0059162595 | D28: =RADIANS(A28) -> 0.058541314 | E28: =(Arkusz1!C$38-Arkusz1!C$36)*(1-ABS('projekty 2 i 3'!G28/Arkusz1!C$39)) -> 0.00091346226 | F28: =RADIANS(L28) -> 0.086667384 | G28: =B28 -> 0.50195346 | H28: =C28 -> 0.0059162595 | I28: =A28 -> 3.3541702 | J28: =H28+E28 -> 0.0068297218 | K28: =DEGREES(G28*(1+Arkusz1!C$49)/Arkusz1!C$23/PI()) -> 1.6115051 | L28: =I28+K28 -> 4.9656753 | M28: =G28^2*(1+Arkusz1!C$48)/Arkusz1!C$23/PI() -> 0.013903062 | N28: =J28+M28+Arkusz1!C$41 -> 0.021458159 | O28: =Arkusz1!C$34/Arkusz1!C$80+(Arkusz1!C$71-Arkusz1!C$32)/Arkusz1!C$80*'projekty 2 i 3'!G28 -> -0.048987374 | P28: =Arkusz1!C$75+Arkusz1!C$76+1/PI()/Arkusz1!C$79*'projekty 2 i 3'!O28^2 -> 0.0083882522 | Q28: =Arkusz1!C$90*(1+1/Arkusz1!C$91*ABS('projekty 2 i 3'!G28)) -> 0.0077739264 | R28: =(N28+Q28+P28*Arkusz1!C$70/Arkusz1!C$5)*(1+Arkusz1!C$92) -> 0.031720935 | S28: =O28*Arkusz1!C$70/Arkusz1!C$5 -> -0.010902518 | T28: =G28+S28 -> 0.49105094 | U28: =T28/R28 -> 15.480343 | V28: =T28^3/R28^2 -> 117.67594 | W28: =I28 -> 3.3541702 | X28: =T28^2 -> 0.24113103 | Y28: =U28/10 -> 1.5480343 | Z28: =V28/100 -> 1.1767594
A29: 4.573128 | B29: 0.6207237 | C29: 0.0068303763 | D29: =RADIANS(A29) -> 0.079816141 | E29: =(Arkusz1!C$38-Arkusz1!C$36)*(1-ABS('projekty 2 i 3'!G29/Arkusz1!C$39)) -> 0.0011786355 | F29: =RADIANS(L29) -> 0.11459729 | G29: =B29 -> 0.6207237 | H29: =C29 -> 0.0068303763 | I29: =A29 -> 4.573128 | J29: =H29+E29 -> 0.0080090118 | K29: =DEGREES(G29*(1+Arkusz1!C$49)/Arkusz1!C$23/PI()) -> 1.9928131 | L29: =I29+K29 -> 6.5659411 | M29: =G29^2*(1+Arkusz1!C$48)/Arkusz1!C$23/PI() -> 0.021260831 | N29: =J29+M29+Arkusz1!C$41 -> 0.029995218 | O29: =Arkusz1!C$34/Arkusz1!C$80+(Arkusz1!C$71-Arkusz1!C$32)/Arkusz1!C$80*'projekty 2 i 3'!G29 -> -0.045047797 | P29: =Arkusz1!C$75+Arkusz1!C$76+1/PI()/Arkusz1!C$79*'projekty 2 i 3'!O29^2 -> 0.0083437538 | Q29: =Arkusz1!C$90*(1+1/Arkusz1!C$91*ABS('projekty 2 i 3'!G29)) -> 0.0079159316 | R29: =(N29+Q29+P29*Arkusz1!C$70/Arkusz1!C$5)*(1+Arkusz1!C$92) -> 0.040563478 | S29: =O29*Arkusz1!C$70/Arkusz1!C$5 -> -0.010025734 | T29: =G29+S29 -> 0.61069797 | U29: =T29/R29 -> 15.055365 | V29: =T29^3/R29^2 -> 138.42325 | W29: =I29 -> 4.573128 | X29: =T29^2 -> 0.37295201 | Y29: =U29/10 -> 1.5055365 | Z29: =V29/100 -> 1.3842325
A30: 6.1311587 | B30: 0.80992499 | C30: 0.0080016285 | D30: =RADIANS(A30) -> 0.10700891 | E30: =(Arkusz1!C$38-Arkusz1!C$36)*(1-ABS('projekty 2 i 3'!G30/Arkusz1!C$39)) -> 0.0016010572 | F30: =RADIANS(L30) -> 0.15239161 | G30: =B30 -> 0.80992499 | H30: =C30 -> 0.0080016285 | I30: =A30 -> 6.1311587 | J30: =H30+E30 -> 0.0096026857 | K30: =DEGREES(G30*(1+Arkusz1!C$49)/Arkusz1!C$23/PI()) -> 2.6002376 | L30: =I30+K30 -> 8.7313963 | M30: =G30^2*(1+Arkusz1!C$48)/Arkusz1!C$23/PI() -> 0.036197049 | N30: =J30+M30+Arkusz1!C$41 -> 0.04652511 | O30: =Arkusz1!C$34/Arkusz1!C$80+(Arkusz1!C$71-Arkusz1!C$32)/Arkusz1!C$80*'projekty 2 i 3'!G30 -> -0.038772043 | P30: =Arkusz1!C$75+Arkusz1!C$76+1/PI()/Arkusz1!C$79*'projekty 2 i 3'!O30^2 -> 0.0082805683 | Q30: =Arkusz1!C$90*(1+1/Arkusz1!C$91*ABS('projekty 2 i 3'!G30)) -> 0.0081421462 | R30: =(N30+Q30+P30*Arkusz1!C$70/Arkusz1!C$5)*(1+Arkusz1!C$92) -> 0.057640364 | S30: =O30*Arkusz1!C$70/Arkusz1!C$5 -> -0.0086290169 | T30: =G30+S30 -> 0.80129597 | U30: =T30/R30 -> 13.901647 | V30: =T30^3/R30^2 -> 154.85508 | W30: =I30 -> 6.1311587 | X30: =T30^2 -> 0.64207523 | Y30: =U30/10 -> 1.3901647 | Z30: =V30/100 -> 1.5485508
A31: 7.0167263 | B31: 0.89086918 | C31: 0.0087188223 | D31: =RADIANS(A31) -> 0.12246498 | E31: =(Arkusz1!C$38-Arkusz1!C$36)*(1-ABS('projekty 2 i 3'!G31/Arkusz1!C$39)) -> 0.0017817779 | F31: =RADIANS(L31) -> 0.17238325 | G31: =B31 -> 0.89086918 | H31: =C31 -> 0.0087188223 | I31: =A31 -> 7.0167263 | J31: =H31+E31 -> 0.0105006 | K31: =DEGREES(G31*(1+Arkusz1!C$49)/Arkusz1!C$23/PI()) -> 2.8601063 | L31: =I31+K31 -> 9.8768326 | M31: =G31^2*(1+Arkusz1!C$48)/Arkusz1!C$23/PI() -> 0.04379368 | N31: =J31+M31+Arkusz1!C$41 -> 0.055019655 | O31: =Arkusz1!C$34/Arkusz1!C$80+(Arkusz1!C$71-Arkusz1!C$32)/Arkusz1!C$80*'projekty 2 i 3'!G31 -> -0.036087146 | P31: =Arkusz1!C$75+Arkusz1!C$76+1/PI()/Arkusz1!C$79*'projekty 2 i 3'!O31^2 -> 0.0082564261 | Q31: =Arkusz1!C$90*(1+1/Arkusz1!C$91*ABS('projekty 2 i 3'!G31)) -> 0.0082389254 | R31: =(N31+Q31+P31*Arkusz1!C$70/Arkusz1!C$5)*(1+Arkusz1!C$92) -> 0.066398034 | S31: =O31*Arkusz1!C$70/Arkusz1!C$5 -> -0.0080314725 | T31: =G31+S31 -> 0.88283771 | U31: =T31/R31 -> 13.296142 | V31: =T31^3/R31^2 -> 156.07458 | W31: =I31 -> 7.0167263 | X31: =T31^2 -> 0.77940242 | Y31: =U31/10 -> 1.3296142 | Z31: =V31/100 -> 1.5607458
A32: 8.0168968 | B32: 1.0043473 | C32: 0.0092386646 | D32: =RADIANS(A32) -> 0.13992125 | E32: =(Arkusz1!C$38-Arkusz1!C$36)*(1-ABS('projekty 2 i 3'!G32/Arkusz1!C$39)) -> 0.0020351357 | F32: =RADIANS(L32) -> 0.19619806 | G32: =B32 -> 1.0043473 | H32: =C32 -> 0.0092386646 | I32: =A32 -> 8.0168968 | J32: =H32+E32 -> 0.0112738 | K32: =DEGREES(G32*(1+Arkusz1!C$49)/Arkusz1!C$23/PI()) -> 3.2244241 | L32: =I32+K32 -> 11.241321 | M32: =G32^2*(1+Arkusz1!C$48)/Arkusz1!C$23/PI() -> 0.055661055 | N32: =J32+M32+Arkusz1!C$41 -> 0.06766023 | O32: =Arkusz1!C$34/Arkusz1!C$80+(Arkusz1!C$71-Arkusz1!C$32)/Arkusz1!C$80*'projekty 2 i 3'!G32 -> -0.032323107 | P32: =Arkusz1!C$75+Arkusz1!C$76+1/PI()/Arkusz1!C$79*'projekty 2 i 3'!O32^2 -> 0.0082254962 | Q32: =Arkusz1!C$90*(1+1/Arkusz1!C$91*ABS('projekty 2 i 3'!G32)) -> 0.0083746032 | R32: =(N32+Q32+P32*Arkusz1!C$70/Arkusz1!C$5)*(1+Arkusz1!C$92) -> 0.07942279 | S32: =O32*Arkusz1!C$70/Arkusz1!C$5 -> -0.0071937566 | T32: =G32+S32 -> 0.99715358 | U32: =T32/R32 -> 12.555006 | V32: =T32^3/R32^2 -> 157.17949 | W32: =I32 -> 8.0168968 | X32: =T32^2 -> 0.99431525 | Y32: =U32/10 -> 1.2555006 | Z32: =V32/100 -> 1.5717949
A33: 8.6874657 | B33: 1.1017361 | C33: 0.0098242907 | D33: =RADIANS(A33) -> 0.15162488 | E33: =(Arkusz1!C$38-Arkusz1!C$36)*(1-ABS('projekty 2 i 3'!G33/Arkusz1!C$39)) -> 0.0022525715 | F33: =RADIANS(L33) -> 0.2133587 | G33: =B33 -> 1.1017361 | H33: =C33 -> 0.0098242907 | I33: =A33 -> 8.6874657 | J33: =H33+E33 -> 0.012076862 | K33: =DEGREES(G33*(1+Arkusz1!C$49)/Arkusz1!C$23/PI()) -> 3.5370875 | L33: =I33+K33 -> 12.224553 | M33: =G33^2*(1+Arkusz1!C$48)/Arkusz1!C$23/PI() -> 0.06697901 | N33: =J33+M33+Arkusz1!C$41 -> 0.079781247 | O33: =Arkusz1!C$34/Arkusz1!C$80+(Arkusz1!C$71-Arkusz1!C$32)/Arkusz1!C$80*'projekty 2 i 3'!G33 -> -0.029092749 | P33: =Arkusz1!C$75+Arkusz1!C$76+1/PI()/Arkusz1!C$79*'projekty 2 i 3'!O33^2 -> 0.0082016655 | Q33: =Arkusz1!C$90*(1+1/Arkusz1!C$91*ABS('projekty 2 i 3'!G33)) -> 0.0084910441 | R33: =(N33+Q33+P33*Arkusz1!C$70/Arkusz1!C$5)*(1+Arkusz1!C$92) -> 0.091899588 | S33: =O33*Arkusz1!C$70/Arkusz1!C$5 -> -0.0064748155 | T33: =G33+S33 -> 1.0952613 | U33: =T33/R33 -> 11.918022 | V33: =T33^3/R33^2 -> 155.57008 | W33: =I33 -> 8.6874657 | X33: =T33^2 -> 1.1995973 | Y33: =U33/10 -> 1.1918022 | Z33: =V33/100 -> 1.5557008
A34: 9.5758747 | B34: 1.1989828 | C34: 0.011067327 | D34: =RADIANS(A34) -> 0.16713054 | E34: =(Arkusz1!C$38-Arkusz1!C$36)*(1-ABS('projekty 2 i 3'!G34/Arkusz1!C$39)) -> 0.00246969 | F34: =RADIANS(L34) -> 0.23431341 | G34: =B34 -> 1.1989828 | H34: =C34 -> 0.011067327 | I34: =A34 -> 9.5758747 | J34: =H34+E34 -> 0.013537017 | K34: =DEGREES(G34*(1+Arkusz1!C$49)/Arkusz1!C$23/PI()) -> 3.8492949 | L34: =I34+K34 -> 13.42517 | M34: =G34^2*(1+Arkusz1!C$48)/Arkusz1!C$23/PI() -> 0.079324887 | N34: =J34+M34+Arkusz1!C$41 -> 0.093587279 | O34: =Arkusz1!C$34/Arkusz1!C$80+(Arkusz1!C$71-Arkusz1!C$32)/Arkusz1!C$80*'projekty 2 i 3'!G34 -> -0.025867103 | P34: =Arkusz1!C$75+Arkusz1!C$76+1/PI()/Arkusz1!C$79*'projekty 2 i 3'!O34^2 -> 0.0081803711 | Q34: =Arkusz1!C$90*(1+1/Arkusz1!C$91*ABS('projekty 2 i 3'!G34)) -> 0.0086073151 | R34: =(N34+Q34+P34*Arkusz1!C$70/Arkusz1!C$5)*(1+Arkusz1!C$92) -> 0.1060955 | S34: =O34*Arkusz1!C$70/Arkusz1!C$5 -> -0.0057569231 | T34: =G34+S34 -> 1.1932259 | U34: =T34/R34 -> 11.246715 | V34: =T34^3/R34^2 -> 150.92946 | W34: =I34 -> 9.5758747 | X34: =T34^2 -> 1.4237879 | Y34: =U34/10 -> 1.1246715 | Z34: =V34/100 -> 1.5092946
A35: 10.575098 | B35: 1.3070268 | C35: 0.012442787 | D35: =RADIANS(A35) -> 0.18457028 | E35: =(Arkusz1!C$38-Arkusz1!C$36)*(1-ABS('projekty 2 i 3'!G35/Arkusz1!C$39)) -> 0.0027109152 | F35: =RADIANS(L35) -> 0.2578072 | G35: =B35 -> 1.3070268 | H35: =C35 -> 0.012442787 | I35: =A35 -> 10.575098 | J35: =H35+E35 -> 0.015153703 | K35: =DEGREES(G35*(1+Arkusz1!C$49)/Arkusz1!C$23/PI()) -> 4.1961665 | L35: =I35+K35 -> 14.771265 | M35: =G35^2*(1+Arkusz1!C$48)/Arkusz1!C$23/PI() -> 0.094265447 | N35: =J35+M35+Arkusz1!C$41 -> 0.11014453 | O35: =Arkusz1!C$34/Arkusz1!C$80+(Arkusz1!C$71-Arkusz1!C$32)/Arkusz1!C$80*'projekty 2 i 3'!G35 -> -0.022283314 | P35: =Arkusz1!C$75+Arkusz1!C$76+1/PI()/Arkusz1!C$79*'projekty 2 i 3'!O35^2 -> 0.0081596436 | Q35: =Arkusz1!C$90*(1+1/Arkusz1!C$91*ABS('projekty 2 i 3'!G35)) -> 0.0087364957 | R35: =(N35+Q35+P35*Arkusz1!C$70/Arkusz1!C$5)*(1+Arkusz1!C$92) -> 0.12311095 | S35: =O35*Arkusz1!C$70/Arkusz1!C$5 -> -0.0049593232 | T35: =G35+S35 -> 1.3020674 | U35: =T35/R35 -> 10.576374 | V35: =T35^3/R35^2 -> 145.64885 | W35: =I35 -> 10.575098 | X35: =T35^2 -> 1.6953796 | Y35: =U35/10 -> 1.0576374 | Z35: =V35/100 -> 1.4564885
A36: 11.23809 | B36: 1.3609422 | C36: 0.013426116 | D36: =RADIANS(A36) -> 0.19614167 | E36: =(Arkusz1!C$38-Arkusz1!C$36)*(1-ABS('projekty 2 i 3'!G36/Arkusz1!C$39)) -> 0.0028312899 | F36: =RADIANS(L36) -> 0.27239965 | G36: =B36 -> 1.3609422 | H36: =C36 -> 0.013426116 | I36: =A36 -> 11.23809 | J36: =H36+E36 -> 0.016257406 | K36: =DEGREES(G36*(1+Arkusz1!C$49)/Arkusz1!C$23/PI()) -> 4.3692603 | L36: =I36+K36 -> 15.60735 | M36: =G36^2*(1+Arkusz1!C$48)/Arkusz1!C$23/PI() -> 0.10220283 | N36: =J36+M36+Arkusz1!C$41 -> 0.11918561 | O36: =Arkusz1!C$34/Arkusz1!C$80+(Arkusz1!C$71-Arkusz1!C$32)/Arkusz1!C$80*'projekty 2 i 3'!G36 -> -0.020494953 | P36: =Arkusz1!C$75+Arkusz1!C$76+1/PI()/Arkusz1!C$79*'projekty 2 i 3'!O36^2 -> 0.0081504543 | Q36: =Arkusz1!C$90*(1+1/Arkusz1!C$91*ABS('projekty 2 i 3'!G36)) -> 0.0088009585 | R36: =(N36+Q36+P36*Arkusz1!C$70/Arkusz1!C$5)*(1+Arkusz1!C$92) -> 0.13239653 | S36: =O36*Arkusz1!C$70/Arkusz1!C$5 -> -0.0045613098 | T36: =G36+S36 -> 1.3563809 | U36: =T36/R36 -> 10.244837 | V36: =T36^3/R36^2 -> 142.36125 | W36: =I36 -> 11.23809 | X36: =T36^2 -> 1.8397691 | Y36: =U36/10 -> 1.0244837 | Z36: =V36/100 -> 1.4236125
A37: 12.989335 | B37: 1.4087131 | C37: 0.014014742 | D37: =RADIANS(A37) -> 0.22670667 | E37: =(Arkusz1!C$38-Arkusz1!C$36)*(1-ABS('projekty 2 i 3'!G37/Arkusz1!C$39)) -> 0.002937946 | F37: =RADIANS(L37) -> 0.30564141 | G37: =B37 -> 1.4087131 | H37: =C37 -> 0.014014742 | I37: =A37 -> 12.989335 | J37: =H37+E37 -> 0.016952688 | K37: =DEGREES(G37*(1+Arkusz1!C$49)/Arkusz1!C$23/PI()) -> 4.5226273 | L37: =I37+K37 -> 17.511963 | M37: =G37^2*(1+Arkusz1!C$48)/Arkusz1!C$23/PI() -> 0.10950368 | N37: =J37+M37+Arkusz1!C$41 -> 0.12718174 | O37: =Arkusz1!C$34/Arkusz1!C$80+(Arkusz1!C$71-Arkusz1!C$32)/Arkusz1!C$80*'projekty 2 i 3'!G37 -> -0.018910405 | P37: =Arkusz1!C$75+Arkusz1!C$76+1/PI()/Arkusz1!C$79*'projekty 2 i 3'!O37^2 -> 0.0081429542 | Q37: =Arkusz1!C$90*(1+1/Arkusz1!C$91*ABS('projekty 2 i 3'!G37)) -> 0.0088580749 | R37: =(N37+Q37+P37*Arkusz1!C$70/Arkusz1!C$5)*(1+Arkusz1!C$92) -> 0.14060913 | S37: =O37*Arkusz1!C$70/Arkusz1!C$5 -> -0.0042086563 | T37: =G37+S37 -> 1.4045045 | U37: =T37/R37 -> 9.9887144 | V37: =T37^3/R37^2 -> 140.13361 | W37: =I37 -> 12.989335 | X37: =T37^2 -> 1.9726328 | Y37: =U37/10 -> 0.99887144 | Z37: =V37/100 -> 1.4013361
A38: 13.745146 | B38: 1.3701767 | C38: =-0.0018*B38^4+0.003*B38^3+0.0059*B38^2-0.0032*B38+0.0055 -> 0.013564817 | D38: =RADIANS(A38) -> 0.23989805 | G38: Tabela 3.3 Charakterystyki aerodynamiczne samolotu PZL TS-11 Iskra
A39: 14.715955 | B39: 1.3151958 | C39: =-0.0018*B39^4+0.003*B39^3+0.0059*B39^2-0.0032*B39+0.0055 -> 0.012936079 | D39: =RADIANS(A39) -> 0.25684187
A40: 15.468925 | B40: 1.2603569 | C40: =-0.0018*B40^4+0.003*B40^3+0.0059*B40^2-0.0032*B40+0.0055 -> 0.012303239 | D40: =RADIANS(A40) -> 0.26998367

Sheet projekt 4
H1: mmin | I1: =Arkusz1!C99 -> 2640 | J1: mśr | K1: =Arkusz1!C100 -> 3240 | L1: mmax | M1: =Arkusz1!C7 -> 3840
B2: Cz | C2: Cx | D2: K | E2: A | F2: B | G2: γ [°] | H2: V [m/s] | I2: w [m/s] | J2: V [m/s] | K2: w [m/s] | L2: V [m/s] | M2: w [m/s]
A3: 1 | B3: =OFFSET('projekty 2 i 3'!$T$37,-A3+1,0,1,1) -> 1.4045045 | C3: =OFFSET('projekty 2 i 3'!$R$37,-A3+1,0,1,1) -> 0.14060913 | D3: =OFFSET('projekty 2 i 3'!$U$37,-A3+1,0,1,1) -> 9.9887144 | E3: =SQRT(1/SQRT(B3^2+C3^2)) -> 0.84169677 | F3: =SQRT(C3^2/(C3^2+B3^2)^(3/2)) -> 0.083845646 | G3: =DEGREES(ATAN(1/D3)) -> 5.7170024 | H3: ='projekt 4'!$E3*SQRT(2*Arkusz1!$C$16/Arkusz1!$C$5/Arkusz1!$C$101*'projekt 4'!I$1) -> 53.371723 | I3: ='projekt 4'!$F3*SQRT(2*Arkusz1!$C$16/Arkusz1!$C$5/Arkusz1!$C$101*'projekt 4'!I$1) -> 5.3166257 | J3: ='projekt 4'!$E3*SQRT(2*Arkusz1!$C$16/Arkusz1!$C$5/Arkusz1!$C$101*'projekt 4'!K$1) -> 59.126445 | K3: ='projekt 4'!$F3*SQRT(2*Arkusz1!$C$16/Arkusz1!$C$5/Arkusz1!$C$101*'projekt 4'!K$1) -> 5.8898824 | L3: ='projekt 4'!$E3*SQRT(2*Arkusz1!$C$16/Arkusz1!$C$5/Arkusz1!$C$101*'projekt 4'!M$1) -> 64.36872 | M3: ='projekt 4'!$F3*SQRT(2*Arkusz1!$C$16/Arkusz1!$C$5/Arkusz1!$C$101*'projekt 4'!M$1) -> 6.4120918 | O3: 0 | P3: 0
A4: 2 | B4: =OFFSET('projekty 2 i 3'!$T$37,-A4+1,0,1,1) -> 1.3563809 | C4: =OFFSET('projekty 2 i 3'!$R$37,-A4+1,0,1,1) -> 0.13239653 | D4: =OFFSET('projekty 2 i 3'!$U$37,-A4+1,0,1,1) -> 10.244837 | E4: =SQRT(1/SQRT(B4^2+C4^2)) -> 0.85660302 | F4: =SQRT(C4^2/(C4^2+B4^2)^(3/2)) -> 0.083217644 | G4: =DEGREES(ATAN(1/D4)) -> 5.5749882 | H4: ='projekt 4'!$E4*SQRT(2*Arkusz1!$C$16/Arkusz1!$C$5/Arkusz1!$C$101*'projekt 4'!I$1) -> 54.316924 | I4: ='projekt 4'!$F4*SQRT(2*Arkusz1!$C$16/Arkusz1!$C$5/Arkusz1!$C$101*'projekt 4'!I$1) -> 5.2768042 | J4: ='projekt 4'!$E4*SQRT(2*Arkusz1!$C$16/Arkusz1!$C$5/Arkusz1!$C$101*'projekt 4'!K$1) -> 60.173561 | K4: ='projekt 4'!$F4*SQRT(2*Arkusz1!$C$16/Arkusz1!$C$5/Arkusz1!$C$101*'projekt 4'!K$1) -> 5.8457673 | L4: ='projekt 4'!$E4*SQRT(2*Arkusz1!$C$16/Arkusz1!$C$5/Arkusz1!$C$101*'projekt 4'!M$1) -> 65.508675 | M4: ='projekt 4'!$F4*SQRT(2*Arkusz1!$C$16/Arkusz1!$C$5/Arkusz1!$C$101*'projekt 4'!M$1) -> 6.3640653 | O4: =Arkusz1!C102 -> 240 | P4: =O4*TAN(RADIANS(Arkusz1!C103)) -> 15.503533
A5: 3 | B5: =OFFSET('projekty 2 i 3'!$T$37,-A5+1,0,1,1) -> 1.3020674 | C5: =OFFSET('projekty 2 i 3'!$R$37,-A5+1,0,1,1) -> 0.12311095 | D5: =OFFSET('projekty 2 i 3'!$U$37,-A5+1,0,1,1) -> 10.576374 | E5: =SQRT(1/SQRT(B5^2+C5^2)) -> 0.87441369 | F5: =SQRT(C5^2/(C5^2+B5^2)^(3/2)) -> 0.082309041 | G5: =DEGREES(ATAN(1/D5)) -> 5.4012797 | H5: ='projekt 4'!$E5*SQRT(2*Arkusz1!$C$16/Arkusz1!$C$5/Arkusz1!$C$101*'projekt 4'!I$1) -> 55.446293 | I5: ='projekt 4'!$F5*SQRT(2*Arkusz1!$C$16/Arkusz1!$C$5/Arkusz1!$C$101*'projekt 4'!I$1) -> 5.21919 | J5: ='projekt 4'!$E5*SQRT(2*Arkusz1!$C$16/Arkusz1!$C$5/Arkusz1!$C$101*'projekt 4'!K$1) -> 61.424702 | K5: ='projekt 4'!$F5*SQRT(2*Arkusz1!$C$16/Arkusz1!$C$5/Arkusz1!$C$101*'projekt 4'!K$1) -> 5.7819409 | L5: ='projekt 4'!$E5*SQRT(2*Arkusz1!$C$16/Arkusz1!$C$5/Arkusz1!$C$101*'projekt 4'!M$1) -> 66.870745 | M5: ='projekt 4'!$F5*SQRT(2*Arkusz1!$C$16/Arkusz1!$C$5/Arkusz1!$C$101*'projekt 4'!M$1) -> 6.29458
A6: 4 | B6: =OFFSET('projekty 2 i 3'!$T$37,-A6+1,0,1,1) -> 1.1932259 | C6: =OFFSET('projekty 2 i 3'!$R$37,-A6+1,0,1,1) -> 0.1060955 | D6: =OFFSET('projekty 2 i 3'!$U$37,-A6+1,0,1,1) -> 11.246715 | E6: =SQRT(1/SQRT(B6^2+C6^2)) -> 0.91365804 | F6: =SQRT(C6^2/(C6^2+B6^2)^(3/2)) -> 0.080918536 | G6: =DEGREES(ATAN(1/D6)) -> 5.0810839 | H6: ='projekt 4'!$E6*SQRT(2*Arkusz1!$C$16/Arkusz1!$C$5/Arkusz1!$C$101*'projekt 4'!I$1) -> 57.934764 | I6: ='projekt 4'!$F6*SQRT(2*Arkusz1!$C$16/Arkusz1!$C$5/Arkusz1!$C$101*'projekt 4'!I$1) -> 5.1310185 | J6: ='projekt 4'!$E6*SQRT(2*Arkusz1!$C$16/Arkusz1!$C$5/Arkusz1!$C$101*'projekt 4'!K$1) -> 64.181489 | K6: ='projekt 4'!$F6*SQRT(2*Arkusz1!$C$16/Arkusz1!$C$5/Arkusz1!$C$101*'projekt 4'!K$1) -> 5.6842625 | L6: ='projekt 4'!$E6*SQRT(2*Arkusz1!$C$16/Arkusz1!$C$5/Arkusz1!$C$101*'projekt 4'!M$1) -> 69.871955 | M6: ='projekt 4'!$F6*SQRT(2*Arkusz1!$C$16/Arkusz1!$C$5/Arkusz1!$C$101*'projekt 4'!M$1) -> 6.1882411
A7: 5 | B7: =OFFSET('projekty 2 i 3'!$T$37,-A7+1,0,1,1) -> 1.0952613 | C7: =OFFSET('projekty 2 i 3'!$R$37,-A7+1,0,1,1) -> 0.091899588 | D7: =OFFSET('projekty 2 i 3'!$U$37,-A7+1,0,1,1) -> 11.918022 | E7: =SQRT(1/SQRT(B7^2+C7^2)) -> 0.95384854 | F7: =SQRT(C7^2/(C7^2+B7^2)^(3/2)) -> 0.079753881 | G7: =DEGREES(ATAN(1/D7)) -> 4.7962562 | H7: ='projekt 4'!$E7*SQRT(2*Arkusz1!$C$16/Arkusz1!$C$5/Arkusz1!$C$101*'projekt 4'!I$1) -> 60.483231 | I7: ='projekt 4'!$F7*SQRT(2*Arkusz1!$C$16/Arkusz1!$C$5/Arkusz1!$C$101*'projekt 4'!I$1) -> 5.0571681 | J7: ='projekt 4'!$E7*SQRT(2*Arkusz1!$C$16/Arkusz1!$C$5/Arkusz1!$C$101*'projekt 4'!K$1) -> 67.00474 | K7: ='projekt 4'!$F7*SQRT(2*Arkusz1!$C$16/Arkusz1!$C$5/Arkusz1!$C$101*'projekt 4'!K$1) -> 5.6024492 | L7: ='projekt 4'!$E7*SQRT(2*Arkusz1!$C$16/Arkusz1!$C$5/Arkusz1!$C$101*'projekt 4'!M$1) -> 72.945522 | M7: ='projekt 4'!$F7*SQRT(2*Arkusz1!$C$16/Arkusz1!$C$5/Arkusz1!$C$101*'projekt 4'!M$1) -> 6.0991742
A8: 6 | B8: =OFFSET('projekty 2 i 3'!$T$37,-A8+1,0,1,1) -> 0.99715358 | C8: =OFFSET('projekty 2 i 3'!$R$37,-A8+1,0,1,1) -> 0.07942279 | D8: =OFFSET('projekty 2 i 3'!$U$37,-A8+1,0,1,1) -> 12.555006 | E8: =SQRT(1/SQRT(B8^2+C8^2)) -> 0.99984425 | F8: =SQRT(C8^2/(C8^2+B8^2)^(3/2)) -> 0.079385687 | G8: =DEGREES(ATAN(1/D8)) -> 4.5539666 | H8: ='projekt 4'!$E8*SQRT(2*Arkusz1!$C$16/Arkusz1!$C$5/Arkusz1!$C$101*'projekt 4'!I$1) -> 63.399805 | I8: ='projekt 4'!$F8*SQRT(2*Arkusz1!$C$16/Arkusz1!$C$5/Arkusz1!$C$101*'projekt 4'!I$1) -> 5.033821 | J8: ='projekt 4'!$E8*SQRT(2*Arkusz1!$C$16/Arkusz1!$C$5/Arkusz1!$C$101*'projekt 4'!K$1) -> 70.235788 | K8: ='projekt 4'!$F8*SQRT(2*Arkusz1!$C$16/Arkusz1!$C$5/Arkusz1!$C$101*'projekt 4'!K$1) -> 5.5765848 | L8: ='projekt 4'!$E8*SQRT(2*Arkusz1!$C$16/Arkusz1!$C$5/Arkusz1!$C$101*'projekt 4'!M$1) -> 76.463041 | M8: ='projekt 4'!$F8*SQRT(2*Arkusz1!$C$16/Arkusz1!$C$5/Arkusz1!$C$101*'projekt 4'!M$1) -> 6.0710166
A9: 7 | B9: =OFFSET('projekty 2 i 3'!$T$37,-A9+1,0,1,1) -> 0.88283771 | C9: =OFFSET('projekty 2 i 3'!$R$37,-A9+1,0,1,1) -> 0.066398034 | D9: =OFFSET('projekty 2 i 3'!$U$37,-A9+1,0,1,1) -> 13.296142 | E9: =SQRT(1/SQRT(B9^2+C9^2)) -> 1.0627892 | F9: =SQRT(C9^2/(C9^2+B9^2)^(3/2)) -> 0.079707036 | G9: =DEGREES(ATAN(1/D9)) -> 4.3011057 | H9: ='projekt 4'!$E9*SQRT(2*Arkusz1!$C$16/Arkusz1!$C$5/Arkusz1!$C$101*'projekt 4'!I$1) -> 67.391126 | I9: ='projekt 4'!$F9*SQRT(2*Arkusz1!$C$16/Arkusz1!$C$5/Arkusz1!$C$101*'projekt 4'!I$1) -> 5.0541977 | J9: ='projekt 4'!$E9*SQRT(2*Arkusz1!$C$16/Arkusz1!$C$5/Arkusz1!$C$101*'projekt 4'!K$1) -> 74.657467 | K9: ='projekt 4'!$F9*SQRT(2*Arkusz1!$C$16/Arkusz1!$C$5/Arkusz1!$C$101*'projekt 4'!K$1) -> 5.5991585 | L9: ='projekt 4'!$E9*SQRT(2*Arkusz1!$C$16/Arkusz1!$C$5/Arkusz1!$C$101*'projekt 4'!M$1) -> 81.276755 | M9: ='projekt 4'!$F9*SQRT(2*Arkusz1!$C$16/Arkusz1!$C$5/Arkusz1!$C$101*'projekt 4'!M$1) -> 6.0955917
A10: 8 | B10: =OFFSET('projekty 2 i 3'!$T$37,-A10+1,0,1,1) -> 0.80129597 | C10: =OFFSET('projekty 2 i 3'!$R$37,-A10+1,0,1,1) -> 0.057640364 | D10: =OFFSET('projekty 2 i 3'!$U$37,-A10+1,0,1,1) -> 13.901647 | E10: =SQRT(1/SQRT(B10^2+C10^2)) -> 1.115689 | F10: =SQRT(C10^2/(C10^2+B10^2)^(3/2)) -> 0.08004905 | G10: =DEGREES(ATAN(1/D10)) -> 4.1144233 | H10: ='projekt 4'!$E10*SQRT(2*Arkusz1!$C$16/Arkusz1!$C$5/Arkusz1!$C$101*'projekt 4'!I$1) -> 70.745484 | I10: ='projekt 4'!$F10*SQRT(2*Arkusz1!$C$16/Arkusz1!$C$5/Arkusz1!$C$101*'projekt 4'!I$1) -> 5.0758847 | J10: ='projekt 4'!$E10*SQRT(2*Arkusz1!$C$16/Arkusz1!$C$5/Arkusz1!$C$101*'projekt 4'!K$1) -> 78.373504 | K10: ='projekt 4'!$F10*SQRT(2*Arkusz1!$C$16/Arkusz1!$C$5/Arkusz1!$C$101*'projekt 4'!K$1) -> 5.6231839 | L10: ='projekt 4'!$E10*SQRT(2*Arkusz1!$C$16/Arkusz1!$C$5/Arkusz1!$C$101*'projekt 4'!M$1) -> 85.322264 | M10: ='projekt 4'!$F10*SQRT(2*Arkusz1!$C$16/Arkusz1!$C$5/Arkusz1!$C$101*'projekt 4'!M$1) -> 6.1217472
A11: 9 | B11: =OFFSET('projekty 2 i 3'!$T$37,-A11+1,0,1,1) -> 0.61069797 | C11: =OFFSET('projekty 2 i 3'!$R$37,-A11+1,0,1,1) -> 0.040563478 | D11: =OFFSET('projekty 2 i 3'!$U$37,-A11+1,0,1,1) -> 15.055365 | E11: =SQRT(1/SQRT(B11^2+C11^2)) -> 1.2782294 | F11: =SQRT(C11^2/(C11^2+B11^2)^(3/2)) -> 0.084715254 | G11: =DEGREES(ATAN(1/D11)) -> 3.80009 | H11: ='projekt 4'!$E11*SQRT(2*Arkusz1!$C$16/Arkusz1!$C$5/Arkusz1!$C$101*'projekt 4'!I$1) -> 81.052119 | I11: ='projekt 4'!$F11*SQRT(2*Arkusz1!$C$16/Arkusz1!$C$5/Arkusz1!$C$101*'projekt 4'!I$1) -> 5.3717672 | J11: ='projekt 4'!$E11*SQRT(2*Arkusz1!$C$16/Arkusz1!$C$5/Arkusz1!$C$101*'projekt 4'!K$1) -> 89.791436 | K11: ='projekt 4'!$F11*SQRT(2*Arkusz1!$C$16/Arkusz1!$C$5/Arkusz1!$C$101*'projekt 4'!K$1) -> 5.9509695 | L11: ='projekt 4'!$E11*SQRT(2*Arkusz1!$C$16/Arkusz1!$C$5/Arkusz1!$C$101*'projekt 4'!M$1) -> 97.752534 | M11: ='projekt 4'!$F11*SQRT(2*Arkusz1!$C$16/Arkusz1!$C$5/Arkusz1!$C$101*'projekt 4'!M$1) -> 6.478595
A12: 10 | B12: =OFFSET('projekty 2 i 3'!$T$37,-A12+1,0,1,1) -> 0.49105094 | C12: =OFFSET('projekty 2 i 3'!$R$37,-A12+1,0,1,1) -> 0.031720935 | D12: =OFFSET('projekty 2 i 3'!$U$37,-A12+1,0,1,1) -> 15.480343 | E12: =SQRT(1/SQRT(B12^2+C12^2)) -> 1.425557 | F12: =SQRT(C12^2/(C12^2+B12^2)^(3/2)) -> 0.091896672 | G12: =DEGREES(ATAN(1/D12)) -> 3.6960604 | H12: ='projekt 4'!$E12*SQRT(2*Arkusz1!$C$16/Arkusz1!$C$5/Arkusz1!$C$101*'projekt 4'!I$1) -> 90.394117 | I12: ='projekt 4'!$F12*SQRT(2*Arkusz1!$C$16/Arkusz1!$C$5/Arkusz1!$C$101*'projekt 4'!I$1) -> 5.8271386 | J12: ='projekt 4'!$E12*SQRT(2*Arkusz1!$C$16/Arkusz1!$C$5/Arkusz1!$C$101*'projekt 4'!K$1) -> 100.14072 | K12: ='projekt 4'!$F12*SQRT(2*Arkusz1!$C$16/Arkusz1!$C$5/Arkusz1!$C$101*'projekt 4'!K$1) -> 6.4554406 | L12: ='projekt 4'!$E12*SQRT(2*Arkusz1!$C$16/Arkusz1!$C$5/Arkusz1!$C$101*'projekt 4'!M$1) -> 109.01941 | M12: ='projekt 4'!$F12*SQRT(2*Arkusz1!$C$16/Arkusz1!$C$5/Arkusz1!$C$101*'projekt 4'!M$1) -> 7.0277936
A13: 11 | B13: =OFFSET('projekty 2 i 3'!$T$37,-A13+1,0,1,1) -> 0.38343068 | C13: =OFFSET('projekty 2 i 3'!$R$37,-A13+1,0,1,1) -> 0.025218761 | D13: =OFFSET('projekty 2 i 3'!$U$37,-A13+1,0,1,1) -> 15.204184 | E13: =SQRT(1/SQRT(B13^2+C13^2)) -> 1.6131989 | F13: =SQRT(C13^2/(C13^2+B13^2)^(3/2)) -> 0.10587355 | G13: =DEGREES(ATAN(1/D13)) -> 3.7630021 | H13: ='projekt 4'!$E13*SQRT(2*Arkusz1!$C$16/Arkusz1!$C$5/Arkusz1!$C$101*'projekt 4'!I$1) -> 102.29242 | I13: ='projekt 4'!$F13*SQRT(2*Arkusz1!$C$16/Arkusz1!$C$5/Arkusz1!$C$101*'projekt 4'!I$1) -> 6.713408 | J13: ='projekt 4'!$E13*SQRT(2*Arkusz1!$C$16/Arkusz1!$C$5/Arkusz1!$C$101*'projekt 4'!K$1) -> 113.32194 | K13: ='projekt 4'!$F13*SQRT(2*Arkusz1!$C$16/Arkusz1!$C$5/Arkusz1!$C$101*'projekt 4'!K$1) -> 7.4372706 | L13: ='projekt 4'!$E13*SQRT(2*Arkusz1!$C$16/Arkusz1!$C$5/Arkusz1!$C$101*'projekt 4'!M$1) -> 123.36931 | M13: ='projekt 4'!$F13*SQRT(2*Arkusz1!$C$16/Arkusz1!$C$5/Arkusz1!$C$101*'projekt 4'!M$1) -> 8.0966747
A14: 12 | B14: =OFFSET('projekty 2 i 3'!$T$37,-A14+1,0,1,1) -> 0.28370542 | C14: =OFFSET('projekty 2 i 3'!$R$37,-A14+1,0,1,1) -> 0.020269093 | D14: =OFFSET('projekty 2 i 3'!$U$37,-A14+1,0,1,1) -> 13.996947 | E14: =SQRT(1/SQRT(B14^2+C14^2)) -> 1.8750524 | F14: =SQRT(C14^2/(C14^2+B14^2)^(3/2)) -> 0.13362094 | G14: =DEGREES(ATAN(1/D14)) -> 4.0865049 | H14: ='projekt 4'!$E14*SQRT(2*Arkusz1!$C$16/Arkusz1!$C$5/Arkusz1!$C$101*'projekt 4'!I$1) -> 118.89647 | I14: ='projekt 4'!$F14*SQRT(2*Arkusz1!$C$16/Arkusz1!$C$5/Arkusz1!$C$101*'projekt 4'!I$1) -> 8.4728612 | J14: ='projekt 4'!$E14*SQRT(2*Arkusz1!$C$16/Arkusz1!$C$5/Arkusz1!$C$101*'projekt 4'!K$1) -> 131.7163 | K14: ='projekt 4'!$F14*SQRT(2*Arkusz1!$C$16/Arkusz1!$C$5/Arkusz1!$C$101*'projekt 4'!K$1) -> 9.3864341 | L14: ='projekt 4'!$E14*SQRT(2*Arkusz1!$C$16/Arkusz1!$C$5/Arkusz1!$C$101*'projekt 4'!M$1) -> 143.39454 | M14: ='projekt 4'!$F14*SQRT(2*Arkusz1!$C$16/Arkusz1!$C$5/Arkusz1!$C$101*'projekt 4'!M$1) -> 10.218655
A15: 13 | B15: =OFFSET('projekty 2 i 3'!$T$37,-A15+1,0,1,1) -> 0.24553283 | C15: =OFFSET('projekty 2 i 3'!$R$37,-A15+1,0,1,1) -> 0.018807606 | D15: =OFFSET('projekty 2 i 3'!$U$37,-A15+1,0,1,1) -> 13.054975 | E15: =SQRT(1/SQRT(B15^2+C15^2)) -> 2.0151623 | F15: =SQRT(C15^2/(C15^2+B15^2)^(3/2)) -> 0.15390885 | G15: =DEGREES(ATAN(1/D15)) -> 4.3802543 | H15: ='projekt 4'!$E15*SQRT(2*Arkusz1!$C$16/Arkusz1!$C$5/Arkusz1!$C$101*'projekt 4'!I$1) -> 127.7808 | I15: ='projekt 4'!$F15*SQRT(2*Arkusz1!$C$16/Arkusz1!$C$5/Arkusz1!$C$101*'projekt 4'!I$1) -> 9.7593111 | J15: ='projekt 4'!$E15*SQRT(2*Arkusz1!$C$16/Arkusz1!$C$5/Arkusz1!$C$101*'projekt 4'!K$1) -> 141.55856 | K15: ='projekt 4'!$F15*SQRT(2*Arkusz1!$C$16/Arkusz1!$C$5/Arkusz1!$C$101*'projekt 4'!K$1) -> 10.811593 | L15: ='projekt 4'!$E15*SQRT(2*Arkusz1!$C$16/Arkusz1!$C$5/Arkusz1!$C$101*'projekt 4'!M$1) -> 154.10944 | M15: ='projekt 4'!$F15*SQRT(2*Arkusz1!$C$16/Arkusz1!$C$5/Arkusz1!$C$101*'projekt 4'!M$1) -> 11.770172
A16: 14 | B16: =OFFSET('projekty 2 i 3'!$T$37,-A16+1,0,1,1) -> 0.199964 | C16: =OFFSET('projekty 2 i 3'!$R$37,-A16+1,0,1,1) -> 0.017458921 | D16: =OFFSET('projekty 2 i 3'!$U$37,-A16+1,0,1,1) -> 11.453399 | E16: =SQRT(1/SQRT(B16^2+C16^2)) -> 2.2320276 | F16: =SQRT(C16^2/(C16^2+B16^2)^(3/2)) -> 0.19414049 | G16: =DEGREES(ATAN(1/D16)) -> 4.9898594 | H16: ='projekt 4'!$E16*SQRT(2*Arkusz1!$C$16/Arkusz1!$C$5/Arkusz1!$C$101*'projekt 4'!I$1) -> 141.53216 | I16: ='projekt 4'!$F16*SQRT(2*Arkusz1!$C$16/Arkusz1!$C$5/Arkusz1!$C$101*'projekt 4'!I$1) -> 12.310386 | J16: ='projekt 4'!$E16*SQRT(2*Arkusz1!$C$16/Arkusz1!$C$5/Arkusz1!$C$101*'projekt 4'!K$1) -> 156.79264 | K16: ='projekt 4'!$F16*SQRT(2*Arkusz1!$C$16/Arkusz1!$C$5/Arkusz1!$C$101*'projekt 4'!K$1) -> 13.637734 | L16: ='projekt 4'!$E16*SQRT(2*Arkusz1!$C$16/Arkusz1!$C$5/Arkusz1!$C$101*'projekt 4'!M$1) -> 170.69421 | M16: ='projekt 4'!$F16*SQRT(2*Arkusz1!$C$16/Arkusz1!$C$5/Arkusz1!$C$101*'projekt 4'!M$1) -> 14.846884
... A19: 17 | B19: =OFFSET('projekty 2 i 3'!$T$37,-A19+1,0,1,1) -> 0.093884914 | C19: =OFFSET('projekty 2 i 3'!$R$37,-A19+1,0,1,1) -> 0.015747731 | D19: =OFFSET('projekty 2 i 3'!$U$37,-A19+1,0,1,1) -> 5.9618058 | E19: =SQRT(1/SQRT(B19^2+C19^2)) -> 3.2410787 | F19: =SQRT(C19^2/(C19^2+B19^2)^(3/2)) -> 0.5361505 | G19: =DEGREES(ATAN(1/D19)) -> 9.5218358 | H19: ='projekt 4'!$E19*SQRT(2*Arkusz1!$C$16/Arkusz1!$C$5/Arkusz1!$C$101*'projekt 4'!I$1) -> 205.51576 | I19: ='projekt 4'!$F19*SQRT(2*Arkusz1!$C$16/Arkusz1!$C$5/Arkusz1!$C$101*'projekt 4'!I$1) -> 33.997132 | J19: ='projekt 4'!$E19*SQRT(2*Arkusz1!$C$16/Arkusz1!$C$5/Arkusz1!$C$101*'projekt 4'!K$1) -> 227.67518 | K19: ='projekt 4'!$F19*SQRT(2*Arkusz1!$C$16/Arkusz1!$C$5/Arkusz1!$C$101*'projekt 4'!K$1) -> 37.662819 | L19: ='projekt 4'!$E19*SQRT(2*Arkusz1!$C$16/Arkusz1!$C$5/Arkusz1!$C$101*'projekt 4'!M$1) -> 247.86134 | M19: ='projekt 4'!$F19*SQRT(2*Arkusz1!$C$16/Arkusz1!$C$5/Arkusz1!$C$101*'projekt 4'!M$1) -> 41.002084
