Workbook
Name Cx_Cz: 'projekty 2 i 3'!$E$2:$F$123
Name Cz_a: 'projekty 2 i 3'!$A$3:$B$237
Name Cz_a_1: 'projekty 2 i 3'!$F$3:$G$237

Sheet Arkusz1
A1: Dana | B1: Symbol | C1: Wartość | D1: Jednostka
A2: Rozpiętość płata | B2: b | C2: 12.4 | D2: m
A3: Wysokość samolotu | B3: hs | C3: 3.96 | D3: m
A4: Długość kadłuba | B4: lk | C4: 9.94 | D4: m
A5: Powierzchnia nośna | B5: S | C5: 21.3 | D5: m2
A6: Masa pustego samolotu | B6: m0 | C6: 1783 | D6: kg
A7: Masa maksymalna samolotu | B7: mk | C7: 2948 | D7: kg
A8: Masa paliwa | B8: mp | C8: 550 | D8: kg
A9: Moc silnika | B9: N | C9: 223000 | D9: W
A10: Obroty silnika | B10: ns | C10: 2575 | D10: 1/min
A11: Zużycie paliwa | B11: q | C11: 0.053 | D11: m3/h
A12: Prędkość maksymalna | B12: Vmax | C12: 117 | D12: m/s
A13: Maksymalna prędkość wznoszenia | B13: wmax | C13: 7.34 | D13: m/s
... A18: kąt skosu krawędzi natarcia płata | B18: Vx0 | C18: 4.92 | D18: °
A19: zbieżność płata | B19: λ | C19: =C17/C16 -> 0.376 | D19: -
A20: wydłużenie geometryczne płata | B20: Λ | C20: =C2*C2/C5 -> 7.2187793 | D20: -
A21: średnia cięciwa aerodynamiczna | B21: ca | C21: =2*C16*(1+C19+C19^2)/(3+3*C19) -> 1.837907 | D21: m
A22: położenie noska ca względem początku cięciwy przykadłubowej | B22: xN | C22: =C2*TAN(RADIANS(C18))*(1+2*C19)/(6+6*C19) -> 0.22651547 | D22: m
A23: gęstość powietrza przy ziemii | B23: ρ | C23: 1.225 | D23: kg/m3
A24: Liczba Reynoldsa 3M | B24: Re3M | C24: 3000000 | D24: -
A25: Czmax dla Reynoldsa 3M | B25: Czmax re | C25: 1.55 | D25: -
A26: lepkość kinematyczna powietrzna na poziomie morza | B26: ν | C26: =1.4607*10^-5 -> 1.4607e-05 | D26: m2/s
A27: Prędkość przeciągnięcia | B27: VS1 | C27: =SQRT(2*C7*C14/C23/C5/C25) -> 37.817215 | D27: m/s
A28: Obliczona liczba Reynoldsa | B28: Re | C28: =C27*C21/C26 -> 4758302.4 | D28: -
A29: środek aerodynamiczny na x | B29: xsa kreska | C29: 0.264 | D29: -
A30: środek aerodynamiczny na z | B30: zsa kreska | C30: -0.039 | D30: -
A31: Współczynnik momentu podłużnego względem środka aerodynamicznego | B31: Cmsa | C31: -0.07 | D31: -
A32: Współczynnik kierunkowy prostej Cz(a) | B32: a∞ | C32: 6.1343 | D32: 1/rad
A33: minimalna wartość Cx | B33: Cx∞ min1 | C33: =MIN('projekty 2 i 3'!C3:C50) -> 0.0052664105 | D33: -
A34: Cz odpowiadające minimalnej wartości Cx | B34: Cz∞1 | C34: ='projekty 2 i 3'!B26 -> 0.25833785 | D34: -
A35: Korekta dottycząca liczby reynoldsa | B35: Cx∞ min2 | C35: =C33*(C28/10^7)^0.11 -> 0.0048532698 | D35: -
A36: maksymalny współczynnik Cz | B36: Czmax | C36: =MAX('projekty 2 i 3'!B3:B50) -> 1.6488925 | D36: -
A37: Minimalny współczynnik Cx' | B37: Cx'∞ min | C37: =MIN('projekty 2 i 3'!J3:J44) -> 0.004917998 | D37: -
A38: korekta technologiczna współczynnika oporu | B38: ΔCxtech | C38: =0.15*C37 -> 0.0007376997 | D38: -
A39: Kąt skosu lini utworzonej z 1/4 cięciwy płata | B39: β25 | C39: =DEGREES(ATAN(TAN(RADIANS(C18))+C16/2/C2*(C19-1))) -> 1.3278015 | D39: °
A40: Współczynnik do wyznaczenia tau 1 | B40: τ1 | C40: =0.023*(C20/C32)^3-0.103*(C20/C32)^2+0.25*(C20/C32) -> 0.18904164 | D40: -
A41: Współczynnik do wyznaczenia tau 2 | B41: τ2 | C41: =-0.18*C19^5+1.52*C19^4-3.51*C19^3+3.5*C19^2-1.33*C19+0.17 -> 0.0071813819 | D41: -
A42: Współczynnik do wyznaczenia delta 1 | B42: δ1 | C42: =0.0537*C20/C32-0.005 -> 0.058193592 | D42: -
A43: Współczynnik do wyznaczenia delta 2 | B43: δ2 | C43: =-0.43*C19^5+1.83*C19^4-3.06*C19^3+2.56*C19^2-C19+0.148 -> 0.0046059905 | D43: -
A44: Współczynnik do wyznaczenia delta 3 | B44: δ3 | C44: =1+C39^3*(-2.2*(10^(-7))*C20^3+(10^(-7))*C20^2+1.6*(10^(-5))) -> 0.99985592 | D44: -
...

Sheet projekty 2 i 3
G1: profil | K1: płat | O1: samolot
E2: dCxRe | G2: Cz | H2: Cx | I2: α [°] | J2: Cx' | K2: αi [°] | L2: αp [°] | M2: Cxi | N2: C'xp | O2: CzH | P2: CxH | Q2: Cx'szk | R2: Cx | S2: ΔCzH | T2: Cz' | U2: K | V2: E | W2: alfa | X2: Cz'2 | Y2: K/10 | Z2: E/100
A3: -13.806644 | B3: -1.1343709 | C3: 0.013346677 | D3: =RADIANS(A3) -> -0.2409714 | E3: =(Arkusz1!C$35-Arkusz1!C$33)*(1-ABS('projekty 2 i 3'!G3/Arkusz1!C$36)) -> -0.00012891673 | F3: =RADIANS(L3) -> -0.29139059 | G3: =B3 -> -1.1343709 | H3: =C3 -> 0.013346677 | I3: =A3 -> -13.806644 | J3: =H3+E3 -> 0.013217761 | K3: =DEGREES(G3*(1+Arkusz1!C$46)/Arkusz1!C$20/PI()) -> -2.8888066 | L3: =I3+K3 -> -16.695451 | M3: =G3^2*(1+Arkusz1!C$45)/Arkusz1!C$20/PI() -> 0.057057744 | N3: =J3+M3+Arkusz1!C$38 -> 0.071013204 | O3: =Arkusz1!C$31/Arkusz1!C$77+(Arkusz1!C$68-Arkusz1!C$29)/Arkusz1!C$77*'projekty 2 i 3'!G3 -> -0.15283663 | P3: =Arkusz1!C$72+Arkusz1!C$73+1/PI()/Arkusz1!C$76*'projekty 2 i 3'!O3^2 -> 0.012385932 | Q3: =Arkusz1!C$92*(1+1/Arkusz1!C$93*ABS('projekty 2 i 3'!G3)) -> 0.014583999 | R3: =(N3+Q3+P3*Arkusz1!C$67/Arkusz1!C$5)*(1+Arkusz1!C$94) -> 0.092292838 | S3: =O3*Arkusz1!C$67/Arkusz1!C$5 -> -0.038819068 | T3: =G3+S3 -> -1.17319 | U3: =T3/R3 -> -12.711604 | V3: =T3^3/R3^2 -> -189.56975 | W3: =I3 -> -13.806644 | X3: =T3^2 -> 1.3763747 | Y3: =U3/10 -> -1.2711604 | Z3: =V3/100 -> -1.8956975 | AA3: =Arkusz1!C$32*('projekty 2 i 3'!D3-'projekty 2 i 3'!D$18) -> -1.1619003
A4: -12.370417 | B4: -1.0339724 | C4: 0.012281402 | D4: =RADIANS(A4) -> -0.21590451 | E4: =(Arkusz1!C$35-Arkusz1!C$33)*(1-ABS('projekty 2 i 3'!G4/Arkusz1!C$36)) -> -0.00015407222 | F4: =RADIANS(L4) -> -0.2618613 | G4: =B4 -> -1.0339724 | H4: =C4 -> 0.012281402 | I4: =A4 -> -12.370417 | J4: =H4+E4 -> 0.01212733 | K4: =DEGREES(G4*(1+Arkusz1!C$46)/Arkusz1!C$20/PI()) -> -2.6331303 | L4: =I4+K4 -> -15.003547 | M4: =G4^2*(1+Arkusz1!C$45)/Arkusz1!C$20/PI() -> 0.047404802 | N4: =J4+M4+Arkusz1!C$38 -> 0.060269832 | O4: =Arkusz1!C$31/Arkusz1!C$77+(Arkusz1!C$68-Arkusz1!C$29)/Arkusz1!C$77*'projekty 2 i 3'!G4 -> -0.15005145 | P4: =Arkusz1!C$72+Arkusz1!C$73+1/PI()/Arkusz1!C$76*'projekty 2 i 3'!O4^2 -> 0.012317823 | Q4: =Arkusz1!C$92*(1+1/Arkusz1!C$93*ABS('projekty 2 i 3'!G4)) -> 0.014378766 | R4: =(N4+Q4+P4*Arkusz1!C$67/Arkusz1!C$5)*(1+Arkusz1!C$94) -> 0.080888297 | S4: =O4*Arkusz1!C$67/Arkusz1!C$5 -> -0.038111659 | T4: =G4+S4 -> -1.0720841 | U4: =T4/R4 -> -13.253884 | V4: =T4^3/R4^2 -> -188.32811 | W4: =I4 -> -12.370417 | X4: =T4^2 -> 1.1493643 | Y4: =U4/10 -> -1.3253884 | Z4: =V4/100 -> -1.8832811 | AA4: =Arkusz1!C$32*('projekty 2 i 3'!D4-'projekty 2 i 3'!D$18) -> -1.0081325
A5: -11.329457 | B5: -0.93373752 | C5: 0.011090068 | D5: =RADIANS(A5) -> -0.19773633 | E5: =(Arkusz1!C$35-Arkusz1!C$33)*(1-ABS('projekty 2 i 3'!G5/Arkusz1!C$36)) -> -0.00017918672 | F5: =RADIANS(L5) -> -0.239238 | G5: =B5 -> -0.93373752 | H5: =C5 -> 0.011090068 | I5: =A5 -> -11.329457 | J5: =H5+E5 -> 0.010910881 | K5: =DEGREES(G5*(1+Arkusz1!C$46)/Arkusz1!C$20/PI()) -> -2.3778705 | L5: =I5+K5 -> -13.707328 | M5: =G5^2*(1+Arkusz1!C$45)/Arkusz1!C$20/PI() -> 0.038659306 | N5: =J5+M5+Arkusz1!C$38 -> 0.050307887 | O5: =Arkusz1!C$31/Arkusz1!C$77+(Arkusz1!C$68-Arkusz1!C$29)/Arkusz1!C$77*'projekty 2 i 3'!G5 -> -0.14727081 | P5: =Arkusz1!C$72+Arkusz1!C$73+1/PI()/Arkusz1!C$76*'projekty 2 i 3'!O5^2 -> 0.012251074 | Q5: =Arkusz1!C$92*(1+1/Arkusz1!C$93*ABS('projekty 2 i 3'!G5)) -> 0.014173867 | R5: =(N5+Q5+P5*Arkusz1!C$67/Arkusz1!C$5)*(1+Arkusz1!C$94) -> 0.070297148 | S5: =O5*Arkusz1!C$67/Arkusz1!C$5 -> -0.037405404 | T5: =G5+S5 -> -0.97114292 | U5: =T5/R5 -> -13.814827 | V5: =T5^3/R5^2 -> -185.34208 | W5: =I5 -> -11.329457 | X5: =T5^2 -> 0.94311858 | Y5: =U5/10 -> -1.3814827 | Z5: =V5/100 -> -1.8534208 | AA5: =Arkusz1!C$32*('projekty 2 i 3'!D5-'projekty 2 i 3'!D$18) -> -0.89668346
A6: -10.355248 | B6: -0.82687665 | C6: 0.0099863956 | D6: =RADIANS(A6) -> -0.18073318 | E6: =(Arkusz1!C$35-Arkusz1!C$33)*(1-ABS('projekty 2 i 3'!G6/Arkusz1!C$36)) -> -0.00020596141 | F6: =RADIANS(L6) -> -0.21748522 | G6: =B6 -> -0.82687665 | H6: =C6 -> 0.0099863956 | I6: =A6 -> -10.355248 | J6: =H6+E6 -> 0.0097804342 | K6: =DEGREES(G6*(1+Arkusz1!C$46)/Arkusz1!C$20/PI()) -> -2.105737 | L6: =I6+K6 -> -12.460985 | M6: =G6^2*(1+Arkusz1!C$45)/Arkusz1!C$20/PI() -> 0.030316977 | N6: =J6+M6+Arkusz1!C$38 -> 0.040835111 | O6: =Arkusz1!C$31/Arkusz1!C$77+(Arkusz1!C$68-Arkusz1!C$29)/Arkusz1!C$77*'projekty 2 i 3'!G6 -> -0.14430636 | P6: =Arkusz1!C$72+Arkusz1!C$73+1/PI()/Arkusz1!C$76*'projekty 2 i 3'!O6^2 -> 0.012181288 | Q6: =Arkusz1!C$92*(1+1/Arkusz1!C$93*ABS('projekty 2 i 3'!G6)) -> 0.013955423 | R6: =(N6+Q6+P6*Arkusz1!C$67/Arkusz1!C$5)*(1+Arkusz1!C$94) -> 0.060199845 | S6: =O6*Arkusz1!C$67/Arkusz1!C$5 -> -0.036652461 | T6: =G6+S6 -> -0.86352911 | U6: =T6/R6 -> -14.344374 | V6: =T6^3/R6^2 -> -177.68068 | W6: =I6 -> -10.355248 | X6: =T6^2 -> 0.74568253 | Y6: =U6/10 -> -1.4344374 | Z6: =V6/100 -> -1.7768068 | AA6: =Arkusz1!C$32*('projekty 2 i 3'!D6-'projekty 2 i 3'!D$18) -> -0.79238101
A7: -9.4451723 | B7: -0.73334954 | C7: 0.0091236852 | D7: =RADIANS(A7) -> -0.16484936 | E7: =(Arkusz1!C$35-Arkusz1!C$33)*(1-ABS('projekty 2 i 3'!G7/Arkusz1!C$36)) -> -0.00022939524 | F7: =RADIANS(L7) -> -0.19744441 | G7: =B7 -> -0.73334954 | H7: =C7 -> 0.0091236852 | I7: =A7 -> -9.4451723 | J7: =H7+E7 -> 0.00889429 | K7: =DEGREES(G7*(1+Arkusz1!C$46)/Arkusz1!C$20/PI()) -> -1.8675594 | L7: =I7+K7 -> -11.312732 | M7: =G7^2*(1+Arkusz1!C$45)/Arkusz1!C$20/PI() -> 0.0238466 | N7: =J7+M7+Arkusz1!C$38 -> 0.03347859 | O7: =Arkusz1!C$31/Arkusz1!C$77+(Arkusz1!C$68-Arkusz1!C$29)/Arkusz1!C$77*'projekty 2 i 3'!G7 -> -0.14171181 | P7: =Arkusz1!C$72+Arkusz1!C$73+1/PI()/Arkusz1!C$76*'projekty 2 i 3'!O7^2 -> 0.012121374 | Q7: =Arkusz1!C$92*(1+1/Arkusz1!C$93*ABS('projekty 2 i 3'!G7)) -> 0.013764236 | R7: =(N7+Q7+P7*Arkusz1!C$67/Arkusz1!C$5)*(1+Arkusz1!C$94) -> 0.052334403 | S7: =O7*Arkusz1!C$67/Arkusz1!C$5 -> -0.035993468 | T7: =G7+S7 -> -0.769343 | U7: =T7/R7 -> -14.700521 | V7: =T7^3/R7^2 -> -166.25912 | W7: =I7 -> -9.4451723 | X7: =T7^2 -> 0.59188866 | Y7: =U7/10 -> -1.4700521 | Z7: =V7/100 -> -1.6625912 | AA7: =Arkusz1!C$32*('projekty 2 i 3'!D7-'projekty 2 i 3'!D$18) -> -0.69494486
A8: -8.6018467 | B8: -0.63319644 | C8: 0.0084393417 | D8: =RADIANS(A8) -> -0.15013055 | E8: =(Arkusz1!C$35-Arkusz1!C$33)*(1-ABS('projekty 2 i 3'!G8/Arkusz1!C$36)) -> -0.00025448924 | F8: =RADIANS(L8) -> -0.17827412 | G8: =B8 -> -0.63319644 | H8: =C8 -> 0.0084393417 | I8: =A8 -> -8.6018467 | J8: =H8+E8 -> 0.0081848525 | K8: =DEGREES(G8*(1+Arkusz1!C$46)/Arkusz1!C$20/PI()) -> -1.6125079 | L8: =I8+K8 -> -10.214355 | M8: =G8^2*(1+Arkusz1!C$45)/Arkusz1!C$20/PI() -> 0.017777937 | N8: =J8+M8+Arkusz1!C$38 -> 0.026700489 | O8: =Arkusz1!C$31/Arkusz1!C$77+(Arkusz1!C$68-Arkusz1!C$29)/Arkusz1!C$77*'projekty 2 i 3'!G8 -> -0.13893344 | P8: =Arkusz1!C$72+Arkusz1!C$73+1/PI()/Arkusz1!C$76*'projekty 2 i 3'!O8^2 -> 0.012058421 | Q8: =Arkusz1!C$92*(1+1/Arkusz1!C$93*ABS('projekty 2 i 3'!G8)) -> 0.013559504 | R8: =(N8+Q8+P8*Arkusz1!C$67/Arkusz1!C$5)*(1+Arkusz1!C$94) -> 0.045055628 | S8: =O8*Arkusz1!C$67/Arkusz1!C$5 -> -0.035287789 | T8: =G8+S8 -> -0.66848423 | U8: =T8/R8 -> -14.836864 | V8: =T8^3/R8^2 -> -147.15513 | W8: =I8 -> -8.6018467 | X8: =T8^2 -> 0.44687117 | Y8: =U8/10 -> -1.4836864 | Z8: =V8/100 -> -1.4715513 | AA8: =Arkusz1!C$32*('projekty 2 i 3'!D8-'projekty 2 i 3'!D$18) -> -0.60465528
A9: -6.6508111 | B9: -0.43943443 | C9: 0.0073552303 | D9: =RADIANS(A9) -> -0.11607855 | E9: =(Arkusz1!C$35-Arkusz1!C$33)*(1-ABS('projekty 2 i 3'!G9/Arkusz1!C$36)) -> -0.00030303757 | F9: =RADIANS(L9) -> -0.13561002 | G9: =B9 -> -0.43943443 | H9: =C9 -> 0.0073552303 | I9: =A9 -> -6.6508111 | J9: =H9+E9 -> 0.0070521927 | K9: =DEGREES(G9*(1+Arkusz1!C$46)/Arkusz1!C$20/PI()) -> -1.1190706 | L9: =I9+K9 -> -7.7698817 | M9: =G9^2*(1+Arkusz1!C$45)/Arkusz1!C$20/PI() -> 0.0085623426 | N9: =J9+M9+Arkusz1!C$38 -> 0.016352235 | O9: =Arkusz1!C$31/Arkusz1!C$77+(Arkusz1!C$68-Arkusz1!C$29)/Arkusz1!C$77*'projekty 2 i 3'!G9 -> -0.13355825 | P9: =Arkusz1!C$72+Arkusz1!C$73+1/PI()/Arkusz1!C$76*'projekty 2 i 3'!O9^2 -> 0.011940166 | Q9: =Arkusz1!C$92*(1+1/Arkusz1!C$93*ABS('projekty 2 i 3'!G9)) -> 0.013163418 | R9: =(N9+Q9+P9*Arkusz1!C$67/Arkusz1!C$5)*(1+Arkusz1!C$94) -> 0.033850277 | S9: =O9*Arkusz1!C$67/Arkusz1!C$5 -> -0.03392254 | T9: =G9+S9 -> -0.47335697 | U9: =T9/R9 -> -13.983844 | V9: =T9^3/R9^2 -> -92.563953 | W9: =I9 -> -6.6508111 | X9: =T9^2 -> 0.22406682 | Y9: =U9/10 -> -1.3983844 | Z9: =V9/100 -> -0.92563953 | AA9: =Arkusz1!C$32*('projekty 2 i 3'!D9-'projekty 2 i 3'!D$18) -> -0.39577012
A10: -5.8083581 | B10: -0.3326281 | C10: 0.0070863035 | D10: =RADIANS(A10) -> -0.10137497 | E10: =(Arkusz1!C$35-Arkusz1!C$33)*(1-ABS('projekty 2 i 3'!G10/Arkusz1!C$36)) -> -0.00032979859 | F10: =RADIANS(L10) -> -0.11615924 | G10: =B10 -> -0.3326281 | H10: =C10 -> 0.0070863035 | I10: =A10 -> -5.8083581 | J10: =H10+E10 -> 0.0067565049 | K10: =DEGREES(G10*(1+Arkusz1!C$46)/Arkusz1!C$20/PI()) -> -0.8470759 | L10: =I10+K10 -> -6.655434 | M10: =G10^2*(1+Arkusz1!C$45)/Arkusz1!C$20/PI() -> 0.0049059408 | N10: =J10+M10+Arkusz1!C$38 -> 0.012400145 | O10: =Arkusz1!C$31/Arkusz1!C$77+(Arkusz1!C$68-Arkusz1!C$29)/Arkusz1!C$77*'projekty 2 i 3'!G10 -> -0.13059531 | P10: =Arkusz1!C$72+Arkusz1!C$73+1/PI()/Arkusz1!C$76*'projekty 2 i 3'!O10^2 -> 0.011876976 | Q10: =Arkusz1!C$92*(1+1/Arkusz1!C$93*ABS('projekty 2 i 3'!G10)) -> 0.012945086 | R10: =(N10+Q10+P10*Arkusz1!C$67/Arkusz1!C$5)*(1+Arkusz1!C$94) -> 0.029496346 | S10: =O10*Arkusz1!C$67/Arkusz1!C$5 -> -0.033169982 | T10: =G10+S10 -> -0.36579808 | U10: =T10/R10 -> -12.401471 | V10: =T10^3/R10^2 -> -56.258459 | W10: =I10 -> -5.8083581 | X10: =T10^2 -> 0.13380824 | Y10: =U10/10 -> -1.2401471 | Z10: =V10/100 -> -0.56258459 | AA10: =Arkusz1!C$32*('projekty 2 i 3'!D10-'projekty 2 i 3'!D$18) -> -0.30557395
A11: -4.8982819 | B11: -0.23910098 | C11: 0.0069318444 | D11: =RADIANS(A11) -> -0.085491148 | E11: =(Arkusz1!C$35-Arkusz1!C$33)*(1-ABS('projekty 2 i 3'!G11/Arkusz1!C$36)) -> -0.00035323242 | F11: =RADIANS(L11) -> -0.096118428 | G11: =B11 -> -0.23910098 | H11: =C11 -> 0.0069318444 | I11: =A11 -> -4.8982819 | J11: =H11+E11 -> 0.006578612 | K11: =DEGREES(G11*(1+Arkusz1!C$46)/Arkusz1!C$20/PI()) -> -0.60889829 | L11: =I11+K11 -> -5.5071802 | M11: =G11^2*(1+Arkusz1!C$45)/Arkusz1!C$20/PI() -> 0.0025349369 | N11: =J11+M11+Arkusz1!C$38 -> 0.0098512486 | O11: =Arkusz1!C$31/Arkusz1!C$77+(Arkusz1!C$68-Arkusz1!C$29)/Arkusz1!C$77*'projekty 2 i 3'!G11 -> -0.12800075 | P11: =Arkusz1!C$72+Arkusz1!C$73+1/PI()/Arkusz1!C$76*'projekty 2 i 3'!O11^2 -> 0.011822806 | Q11: =Arkusz1!C$92*(1+1/Arkusz1!C$93*ABS('projekty 2 i 3'!G11)) -> 0.012753899 | R11: =(N11+Q11+P11*Arkusz1!C$67/Arkusz1!C$5)*(1+Arkusz1!C$94) -> 0.02663235 | S11: =O11*Arkusz1!C$67/Arkusz1!C$5 -> -0.032510989 | T11: =G11+S11 -> -0.27161197 | U11: =T11/R11 -> -10.198573 | V11: =T11^3/R11^2 -> -28.250605 | W11: =I11 -> -4.8982819 | X11: =T11^2 -> 0.073773063 | Y11: =U11/10 -> -1.0198573 | Z11: =V11/100 -> -0.28250605 | AA11: =Arkusz1!C$32*('projekty 2 i 3'!D11-'projekty 2 i 3'!D$18) -> -0.20813781
A12: -4.444989 | B12: -0.17903094 | C12: 0.0068317213 | D12: =RADIANS(A12) -> -0.077579693 | E12: =(Arkusz1!C$35-Arkusz1!C$33)*(1-ABS('projekty 2 i 3'!G12/Arkusz1!C$36)) -> -0.00036828336 | F12: =RADIANS(L12) -> -0.085537051 | G12: =B12 -> -0.17903094 | H12: =C12 -> 0.0068317213 | I12: =A12 -> -4.444989 | J12: =H12+E12 -> 0.0064634379 | K12: =DEGREES(G12*(1+Arkusz1!C$46)/Arkusz1!C$20/PI()) -> -0.45592299 | L12: =I12+K12 -> -4.900912 | M12: =G12^2*(1+Arkusz1!C$45)/Arkusz1!C$20/PI() -> 0.0014212178 | N12: =J12+M12+Arkusz1!C$38 -> 0.0086223554 | O12: =Arkusz1!C$31/Arkusz1!C$77+(Arkusz1!C$68-Arkusz1!C$29)/Arkusz1!C$77*'projekty 2 i 3'!G12 -> -0.12633434 | P12: =Arkusz1!C$72+Arkusz1!C$73+1/PI()/Arkusz1!C$76*'projekty 2 i 3'!O12^2 -> 0.011788588 | Q12: =Arkusz1!C$92*(1+1/Arkusz1!C$93*ABS('projekty 2 i 3'!G12)) -> 0.012631104 | R12: =(N12+Q12+P12*Arkusz1!C$67/Arkusz1!C$5)*(1+Arkusz1!C$94) -> 0.025217556 | S12: =O12*Arkusz1!C$67/Arkusz1!C$5 -> -0.032087735 | T12: =G12+S12 -> -0.21111868 | U12: =T12/R12 -> -8.3718929 | V12: =T12^3/R12^2 -> -14.79701 | W12: =I12 -> -4.444989 | X12: =T12^2 -> 0.044571096 | Y12: =U12/10 -> -0.83718929 | Z12: =V12/100 -> -0.1479701 | AA12: =Arkusz1!C$32*('projekty 2 i 3'!D12-'projekty 2 i 3'!D$18) -> -0.15960657
A13: -3.9895147 | B13: -0.135594 | C13: 0.0065990184 | D13: =RADIANS(A13) -> -0.069630166 | E13: =(Arkusz1!C$35-Arkusz1!C$33)*(1-ABS('projekty 2 i 3'!G13/Arkusz1!C$36)) -> -0.00037916677 | F13: =RADIANS(L13) -> -0.07565689 | G13: =B13 -> -0.135594 | H13: =C13 -> 0.0065990184 | I13: =A13 -> -3.9895147 | J13: =H13+E13 -> 0.0062198517 | K13: =DEGREES(G13*(1+Arkusz1!C$46)/Arkusz1!C$20/PI()) -> -0.3453058 | L13: =I13+K13 -> -4.3348205 | M13: =G13^2*(1+Arkusz1!C$45)/Arkusz1!C$20/PI() -> 0.00081523984 | N13: =J13+M13+Arkusz1!C$38 -> 0.0077727912 | O13: =Arkusz1!C$31/Arkusz1!C$77+(Arkusz1!C$68-Arkusz1!C$29)/Arkusz1!C$77*'projekty 2 i 3'!G13 -> -0.12512934 | P13: =Arkusz1!C$72+Arkusz1!C$73+1/PI()/Arkusz1!C$76*'projekty 2 i 3'!O13^2 -> 0.011764124 | Q13: =Arkusz1!C$92*(1+1/Arkusz1!C$93*ABS('projekty 2 i 3'!G13)) -> 0.012542311 | R13: =(N13+Q13+P13*Arkusz1!C$67/Arkusz1!C$5)*(1+Arkusz1!C$94) -> 0.024235202 | S13: =O13*Arkusz1!C$67/Arkusz1!C$5 -> -0.031781678 | T13: =G13+S13 -> -0.16737568 | U13: =T13/R13 -> -6.9063044 | V13: =T13^3/R13^2 -> -7.9833246 | W13: =I13 -> -3.9895147 | X13: =T13^2 -> 0.028014619 | Y13: =U13/10 -> -0.69063044 | Z13: =V13/100 -> -0.079833246 | AA13: =Arkusz1!C$32*('projekty 2 i 3'!D13-'projekty 2 i 3'!D$18) -> -0.11084179
A14: -3.5331678 | B14: -0.098810306 | C14: 0.0064764365 | D14: =RADIANS(A14) -> -0.061665411 | E14: =(Arkusz1!C$35-Arkusz1!C$33)*(1-ABS('projekty 2 i 3'!G14/Arkusz1!C$36)) -> -0.00038838316 | F14: =RADIANS(L14) -> -0.066057215 | G14: =B14 -> -0.098810306 | H14: =C14 -> 0.0064764365 | I14: =A14 -> -3.5331678 | J14: =H14+E14 -> 0.0060880533 | K14: =DEGREES(G14*(1+Arkusz1!C$46)/Arkusz1!C$20/PI()) -> -0.25163186 | L14: =I14+K14 -> -3.7847996 | M14: =G14^2*(1+Arkusz1!C$45)/Arkusz1!C$20/PI() -> 0.00043292127 | N14: =J14+M14+Arkusz1!C$38 -> 0.0072586743 | O14: =Arkusz1!C$31/Arkusz1!C$77+(Arkusz1!C$68-Arkusz1!C$29)/Arkusz1!C$77*'projekty 2 i 3'!G14 -> -0.12410892 | P14: =Arkusz1!C$72+Arkusz1!C$73+1/PI()/Arkusz1!C$76*'projekty 2 i 3'!O14^2 -> 0.01174359 | Q14: =Arkusz1!C$92*(1+1/Arkusz1!C$93*ABS('projekty 2 i 3'!G14)) -> 0.012467118 | R14: =(N14+Q14+P14*Arkusz1!C$67/Arkusz1!C$5)*(1+Arkusz1!C$94) -> 0.023616896 | S14: =O14*Arkusz1!C$67/Arkusz1!C$5 -> -0.0315225 | T14: =G14+S14 -> -0.13033281 | U14: =T14/R14 -> -5.5186256 | V14: =T14^3/R14^2 -> -3.9693154 | W14: =I14 -> -3.5331678 | X14: =T14^2 -> 0.01698664 | Y14: =U14/10 -> -0.55186256 | Z14: =V14/100 -> -0.039693154 | AA14: =Arkusz1!C$32*('projekty 2 i 3'!D14-'projekty 2 i 3'!D$18) -> -0.061983588
... A37: 9.578298 | B37: 1.4003503 | C37: 0.01476289 | D37: =RADIANS(A37) -> 0.16717284 | E37: =(Arkusz1!C$35-Arkusz1!C$33)*(1-ABS('projekty 2 i 3'!G37/Arkusz1!C$36)) -> -6.2273858e-05 | F37: =RADIANS(L37) -> 0.22941396 | G37: =B37 -> 1.4003503 | H37: =C37 -> 0.01476289 | I37: =A37 -> 9.578298 | J37: =H37+E37 -> 0.014700616 | K37: =DEGREES(G37*(1+Arkusz1!C$46)/Arkusz1!C$20/PI()) -> 3.5661539 | L37: =I37+K37 -> 13.144452 | M37: =G37^2*(1+Arkusz1!C$45)/Arkusz1!C$20/PI() -> 0.086951648 | N37: =J37+M37+Arkusz1!C$38 -> 0.10238996 | O37: =Arkusz1!C$31/Arkusz1!C$77+(Arkusz1!C$68-Arkusz1!C$29)/Arkusz1!C$77*'projekty 2 i 3'!G37 -> -0.082520387 | P37: =Arkusz1!C$72+Arkusz1!C$73+1/PI()/Arkusz1!C$76*'projekty 2 i 3'!O37^2 -> 0.011049786 | Q37: =Arkusz1!C$92*(1+1/Arkusz1!C$93*ABS('projekty 2 i 3'!G37)) -> 0.015127711 | R37: =(N37+Q37+P37*Arkusz1!C$67/Arkusz1!C$5)*(1+Arkusz1!C$94) -> 0.12513719 | S37: =O37*Arkusz1!C$67/Arkusz1!C$5 -> -0.020959404 | T37: =G37+S37 -> 1.3793909 | U37: =T37/R37 -> 11.02303 | V37: =T37^3/R37^2 -> 167.6059 | W37: =I37 -> 9.578298 | X37: =T37^2 -> 1.9027193 | Y37: =U37/10 -> 1.102303 | Z37: =V37/100 -> 1.676059 | AA37: =Arkusz1!C$32*('projekty 2 i 3'!D37-'projekty 2 i 3'!D$18) -> 1.3417789
A38: 11.015398 | B38: 1.4940956 | C38: =0.0001*B38^4+0.0011*B38^3+0.0047*B38^2-0.0023*B38+0.0057 -> 0.01692265 | D38: =RADIANS(A38) -> 0.19225496 | E38: =(Arkusz1!C$35-Arkusz1!C$33)*(1-ABS('projekty 2 i 3'!G38/Arkusz1!C$36)) -> -3.8785375e-05 | F38: =RADIANS(L38) -> 0.25866277 | G38: =B38 -> 1.4940956 | H38: =C38 -> 0.01692265 | I38: =A38 -> 11.015398 | J38: =H38+E38 -> 0.016883864 | K38: =DEGREES(G38*(1+Arkusz1!C$46)/Arkusz1!C$20/PI()) -> 3.8048871 | L38: =I38+K38 -> 14.820285 | M38: =G38^2*(1+Arkusz1!C$45)/Arkusz1!C$20/PI() -> 0.098983132 | N38: =J38+M38+Arkusz1!C$38 -> 0.1166047 | O38: =Arkusz1!C$31/Arkusz1!C$77+(Arkusz1!C$68-Arkusz1!C$29)/Arkusz1!C$77*'projekty 2 i 3'!G38 -> -0.07991978 | P38: =Arkusz1!C$72+Arkusz1!C$73+1/PI()/Arkusz1!C$76*'projekty 2 i 3'!O38^2 -> 0.011015679 | Q38: =Arkusz1!C$92*(1+1/Arkusz1!C$93*ABS('projekty 2 i 3'!G38)) -> 0.015319344 | R38: =(N38+Q38+P38*Arkusz1!C$67/Arkusz1!C$5)*(1+Arkusz1!C$94) -> 0.1401108 | S38: =O38*Arkusz1!C$67/Arkusz1!C$5 -> -0.020298874 | T38: =G38+S38 -> 1.4737967 | U38: =T38/R38 -> 10.518795 | V38: =T38^3/R38^2 -> 163.0683 | W38: =I38 -> 11.015398 | X38: =T38^2 -> 2.1720767 | Y38: =U38/10 -> 1.0518795 | Z38: =V38/100 -> 1.630683 | AA38: =Arkusz1!C$32*('projekty 2 i 3'!D38-'projekty 2 i 3'!D$18) -> 1.4956402
A39: 12.122672 | B39: 1.5910311 | C39: =0.0001*B39^4+0.0011*B39^3+0.0047*B39^2-0.0023*B39+0.0057 -> 0.019009158 | D39: =RADIANS(A39) -> 0.21158054 | E39: =(Arkusz1!C$35-Arkusz1!C$33)*(1-ABS('projekty 2 i 3'!G39/Arkusz1!C$36)) -> -1.4497545e-05 | F39: =RADIANS(L39) -> 0.28229682 | G39: =B39 -> 1.5910311 | H39: =C39 -> 0.019009158 | I39: =A39 -> 12.122672 | J39: =H39+E39 -> 0.01899466 | K39: =DEGREES(G39*(1+Arkusz1!C$46)/Arkusz1!C$20/PI()) -> 4.0517446 | L39: =I39+K39 -> 16.174416 | M39: =G39^2*(1+Arkusz1!C$45)/Arkusz1!C$20/PI() -> 0.11224365 | N39: =J39+M39+Arkusz1!C$38 -> 0.13197601 | O39: =Arkusz1!C$31/Arkusz1!C$77+(Arkusz1!C$68-Arkusz1!C$29)/Arkusz1!C$77*'projekty 2 i 3'!G39 -> -0.077230671 | P39: =Arkusz1!C$72+Arkusz1!C$73+1/PI()/Arkusz1!C$76*'projekty 2 i 3'!O39^2 -> 0.01098156 | Q39: =Arkusz1!C$92*(1+1/Arkusz1!C$93*ABS('projekty 2 i 3'!G39)) -> 0.015517499 | R39: =(N39+Q39+P39*Arkusz1!C$67/Arkusz1!C$5)*(1+Arkusz1!C$94) -> 0.15629403 | S39: =O39*Arkusz1!C$67/Arkusz1!C$5 -> -0.019615865 | T39: =G39+S39 -> 1.5714152 | U39: =T39/R39 -> 10.054224 | V39: =T39^3/R39^2 -> 158.85033 | W39: =I39 -> 12.122672 | X39: =T39^2 -> 2.4693459 | Y39: =U39/10 -> 1.0054224 | Z39: =V39/100 -> 1.5885033 | AA39: =Arkusz1!C$32*('projekty 2 i 3'!D39-'projekty 2 i 3'!D$18) -> 1.614189
A40: 12.5812 | B40: 1.6111817 | C40: =0.0001*B40^4+0.0011*B40^3+0.0047*B40^2-0.0023*B40+0.0057 -> 0.01946964 | D40: =RADIANS(A40) -> 0.21958337 | E40: =(Arkusz1!C$35-Arkusz1!C$33)*(1-ABS('projekty 2 i 3'!G40/Arkusz1!C$36)) -> -9.448683e-06 | F40: =RADIANS(L40) -> 0.29119528 | G40: =B40 -> 1.6111817 | H40: =C40 -> 0.01946964 | I40: =A40 -> 12.5812 | J40: =H40+E40 -> 0.019460192 | K40: =DEGREES(G40*(1+Arkusz1!C$46)/Arkusz1!C$20/PI()) -> 4.1030604 | L40: =I40+K40 -> 16.684261 | M40: =G40^2*(1+Arkusz1!C$45)/Arkusz1!C$20/PI() -> 0.11510481 | N40: =J40+M40+Arkusz1!C$38 -> 0.1353027 | O40: =Arkusz1!C$31/Arkusz1!C$77+(Arkusz1!C$68-Arkusz1!C$29)/Arkusz1!C$77*'projekty 2 i 3'!G40 -> -0.076671669 | P40: =Arkusz1!C$72+Arkusz1!C$73+1/PI()/Arkusz1!C$76*'projekty 2 i 3'!O40^2 -> 0.010974615 | Q40: =Arkusz1!C$92*(1+1/Arkusz1!C$93*ABS('projekty 2 i 3'!G40)) -> 0.01555869 | R40: =(N40+Q40+P40*Arkusz1!C$67/Arkusz1!C$5)*(1+Arkusz1!C$94) -> 0.1597948 | S40: =O40*Arkusz1!C$67/Arkusz1!C$5 -> -0.019473884 | T40: =G40+S40 -> 1.5917078 | U40: =T40/R40 -> 9.9609491 | V40: =T40^3/R40^2 -> 157.93006 | W40: =I40 -> 12.5812 | X40: =T40^2 -> 2.5335338 | Y40: =U40/10 -> 0.99609491 | Z40: =V40/100 -> 1.5793006 | AA40: =Arkusz1!C$32*('projekty 2 i 3'!D40-'projekty 2 i 3'!D$18) -> 1.6632808
A41: 12.843403 | B41: 1.6212706 | C41: =0.0001*B41^4+0.0011*B41^3+0.0047*B41^2-0.0023*B41+0.0057 -> 0.019703719 | D41: =RADIANS(A41) -> 0.22415967 | E41: =(Arkusz1!C$35-Arkusz1!C$33)*(1-ABS('projekty 2 i 3'!G41/Arkusz1!C$36)) -> -6.9208358e-06 | F41: =RADIANS(L41) -> 0.29622001 | G41: =B41 -> 1.6212706 | H41: =C41 -> 0.019703719 | I41: =A41 -> 12.843403 | J41: =H41+E41 -> 0.019696798 | K41: =DEGREES(G41*(1+Arkusz1!C$46)/Arkusz1!C$20/PI()) -> 4.1287531 | L41: =I41+K41 -> 16.972156 | M41: =G41^2*(1+Arkusz1!C$45)/Arkusz1!C$20/PI() -> 0.11655086 | N41: =J41+M41+Arkusz1!C$38 -> 0.13698535 | O41: =Arkusz1!C$31/Arkusz1!C$77+(Arkusz1!C$68-Arkusz1!C$29)/Arkusz1!C$77*'projekty 2 i 3'!G41 -> -0.07639179 | P41: =Arkusz1!C$72+Arkusz1!C$73+1/PI()/Arkusz1!C$76*'projekty 2 i 3'!O41^2 -> 0.010971156 | Q41: =Arkusz1!C$92*(1+1/Arkusz1!C$93*ABS('projekty 2 i 3'!G41)) -> 0.015579314 | R41: =(N41+Q41+P41*Arkusz1!C$67/Arkusz1!C$5)*(1+Arkusz1!C$94) -> 0.16156529 | S41: =O41*Arkusz1!C$67/Arkusz1!C$5 -> -0.019402797 | T41: =G41+S41 -> 1.6018678 | U41: =T41/R41 -> 9.9146782 | V41: =T41^3/R41^2 -> 157.46496 | W41: =I41 -> 12.843403 | X41: =T41^2 -> 2.5659806 | Y41: =U41/10 -> 0.99146782 | Z41: =V41/100 -> 1.5746496 | AA41: =Arkusz1!C$32*('projekty 2 i 3'!D41-'projekty 2 i 3'!D$18) -> 1.6913532
A42: 13.171484 | B42: 1.6313868 | C42: =0.0001*B42^4+0.0011*B42^3+0.0047*B42^2-0.0023*B42+0.0057 -> 0.019940807 | D42: =RADIANS(A42) -> 0.22988577 | E42: =(Arkusz1!C$35-Arkusz1!C$33)*(1-ABS('projekty 2 i 3'!G42/Arkusz1!C$36)) -> -4.3861565e-06 | F42: =RADIANS(L42) -> 0.30239574 | G42: =B42 -> 1.6313868 | H42: =C42 -> 0.019940807 | I42: =A42 -> 13.171484 | J42: =H42+E42 -> 0.019936421 | K42: =DEGREES(G42*(1+Arkusz1!C$46)/Arkusz1!C$20/PI()) -> 4.1545151 | L42: =I42+K42 -> 17.326 | M42: =G42^2*(1+Arkusz1!C$45)/Arkusz1!C$20/PI() -> 0.11800987 | N42: =J42+M42+Arkusz1!C$38 -> 0.13868399 | O42: =Arkusz1!C$31/Arkusz1!C$77+(Arkusz1!C$68-Arkusz1!C$29)/Arkusz1!C$77*'projekty 2 i 3'!G42 -> -0.076111154 | P42: =Arkusz1!C$72+Arkusz1!C$73+1/PI()/Arkusz1!C$76*'projekty 2 i 3'!O42^2 -> 0.0109677 | Q42: =Arkusz1!C$92*(1+1/Arkusz1!C$93*ABS('projekty 2 i 3'!G42)) -> 0.015599993 | R42: =(N42+Q42+P42*Arkusz1!C$67/Arkusz1!C$5)*(1+Arkusz1!C$94) -> 0.16335247 | S42: =O42*Arkusz1!C$67/Arkusz1!C$5 -> -0.019331518 | T42: =G42+S42 -> 1.6120553 | U42: =T42/R42 -> 9.8685704 | V42: =T42^3/R42^2 -> 156.99594 | W42: =I42 -> 13.171484 | X42: =T42^2 -> 2.5987224 | Y42: =U42/10 -> 0.98685704 | Z42: =V42/100 -> 1.5699594 | AA42: =Arkusz1!C$32*('projekty 2 i 3'!D42-'projekty 2 i 3'!D$18) -> 1.7264788
A43: 13.565444 | B43: 1.6415303 | C43: =0.0001*B43^4+0.0011*B43^3+0.0047*B43^2-0.0023*B43+0.0057 -> 0.020180935 | D43: =RADIANS(A43) -> 0.23676165 | E43: =(Arkusz1!C$35-Arkusz1!C$33)*(1-ABS('projekty 2 i 3'!G43/Arkusz1!C$36)) -> -1.8446453e-06 | F43: =RADIANS(L43) -> 0.30972247 | G43: =B43 -> 1.6415303 | H43: =C43 -> 0.020180935 | I43: =A43 -> 13.565444 | J43: =H43+E43 -> 0.02017909 | K43: =DEGREES(G43*(1+Arkusz1!C$46)/Arkusz1!C$20/PI()) -> 4.1803466 | L43: =I43+K43 -> 17.74579 | M43: =G43^2*(1+Arkusz1!C$45)/Arkusz1!C$20/PI() -> 0.11948193 | N43: =J43+M43+Arkusz1!C$38 -> 0.14039872 | O43: =Arkusz1!C$31/Arkusz1!C$77+(Arkusz1!C$68-Arkusz1!C$29)/Arkusz1!C$77*'projekty 2 i 3'!G43 -> -0.075829762 | P43: =Arkusz1!C$72+Arkusz1!C$73+1/PI()/Arkusz1!C$76*'projekty 2 i 3'!O43^2 -> 0.010964249 | Q43: =Arkusz1!C$92*(1+1/Arkusz1!C$93*ABS('projekty 2 i 3'!G43)) -> 0.015620728 | R43: =(N43+Q43+P43*Arkusz1!C$67/Arkusz1!C$5)*(1+Arkusz1!C$94) -> 0.16515644 | S43: =O43*Arkusz1!C$67/Arkusz1!C$5 -> -0.019260048 | T43: =G43+S43 -> 1.6222703 | U43: =T43/R43 -> 9.822628 | V43: =T43^3/R43^2 -> 156.52316 | W43: =I43 -> 13.565444 | X43: =T43^2 -> 2.6317608 | Y43: =U43/10 -> 0.9822628 | Z43: =V43/100 -> 1.5652316 | AA43: =Arkusz1!C$32*('projekty 2 i 3'!D43-'projekty 2 i 3'!D$18) -> 1.7686576
A44: 15.277399 | B44: 1.6488925 | C44: =0.0001*B44^4+0.0011*B44^3+0.0047*B44^2-0.0023*B44+0.0057 -> 0.020356732 | D44: =RADIANS(A44) -> 0.26664091 | E44: =(Arkusz1!C$35-Arkusz1!C$33)*(1-ABS('projekty 2 i 3'!G44/Arkusz1!C$36)) -> 0 | F44: =RADIANS(L44) -> 0.33992895 | G44: =B44 -> 1.6488925 | H44: =C44 -> 0.020356732 | I44: =A44 -> 15.277399 | J44: =H44+E44 -> 0.020356732 | K44: =DEGREES(G44*(1+Arkusz1!C$46)/Arkusz1!C$20/PI()) -> 4.1990953 | L44: =I44+K44 -> 19.476494 | M44: =G44^2*(1+Arkusz1!C$45)/Arkusz1!C$20/PI() -> 0.12055608 | N44: =J44+M44+Arkusz1!C$38 -> 0.14165051 | O44: =Arkusz1!C$31/Arkusz1!C$77+(Arkusz1!C$68-Arkusz1!C$29)/Arkusz1!C$77*'projekty 2 i 3'!G44 -> -0.075625526 | P44: =Arkusz1!C$72+Arkusz1!C$73+1/PI()/Arkusz1!C$76*'projekty 2 i 3'!O44^2 -> 0.010961751 | Q44: =Arkusz1!C$92*(1+1/Arkusz1!C$93*ABS('projekty 2 i 3'!G44)) -> 0.015635778 | R44: =(N44+Q44+P44*Arkusz1!C$67/Arkusz1!C$5)*(1+Arkusz1!C$94) -> 0.16647329 | S44: =O44*Arkusz1!C$67/Arkusz1!C$5 -> -0.019208173 | T44: =G44+S44 -> 1.6296843 | U44: =T44/R44 -> 9.7894643 | V44: =T44^3/R44^2 -> 156.17853 | W44: =I44 -> 15.277399 | X44: =T44^2 -> 2.655871 | Y44: =U44/10 -> 0.97894643 | Z44: =V44/100 -> 1.5617853 | AA44: =Arkusz1!C$32*('projekty 2 i 3'!D44-'projekty 2 i 3'!D$18) -> 1.9519459
A45: 15.541783 | B45: 1.6423483 | C45: =0.0001*B45^4+0.0011*B45^3+0.0047*B45^2-0.0023*B45+0.0057 -> 0.020200405 | D45: =RADIANS(A45) -> 0.27125529 | G45: Tabela 3.3 Charakterystyki aerodynamiczne samolotu Piper PA-31 Navajo
A46: 15.806604 | B46: 1.6324775 | C46: =0.0001*B46^4+0.0011*B46^3+0.0047*B46^2-0.0023*B46+0.0057 -> 0.019966512 | D46: =RADIANS(A46) -> 0.27587729
A47: 16.533007 | B47: 1.619471 | C47: =0.0001*B47^4+0.0011*B47^3+0.0047*B47^2-0.0023*B47+0.0057 -> 0.019661791 | D47: =RADIANS(A47) -> 0.28855541
A48: 16.86327 | B48: 1.6129541 | C48: =0.0001*B48^4+0.0011*B48^3+0.0047*B48^2-0.0023*B48+0.0057 -> 0.019510591 | D48: =RADIANS(A48) -> 0.29431958
A49: 16.930457 | B49: 1.6030015 | C49: =0.0001*B49^4+0.0011*B49^3+0.0047*B49^2-0.0023*B49+0.0057 -> 0.019281577 | D49: =RADIANS(A49) -> 0.29549221
A50: 18.18781 | B50: 1.5602735 | C50: =0.0001*B50^4+0.0011*B50^3+0.0047*B50^2-0.0023*B50+0.0057 -> 0.018324213 | D50: =RADIANS(A50) -> 0.31743717

Sheet projekt 4
H1: mmin | I1: =Arkusz1!C101 -> 1863 | J1: mśr | K1: =Arkusz1!C102 -> 2405.5 | L1: mmax | M1: =Arkusz1!C7 -> 2948
B2: Cz | C2: Cx | D2: K | E2: A | F2: B | G2: γ [°] | H2: V [m/s] | I2: w [m/s] | J2: V [m/s] | K2: w [m/s] | L2: V [m/s] | M2: w [m/s]
A3: 1 | B3: =OFFSET('projekty 2 i 3'!$T$44,-A3+1,0,1,1) -> 1.6296843 | C3: =OFFSET('projekty 2 i 3'!$R$44,-A3+1,0,1,1) -> 0.16647329 | D3: =OFFSET('projekty 2 i 3'!$U$44,-A3+1,0,1,1) -> 9.7894643 | E3: =SQRT(1/SQRT(B3^2+C3^2)) -> 0.78130605 | F3: =SQRT(C3^2/(C3^2+B3^2)^(3/2)) -> 0.079397737 | G3: =DEGREES(ATAN(1/D3)) -> 5.8325693 | H3: ='projekt 4'!$E3*SQRT(2*Arkusz1!$C$14/Arkusz1!$C$5/Arkusz1!$C$103*'projekt 4'!I$1) -> 36.926675 | I3: ='projekt 4'!$F3*SQRT(2*Arkusz1!$C$14/Arkusz1!$C$5/Arkusz1!$C$103*'projekt 4'!I$1) -> 3.7525556 | J3: ='projekt 4'!$E3*SQRT(2*Arkusz1!$C$14/Arkusz1!$C$5/Arkusz1!$C$103*'projekt 4'!K$1) -> 41.960094 | K3: ='projekt 4'!$F3*SQRT(2*Arkusz1!$C$14/Arkusz1!$C$5/Arkusz1!$C$103*'projekt 4'!K$1) -> 4.2640608 | L3: ='projekt 4'!$E3*SQRT(2*Arkusz1!$C$14/Arkusz1!$C$5/Arkusz1!$C$103*'projekt 4'!M$1) -> 46.451262 | M3: ='projekt 4'!$F3*SQRT(2*Arkusz1!$C$14/Arkusz1!$C$5/Arkusz1!$C$103*'projekt 4'!M$1) -> 4.7204614 | O3: 0 | P3: 0
A4: 2 | B4: =OFFSET('projekty 2 i 3'!$T$44,-A4+1,0,1,1) -> 1.6222703 | C4: =OFFSET('projekty 2 i 3'!$R$44,-A4+1,0,1,1) -> 0.16515644 | D4: =OFFSET('projekty 2 i 3'!$U$44,-A4+1,0,1,1) -> 9.822628 | E4: =SQRT(1/SQRT(B4^2+C4^2)) -> 0.783103 | F4: =SQRT(C4^2/(C4^2+B4^2)^(3/2)) -> 0.079314423 | G4: =DEGREES(ATAN(1/D4)) -> 5.8130121 | H4: ='projekt 4'!$E4*SQRT(2*Arkusz1!$C$14/Arkusz1!$C$5/Arkusz1!$C$103*'projekt 4'!I$1) -> 37.011604 | I4: ='projekt 4'!$F4*SQRT(2*Arkusz1!$C$14/Arkusz1!$C$5/Arkusz1!$C$103*'projekt 4'!I$1) -> 3.748618 | J4: ='projekt 4'!$E4*SQRT(2*Arkusz1!$C$14/Arkusz1!$C$5/Arkusz1!$C$103*'projekt 4'!K$1) -> 42.056599 | K4: ='projekt 4'!$F4*SQRT(2*Arkusz1!$C$14/Arkusz1!$C$5/Arkusz1!$C$103*'projekt 4'!K$1) -> 4.2595864 | L4: ='projekt 4'!$E4*SQRT(2*Arkusz1!$C$14/Arkusz1!$C$5/Arkusz1!$C$103*'projekt 4'!M$1) -> 46.558096 | M4: ='projekt 4'!$F4*SQRT(2*Arkusz1!$C$14/Arkusz1!$C$5/Arkusz1!$C$103*'projekt 4'!M$1) -> 4.7155081 | O4: 140 | P4: =O4*TAN(RADIANS(Arkusz1!C105)) -> 9.7979465
A5: 3 | B5: =OFFSET('projekty 2 i 3'!$T$44,-A5+1,0,1,1) -> 1.6120553 | C5: =OFFSET('projekty 2 i 3'!$R$44,-A5+1,0,1,1) -> 0.16335247 | D5: =OFFSET('projekty 2 i 3'!$U$44,-A5+1,0,1,1) -> 9.8685704 | E5: =SQRT(1/SQRT(B5^2+C5^2)) -> 0.7855989 | F5: =SQRT(C5^2/(C5^2+B5^2)^(3/2)) -> 0.079200567 | G5: =DEGREES(ATAN(1/D5)) -> 5.7861341 | H5: ='projekt 4'!$E5*SQRT(2*Arkusz1!$C$14/Arkusz1!$C$5/Arkusz1!$C$103*'projekt 4'!I$1) -> 37.129567 | I5: ='projekt 4'!$F5*SQRT(2*Arkusz1!$C$14/Arkusz1!$C$5/Arkusz1!$C$103*'projekt 4'!I$1) -> 3.7432368 | J5: ='projekt 4'!$E5*SQRT(2*Arkusz1!$C$14/Arkusz1!$C$5/Arkusz1!$C$103*'projekt 4'!K$1) -> 42.190642 | K5: ='projekt 4'!$F5*SQRT(2*Arkusz1!$C$14/Arkusz1!$C$5/Arkusz1!$C$103*'projekt 4'!K$1) -> 4.2534718 | L5: ='projekt 4'!$E5*SQRT(2*Arkusz1!$C$14/Arkusz1!$C$5/Arkusz1!$C$103*'projekt 4'!M$1) -> 46.706486 | M5: ='projekt 4'!$F5*SQRT(2*Arkusz1!$C$14/Arkusz1!$C$5/Arkusz1!$C$103*'projekt 4'!M$1) -> 4.708739
A6: 4 | B6: =OFFSET('projekty 2 i 3'!$T$44,-A6+1,0,1,1) -> 1.6018678 | C6: =OFFSET('projekty 2 i 3'!$R$44,-A6+1,0,1,1) -> 0.16156529 | D6: =OFFSET('projekty 2 i 3'!$U$44,-A6+1,0,1,1) -> 9.9146782 | E6: =SQRT(1/SQRT(B6^2+C6^2)) -> 0.78811163 | F6: =SQRT(C6^2/(C6^2+B6^2)^(3/2)) -> 0.079088122 | G6: =DEGREES(ATAN(1/D6)) -> 5.7594073 | H6: ='projekt 4'!$E6*SQRT(2*Arkusz1!$C$14/Arkusz1!$C$5/Arkusz1!$C$103*'projekt 4'!I$1) -> 37.248325 | I6: ='projekt 4'!$F6*SQRT(2*Arkusz1!$C$14/Arkusz1!$C$5/Arkusz1!$C$103*'projekt 4'!I$1) -> 3.7379224 | J6: ='projekt 4'!$E6*SQRT(2*Arkusz1!$C$14/Arkusz1!$C$5/Arkusz1!$C$103*'projekt 4'!K$1) -> 42.325588 | K6: ='projekt 4'!$F6*SQRT(2*Arkusz1!$C$14/Arkusz1!$C$5/Arkusz1!$C$103*'projekt 4'!K$1) -> 4.247433 | L6: ='projekt 4'!$E6*SQRT(2*Arkusz1!$C$14/Arkusz1!$C$5/Arkusz1!$C$103*'projekt 4'!M$1) -> 46.855876 | M6: ='projekt 4'!$F6*SQRT(2*Arkusz1!$C$14/Arkusz1!$C$5/Arkusz1!$C$103*'projekt 4'!M$1) -> 4.7020538
A7: 5 | B7: =OFFSET('projekty 2 i 3'!$T$44,-A7+1,0,1,1) -> 1.5917078 | C7: =OFFSET('projekty 2 i 3'!$R$44,-A7+1,0,1,1) -> 0.1597948 | D7: =OFFSET('projekty 2 i 3'!$U$44,-A7+1,0,1,1) -> 9.9609491 | E7: =SQRT(1/SQRT(B7^2+C7^2)) -> 0.79064137 | F7: =SQRT(C7^2/(C7^2+B7^2)^(3/2)) -> 0.07897711 | G7: =DEGREES(ATAN(1/D7)) -> 5.7328321 | H7: ='projekt 4'!$E7*SQRT(2*Arkusz1!$C$14/Arkusz1!$C$5/Arkusz1!$C$103*'projekt 4'!I$1) -> 37.367888 | I7: ='projekt 4'!$F7*SQRT(2*Arkusz1!$C$14/Arkusz1!$C$5/Arkusz1!$C$103*'projekt 4'!I$1) -> 3.7326756 | J7: ='projekt 4'!$E7*SQRT(2*Arkusz1!$C$14/Arkusz1!$C$5/Arkusz1!$C$103*'projekt 4'!K$1) -> 42.461448 | K7: ='projekt 4'!$F7*SQRT(2*Arkusz1!$C$14/Arkusz1!$C$5/Arkusz1!$C$103*'projekt 4'!K$1) -> 4.241471 | L7: ='projekt 4'!$E7*SQRT(2*Arkusz1!$C$14/Arkusz1!$C$5/Arkusz1!$C$103*'projekt 4'!M$1) -> 47.006278 | M7: ='projekt 4'!$F7*SQRT(2*Arkusz1!$C$14/Arkusz1!$C$5/Arkusz1!$C$103*'projekt 4'!M$1) -> 4.6954537
A8: 6 | B8: =OFFSET('projekty 2 i 3'!$T$44,-A8+1,0,1,1) -> 1.5714152 | C8: =OFFSET('projekty 2 i 3'!$R$44,-A8+1,0,1,1) -> 0.15629403 | D8: =OFFSET('projekty 2 i 3'!$U$44,-A8+1,0,1,1) -> 10.054224 | E8: =SQRT(1/SQRT(B8^2+C8^2)) -> 0.79576666 | F8: =SQRT(C8^2/(C8^2+B8^2)^(3/2)) -> 0.078758894 | G8: =DEGREES(ATAN(1/D8)) -> 5.6799967 | H8: ='projekt 4'!$E8*SQRT(2*Arkusz1!$C$14/Arkusz1!$C$5/Arkusz1!$C$103*'projekt 4'!I$1) -> 37.610123 | I8: ='projekt 4'!$F8*SQRT(2*Arkusz1!$C$14/Arkusz1!$C$5/Arkusz1!$C$103*'projekt 4'!I$1) -> 3.7223621 | J8: ='projekt 4'!$E8*SQRT(2*Arkusz1!$C$14/Arkusz1!$C$5/Arkusz1!$C$103*'projekt 4'!K$1) -> 42.736702 | K8: ='projekt 4'!$F8*SQRT(2*Arkusz1!$C$14/Arkusz1!$C$5/Arkusz1!$C$103*'projekt 4'!K$1) -> 4.2297517 | L8: ='projekt 4'!$E8*SQRT(2*Arkusz1!$C$14/Arkusz1!$C$5/Arkusz1!$C$103*'projekt 4'!M$1) -> 47.310993 | M8: ='projekt 4'!$F8*SQRT(2*Arkusz1!$C$14/Arkusz1!$C$5/Arkusz1!$C$103*'projekt 4'!M$1) -> 4.68248
A9: 7 | B9: =OFFSET('projekty 2 i 3'!$T$44,-A9+1,0,1,1) -> 1.4737967 | C9: =OFFSET('projekty 2 i 3'!$R$44,-A9+1,0,1,1) -> 0.1401108 | D9: =OFFSET('projekty 2 i 3'!$U$44,-A9+1,0,1,1) -> 10.518795 | E9: =SQRT(1/SQRT(B9^2+C9^2)) -> 0.82187229 | F9: =SQRT(C9^2/(C9^2+B9^2)^(3/2)) -> 0.077782987 | G9: =DEGREES(ATAN(1/D9)) -> 5.4306695 | H9: ='projekt 4'!$E9*SQRT(2*Arkusz1!$C$14/Arkusz1!$C$5/Arkusz1!$C$103*'projekt 4'!I$1) -> 38.843947 | I9: ='projekt 4'!$F9*SQRT(2*Arkusz1!$C$14/Arkusz1!$C$5/Arkusz1!$C$103*'projekt 4'!I$1) -> 3.6762381 | J9: ='projekt 4'!$E9*SQRT(2*Arkusz1!$C$14/Arkusz1!$C$5/Arkusz1!$C$103*'projekt 4'!K$1) -> 44.138707 | K9: ='projekt 4'!$F9*SQRT(2*Arkusz1!$C$14/Arkusz1!$C$5/Arkusz1!$C$103*'projekt 4'!K$1) -> 4.1773406 | L9: ='projekt 4'!$E9*SQRT(2*Arkusz1!$C$14/Arkusz1!$C$5/Arkusz1!$C$103*'projekt 4'!M$1) -> 48.863061 | M9: ='projekt 4'!$F9*SQRT(2*Arkusz1!$C$14/Arkusz1!$C$5/Arkusz1!$C$103*'projekt 4'!M$1) -> 4.6244591
A10: 8 | B10: =OFFSET('projekty 2 i 3'!$T$44,-A10+1,0,1,1) -> 1.3793909 | C10: =OFFSET('projekty 2 i 3'!$R$44,-A10+1,0,1,1) -> 0.12513719 | D10: =OFFSET('projekty 2 i 3'!$U$44,-A10+1,0,1,1) -> 11.02303 | E10: =SQRT(1/SQRT(B10^2+C10^2)) -> 0.84970157 | F10: =SQRT(C10^2/(C10^2+B10^2)^(3/2)) -> 0.076768957 | G10: =DEGREES(ATAN(1/D10)) -> 5.1836357 | H10: ='projekt 4'!$E10*SQRT(2*Arkusz1!$C$14/Arkusz1!$C$5/Arkusz1!$C$103*'projekt 4'!I$1) -> 40.159235 | I10: ='projekt 4'!$F10*SQRT(2*Arkusz1!$C$14/Arkusz1!$C$5/Arkusz1!$C$103*'projekt 4'!I$1) -> 3.6283123 | J10: ='projekt 4'!$E10*SQRT(2*Arkusz1!$C$14/Arkusz1!$C$5/Arkusz1!$C$103*'projekt 4'!K$1) -> 45.63328 | K10: ='projekt 4'!$F10*SQRT(2*Arkusz1!$C$14/Arkusz1!$C$5/Arkusz1!$C$103*'projekt 4'!K$1) -> 4.122882 | L10: ='projekt 4'!$E10*SQRT(2*Arkusz1!$C$14/Arkusz1!$C$5/Arkusz1!$C$103*'projekt 4'!M$1) -> 50.517604 | M10: ='projekt 4'!$F10*SQRT(2*Arkusz1!$C$14/Arkusz1!$C$5/Arkusz1!$C$103*'projekt 4'!M$1) -> 4.5641716
A11: 9 | B11: =OFFSET('projekty 2 i 3'!$T$44,-A11+1,0,1,1) -> 1.2717222 | C11: =OFFSET('projekty 2 i 3'!$R$44,-A11+1,0,1,1) -> 0.11010578 | D11: =OFFSET('projekty 2 i 3'!$U$44,-A11+1,0,1,1) -> 11.550004 | E11: =SQRT(1/SQRT(B11^2+C11^2)) -> 0.88510141 | F11: =SQRT(C11^2/(C11^2+B11^2)^(3/2)) -> 0.076346515 | G11: =DEGREES(ATAN(1/D11)) -> 4.9483322 | H11: ='projekt 4'!$E11*SQRT(2*Arkusz1!$C$14/Arkusz1!$C$5/Arkusz1!$C$103*'projekt 4'!I$1) -> 41.832329 | I11: ='projekt 4'!$F11*SQRT(2*Arkusz1!$C$14/Arkusz1!$C$5/Arkusz1!$C$103*'projekt 4'!I$1) -> 3.6083465 | J11: ='projekt 4'!$E11*SQRT(2*Arkusz1!$C$14/Arkusz1!$C$5/Arkusz1!$C$103*'projekt 4'!K$1) -> 47.534431 | K11: ='projekt 4'!$F11*SQRT(2*Arkusz1!$C$14/Arkusz1!$C$5/Arkusz1!$C$103*'projekt 4'!K$1) -> 4.1001948 | L11: ='projekt 4'!$E11*SQRT(2*Arkusz1!$C$14/Arkusz1!$C$5/Arkusz1!$C$103*'projekt 4'!M$1) -> 52.622243 | M11: ='projekt 4'!$F11*SQRT(2*Arkusz1!$C$14/Arkusz1!$C$5/Arkusz1!$C$103*'projekt 4'!M$1) -> 4.539056
A12: 10 | B12: =OFFSET('projekty 2 i 3'!$T$44,-A12+1,0,1,1) -> 1.177591 | C12: =OFFSET('projekty 2 i 3'!$R$44,-A12+1,0,1,1) -> 0.097841171 | D12: =OFFSET('projekty 2 i 3'!$U$44,-A12+1,0,1,1) -> 12.035741 | E12: =SQRT(1/SQRT(B12^2+C12^2)) -> 0.91993221 | F12: =SQRT(C12^2/(C12^2+B12^2)^(3/2)) -> 0.076170905 | G12: =DEGREES(ATAN(1/D12)) -> 4.7495605 | H12: ='projekt 4'!$E12*SQRT(2*Arkusz1!$C$14/Arkusz1!$C$5/Arkusz1!$C$103*'projekt 4'!I$1) -> 43.478529 | I12: ='projekt 4'!$F12*SQRT(2*Arkusz1!$C$14/Arkusz1!$C$5/Arkusz1!$C$103*'projekt 4'!I$1) -> 3.6000467 | J12: ='projekt 4'!$E12*SQRT(2*Arkusz1!$C$14/Arkusz1!$C$5/Arkusz1!$C$103*'projekt 4'!K$1) -> 49.405022 | K12: ='projekt 4'!$F12*SQRT(2*Arkusz1!$C$14/Arkusz1!$C$5/Arkusz1!$C$103*'projekt 4'!K$1) -> 4.0907636 | L12: ='projekt 4'!$E12*SQRT(2*Arkusz1!$C$14/Arkusz1!$C$5/Arkusz1!$C$103*'projekt 4'!M$1) -> 54.693051 | M12: ='projekt 4'!$F12*SQRT(2*Arkusz1!$C$14/Arkusz1!$C$5/Arkusz1!$C$103*'projekt 4'!M$1) -> 4.5286154
A13: 11 | B13: =OFFSET('projekty 2 i 3'!$T$44,-A13+1,0,1,1) -> 1.0801647 | C13: =OFFSET('projekty 2 i 3'!$R$44,-A13+1,0,1,1) -> 0.086109593 | D13: =OFFSET('projekty 2 i 3'!$U$44,-A13+1,0,1,1) -> 12.544069 | E13: =SQRT(1/SQRT(B13^2+C13^2)) -> 0.96065446 | F13: =SQRT(C13^2/(C13^2+B13^2)^(3/2)) -> 0.076340174 | G13: =DEGREES(ATAN(1/D13)) -> 4.5579204 | H13: ='projekt 4'!$E13*SQRT(2*Arkusz1!$C$14/Arkusz1!$C$5/Arkusz1!$C$103*'projekt 4'!I$1) -> 45.403174 | I13: ='projekt 4'!$F13*SQRT(2*Arkusz1!$C$14/Arkusz1!$C$5/Arkusz1!$C$103*'projekt 4'!I$1) -> 3.6080468 | J13: ='projekt 4'!$E13*SQRT(2*Arkusz1!$C$14/Arkusz1!$C$5/Arkusz1!$C$103*'projekt 4'!K$1) -> 51.592013 | K13: ='projekt 4'!$F13*SQRT(2*Arkusz1!$C$14/Arkusz1!$C$5/Arkusz1!$C$103*'projekt 4'!K$1) -> 4.0998542 | L13: ='projekt 4'!$E13*SQRT(2*Arkusz1!$C$14/Arkusz1!$C$5/Arkusz1!$C$103*'projekt 4'!M$1) -> 57.114125 | M13: ='projekt 4'!$F13*SQRT(2*Arkusz1!$C$14/Arkusz1!$C$5/Arkusz1!$C$103*'projekt 4'!M$1) -> 4.5386791
A14: 12 | B14: =OFFSET('projekty 2 i 3'!$T$44,-A14+1,0,1,1) -> 0.96920079 | C14: =OFFSET('projekty 2 i 3'!$R$44,-A14+1,0,1,1) -> 0.074454257 | D14: =OFFSET('projekty 2 i 3'!$U$44,-A14+1,0,1,1) -> 13.017399 | E14: =SQRT(1/SQRT(B14^2+C14^2)) -> 1.0142716 | F14: =SQRT(C14^2/(C14^2+B14^2)^(3/2)) -> 0.077687715 | G14: =DEGREES(ATAN(1/D14)) -> 4.392849 | H14: ='projekt 4'!$E14*SQRT(2*Arkusz1!$C$14/Arkusz1!$C$5/Arkusz1!$C$103*'projekt 4'!I$1) -> 47.937269 | I14: ='projekt 4'!$F14*SQRT(2*Arkusz1!$C$14/Arkusz1!$C$5/Arkusz1!$C$103*'projekt 4'!I$1) -> 3.6717353 | J14: ='projekt 4'!$E14*SQRT(2*Arkusz1!$C$14/Arkusz1!$C$5/Arkusz1!$C$103*'projekt 4'!K$1) -> 54.471526 | K14: ='projekt 4'!$F14*SQRT(2*Arkusz1!$C$14/Arkusz1!$C$5/Arkusz1!$C$103*'projekt 4'!K$1) -> 4.172224 | L14: ='projekt 4'!$E14*SQRT(2*Arkusz1!$C$14/Arkusz1!$C$5/Arkusz1!$C$103*'projekt 4'!M$1) -> 60.301845 | M14: ='projekt 4'!$F14*SQRT(2*Arkusz1!$C$14/Arkusz1!$C$5/Arkusz1!$C$103*'projekt 4'!M$1) -> 4.6187949
A15: 13 | B15: =OFFSET('projekty 2 i 3'!$T$44,-A15+1,0,1,1) -> 0.8682871 | C15: =OFFSET('projekty 2 i 3'!$R$44,-A15+1,0,1,1) -> 0.063818496 | D15: =OFFSET('projekty 2 i 3'!$U$44,-A15+1,0,1,1) -> 13.605571 | E15: =SQRT(1/SQRT(B15^2+C15^2)) -> 1.071725 | F15: =SQRT(C15^2/(C15^2+B15^2)^(3/2)) -> 0.078559134 | G15: =DEGREES(ATAN(1/D15)) -> 4.2036411 | H15: ='projekt 4'!$E15*SQRT(2*Arkusz1!$C$14/Arkusz1!$C$5/Arkusz1!$C$103*'projekt 4'!I$1) -> 50.652675 | I15: ='projekt 4'!$F15*SQRT(2*Arkusz1!$C$14/Arkusz1!$C$5/Arkusz1!$C$103*'projekt 4'!I$1) -> 3.7129209 | J15: ='projekt 4'!$E15*SQRT(2*Arkusz1!$C$14/Arkusz1!$C$5/Arkusz1!$C$103*'projekt 4'!K$1) -> 57.557065 | K15: ='projekt 4'!$F15*SQRT(2*Arkusz1!$C$14/Arkusz1!$C$5/Arkusz1!$C$103*'projekt 4'!K$1) -> 4.2190236 | L15: ='projekt 4'!$E15*SQRT(2*Arkusz1!$C$14/Arkusz1!$C$5/Arkusz1!$C$103*'projekt 4'!M$1) -> 63.717643 | M15: ='projekt 4'!$F15*SQRT(2*Arkusz1!$C$14/Arkusz1!$C$5/Arkusz1!$C$103*'projekt 4'!M$1) -> 4.6706036
A16: 14 | B16: =OFFSET('projekty 2 i 3'!$T$44,-A16+1,0,1,1) -> 0.77061363 | C16: =OFFSET('projekty 2 i 3'!$R$44,-A16+1,0,1,1) -> 0.054581229 | D16: =OFFSET('projekty 2 i 3'!$U$44,-A16+1,0,1,1) -> 14.118657 | E16: =SQRT(1/SQRT(B16^2+C16^2)) -> 1.1377277 | F16: =SQRT(C16^2/(C16^2+B16^2)^(3/2)) -> 0.080381914 | G16: =DEGREES(ATAN(1/D16)) -> 4.0513951 | H16: ='projekt 4'!$E16*SQRT(2*Arkusz1!$C$14/Arkusz1!$C$5/Arkusz1!$C$103*'projekt 4'!I$1) -> 53.772144 | I16: ='projekt 4'!$F16*SQRT(2*Arkusz1!$C$14/Arkusz1!$C$5/Arkusz1!$C$103*'projekt 4'!I$1) -> 3.7990705 | J16: ='projekt 4'!$E16*SQRT(2*Arkusz1!$C$14/Arkusz1!$C$5/Arkusz1!$C$103*'projekt 4'!K$1) -> 61.101744 | K16: ='projekt 4'!$F16*SQRT(2*Arkusz1!$C$14/Arkusz1!$C$5/Arkusz1!$C$103*'projekt 4'!K$1) -> 4.3169161 | L16: ='projekt 4'!$E16*SQRT(2*Arkusz1!$C$14/Arkusz1!$C$5/Arkusz1!$C$103*'projekt 4'!M$1) -> 67.641724 | M16: ='projekt 4'!$F16*SQRT(2*Arkusz1!$C$14/Arkusz1!$C$5/Arkusz1!$C$103*'projekt 4'!M$1) -> 4.778974
... A23: 21 | B23: =OFFSET('projekty 2 i 3'!$T$44,-A23+1,0,1,1) -> 0.11836795 | C23: =OFFSET('projekty 2 i 3'!$R$44,-A23+1,0,1,1) -> 0.023072784 | D23: =OFFSET('projekty 2 i 3'!$U$44,-A23+1,0,1,1) -> 5.1301981 | E23: =SQRT(1/SQRT(B23^2+C23^2)) -> 2.8796126 | F23: =SQRT(C23^2/(C23^2+B23^2)^(3/2)) -> 0.55093734 | G23: =DEGREES(ATAN(1/D23)) -> 11.030028 | H23: ='projekt 4'!$E23*SQRT(2*Arkusz1!$C$14/Arkusz1!$C$5/Arkusz1!$C$103*'projekt 4'!I$1) -> 136.09842 | I23: ='projekt 4'!$F23*SQRT(2*Arkusz1!$C$14/Arkusz1!$C$5/Arkusz1!$C$103*'projekt 4'!I$1) -> 26.038815 | J23: ='projekt 4'!$E23*SQRT(2*Arkusz1!$C$14/Arkusz1!$C$5/Arkusz1!$C$103*'projekt 4'!K$1) -> 154.64979 | K23: ='projekt 4'!$F23*SQRT(2*Arkusz1!$C$14/Arkusz1!$C$5/Arkusz1!$C$103*'projekt 4'!K$1) -> 29.588127 | L23: ='projekt 4'!$E23*SQRT(2*Arkusz1!$C$14/Arkusz1!$C$5/Arkusz1!$C$103*'projekt 4'!M$1) -> 171.20262 | M23: ='projekt 4'!$F23*SQRT(2*Arkusz1!$C$14/Arkusz1!$C$5/Arkusz1!$C$103*'projekt 4'!M$1) -> 32.75507
C40: mmin | D40: =I1 -> 1863 | F40: mśr | G40: =K1 -> 2405.5 | I40: mmax | J40: =M1 -> 2948
C41: obliczone [m/s] | D41: z wykresu | E41: błąd | F41: obliczone | G41: z wykresu | H41: błąd | I41: obliczone | J41: z wykresu | K41: błąd
B42: Vopt | C42: =SQRT(2*Arkusz1!$C$14/Arkusz1!$C$5/Arkusz1!$C$103/SQRT(Arkusz1!$C$97*PI()*Arkusz1!$C$95)*'projekt 4'!D$40) -> 59.118072 | D42: 59 | E42: =100*ABS(C42-D42)/MAX(C42:D42) -> 0.19972227 | F42: =SQRT(2*Arkusz1!$C$14/Arkusz1!$C$5/Arkusz1!$C$103/SQRT(Arkusz1!$C$97*PI()*Arkusz1!$C$95)*'projekt 4'!G$40) -> 67.176367 | G42: 67 | H42: =100*ABS(F42-G42)/MAX(F42:G42) -> 0.26254371 | I42: =SQRT(2*Arkusz1!$C$14/Arkusz1!$C$5/Arkusz1!$C$103/SQRT(Arkusz1!$C$97*PI()*Arkusz1!$C$95)*'projekt 4'!J$40) -> 74.36654 | J42: 74 | K42: =100*ABS(I42-J42)/MAX(I42:J42) -> 0.49288251
B43: Vek | C43: =C42/(3^(1/4)) -> 44.920021 | D43: 45 | E43: =100*ABS(C43-D43)/MAX(C43:D43) -> 0.17773169 | F43: =F42/(3^(1/4)) -> 51.043001 | G43: 51 | H43: =100*ABS(F43-G43)/MAX(F43:G43) -> 0.084244902 | I43: =I42/(3^(1/4)) -> 56.506351 | J43: 56.5 | K43: =100*ABS(I43-J43)/MAX(I43:J43) -> 0.011238842
B44: wopt | C44: =SQRT(8*SQRT(Arkusz1!$C$95)*Arkusz1!$C$14/Arkusz1!$C$5/Arkusz1!$C$103/((Arkusz1!$C$97*PI())^(3/2))*'projekt 4'!D$40) -> 4.0883214 | D44: 4.1 | E44: =100*ABS(C44-D44)/MAX(C44:D44) -> 0.28484467 | F44: =SQRT(8*SQRT(Arkusz1!$C$95)*Arkusz1!$C$14/Arkusz1!$C$5/Arkusz1!$C$103/((Arkusz1!$C$97*PI())^(3/2))*'projekt 4'!G$40) -> 4.6455943 | G44: 4.6 | H44: =100*ABS(F44-G44)/MAX(F44:G44) -> 0.98145243 | I44: =SQRT(8*SQRT(Arkusz1!$C$95)*Arkusz1!$C$14/Arkusz1!$C$5/Arkusz1!$C$103/((Arkusz1!$C$97*PI())^(3/2))*'projekt 4'!J$40) -> 5.142832 | J44: 5.1 | K44: =100*ABS(I44-J44)/MAX(I44:J44) -> 0.83284885
B45: wek | C45: =C44*2/(3^(3/4)) -> 3.5870223 | D45: 3.6 | E45: =100*ABS(C45-D45)/MAX(C45:D45) -> 0.36049056 | F45: =F44*2/(3^(3/4)) -> 4.075964 | G45: 4.1 | H45: =100*ABS(F45-G45)/MAX(F45:G45) -> 0.58624503 | I45: =I44*2/(3^(3/4)) -> 4.5122317 | J45: 4.5 | K45: =100*ABS(I45-J45)/MAX(I45:J45) -> 0.27107903

Sheet projekt 5
A1: =Arkusz1!C11 -> 0.053 | B1: h | C1: N | D1: CN
A2: =Arkusz1!C$23*(1-'projekt 5'!B2/44300)^4.256 -> 1.225 | B2: 0 | C2: =Arkusz1!C$9*('projekt 5'!A2/A$2-Arkusz1!C$106)/(1-Arkusz1!C$106) -> 223000 | D2: =C2/A2/Arkusz1!$C$110^5/(Arkusz1!$C$10/60)^3 -> 0.10859254
A3: =Arkusz1!C$23*(1-'projekt 5'!B3/44300)^4.256 -> 1.1115636 | B3: 1000 | C3: =Arkusz1!C$9*('projekt 5'!A3/A$2-Arkusz1!C$106)/(1-Arkusz1!C$106) -> 199534.03 | D3: =C3/A3/Arkusz1!$C$110^5/(Arkusz1!$C$10/60)^3 -> 0.10708136
A4: =Arkusz1!C$23*(1-'projekt 5'!B4/44300)^4.256 -> 1.0063439 | B4: 2000 | C4: =Arkusz1!C$9*('projekt 5'!A4/A$2-Arkusz1!C$106)/(1-Arkusz1!C$106) -> 177767.81 | D4: =C4/A4/Arkusz1!$C$110^5/(Arkusz1!$C$10/60)^3 -> 0.10537508
A5: =Arkusz1!C$23*(1-'projekt 5'!B5/44300)^4.256 -> 0.90891914 | B5: 3000 | C5: =Arkusz1!C$9*('projekt 5'!A5/A$2-Arkusz1!C$106)/(1-Arkusz1!C$106) -> 157614.07 | D5: =C5/A5/Arkusz1!$C$110^5/(Arkusz1!$C$10/60)^3 -> 0.10344297
A6: =Arkusz1!C$23*(1-'projekt 5'!B6/44300)^4.256 -> 0.8188797 | B6: 4000 | C6: =Arkusz1!C$9*('projekt 5'!A6/A$2-Arkusz1!C$106)/(1-Arkusz1!C$106) -> 138988.1 | D6: =C6/A6/Arkusz1!$C$110^5/(Arkusz1!$C$10/60)^3 -> 0.10124854
A7: =Arkusz1!C$23*(1-'projekt 5'!B7/44300)^4.256 -> 0.73582836 | B7: 5000 | C7: =Arkusz1!C$9*('projekt 5'!A7/A$2-Arkusz1!C$106)/(1-Arkusz1!C$106) -> 121807.72 | D7: =C7/A7/Arkusz1!$C$110^5/(Arkusz1!$C$10/60)^3 -> 0.098748279
A8: =Arkusz1!C$23*(1-'projekt 5'!B8/44300)^4.256 -> 0.65938006 | B8: 6000 | C8: =Arkusz1!C$9*('projekt 5'!A8/A$2-Arkusz1!C$106)/(1-Arkusz1!C$106) -> 105993.28 | D8: =C8/A8/Arkusz1!$C$110^5/(Arkusz1!$C$10/60)^3 -> 0.095890095
A9: =Arkusz1!C$23*(1-'projekt 5'!B9/44300)^4.256 -> 0.58916185 | B9: 7000 | C9: =Arkusz1!C$9*('projekt 5'!A9/A$2-Arkusz1!C$106)/(1-Arkusz1!C$106) -> 91467.619 | D9: =C9/A9/Arkusz1!$C$110^5/(Arkusz1!$C$10/60)^3 -> 0.092611302
A10: =Arkusz1!C$23*(1-'projekt 5'!B10/44300)^4.256 -> 0.52481281 | B10: 8000 | C10: =Arkusz1!C$9*('projekt 5'!A10/A$2-Arkusz1!C$106)/(1-Arkusz1!C$106) -> 78156.082 | D10: =C10/A10/Arkusz1!$C$110^5/(Arkusz1!$C$10/60)^3 -> 0.088836121
I15: h | J15: =B2 -> 0 | K15: N | L15: =C2 -> 223000 | M15: CN | N15: =C2/A2/Arkusz1!$C$110^5/(Arkusz1!$C$10/60)^3 -> 0.10859254 | P15: h | Q15: =B7 -> 5000 | R15: N | S15: =C7 -> 121807.72 | T15: CN | U15: =C7/A7/Arkusz1!$C$110^5/(Arkusz1!$C$10/60)^3 -> 0.098748279
I16: LP | J16: V | K16: J | L16: bs | M16: etas | N16: Nr | P16: LP | Q16: V | R16: J | S16: bs | T16: etas | U16: Nr
I17: 1 | J17: 0 | K17: =J17/(Arkusz1!$C$10/60)/Arkusz1!$C$110 -> 0 | L17: 22 | M17: 0 | N17: =$C$2*M17 -> 0 | P17: 1 | Q17: 0 | R17: =Q17/(Arkusz1!$C$10/60)/Arkusz1!$C$110 -> 0 | S17: 21.5 | T17: 0 | U17: =$C$7*T17 -> 0
I18: 2 | J18: 20 | K18: =J18/(Arkusz1!$C$10/60)/Arkusz1!$C$110 -> 0.25299145 | L18: 22.5 | M18: 0.342 | N18: =$C$2*M18 -> 76266 | P18: 2 | Q18: 20 | R18: =Q18/(Arkusz1!$C$10/60)/Arkusz1!$C$110 -> 0.25299145 | S18: 22 | T18: 0.359 | U18: =$C$7*T18 -> 43728.972
I19: 3 | J19: 40 | K19: =J19/(Arkusz1!$C$10/60)/Arkusz1!$C$110 -> 0.50598291 | L19: 24 | M19: 0.59 | N19: =$C$2*M19 -> 131570 | P19: 3 | Q19: 40 | R19: =Q19/(Arkusz1!$C$10/60)/Arkusz1!$C$110 -> 0.50598291 | S19: 22.6 | T19: 0.616 | U19: =$C$7*T19 -> 75033.557
I20: 4 | J20: 60 | K20: =J20/(Arkusz1!$C$10/60)/Arkusz1!$C$110 -> 0.75897436 | L20: 25.5 | M20: 0.754 | N20: =$C$2*M20 -> 168142 | P20: 4 | Q20: 60 | R20: =Q20/(Arkusz1!$C$10/60)/Arkusz1!$C$110 -> 0.75897436 | S20: 24.5 | T20: 0.781 | U20: =$C$7*T20 -> 95131.831
I21: 5 | J21: 80 | K21: =J21/(Arkusz1!$C$10/60)/Arkusz1!$C$110 -> 1.0119658 | L21: 28 | M21: 0.816 | N21: =$C$2*M21 -> 181968 | P21: 5 | Q21: 80 | R21: =Q21/(Arkusz1!$C$10/60)/Arkusz1!$C$110 -> 1.0119658 | S21: 27 | T21: 0.827 | U21: =$C$7*T21 -> 100734.99
I22: 6 | J22: 100 | K22: =J22/(Arkusz1!$C$10/60)/Arkusz1!$C$110 -> 1.2649573 | L22: 31.5 | M22: 0.848 | N22: =$C$2*M22 -> 189104 | P22: 6 | Q22: 100 | R22: =Q22/(Arkusz1!$C$10/60)/Arkusz1!$C$110 -> 1.2649573 | S22: 31 | T22: 0.853 | U22: =$C$7*T22 -> 103901.99
I23: 7 | J23: 120 | K23: =J23/(Arkusz1!$C$10/60)/Arkusz1!$C$110 -> 1.5179487 | L23: 35 | M23: 0.846 | N23: =$C$2*M23 -> 188658 | P23: 7 | Q23: 120 | R23: =Q23/(Arkusz1!$C$10/60)/Arkusz1!$C$110 -> 1.5179487 | S23: 34.5 | T23: 0.812 | U23: =$C$7*T23 -> 98907.871
I24: 8 | J24: 140 | K24: =J24/(Arkusz1!$C$10/60)/Arkusz1!$C$110 -> 1.7709402 | L24: 38.5 | M24: 0.814 | N24: =$C$2*M24 -> 181522 | P24: 8 | Q24: 140 | R24: =Q24/(Arkusz1!$C$10/60)/Arkusz1!$C$110 -> 1.7709402 | S24: 37.5 | T24: 0.782 | U24: =$C$7*T24 -> 95253.639
I26: h | J26: =B3 -> 1000 | K26: N | L26: =C3 -> 199534.03 | M26: CN | N26: =C3/A3/Arkusz1!$C$110^5/(Arkusz1!$C$10/60)^3 -> 0.10708136 | P26: h | Q26: =B8 -> 6000 | R26: N | S26: =C8 -> 105993.28 | T26: CN | U26: =C8/A8/Arkusz1!$C$110^5/(Arkusz1!$C$10/60)^3 -> 0.095890095
I27: LP | J27: V | K27: J | L27: bs | M27: etas | N27: Nr | P27: LP | Q27: V | R27: J | S27: bs | T27: etas | U27: Nr
I28: 1 | J28: 0 | K28: =J28/(Arkusz1!$C$10/60)/Arkusz1!$C$110 -> 0 | L28: 21.9 | M28: 0 | N28: =$C$3*M28 -> 0 | P28: 1 | Q28: 0 | R28: =Q28/(Arkusz1!$C$10/60)/Arkusz1!$C$110 -> 0 | S28: 21 | T28: 0 | U28: =$C$8*T28 -> 0
I29: 2 | J29: 20 | K29: =J29/(Arkusz1!$C$10/60)/Arkusz1!$C$110 -> 0.25299145 | L29: 22.4 | M29: 0.344 | N29: =$C$3*M29 -> 68639.706 | P29: 2 | Q29: 20 | R29: =Q29/(Arkusz1!$C$10/60)/Arkusz1!$C$110 -> 0.25299145 | S29: 21.5 | T29: 0.364 | U29: =$C$8*T29 -> 38581.553
I30: 3 | J30: 40 | K30: =J30/(Arkusz1!$C$10/60)/Arkusz1!$C$110 -> 0.50598291 | L30: 23.5 | M30: 0.593 | N30: =$C$3*M30 -> 118323.68 | P30: 3 | Q30: 40 | R30: =Q30/(Arkusz1!$C$10/60)/Arkusz1!$C$110 -> 0.50598291 | S30: 22 | T30: 0.625 | U30: =$C$8*T30 -> 66245.799
I31: 4 | J31: 60 | K31: =J31/(Arkusz1!$C$10/60)/Arkusz1!$C$110 -> 0.75897436 | L31: 25.2 | M31: 0.758 | N31: =$C$3*M31 -> 151246.79 | P31: 4 | Q31: 60 | R31: =Q31/(Arkusz1!$C$10/60)/Arkusz1!$C$110 -> 0.75897436 | S31: 24 | T31: 0.788 | U31: =$C$8*T31 -> 83522.703
I32: 5 | J32: 80 | K32: =J32/(Arkusz1!$C$10/60)/Arkusz1!$C$110 -> 1.0119658 | L32: 27.7 | M32: 0.818 | N32: =$C$3*M32 -> 163218.84 | P32: 5 | Q32: 80 | R32: =Q32/(Arkusz1!$C$10/60)/Arkusz1!$C$110 -> 1.0119658 | S32: 26.8 | T32: 0.829 | U32: =$C$8*T32 -> 87868.428
I33: 6 | J33: 100 | K33: =J33/(Arkusz1!$C$10/60)/Arkusz1!$C$110 -> 1.2649573 | L33: 31.4 | M33: 0.849 | N33: =$C$3*M33 -> 169404.39 | P33: 6 | Q33: 100 | R33: =Q33/(Arkusz1!$C$10/60)/Arkusz1!$C$110 -> 1.2649573 | S33: 30.8 | T33: 0.854 | U33: =$C$8*T33 -> 90518.26
I34: 7 | J34: 120 | K34: =J34/(Arkusz1!$C$10/60)/Arkusz1!$C$110 -> 1.5179487 | L34: 34.9 | M34: 0.841 | N34: =$C$3*M34 -> 167808.12 | P34: 7 | Q34: 120 | R34: =Q34/(Arkusz1!$C$10/60)/Arkusz1!$C$110 -> 1.5179487 | S34: 34.2 | T34: 0.801 | U34: =$C$8*T34 -> 84900.616
I35: 8 | J35: 140 | K35: =J35/(Arkusz1!$C$10/60)/Arkusz1!$C$110 -> 1.7709402 | L35: 38 | M35: 0.809 | N35: =$C$3*M35 -> 161423.03 | P35: 8 | Q35: 140 | R35: =Q35/(Arkusz1!$C$10/60)/Arkusz1!$C$110 -> 1.7709402 | S35: 37.2 | T35: 0.775 | U35: =$C$8*T35 -> 82144.791
I37: h | J37: =B4 -> 2000 | K37: N | L37: =C4 -> 177767.81 | M37: CN | N37: =C4/A4/Arkusz1!$C$110^5/(Arkusz1!$C$10/60)^3 -> 0.10537508 | P37: h | Q37: =B9 -> 7000 | R37: N | S37: =C9 -> 91467.619 | T37: CN | U37: =C9/A9/Arkusz1!$C$110^5/(Arkusz1!$C$10/60)^3 -> 0.092611302
I38: LP | J38: V | K38: J | L38: bs | M38: etas | N38: Nr | P38: LP | Q38: V | R38: J | S38: bs | T38: etas | U38: Nr
I39: 1 | J39: 0 | K39: =J39/(Arkusz1!$C$10/60)/Arkusz1!$C$110 -> 0 | L39: 21.8 | M39: 0 | N39: =$C$4*M39 -> 0 | P39: 1 | Q39: 0 | R39: =Q39/(Arkusz1!$C$10/60)/Arkusz1!$C$110 -> 0 | S39: 20.5 | T39: 0 | U39: =$C$9*T39 -> 0
I40: 2 | J40: 20 | K40: =J40/(Arkusz1!$C$10/60)/Arkusz1!$C$110 -> 0.25299145 | L40: 22.3 | M40: 0.347 | N40: =$C$4*M40 -> 61685.43 | P40: 2 | Q40: 20 | R40: =Q40/(Arkusz1!$C$10/60)/Arkusz1!$C$110 -> 0.25299145 | S40: 21 | T40: 0.367 | U40: =$C$9*T40 -> 33568.616
I41: 3 | J41: 40 | K41: =J41/(Arkusz1!$C$10/60)/Arkusz1!$C$110 -> 0.50598291 | L41: 23.2 | M41: 0.597 | N41: =$C$4*M41 -> 106127.38 | P41: 3 | Q41: 40 | R41: =Q41/(Arkusz1!$C$10/60)/Arkusz1!$C$110 -> 0.50598291 | S41: 21.5 | T41: 0.631 | U41: =$C$9*T41 -> 57716.067
I42: 4 | J42: 60 | K42: =J42/(Arkusz1!$C$10/60)/Arkusz1!$C$110 -> 0.75897436 | L42: 25 | M42: 0.763 | N42: =$C$4*M42 -> 135636.84 | P42: 4 | Q42: 60 | R42: =Q42/(Arkusz1!$C$10/60)/Arkusz1!$C$110 -> 0.75897436 | S42: 23.7 | T42: 0.794 | U42: =$C$9*T42 -> 72625.289
I43: 5 | J43: 80 | K43: =J43/(Arkusz1!$C$10/60)/Arkusz1!$C$110 -> 1.0119658 | L43: 27.5 | M43: 0.821 | N43: =$C$4*M43 -> 145947.37 | P43: 5 | Q43: 80 | R43: =Q43/(Arkusz1!$C$10/60)/Arkusz1!$C$110 -> 1.0119658 | S43: 26.6 | T43: 0.83 | U43: =$C$9*T43 -> 75918.123
I44: 6 | J44: 100 | K44: =J44/(Arkusz1!$C$10/60)/Arkusz1!$C$110 -> 1.2649573 | L44: 31.3 | M44: 0.85 | N44: =$C$4*M44 -> 151102.64 | P44: 6 | Q44: 100 | R44: =Q44/(Arkusz1!$C$10/60)/Arkusz1!$C$110 -> 1.2649573 | S44: 30.4 | T44: 0.855 | U44: =$C$9*T44 -> 78204.814
I45: 7 | J45: 120 | K45: =J45/(Arkusz1!$C$10/60)/Arkusz1!$C$110 -> 1.5179487 | L45: 34.8 | M45: 0.835 | N45: =$C$4*M45 -> 148436.12 | P45: 7 | Q45: 120 | R45: =Q45/(Arkusz1!$C$10/60)/Arkusz1!$C$110 -> 1.5179487 | S45: 34 | T45: 0.792 | U45: =$C$9*T45 -> 72442.354
I46: 8 | J46: 140 | K46: =J46/(Arkusz1!$C$10/60)/Arkusz1!$C$110 -> 1.7709402 | L46: 37.8 | M46: 0.801 | N46: =$C$4*M46 -> 142392.01 | P46: 8 | Q46: 140 | R46: =Q46/(Arkusz1!$C$10/60)/Arkusz1!$C$110 -> 1.7709402 | S46: 37 | T46: 0.768 | U46: =$C$9*T46 -> 70247.131
...
