Workbook
Name g_v__dane: Podsumowanie!#REF!
Name g_v__dane_1: Podsumowanie!#REF!
Name Piper_V: Podsumowanie!#REF!
Name Piper_Vmin: Podsumowanie!#REF!
Name V_minmax: Podsumowanie!#REF!
Name V_Piper: Podsumowanie!$AC$3:$AD$92
Name V_Piper_1: Podsumowanie!#REF!
Name V_Piper_ciągu_zmienna: Podsumowanie!#REF!
Name V2_Piper: Podsumowanie!$AI$46:$AJ$133
Name w_V__dane: Podsumowanie!#REF!

Sheet Podsumowanie
A1: g | B1: 9.81 | C1: m/s2 | AC1: ciągu | AD1: m zmienna | AE1: ciągu | AF1: mśr | AG1: mocy | AH1: mśr | AI1: ciągu | AJ1: mmax | AK1: mocy | AL1: mmax
A2: ρ0 | B2: 1.2255 | C2: kg/m3 | M2: h [m] | N2: Vmin [m/s] | O2: Vmin [km/h] | P2: Vmax [m/s] | Q2: Vmax [km/h] | R2: wmax [m/s] | S2: 10·wmax [m/s] | T2: Vw [m/s] | U2: Vw [km/h] | V2: γmax [°] | W2: 10·γmax [°] | X2: Vγ [m/s] | Y2: Vγ [km/h] | Z2: 1/wmax | AA2: 10th [min] | AC2: Vmin
A3: S | B3: 21.3 | C3: m2 | M3: 0 | N3: =AC3 -> 36.920589 | O3: =N3*3.6 -> 132.91412 | P3: =AC12 -> 107.27479 | Q3: =P3*3.6 -> 386.18923 | R3: =AD21 -> 8.1692154 | S3: =10*R3 -> 81.692154 | T3: =AC21 -> 65.224001 | U3: =T3*3.6 -> 234.8064 | V3: =AD30 -> 8.4556977 | W3: =10*V3 -> 84.556977 | X3: =AC30 -> 46.19532 | Y3: =X3*3.6 -> 166.30315 | Z3: =1/R3 -> 0.12241078 | AA3: 0 | AC3: 36.920589 | AD3: 5.0663785 | AE3: 35.110565 | AF3: 5.9288321 | AG3: 35.110565 | AH3: 5.6332117 | AI3: 36.920589 | AJ3: 5.0663785 | AK3: 36.920589 | AL3: 4.8585993
A4: mmax | B4: 2948 | C4: kg | M4: 1000 | N4: =AC4 -> 38.740094 | O4: =N4*3.6 -> 139.46434 | P4: =AC13 -> 106.26395 | Q4: =P4*3.6 -> 382.55022 | R4: =AD22 -> 6.9363918 | S4: =10*R4 -> 69.363918 | T4: =AC22 -> 66.706561 | U4: =T4*3.6 -> 240.14362 | V4: =AD31 -> 6.9628271 | W4: =10*V4 -> 69.628271 | X4: =AC31 -> 51.403866 | Y4: =X4*3.6 -> 185.05392 | Z4: =1/R4 -> 0.14416717 | AA4: =(Z4+Z3)/2*(M4-M3)/6 -> 22.214829 | AC4: 38.740094 | AD4: 4.2768174 | AE4: 36.879607 | AF4: 5.0255474 | AG4: 36.879607 | AH4: 4.8284672 | AI4: 38.807483 | AJ4: 4.1937057 | AK4: 38.807483 | AL4: 4.0136303
A5: mpal | B5: 550 | C5: kg | M5: 2000 | N5: =AC5 -> 40.761766 | O5: =N5*3.6 -> 146.74236 | P5: =AC14 -> 104.91617 | Q5: =P5*3.6 -> 377.6982 | R5: =AD23 -> 5.7589761 | S5: =10*R5 -> 57.589761 | T5: =AC23 -> 68.323899 | U5: =T5*3.6 -> 245.96604 | V5: =AD32 -> 5.5520404 | W5: =10*V5 -> 55.520404 | X5: =AC32 -> 56.042726 | Y5: =X5*3.6 -> 201.75381 | Z5: =1/R5 -> 0.17364198 | AA5: =(Z5+Z4)/2*(M5-M4)/6+AA4 -> 48.698925 | AC5: 40.761766 | AD5: 3.4734043 | AE5: 38.845209 | AF5: 4.2043796 | AG5: 38.845209 | AH5: 4.0237226 | AI5: 40.829155 | AJ5: 3.3348848 | AK5: 40.761766 | AL5: 3.1825133
A6: mk | B6: 1863 | C6: kg | M6: 3000 | N6: =AC6 -> 42.850828 | O6: =N6*3.6 -> 154.26298 | P6: =AC15 -> 103.43361 | Q6: =P6*3.6 -> 372.36099 | R6: =AD24 -> 4.6923759 | S6: =10*R6 -> 46.923759 | T6: =AC24 -> 69.806459 | U6: =T6*3.6 -> 251.30325 | V6: =AD33 -> 4.3380751 | W6: =10*V6 -> 43.380751 | X6: =AC33 -> 60.193286 | Y6: =X6*3.6 -> 216.69583 | Z6: =1/R6 -> 0.21311166 | AA6: =(Z6+Z5)/2*(M6-M5)/6+AA5 -> 80.928395 | AC6: 42.850828 | AD6: 2.6838431 | AE6: 40.810811 | AF6: 3.3667883 | AG6: 40.810811 | AH6: 3.2189781 | AI6: 42.918217 | AJ6: 2.4760638 | AK6: 42.918217 | AL6: 2.3513963
A7: mobl | B7: =(B4+B6)/2 -> 2405.5 | C7: kg | M7: 4000 | N7: =AC7 -> 45.074667 | O7: =N7*3.6 -> 162.2688 | P7: =AC16 -> 101.34455 | Q7: =P7*3.6 -> 364.84037 | R7: =AD25 -> 3.5980718 | S7: =10*R7 -> 35.980718 | T7: =AC25 -> 71.356407 | U7: =T7*3.6 -> 256.88307 | V7: =AD34 -> 3.2225706 | W7: =10*V7 -> 32.225706 | X7: =AC34 -> 63.855544 | Y7: =X7*3.6 -> 229.87996 | Z7: =1/R7 -> 0.27792664 | AA7: =(Z7+Z6)/2*(M7-M6)/6+AA6 -> 121.84825 | AC7: 45.074667 | AD7: 1.8942819 | AE7: 43.071253 | AF7: 2.5620438 | AG7: 42.972973 | AH7: 2.4306569 | AI7: 45.074667 | AJ7: 1.6172429 | AK7: 45.142056 | AL7: 1.5064273
A8: Q | B8: =(B7+B5/2)*B1 -> 26295.705 | C8: N | M8: 5000 | N8: =AC8 -> 47.500674 | O8: =N8*3.6 -> 171.00243 | P8: =AC17 -> 98.91854 | Q8: =P8*3.6 -> 356.10674 | R8: =AD26 -> 2.6145833 | S8: =10*R8 -> 26.145833 | T8: =AC26 -> 72.569411 | U8: =T8*3.6 -> 261.24988 | V8: =AD35 -> 2.254607 | W8: =10*V8 -> 22.54607 | X8: =AC35 -> 67.517803 | Y8: =X8*3.6 -> 243.06409 | Z8: =1/R8 -> 0.38247012 | AA8: =(Z8+Z7)/2*(M8-M7)/6+AA7 -> 176.88132 | AC8: 47.500674 | AD8: 1.0908688 | AE8: 45.429975 | AF8: 1.7080292 | AG8: 45.429975 | AH8: 1.5930657 | AI8: 47.702841 | AJ8: 1.021609 | AK8: 47.77023 | AL8: 0.68916223
A9: Nmax | B9: =223000*2 -> 446000 | C9: W | M9: 6000 | N9: =AC9 -> 50.061459 | O9: =N9*3.6 -> 180.22125 | P9: =AC18 -> 94.875195 | Q9: =P9*3.6 -> 341.5507 | R9: =AD27 -> 1.603391 | S9: =10*R9 -> 16.03391 | T9: =AC27 -> 73.917192 | U9: =T9*3.6 -> 266.10189 | V9: =AD36 -> 1.3195137 | W9: =10*V9 -> 13.195137 | X9: =AC36 -> 70.773143 | Y9: =X9*3.6 -> 254.78332 | Z9: =1/R9 -> 0.62367821 | AA9: =(Z9+Z8)/2*(M9-M8)/6+AA8 -> 260.72701 | AC9: 50.061459 | AD9: 0.27360372 | AE9: 48.083538 | AF9: 0.88686131 | AG9: 47.985258 | AH9: 0.77189781 | AI9: 50.331015 | AJ9: 0.14893617 | AK9: 51.880964 | AL9: -0.0034352837
A10: Nnom | B10: 1 | C10: W | M10: 7000 | N10: =AC10 -> 58.350315 | O10: =N10*3.6 -> 210.06114 | P10: =AC19 -> 89.281902 | Q10: =P10*3.6 -> 321.41485 | R10: =AD28 -> 0.73905109 | S10: =10*R10 -> 7.3905109 | T10: =AC28 -> 75.601919 | U10: =T10*3.6 -> 272.16691 | V10: =AD37 -> 0.54847156 | W10: =10*V10 -> 5.4847156 | X10: =AC37 -> 73.4588 | Y10: =X10*3.6 -> 264.45168 | Z10: =1/R10 -> 1.3530864 | AA10: =(Z10+Z9)/2*(M10-M9)/6+AA9 -> 425.4574 | AC10: 58.350315 | AD10: -0.0034352837 | AE10: 50.933661 | AF10: 0.016423358 | AG10: 52.014742 | AH10: 0.016423358
A11: ns | B11: 42.92 | C11: 1/s | M11: =AC41 -> 7700 | O11: 275 | Q11: =O11 -> 275 | S11: 0 | U11: =O11 -> 275 | W11: =S11 -> 0 | Y11: =O11 -> 275 | AA11: 500 | AC11: Vmax
A12: D | B12: 1.84 | C12: m | AC12: 107.27479 | AD12: -0.017287234 | AE12: 106.95332 | AF12: 0.016423358 | AG12: 106.28571 | AH12: 0 | AI12: 106.19656 | AJ12: -0.0034352837 | AK12: 106.60089 | AL12: -0.0034352837
A13: Λe | B13: 5.884 | C13: - | M13: h [m] | N13: Vmin [m/s] | O13: Vmin [km/h] | P13: Vmax [m/s] | Q13: Vmax [km/h] | R13: wmax [m/s] | S13: 10·wmax [m/s] | T13: Vw [m/s] | U13: Vw [km/h] | V13: γmax [°] | W13: 10·γmax [°] | X13: Vγ [m/s] | Y13: Vγ [km/h] | Z13: 1/wmax | AA13: 10th [min] | AC13: 106.26395 | AD13: -0.0034352837 | AE13: 105.77396 | AF13: 0.016423358 | AG13: 105.5774 | AH13: 0.016423358 | AI13: 104.91617 | AJ13: -0.017287234 | AK13: 105.65745 | AL13: -0.0034352837
A14: (Cx)min | B14: 0.02214 | C14: - | M14: 0 | N14: =AE3 -> 35.110565 | O14: =N14*3.6 -> 126.39803 | P14: =AE12 -> 106.95332 | Q14: =P14*3.6 -> 385.03194 | R14: =AF21 -> 8.5237226 | S14: =10*R14 -> 85.237226 | T14: =AE21 -> 60.17199 | U14: =T14*3.6 -> 216.61916 | V14: =AF30 -> 9.7178131 | W14: =10*V14 -> 97.178131 | X14: =AE30 -> 43.05925 | Y14: =X14*3.6 -> 155.0133 | Z14: =1/R14 -> 0.11731963 | AA14: 0 | AC14: 104.91617 | AD14: -0.0034352837 | AE14: 104.29975 | AF14: 0.016423358 | AG14: 104.98771 | AH14: 0.016423358 | AI14: 103.23144 | AJ14: -0.017287234 | AK14: 103.23144 | AL14: -0.017287234
A15: Czmax | B15: 1.63 | C15: - | M15: 1000 | N15: =AE4 -> 36.879607 | O15: =N15*3.6 -> 132.76658 | P15: =AE13 -> 105.77396 | Q15: =P15*3.6 -> 380.78624 | R15: =AF22 -> 7.2755474 | S15: =10*R15 -> 72.755474 | T15: =AE22 -> 61.154791 | U15: =T15*3.6 -> 220.15725 | V15: =AF31 -> 8.0599647 | W15: =10*V15 -> 80.599647 | X15: =AE31 -> 46.058041 | Y15: =X15*3.6 -> 165.80895 | Z15: =1/R15 -> 0.1374467 | AA15: =(Z15+Z14)/2*(M15-M14)/6 -> 21.230528 | AC15: 103.43361 | AD15: -0.0034352837 | AE15: 102.62899 | AF15: 0.016423358 | AG15: 102.33415 | AH15: 0.016423358 | AI15: 101.07499 | AJ15: -0.0034352837 | AK15: 100.94021 | AL15: -0.0034352837
A16: a∞ | B16: 6.134 | C16: 1/rad | M16: 2000 | N16: =AE5 -> 38.845209 | O16: =N16*3.6 -> 139.84275 | P16: =AE14 -> 104.29975 | Q16: =P16*3.6 -> 375.47912 | R16: =AF23 -> 6.0930657 | S16: =10*R16 -> 60.930657 | T16: =AE23 -> 62.530713 | U16: =T16*3.6 -> 225.11057 | V16: =AF32 -> 6.5255732 | W16: =10*V16 -> 65.255732 | X16: =AE32 -> 48.476421 | Y16: =X16*3.6 -> 174.51511 | Z16: =1/R16 -> 0.16412099 | AA16: =(Z16+Z15)/2*(M16-M15)/6+AA15 -> 46.361169 | AC16: 101.34455 | AD16: -0.0034352837 | AE16: 100.27027 | AF16: 0.016423358 | AG16: 99.97543 | AH16: 0.016423358 | AI16: 98.17726 | AJ16: -0.0034352837 | AK16: 97.638148 | AL16: -0.0034352837
A17: k | B17: 0.12 | C17: - | M17: 3000 | N17: =AE6 -> 40.810811 | O17: =N17*3.6 -> 146.91892 | P17: =AE15 -> 102.62899 | Q17: =P17*3.6 -> 369.46437 | R17: =AF24 -> 4.959854 | S17: =10*R17 -> 49.59854 | T17: =AE24 -> 63.415233 | U17: =T17*3.6 -> 228.29484 | V17: =AF33 -> 5.0793651 | W17: =10*V17 -> 50.793651 | X17: =AE33 -> 51.378476 | Y17: =X17*3.6 -> 184.96252 | Z17: =1/R17 -> 0.20161884 | AA17: =(Z17+Z16)/2*(M17-M16)/6+AA16 -> 76.839488 | AC17: 98.91854 | AD17: -0.0034352837 | AE17: 97.027027 | AF17: 0.016423358 | AG17: 96.339066 | AH17: 0 | AI17: 94.336083 | AJ17: -0.017287234 | AK17: 93.79697 | AL17: -0.0034352837
A18: φ | B18: 1 | C18: ° | M18: 4000 | N18: =AE7 -> 43.071253 | O18: =N18*3.6 -> 155.05651 | P18: =AE16 -> 100.27027 | Q18: =P18*3.6 -> 360.97297 | R18: =AF25 -> 3.8594891 | S18: =10*R18 -> 38.594891 | T18: =AE25 -> 64.594595 | U18: =T18*3.6 -> 232.54054 | V18: =AF34 -> 3.8447972 | W18: =10*V18 -> 38.447972 | X18: =AE34 -> 53.893591 | Y18: =X18*3.6 -> 194.01693 | Z18: =1/R18 -> 0.25910165 | AA18: =(Z18+Z17)/2*(M18-M17)/6+AA17 -> 115.23286 | AC18: 94.875195 | AD18: -0.0034352837 | AE18: 92.702703 | AF18: 0.016423358 | AG18: 92.211302 | AH18: 0.016423358 | AI18: 88.271066 | AJ18: -0.0034352837 | AK18: 87.327619 | AL18: -0.0034352837
A19: α0 | B19: -2.97 | C19: ° | M19: 5000 | N19: =AE8 -> 45.429975 | O19: =N19*3.6 -> 163.54791 | P19: =AE17 -> 97.027027 | Q19: =P19*3.6 -> 349.2973 | R19: =AF26 -> 2.7919708 | S19: =10*R19 -> 27.919708 | T19: =AE26 -> 65.479115 | U19: =T19*3.6 -> 235.72482 | V19: =AF35 -> 2.6455026 | W19: =10*V19 -> 26.455026 | X19: =AE35 -> 58.053204 | Y19: =X19*3.6 -> 208.99154 | Z19: =1/R19 -> 0.35816993 | AA19: =(Z19+Z18)/2*(M19-M18)/6+AA18 -> 166.67216 | AC19: 89.281902 | AD19: -0.0034352837 | AE19: 85.331695 | AF19: 0.016423358 | AG19: 84.742015 | AH19: 0.016423358
A20: ηś | B20: 0.846 | C20: - | M20: 6000 | N20: =AE9 -> 48.083538 | O20: =N20*3.6 -> 173.10074 | P20: =AE18 -> 92.702703 | Q20: =P20*3.6 -> 333.72973 | R20: =AF27 -> 1.7737226 | S20: =10*R20 -> 17.737226 | T20: =AE27 -> 66.658477 | U20: =T20*3.6 -> 239.97052 | V20: =AF36 -> 1.6049383 | W20: =10*V20 -> 16.049383 | X20: =AE36 -> 61.245466 | Y20: =X20*3.6 -> 220.48368 | Z20: =1/R20 -> 0.56378601 | AA20: =(Z20+Z19)/2*(M20-M19)/6+AA19 -> 243.50182 | AC20: Vw
A21: qN | B21: =B4/(B9/1000) -> 6.6098655 | M21: 7000 | N21: =AE10 -> 50.933661 | O21: =N21*3.6 -> 183.36118 | P21: =AE19 -> 85.331695 | Q21: =P21*3.6 -> 307.1941 | R21: =AF28 -> 0.66145833 | S21: =10*R21 -> 6.6145833 | T21: =AE28 -> 67.641278 | U21: =T21*3.6 -> 243.5086 | V21: =AF37 -> 0.65255732 | W21: =10*V21 -> 6.5255732 | X21: =AE37 -> 65 | Y21: =X21*3.6 -> 234 | Z21: =1/R21 -> 1.511811 | AA21: =(Z21+Z20)/2*(M21-M20)/6+AA20 -> 416.46824 | AC21: 65.224001 | AD21: 8.1692154 | AE21: 60.17199 | AF21: 8.5237226 | AG21: 61.941032 | AH21: 8.4580292 | AI21: 60.708933 | AJ21: 7.3658023 | AK21: 64.213165 | AL21: 7.3103945
A22: qt | B22: =0.022*B24 -> 18.48 | M22: =AE41 -> 7600 | O22: 245 | Q22: =O22 -> 245 | S22: =S11 -> 0 | U22: =O22 -> 245 | W22: =W11 -> 0 | Y22: =O22 -> 245 | AA22: =AA11 -> 500 | AC22: 66.706561 | AD22: 6.9363918 | AE22: 61.154791 | AF22: 7.2755474 | AG22: 62.923833 | AH22: 7.209854 | AI22: 62.326271 | AJ22: 6.1606826 | AK22: 65.493558 | AL22: 6.063719
A23: qe | B23: =B22/B10 -> 18.48 | AC23: 68.323899 | AD23: 5.7589761 | AE23: 62.530713 | AF23: 6.0930657 | AG23: 64.398034 | AH23: 6.0109489 | AI23: 63.87622 | AJ23: 5.0109707 | AK23: 66.841339 | AL23: 4.9001551
A24: ρpal | B24: 840 | C24: kg/m3 | M24: h [m] | N24: Vmin [m/s] | O24: Vmin [km/h] | P24: Vmax [m/s] | Q24: Vmax [km/h] | R24: wmax [m/s] | S24: 10·wmax [m/s] | T24: Vw [m/s] | U24: Vw [km/h] | V24: γmax [°] | W24: 10·γmax [°] | X24: Vγ [m/s] | Y24: Vγ [km/h] | Z24: 1/wmax | AA24: 10th [min] | AC24: 69.806459 | AD24: 4.6923759 | AE24: 63.415233 | AF24: 4.959854 | AG24: 65.479115 | AH24: 4.8613139 | AI24: 65.358779 | AJ24: 3.8889628 | AK24: 68.323899 | AL24: 3.7781472
A25: thp | B25: 45.4 | C25: min | M25: 0 | N25: =AG3 -> 35.110565 | O25: =N25*3.6 -> 126.39803 | P25: =AG12 -> 106.28571 | Q25: =P25*3.6 -> 382.62857 | R25: =AH21 -> 8.4580292 | S25: =10*R25 -> 84.580292 | T25: =AG21 -> 61.941032 | U25: =T25*3.6 -> 222.98771 | V25: =AH30 -> 9.5414462 | W25: =10*V25 -> 95.414462 | X25: =AG30 -> 41.414752 | Y25: =X25*3.6 -> 149.09311 | Z25: =1/R25 -> 0.11823085 | AA25: 0 | AC25: 71.356407 | AD25: 3.5980718 | AE25: 64.594595 | AF25: 3.8594891 | AG25: 66.461916 | AH25: 3.7445255 | AI25: 66.571783 | AJ25: 2.8777704 | AK25: 69.739069 | AL25: 2.7253989
A26: Δt | B26: 1.25 | C26: h | M26: 1000 | N26: =AG4 -> 36.879607 | O26: =N26*3.6 -> 132.76658 | P26: =AG13 -> 105.5774 | Q26: =P26*3.6 -> 380.07862 | R26: =AH22 -> 7.209854 | S26: =10*R26 -> 72.09854 | T26: =AG22 -> 62.923833 | U26: =T26*3.6 -> 226.5258 | V26: =AH31 -> 7.8835979 | W26: =10*V26 -> 78.835979 | X26: =AG31 -> 43.639661 | Y26: =X26*3.6 -> 157.10278 | Z26: =1/R26 -> 0.13869906 | AA26: =(Z26+Z25)/2*(M26-M25)/6 -> 21.410826 | AC26: 72.569411 | AD26: 2.6145833 | AE26: 65.479115 | AF26: 2.7919708 | AG26: 67.837838 | AH26: 2.7262774 | AI26: 67.650008 | AJ26: 1.9912456 | AK26: 70.817295 | AL26: 1.7142066
A27: ht | B27: 4550 | C27: m | M27: 2000 | N27: =AG5 -> 38.845209 | O27: =N27*3.6 -> 139.84275 | P27: =AG14 -> 104.98771 | Q27: =P27*3.6 -> 377.95577 | R27: =AH23 -> 6.0109489 | S27: =10*R27 -> 60.109489 | T27: =AG23 -> 64.398034 | U27: =T27*3.6 -> 231.83292 | V27: =AH32 -> 6.366843 | W27: =10*V27 -> 63.66843 | X27: =AG32 -> 46.444982 | Y27: =X27*3.6 -> 167.20193 | Z27: =1/R27 -> 0.16636308 | AA27: =(Z27+Z26)/2*(M27-M26)/6+AA26 -> 46.832672 | AC27: 73.917192 | AD27: 1.603391 | AE27: 66.658477 | AF27: 1.7737226 | AG27: 68.722359 | AH27: 1.7408759 | AI27: 69.065179 | AJ27: 0.95234929 | AK27: 71.962909 | AL27: 0.73071809
A28: hp | B28: 3700 | C28: m | M28: 3000 | N28: =AG6 -> 40.810811 | O28: =N28*3.6 -> 146.91892 | P28: =AG15 -> 102.33415 | Q28: =P28*3.6 -> 368.40295 | R28: =AH24 -> 4.8613139 | S28: =10*R28 -> 48.613139 | T28: =AG24 -> 65.479115 | U28: =T28*3.6 -> 235.72482 | V28: =AH33 -> 4.973545 | W28: =10*V28 -> 49.73545 | X28: =AG33 -> 49.443773 | Y28: =X28*3.6 -> 177.99758 | Z28: =1/R28 -> 0.20570571 | AA28: =(Z28+Z27)/2*(M28-M27)/6+AA27 -> 77.838404 | AC28: 75.601919 | AD28: 0.73905109 | AE28: 67.641278 | AF28: 0.66145833 | AG28: 69.80344 | AH28: 0.65693431
A29: φ | B29: =RADIANS(B18) -> 0.017453293 | C29: rad | M29: 4000 | N29: =AG7 -> 42.972973 | O29: =N29*3.6 -> 154.7027 | P29: =AG16 -> 99.97543 | Q29: =P29*3.6 -> 359.91155 | R29: =AH25 -> 3.7445255 | S29: =10*R29 -> 37.445255 | T29: =AG25 -> 66.461916 | U29: =T29*3.6 -> 239.2629 | V29: =AH34 -> 3.7389771 | W29: =10*V29 -> 37.389771 | X29: =AG34 -> 52.732769 | Y29: =X29*3.6 -> 189.83797 | Z29: =1/R29 -> 0.26705653 | AA29: =(Z29+Z28)/2*(M29-M28)/6+AA28 -> 117.23526 | AC29: Vy
A30: α0 | B30: =RADIANS(B19) -> -0.051836279 | C30: rad | M30: 5000 | N30: =AG8 -> 45.429975 | O30: =N30*3.6 -> 163.54791 | P30: =AG17 -> 96.339066 | Q30: =P30*3.6 -> 346.82064 | R30: =AH26 -> 2.7262774 | S30: =10*R30 -> 27.262774 | T30: =AG26 -> 67.837838 | U30: =T30*3.6 -> 244.21622 | V30: =AH35 -> 2.5573192 | W30: =10*V30 -> 25.573192 | X30: =AG35 -> 55.73156 | Y30: =X30*3.6 -> 200.63362 | Z30: =1/R30 -> 0.36680054 | AA30: =(Z30+Z29)/2*(M30-M29)/6+AA29 -> 170.05668 | AC30: 46.19532 | AD30: 8.4556977 | AE30: 43.05925 | AF30: 9.7178131 | AG30: 41.414752 | AH30: 9.5414462 | AI30: 44.974568 | AJ30: 8.1444724 | AK30: 43.591048 | AL30: 7.9644281
A31: Qmax | B31: =Podsumowanie!B1*(Podsumowanie!B7+Podsumowanie!B5) -> 28993.455 | C31: N | M31: 6000 | N31: =AG9 -> 47.985258 | O31: =N31*3.6 -> 172.74693 | P31: =AG18 -> 92.211302 | Q31: =P31*3.6 -> 331.96069 | R31: =AH27 -> 1.7408759 | S31: =10*R31 -> 17.408759 | T31: =AG27 -> 68.722359 | U31: =T31*3.6 -> 247.40049 | V31: =AH36 -> 1.4991182 | W31: =10*V31 -> 14.991182 | X31: =AG36 -> 59.697703 | Y31: =X31*3.6 -> 214.91173 | Z31: =1/R31 -> 0.57442348 | AA31: =(Z31+Z30)/2*(M31-M30)/6+AA30 -> 248.49201 | AC31: 51.403866 | AD31: 6.9628271 | AE31: 46.058041 | AF31: 8.0599647 | AG31: 43.639661 | AH31: 7.8835979 | AI31: 47.822991 | AJ31: 6.5701182 | AK31: 46.683622 | AL31: 6.3900238
A32: qe | B32: 0.31 | C32: kg/kWh | M32: 7000 | N32: =AG10 -> 52.014742 | O32: =N32*3.6 -> 187.25307 | P32: =AG19 -> 84.742015 | Q32: =P32*3.6 -> 305.07125 | R32: =AH28 -> 0.65693431 | S32: =10*R32 -> 6.5693431 | T32: =AG28 -> 69.80344 | U32: =T32*3.6 -> 251.29238 | V32: =AH37 -> 0.52910053 | W32: =10*V32 -> 5.2910053 | X32: =AG37 -> 64.147521 | Y32: =X32*3.6 -> 230.93108 | Z32: =1/R32 -> 1.5222222 | AA32: =(Z32+Z31)/2*(M32-M31)/6+AA31 -> 423.21249 | AC32: 56.042726 | AD32: 5.5520404 | AE32: 48.476421 | AF32: 6.5255732 | AG32: 46.444982 | AH32: 6.366843 | AI32: 50.508647 | AJ32: 5.1269449 | AK32: 49.125127 | AL32: 5.0124744
A33: Czmax- | B33: -1.173 | M33: =AG41 -> 7590 | O33: 250 | Q33: =O33 -> 250 | S33: =S22 -> 0 | U33: =O33 -> 250 | W33: =W22 -> 0 | Y33: =O33 -> 250 | AA33: =AA11 -> 500 | AC33: 60.193286 | AD33: 4.3380751 | AE33: 51.378476 | AF33: 5.0793651 | AG33: 49.443773 | AH33: 4.973545 | AI33: 54.008138 | AJ33: 3.8311459 | AK33: 52.543235 | AL33: 3.7330854
AC34: 63.855544 | AD34: 3.2225706 | AE34: 53.893591 | AF34: 3.8447972 | AG34: 52.732769 | AH34: 3.7389771 | AI34: 57.182096 | AJ34: 2.666561 | AK34: 56.286877 | AL34: 2.5519904
M35: h [m] | N35: Vmin [m/s] | O35: Vmin [km/h] | P35: Vmax [m/s] | Q35: Vmax [km/h] | R35: wmax [m/s] | S35: 10·wmax [m/s] | T35: Vw [m/s] | U35: Vw [km/h] | V35: γmax [°] | W35: 10·γmax [°] | X35: Vγ [m/s] | Y35: Vγ [km/h] | Z35: 1/wmax | AA35: 10th [min] | AC35: 67.517803 | AD35: 2.254607 | AE35: 58.053204 | AF35: 2.6455026 | AG35: 55.73156 | AH35: 2.5573192 | AI35: 60.356053 | AJ35: 1.8462385 | AK35: 60.193286 | AL35: 1.5511899
M36: 0 | N36: =AI3 -> 36.920589 | O36: =N36*3.6 -> 132.91412 | P36: =AI12 -> 106.19656 | Q36: =P36*3.6 -> 382.30762 | R36: =AJ21 -> 7.3658023 | S36: =10*R36 -> 73.658023 | T36: =AI21 -> 60.708933 | U36: =T36*3.6 -> 218.55216 | V36: =AJ30 -> 8.1444724 | W36: =10*V36 -> 81.444724 | X36: =AI30 -> 44.974568 | Y36: =X36*3.6 -> 161.90844 | Z36: =1/R36 -> 0.13576254 | AA36: 0 | AC36: 70.773143 | AD36: 1.3195137 | AE36: 61.245466 | AF36: 1.6049383 | AG36: 59.697703 | AH36: 1.4991182 | AI36: 64.181078 | AJ36: 0.82906125 | AK36: 64.262462 | AL36: 0.59953638
M37: 1000 | N37: =AI4 -> 38.807483 | O37: =N37*3.6 -> 139.70694 | P37: =AI13 -> 104.91617 | Q37: =P37*3.6 -> 377.6982 | R37: =AJ22 -> 6.1606826 | S37: =10*R37 -> 61.606826 | T37: =AI22 -> 62.326271 | U37: =T37*3.6 -> 224.37458 | V37: =AJ31 -> 6.5701182 | W37: =10*V37 -> 65.701182 | X37: =AI31 -> 47.822991 | Y37: =X37*3.6 -> 172.16277 | Z37: =1/R37 -> 0.16231967 | AA37: =(Z37+Z36)/2*(M37-M36)/6 -> 24.840184 | AC37: 73.4588 | AD37: 0.54847156 | AE37: 65 | AF37: 0.65255732 | AG37: 64.147521 | AH37: 0.52910053
M38: 2000 | N38: =AI5 -> 40.829155 | O38: =N38*3.6 -> 146.98496 | P38: =AI14 -> 103.23144 | Q38: =P38*3.6 -> 371.63319 | R38: =AJ23 -> 5.0109707 | S38: =10*R38 -> 50.109707 | T38: =AI23 -> 63.87622 | U38: =T38*3.6 -> 229.95439 | V38: =AJ32 -> 5.1269449 | W38: =10*V38 -> 51.269449 | X38: =AI32 -> 50.508647 | Y38: =X38*3.6 -> 181.83113 | Z38: =1/R38 -> 0.19956213 | AA38: =(Z38+Z37)/2*(M38-M37)/6+AA37 -> 54.997001
M39: 3000 | N39: =AI6 -> 42.918217 | O39: =N39*3.6 -> 154.50558 | P39: =AI15 -> 101.07499 | Q39: =P39*3.6 -> 363.86997 | R39: =AJ24 -> 3.8889628 | S39: =10*R39 -> 38.889628 | T39: =AI24 -> 65.358779 | U39: =T39*3.6 -> 235.29161 | V39: =AJ33 -> 3.8311459 | W39: =10*V39 -> 38.311459 | X39: =AI33 -> 54.008138 | Y39: =X39*3.6 -> 194.4293 | Z39: =1/R39 -> 0.25713797 | AA39: =(Z39+Z38)/2*(M39-M38)/6+AA38 -> 93.055343
M40: 4000 | N40: =AI7 -> 45.074667 | O40: =N40*3.6 -> 162.2688 | P40: =AI16 -> 98.17726 | Q40: =P40*3.6 -> 353.43814 | R40: =AJ25 -> 2.8777704 | S40: =10*R40 -> 28.777704 | T40: =AI25 -> 66.571783 | U40: =T40*3.6 -> 239.65842 | V40: =AJ34 -> 2.666561 | W40: =10*V40 -> 26.66561 | X40: =AI34 -> 57.182096 | Y40: =X40*3.6 -> 205.85554 | Z40: =1/R40 -> 0.34749124 | AA40: =(Z40+Z39)/2*(M40-M39)/6+AA39 -> 143.44111 | AC40: ht1 | AD40: hp1 | AE40: ht2 | AF40: hp2 | AG40: ht3 | AH40: hp3 | AI40: ht4 | AJ40: hp4 | AK40: ht5 | AL40: hp5
...

Sheet Meotda CIągu, zmienna masa
A1: kąt pochylenia osi silnika fi | B1: φ | C1: =Podsumowanie!B29 -> 0.017453293 | D1: rad
A2: średnica śmigła | B2: D | C2: =Podsumowanie!B12 -> 1.84 | D2: m | K2: Metoda ciągu, zmienna masa, h=0m
A3: Współczynnik kierunkowy prostej Cz(a) | B3: a∞ | C3: =Podsumowanie!B16 -> 6.134 | D3: 1/rad | E3: =DEGREES(C6) -> -2.97 | K3: V [m/s] | L3: J | M3: ηs | N3: Nr [W] | O3: Ps [N] | P3: α [°] | Q3: γ [°] | R3: w [m/s] | S3: Nr/w | U3: γ | V3: [°] | W3: [rad] | X3: [rad] | Y3: [°] | Z3: α
A4: Moc silnika | B4: Nmax | C4: =Podsumowanie!B9 -> 446000 | D4: W | I4: =C$3*(X4-C$6) -> 1.5452115 | J4: =(C$14+G$11*(K$18-G14)/(K$18-G$14)) -> 2955.5 | K4: =SQRT(2*(C$14+G11)*C$12/C$5/C$15/G8) -> 36.916857 | L4: =K4/C$9/C$2 -> 0.46746294 | M4: =0.185*L4^3-0.9822*L4^2+1.6209*L4 -> 0.56197665 | N4: =G$9*M4 -> 250641.59 | O4: =N4/K4 -> 6789.3533 | P4: =Y4 -> 11.463338 | Q4: =V4 -> 7.900192 | R4: =K4*SIN(RADIANS(Q4)) -> 5.0741432 | S4: =(N4/1000)/(R4*3600) -> 0.013721068 | T4: 1 | U4: =0.5*G$8*C$5*C$3*(X4-C$6)*K4^2+N4/K4*SIN(X4-C$1)-C$12*(C$14+G$11*(K$18-K4)/(K$18-K$4))*COS(W4) -> -1.0570882e-05 | V4: =DEGREES(W4) -> 7.900192 | W4: 0.13788436 | X4: 0.200073 | Y4: =DEGREES(X4) -> 11.463338 | Z4: =-0.5*G$8*C$5*K4^2*(C$8+(C$3^2)*(X4-C$6)^2/(PI()*C$7))+N4/K4*COS(X4-C$1)-C$12*(C$14+G$11*(K$18-K4)/(K$18-K$4))*SIN(W4) -> -3.3001561e-07 | AB4: =T4 -> 1
A5: Powierzchnia nośna | B5: S | C5: =Podsumowanie!B3 -> 21.3 | D5: m2 | I5: =C$3*(X5-C$6) -> 1.4011738 | J5: =(C$14+G$11*(K$18-K5)/(K$18-G$14)) -> 2916.2143 | K5: =G$14+T4*G$13 -> 38.783391 | L5: =K5/C$9/C$2 -> 0.49109809 | M5: =0.185*L5^3-0.9822*L5^2+1.6209*L5 -> 0.58104823 | N5: =G$9*M5 -> 259147.51 | O5: =N5/K5 -> 6681.9199 | P5: =Y5 -> 10.117927 | Q5: =V5 -> 8.1240717 | R5: =K5*SIN(RADIANS(Q5)) -> 5.4807586 | S5: =(N5/1000)/(R5*3600) -> 0.013134207 | T5: 2 | U5: =0.5*G$8*C$5*C$3*(X5-C$6)*K5^2+N5/K5*SIN(X5-C$1)-C$12*(C$14+G$11*(K$18-K5)/(K$18-K$4))*COS(W5) -> 3.2278331e-07 | V5: =DEGREES(W5) -> 8.1240717 | W5: 0.1417918 | X5: 0.17659114 | Y5: =DEGREES(X5) -> 10.117927 | Z5: =-0.5*G$8*C$5*K5^2*(C$8+(C$3^2)*(X5-C$6)^2/(PI()*C$7))+N5/K5*COS(X5-C$1)-C$12*(C$14+G$11*(K$18-K5)/(K$18-K$4))*SIN(W5) -> -1.1342759e-06 | AB5: =T5 -> 2
A6: Kąt zerowej siły nośnej | B6: α0 | C6: =Podsumowanie!B30 -> -0.051836279 | D6: rad | I6: =C$3*(X6-C$6) -> 1.0743331 | J6: =(C$14+G$11*(K$18-K6)/(K$18-G$14)) -> 2876.9286 | K6: =G$14+T5*G$13 -> 44.261592 | L6: =K6/C$9/C$2 -> 0.56046628 | M6: =0.185*L6^3-0.9822*L6^2+1.6209*L6 -> 0.63249891 | N6: =G$9*M6 -> 282094.51 | O6: =N6/K6 -> 6373.3477 | P6: =Y6 -> 7.0650102 | Q6: =V6 -> 8.438312 | R6: =K6*SIN(RADIANS(Q6)) -> 6.4951449 | S6: =(N6/1000)/(R6*3600) -> 0.012064332 | T6: 3 | U6: =0.5*G$8*C$5*C$3*(X6-C$6)*K6^2+N6/K6*SIN(X6-C$1)-C$12*(C$14+G$11*(K$18-K6)/(K$18-K$4))*COS(W6) -> 5.255788e-08 | V6: =DEGREES(W6) -> 8.438312 | W6: 0.14727633 | X6: 0.12330769 | Y6: =DEGREES(X6) -> 7.0650102 | Z6: =-0.5*G$8*C$5*K6^2*(C$8+(C$3^2)*(X6-C$6)^2/(PI()*C$7))+N6/K6*COS(X6-C$1)-C$12*(C$14+G$11*(K$18-K6)/(K$18-K$4))*SIN(W6) -> -2.3719713e-07 | AB6: =T6 -> 3
A7: wydłużenie Oswalda | B7: Λe | C7: =Podsumowanie!B13 -> 5.884 | D7: - | F7: h | G7: 0 | H7: m | I7: =C$3*(X7-C$6) -> 0.84636715 | J7: =(C$14+G$11*(K$18-K7)/(K$18-G$14)) -> 2837.6429 | K7: =G$14+T6*G$13 -> 49.739792 | L7: =K7/C$9/C$2 -> 0.62983448 | M7: =0.185*L7^3-0.9822*L7^2+1.6209*L7 -> 0.67749059 | N7: =G$9*M7 -> 302160.8 | O7: =N7/K7 -> 6074.8304 | P7: =Y7 -> 4.9356514 | Q7: =V7 -> 8.3940696 | R7: =K7*SIN(RADIANS(Q7)) -> 7.2610464 | S7: =(N7/1000)/(R7*3600) -> 0.01155943 | T7: 4 | U7: =0.5*G$8*C$5*C$3*(X7-C$6)*K7^2+N7/K7*SIN(X7-C$1)-C$12*(C$14+G$11*(K$18-K7)/(K$18-K$4))*COS(W7) -> -0.00011757797 | V7: =DEGREES(W7) -> 8.3940696 | W7: 0.14650415 | X7: 0.086143368 | Y7: =DEGREES(X7) -> 4.9356514 | Z7: =-0.5*G$8*C$5*K7^2*(C$8+(C$3^2)*(X7-C$6)^2/(PI()*C$7))+N7/K7*COS(X7-C$1)-C$12*(C$14+G$11*(K$18-K7)/(K$18-K$4))*SIN(W7) -> -1.0342048e-05 | AB7: =T7 -> 4
A8: Minimalny współczynnik Cx z danych | B8: (Cx)min | C8: =Podsumowanie!B14 -> 0.02214 | D8: - | F8: ρh | G8: =C$11*(1-G7/44300)^4.256 -> 1.2255 | H8: kg/m3 | I8: =C$3*(X8-C$6) -> 0.68159633 | J8: =(C$14+G$11*(K$18-K8)/(K$18-G$14)) -> 2798.3571 | K8: =G$14+T7*G$13 -> 55.217993 | L8: =K8/C$9/C$2 -> 0.69920268 | M8: =0.185*L8^3-0.9822*L8^2+1.6209*L8 -> 0.71639379 | N8: =G$9*M8 -> 319511.63 | O8: =N8/K8 -> 5786.3681 | P8: =Y8 -> 3.3965786 | Q8: =V8 -> 8.1110662 | R8: =K8*SIN(RADIANS(Q8)) -> 7.7908416 | S8: =(N8/1000)/(R8*3600) -> 0.011391995 | T8: 5 | U8: =0.5*G$8*C$5*C$3*(X8-C$6)*K8^2+N8/K8*SIN(X8-C$1)-C$12*(C$14+G$11*(K$18-K8)/(K$18-K$4))*COS(W8) -> -5.495318e-05 | V8: =DEGREES(W8) -> 8.1110662 | W8: 0.14156481 | X8: 0.05928148 | Y8: =DEGREES(X8) -> 3.3965786 | Z8: =-0.5*G$8*C$5*K8^2*(C$8+(C$3^2)*(X8-C$6)^2/(PI()*C$7))+N8/K8*COS(X8-C$1)-C$12*(C$14+G$11*(K$18-K8)/(K$18-K$4))*SIN(W8) -> -3.8640037e-06 | AB8: =T8 -> 5
A9: Obroty silnika | B9: ns | C9: =Podsumowanie!B11 -> 42.92 | D9: 1/s | F9: Nh | G9: =C$4*((G8/C$11)-C$10)/(1-C$10) -> 446000 | H9: W | I9: =C$3*(X9-C$6) -> 0.55893185 | J9: =(C$14+G$11*(K$18-K9)/(K$18-G$14)) -> 2759.0714 | K9: =G$14+T8*G$13 -> 60.696194 | L9: =K9/C$9/C$2 -> 0.76857087 | M9: =0.185*L9^3-0.9822*L9^2+1.6209*L9 -> 0.74957903 | N9: =G$9*M9 -> 334312.25 | O9: =N9/K9 -> 5507.9607 | P9: =Y9 -> 2.250808 | Q9: =V9 -> 7.6575367 | R9: =K9*SIN(RADIANS(Q9)) -> 8.0878714 | S9: =(N9/1000)/(R9*3600) -> 0.011481947 | T9: 6 | U9: =0.5*G$8*C$5*C$3*(X9-C$6)*K9^2+N9/K9*SIN(X9-C$1)-C$12*(C$14+G$11*(K$18-K9)/(K$18-K$4))*COS(W9) -> -2.5338304e-05 | V9: =DEGREES(W9) -> 7.6575367 | W9: 0.13364923 | X9: 0.03928401 | Y9: =DEGREES(X9) -> 2.250808 | Z9: =-0.5*G$8*C$5*K9^2*(C$8+(C$3^2)*(X9-C$6)^2/(PI()*C$7))+N9/K9*COS(X9-C$1)-C$12*(C$14+G$11*(K$18-K9)/(K$18-K$4))*SIN(W9) -> -1.4336943e-06 | AB9: =T9 -> 6
A10: współczynnik korekcyjny | B10: k | C10: =Podsumowanie!B17 -> 0.12 | D10: - | F10: CN | G10: =G9/G8/C$9^3/C$2^5 -> 0.21824952 | H10: - | I10: =C$3*(X10-C$6) -> 0.46532178 | J10: =(C$14+G$11*(K$18-K10)/(K$18-G$14)) -> 2719.7857 | K10: =G$14+T9*G$13 -> 66.174394 | L10: =K10/C$9/C$2 -> 0.83793907 | M10: =0.185*L10^3-0.9822*L10^2+1.6209*L10 -> 0.77741682 | N10: =G$9*M10 -> 346727.9 | O10: =N10/K10 -> 5239.6082 | P10: =Y10 -> 1.3764255 | Q10: =V10 -> 7.0741738 | R10: =K10*SIN(RADIANS(Q10)) -> 8.1496525 | S10: =(N10/1000)/(R10*3600) -> 0.011818087 | T10: 7 | U10: =0.5*G$8*C$5*C$3*(X10-C$6)*K10^2+N10/K10*SIN(X10-C$1)-C$12*(C$14+G$11*(K$18-K10)/(K$18-K$4))*COS(W10) -> -1.0119536e-05 | V10: =DEGREES(W10) -> 7.0741738 | W10: 0.12346762 | X10: 0.024023156 | Y10: =DEGREES(X10) -> 1.3764255 | Z10: =-0.5*G$8*C$5*K10^2*(C$8+(C$3^2)*(X10-C$6)^2/(PI()*C$7))+N10/K10*COS(X10-C$1)-C$12*(C$14+G$11*(K$18-K10)/(K$18-K$4))*SIN(W10) -> -4.5463548e-07 | AB10: =T10 -> 7
A11: gęstość powietrza przy ziemii | B11: ρ | C11: =Podsumowanie!B2 -> 1.2255 | D11: kg/m3 | F11: mph | G11: =C13 -> 550 | H11: kg | I11: =C$3*(X11-C$6) -> 0.39236429 | J11: =(C$14+G$11*(K$18-K11)/(K$18-G$14)) -> 2680.5 | K11: =G$14+T10*G$13 -> 71.652595 | L11: =K11/C$9/C$2 -> 0.90730727 | M11: =0.185*L11^3-0.9822*L11^2+1.6209*L11 -> 0.80027767 | N11: =G$9*M11 -> 356923.84 | O11: =N11/K11 -> 4981.3107 | P11: =Y11 -> 0.69495239 | Q11: =V11 -> 6.3860485 | R11: =K11*SIN(RADIANS(Q11)) -> 7.9696994 | S11: =(N11/1000)/(R11*3600) -> 0.012440307 | T11: 8 | U11: =0.5*G$8*C$5*C$3*(X11-C$6)*K11^2+N11/K11*SIN(X11-C$1)-C$12*(C$14+G$11*(K$18-K11)/(K$18-K$4))*COS(W11) -> -2.526438e-06 | V11: =DEGREES(W11) -> 6.3860485 | W11: 0.11145757 | X11: 0.012129207 | Y11: =DEGREES(X11) -> 0.69495239 | Z11: =-0.5*G$8*C$5*K11^2*(C$8+(C$3^2)*(X11-C$6)^2/(PI()*C$7))+N11/K11*COS(X11-C$1)-C$12*(C$14+G$11*(K$18-K11)/(K$18-K$4))*SIN(W11) -> -7.5802291e-08 | AB11: =T11 -> 8
A12: Przyspieszenie grawitacyjne | B12: g | C12: =Podsumowanie!B1 -> 9.81 | D12: m/s2 | F12: dmp | G12: {=(G25-G7)*C$16*MIN(IF(S4:S18>0,S4:S18))} -> 3.5315186 | H12: kg | I12: =C$3*(X12-C$6) -> 0.33446527 | J12: =(C$14+G$11*(K$18-K12)/(K$18-G$14)) -> 2641.2143 | K12: =G$14+T11*G$13 -> 77.130796 | L12: =K12/C$9/C$2 -> 0.97667546 | M12: =0.185*L12^3-0.9822*L12^2+1.6209*L12 -> 0.8185321 | N12: =G$9*M12 -> 365065.32 | O12: =N12/K12 -> 4733.0682 | P12: =Y12 -> 0.15413567 | Q12: =V12 -> 5.6089053 | R12: =K12*SIN(RADIANS(Q12)) -> 7.5385776 | S12: =(N12/1000)/(R12*3600) -> 0.013451746 | T12: 9 | U12: =0.5*G$8*C$5*C$3*(X12-C$6)*K12^2+N12/K12*SIN(X12-C$1)-C$12*(C$14+G$11*(K$18-K12)/(K$18-K$4))*COS(W12) -> -1.7978891e-08 | V12: =DEGREES(W12) -> 5.6089053 | W12: 0.097893865 | X12: 0.002690175 | Y12: =DEGREES(X12) -> 0.15413567 | Z12: =-0.5*G$8*C$5*K12^2*(C$8+(C$3^2)*(X12-C$6)^2/(PI()*C$7))+N12/K12*COS(X12-C$1)-C$12*(C$14+G$11*(K$18-K12)/(K$18-K$4))*SIN(W12) -> 1.7542334e-08 | AB12: =T12 -> 9
A13: Masa paliwa | B13: mp | C13: =Podsumowanie!B5 -> 550 | D13: kg | F13: v | G13: =(K18-G14)/T17 -> 5.4782007 | H13: m/s | I13: =C$3*(X13-C$6) -> 0.28778967 | J13: =(C$14+G$11*(K$18-K13)/(K$18-G$14)) -> 2601.9286 | K13: =G$14+T12*G$13 -> 82.608997 | L13: =K13/C$9/C$2 -> 1.0460437 | M13: =0.185*L13^3-0.9822*L13^2+1.6209*L13 -> 0.83255062 | N13: =G$9*M13 -> 371317.58 | O13: =N13/K13 -> 4494.8806 | P13: =Y13 -> -0.28184649 | Q13: =V13 -> 4.7526561 | R13: =K13*SIN(RADIANS(Q13)) -> 6.8445193 | S13: =(N13/1000)/(R13*3600) -> 0.015069542 | T13: 10 | U13: =0.5*G$8*C$5*C$3*(X13-C$6)*K13^2+N13/K13*SIN(X13-C$1)-C$12*(C$14+G$11*(K$18-K13)/(K$18-K$4))*COS(W13) -> -2.9703006e-07 | V13: =DEGREES(W13) -> 4.7526561 | W13: 0.082949497 | X13: -0.0049191493 | Y13: =DEGREES(X13) -> -0.28184649 | Z13: =-0.5*G$8*C$5*K13^2*(C$8+(C$3^2)*(X13-C$6)^2/(PI()*C$7))+N13/K13*COS(X13-C$1)-C$12*(C$14+G$11*(K$18-K13)/(K$18-K$4))*SIN(W13) -> 1.8508217e-09 | AB13: =T13 -> 10
A14: Miminalna masa samolotu | B14: mmin | C14: =Podsumowanie!B7 -> 2405.5 | D14: kg | F14: Vmin | G14: =SQRT(2*(C$14)*C$12/C$5/C$15/G8) -> 33.30519 | H14: m/s | I14: =C$3*(X14-C$6) -> 0.24964072 | J14: =(C$14+G$11*(K$18-K14)/(K$18-G$14)) -> 2562.6429 | K14: =G$14+T13*G$13 -> 88.087197 | L14: =K14/C$9/C$2 -> 1.1154119 | M14: =0.185*L14^3-0.9822*L14^2+1.6209*L14 -> 0.84270374 | N14: =G$9*M14 -> 375845.87 | O14: =N14/K14 -> 4266.748 | P14: =Y14 -> -0.63818398 | Q14: =V14 -> 3.8234034 | R14: =K14*SIN(RADIANS(Q14)) -> 5.8737832 | S14: =(N14/1000)/(R14*3600) -> 0.017774171 | T14: 11 | U14: =0.5*G$8*C$5*C$3*(X14-C$6)*K14^2+N14/K14*SIN(X14-C$1)-C$12*(C$14+G$11*(K$18-K14)/(K$18-K$4))*COS(W14) -> -8.3558916e-07 | V14: =DEGREES(W14) -> 3.8234034 | W14: 0.066730978 | X14: -0.011138412 | Y14: =DEGREES(X14) -> -0.63818398 | Z14: =-0.5*G$8*C$5*K14^2*(C$8+(C$3^2)*(X14-C$6)^2/(PI()*C$7))+N14/K14*COS(X14-C$1)-C$12*(C$14+G$11*(K$18-K14)/(K$18-K$4))*SIN(W14) -> -1.6191734e-08 | AB14: =T14 -> 11
A15: maksymalny współczynnik siły nośnej | B15: Czmax | C15: =Podsumowanie!B15 -> 1.63 | D15: - | I15: =C$3*(X15-C$6) -> 0.21807923 | J15: =(C$14+G$11*(K$18-K15)/(K$18-G$14)) -> 2523.3571 | K15: =G$14+T14*G$13 -> 93.565398 | L15: =K15/C$9/C$2 -> 1.1847801 | M15: =0.185*L15^3-0.9822*L15^2+1.6209*L15 -> 0.84936198 | N15: =G$9*M15 -> 378815.44 | O15: =N15/K15 -> 4048.6703 | P15: =Y15 -> -0.93298996 | Q15: =V15 -> 2.8246509 | R15: =K15*SIN(RADIANS(Q15)) -> 4.6108552 | S15: =(N15/1000)/(R15*3600) -> 0.022821474 | T15: 12 | U15: =0.5*G$8*C$5*C$3*(X15-C$6)*K15^2+N15/K15*SIN(X15-C$1)-C$12*(C$14+G$11*(K$18-K15)/(K$18-K$4))*COS(W15) -> -5.9337253e-07 | V15: =DEGREES(W15) -> 2.8246509 | W15: 0.049299459 | X15: -0.016283747 | Y15: =DEGREES(X15) -> -0.93298996 | Z15: =-0.5*G$8*C$5*K15^2*(C$8+(C$3^2)*(X15-C$6)^2/(PI()*C$7))+N15/K15*COS(X15-C$1)-C$12*(C$14+G$11*(K$18-K15)/(K$18-K$4))*SIN(W15) -> -1.1696557e-08 | AB15: =T15 -> 12
A16: Jednostkowe zużycie paliwa | B16: qe | C16: =Podsumowanie!B32 -> 0.31 | D16: kg/kWh | I16: =C$3*(X16-C$6) -> 0.19168305 | J16: =(C$14+G$11*(K$18-K16)/(K$18-G$14)) -> 2484.0714 | K16: =G$14+T15*G$13 -> 99.043599 | L16: =K16/C$9/C$2 -> 1.2541482 | M16: =0.185*L16^3-0.9822*L16^2+1.6209*L16 -> 0.85289586 | N16: =G$9*M16 -> 380391.55 | O16: =N16/K16 -> 3840.6475 | P16: =Y16 -> -1.1795484 | Q16: =V16 -> 1.758047 | R16: =K16*SIN(RADIANS(Q16)) -> 3.0385481 | S16: =(N16/1000)/(R16*3600) -> 0.034774608 | T16: 13 | U16: =0.5*G$8*C$5*C$3*(X16-C$6)*K16^2+N16/K16*SIN(X16-C$1)-C$12*(C$14+G$11*(K$18-K16)/(K$18-K$4))*COS(W16) -> -2.8164141e-07 | V16: =DEGREES(W16) -> 1.758047 | W16: 0.030683709 | X16: -0.020587004 | Y16: =DEGREES(X16) -> -1.1795484 | Z16: =-0.5*G$8*C$5*K16^2*(C$8+(C$3^2)*(X16-C$6)^2/(PI()*C$7))+N16/K16*COS(X16-C$1)-C$12*(C$14+G$11*(K$18-K16)/(K$18-K$4))*SIN(W16) -> -4.6806008e-09 | AB16: =T16 -> 13
B17: Czmax- | C17: =Podsumowanie!B33 -> -1.173 | I17: =C$3*(X17-C$6) -> 0.16939072 | J17: =(C$14+G$11*(K$18-K17)/(K$18-G$14)) -> 2444.7857 | K17: =G$14+T16*G$13 -> 104.5218 | L17: =K17/C$9/C$2 -> 1.3235164 | M17: =0.185*L17^3-0.9822*L17^2+1.6209*L17 -> 0.85367587 | N17: =G$9*M17 -> 380739.44 | O17: =N17/K17 -> 3642.6797 | P17: =Y17 -> -1.3877742 | Q17: =V17 -> 0.62384847 | R17: =K17*SIN(RADIANS(Q17)) -> 1.1380328 | S17: =(N17/1000)/(R17*3600) -> 0.092933134 | T17: 14 | U17: =0.5*G$8*C$5*C$3*(X17-C$6)*K17^2+N17/K17*SIN(X17-C$1)-C$12*(C$14+G$11*(K$18-K17)/(K$18-K$4))*COS(W17) -> -1.1749216e-07 | V17: =DEGREES(W17) -> 0.62384847 | W17: 0.01088821 | X17: -0.024221228 | Y17: =DEGREES(X17) -> -1.3877742 | Z17: =-0.5*G$8*C$5*K17^2*(C$8+(C$3^2)*(X17-C$6)^2/(PI()*C$7))+N17/K17*COS(X17-C$1)-C$12*(C$14+G$11*(K$18-K17)/(K$18-K$4))*SIN(W17) -> -1.93495e-09 | AB17: =T17 -> 14
I18: =C$3*(X18-C$6) -> 0.15039743 | J18: =(C$14+G$11*(K$18-K18)/(K$18-G$14)) -> 2405.5 | K18: 110 | L18: =K18/C$9/C$2 -> 1.3928846 | M18: =0.185*L18^3-0.9822*L18^2+1.6209*L18 -> 0.85207255 | N18: =G$9*M18 -> 380024.36 | O18: =N18/K18 -> 3454.7669 | P18: =Y18 -> -1.5651845 | Q18: =V18 -> -0.57879071 | R18: =K18*SIN(RADIANS(Q18)) -> -1.1111795 | S18: =(N18/1000)/(R18*3600) -> -0.095000243 | T18: 15 | U18: =0.5*G$8*C$5*C$3*(X18-C$6)*K18^2+N18/K18*SIN(X18-C$1)-C$12*(C$14+G$11*(K$18-K18)/(K$18-K$4))*COS(W18) -> 0.00011893759 | V18: =DEGREES(W18) -> -0.57879071 | W18: -0.010101803 | X18: -0.027317624 | Y18: =DEGREES(X18) -> -1.5651845 | Z18: =-0.5*G$8*C$5*K18^2*(C$8+(C$3^2)*(X18-C$6)^2/(PI()*C$7))+N18/K18*COS(X18-C$1)-C$12*(C$14+G$11*(K$18-K18)/(K$18-K$4))*SIN(W18) -> -1.3769417e-05 | AB18: =T18 -> 15
K20: Metoda ciągu, zmienna masa, h=1000m
K21: V [m/s] | L21: J | M21: ηs | N21: Nr [W] | O21: Ps [N] | P21: α [°] | Q21: γ [°] | R21: w [m/s] | S21: Nr/w | U21: γ | V21: [°] | W21: [rad] | X21: [rad] | Y21: [°] | Z21: α
K22: =SQRT(2*(C$14+G29)*C$12/C$5/C$15/G26) -> 38.731649 | L22: =K22/C$9/C$2 -> 0.4904429 | M22: =0.1881*L22^3-0.9979*L22^2+1.6359*L22 -> 0.58447626 | N22: =G$27*M22 -> 233245.81 | O22: =N22/K22 -> 6022.0985 | P22: =Y22 -> 11.581042 | Q22: =V22 -> 6.3322338 | R22: =K22*SIN(RADIANS(Q22)) -> 4.2718484 | S22: =(N22/1000)/(R22*3600) -> 0.015166854 | T22: 1 | U22: =0.5*G$26*C$5*C$3*(X22-C$6)*K22^2+N22/K22*SIN(X22-C$1)-C$12*(C$14+G$29*(K$36-K22)/(K$36-K$22))*COS(W22) -> -1.0910298e-08 | V22: =DEGREES(W22) -> 6.3322338 | W22: 0.11051833 | X22: 0.20212731 | Y22: =DEGREES(X22) -> 11.581042 | Z22: =-0.5*G$26*C$5*K22^2*(C$8+(C$3^2)*(X22-C$6)^2/(PI()*C$7))+N22/K22*COS(X22-C$1)-C$12*(C$14+G$29*(K$36-K22)/(K$36-K$22))*SIN(W22) -> -2.1918822e-10 | AB22: =T22 -> 1
K23: =G$32+T22*G$31 -> 40.323093 | L23: =K23/C$9/C$2 -> 0.5105947 | M23: =0.1881*L23^3-0.9979*L23^2+1.6359*L23 -> 0.60016145 | N23: =G$27*M23 -> 239505.26 | O23: =N23/K23 -> 5939.655 | P23: =Y23 -> 10.455046 | Q23: =V23 -> 6.5321219 | R23: =K23*SIN(RADIANS(Q23)) -> 4.5871642 | S23: =(N23/1000)/(R23*3600) -> 0.014503348 | T23: 2 | U23: =0.5*G$26*C$5*C$3*(X23-C$6)*K23^2+N23/K23*SIN(X23-C$1)-C$12*(C$14+G$29*(K$36-K23)/(K$36-K$22))*COS(W23) -> 5.2733958e-07 | V23: =DEGREES(W23) -> 6.5321219 | W23: 0.11400703 | X23: 0.18247498 | Y23: =DEGREES(X23) -> 10.455046 | Z23: =-0.5*G$26*C$5*K23^2*(C$8+(C$3^2)*(X23-C$6)^2/(PI()*C$7))+N23/K23*COS(X23-C$1)-C$12*(C$14+G$29*(K$36-K23)/(K$36-K$22))*SIN(W23) -> -1.805276e-06 | AB23: =T23 -> 2
K24: =G$32+T23*G$31 -> 45.682855 | L24: =K24/C$9/C$2 -> 0.57846316 | M24: =0.1881*L24^3-0.9979*L24^2+1.6359*L24 -> 0.64880056 | N24: =G$27*M24 -> 258915.58 | O24: =N24/K24 -> 5667.675 | P24: =Y24 -> 7.4579507 | Q24: =V24 -> 6.903828 | R24: =K24*SIN(RADIANS(Q24)) -> 5.4912238 | S24: =(N24/1000)/(R24*3600) -> 0.013097444 | T24: 3 | U24: =0.5*G$26*C$5*C$3*(X24-C$6)*K24^2+N24/K24*SIN(X24-C$1)-C$12*(C$14+G$29*(K$36-K24)/(K$36-K$22))*COS(W24) -> 1.0032454e-07 | V24: =DEGREES(W24) -> 6.903828 | W24: 0.12049453 | X24: 0.1301658 | Y24: =DEGREES(X24) -> 7.4579507 | Z24: =-0.5*G$26*C$5*K24^2*(C$8+(C$3^2)*(X24-C$6)^2/(PI()*C$7))+N24/K24*COS(X24-C$1)-C$12*(C$14+G$29*(K$36-K24)/(K$36-K$22))*SIN(W24) -> -4.3513955e-07 | AB24: =T24 -> 3
F25: h | G25: 1000 | H25: m | K25: =G$32+T24*G$31 -> 51.042618 | L25: =K25/C$9/C$2 -> 0.64633162 | M25: =0.1881*L25^3-0.9979*L25^2+1.6359*L25 -> 0.69125388 | N25: =G$27*M25 -> 275857.34 | O25: =N25/K25 -> 5404.4514 | P25: =Y25 -> 5.3305515 | Q25: =V25 -> 6.9411445 | R25: =K25*SIN(RADIANS(Q25)) -> 6.1684858 | S25: =(N25/1000)/(R25*3600) -> 0.012422342 | T25: 4 | U25: =0.5*G$26*C$5*C$3*(X25-C$6)*K25^2+N25/K25*SIN(X25-C$1)-C$12*(C$14+G$29*(K$36-K25)/(K$36-K$22))*COS(W25) -> -0.00016862762 | V25: =DEGREES(W25) -> 6.9411445 | W25: 0.12114583 | X25: 0.093035674 | Y25: =DEGREES(X25) -> 5.3305515 | Z25: =-0.5*G$26*C$5*K25^2*(C$8+(C$3^2)*(X25-C$6)^2/(PI()*C$7))+N25/K25*COS(X25-C$1)-C$12*(C$14+G$29*(K$36-K25)/(K$36-K$22))*SIN(W25) -> -1.5675193e-05 | AB25: =T25 -> 4
F26: ρh | G26: =C$11*(1-G25/44300)^4.256 -> 1.1120173 | H26: kg/m3 | K26: =G$32+T25*G$31 -> 56.40238 | L26: =K26/C$9/C$2 -> 0.71420007 | M26: =0.1881*L26^3-0.9979*L26^2+1.6359*L26 -> 0.72787424 | N26: =G$27*M26 -> 290471.36 | O26: =N26/K26 -> 5149.9841 | P26: =Y26 -> 3.7708792 | Q26: =V26 -> 6.7517717 | R26: =K26*SIN(RADIANS(Q26)) -> 6.6311209 | S26: =(N26/1000)/(R26*3600) -> 0.012167851 | T26: 5 | U26: =0.5*G$26*C$5*C$3*(X26-C$6)*K26^2+N26/K26*SIN(X26-C$1)-C$12*(C$14+G$29*(K$36-K26)/(K$36-K$22))*COS(W26) -> -7.656424e-05 | V26: =DEGREES(W26) -> 6.7517717 | W26: 0.11784065 | X26: 0.065814258 | Y26: =DEGREES(X26) -> 3.7708792 | Z26: =-0.5*G$26*C$5*K26^2*(C$8+(C$3^2)*(X26-C$6)^2/(PI()*C$7))+N26/K26*COS(X26-C$1)-C$12*(C$14+G$29*(K$36-K26)/(K$36-K$22))*SIN(W26) -> -5.7635884e-06 | AB26: =T26 -> 5
F27: Nh | G27: =C$4*((G26/C$11)-C$10)/(1-C$10) -> 399068.06 | H27: W | K27: =G$32+T26*G$31 -> 61.762142 | L27: =K27/C$9/C$2 -> 0.78206853 | M27: =0.1881*L27^3-0.9979*L27^2+1.6359*L27 -> 0.75901443 | N27: =G$27*M27 -> 302898.41 | O27: =N27/K27 -> 4904.2732 | P27: =Y27 -> 2.5961083 | Q27: =V27 -> 6.398851 | R27: =K27*SIN(RADIANS(Q27)) -> 6.8833292 | S27: =(N27/1000)/(R27*3600) -> 0.012223511 | T27: 6 | U27: =0.5*G$26*C$5*C$3*(X27-C$6)*K27^2+N27/K27*SIN(X27-C$1)-C$12*(C$14+G$29*(K$36-K27)/(K$36-K$22))*COS(W27) -> -3.5700865e-05 | V27: =DEGREES(W27) -> 6.398851 | W27: 0.11168102 | X27: 0.045310637 | Y27: =DEGREES(X27) -> 2.5961083 | Z27: =-0.5*G$26*C$5*K27^2*(C$8+(C$3^2)*(X27-C$6)^2/(PI()*C$7))+N27/K27*COS(X27-C$1)-C$12*(C$14+G$29*(K$36-K27)/(K$36-K$22))*SIN(W27) -> -2.1828578e-06 | AB27: =T27 -> 6
F28: CN | G28: =G27/G26/C$9^3/C$2^5 -> 0.21521234 | H28: - | K28: =G$32+T27*G$31 -> 67.121904 | L28: =K28/C$9/C$2 -> 0.84993699 | M28: =0.1881*L28^3-0.9979*L28^2+1.6359*L28 -> 0.78502728 | N28: =G$27*M28 -> 313279.31 | O28: =N28/K28 -> 4667.3187 | P28: =Y28 -> 1.6908053 | Q28: =V28 -> 5.9209475 | R28: =K28*SIN(RADIANS(Q28)) -> 6.9240403 | S28: =(N28/1000)/(R28*3600) -> 0.0125681 | T28: 7 | U28: =0.5*G$26*C$5*C$3*(X28-C$6)*K28^2+N28/K28*SIN(X28-C$1)-C$12*(C$14+G$29*(K$36-K28)/(K$36-K$22))*COS(W28) -> -1.544031e-05 | V28: =DEGREES(W28) -> 5.9209475 | W28: 0.10334003 | X28: 0.029510119 | Y28: =DEGREES(X28) -> 1.6908053 | Z28: =-0.5*G$26*C$5*K28^2*(C$8+(C$3^2)*(X28-C$6)^2/(PI()*C$7))+N28/K28*COS(X28-C$1)-C$12*(C$14+G$29*(K$36-K28)/(K$36-K$22))*SIN(W28) -> -7.6592232e-07 | AB28: =T28 -> 7
F29: mph | G29: =G11-G12 -> 546.46848 | H29: kg | K29: =G$32+T28*G$31 -> 72.481666 | L29: =K29/C$9/C$2 -> 0.91780544 | M29: =0.1881*L29^3-0.9979*L29^2+1.6359*L29 -> 0.8062656 | N29: =G$27*M29 -> 321754.85 | O29: =N29/K29 -> 4439.1205 | P29: =Y29 -> 0.97940563 | Q29: =V29 -> 5.3423394 | R29: =K29*SIN(RADIANS(Q29)) -> 6.7485044 | S29: =(N29/1000)/(R29*3600) -> 0.013243875 | T29: 8 | U29: =0.5*G$26*C$5*C$3*(X29-C$6)*K29^2+N29/K29*SIN(X29-C$1)-C$12*(C$14+G$29*(K$36-K29)/(K$36-K$22))*COS(W29) -> -5.2358046e-06 | V29: =DEGREES(W29) -> 5.3423394 | W29: 0.093241412 | X29: 0.017093853 | Y29: =DEGREES(X29) -> 0.97940563 | Z29: =-0.5*G$26*C$5*K29^2*(C$8+(C$3^2)*(X29-C$6)^2/(PI()*C$7))+N29/K29*COS(X29-C$1)-C$12*(C$14+G$29*(K$36-K29)/(K$36-K$22))*SIN(W29) -> -1.9984691e-07 | AB29: =T29 -> 8
F30: dmp | G30: {=(G43-G25)*C$16*MIN(IF(S22:S36>0,S22:S36))} -> 3.7720337 | H30: kg | K30: =G$32+T29*G$31 -> 77.841428 | L30: =K30/C$9/C$2 -> 0.9856739 | M30: =0.1881*L30^3-0.9979*L30^2+1.6359*L30 -> 0.8230822 | N30: =G$27*M30 -> 328465.82 | O30: =N30/K30 -> 4219.6787 | P30: =Y30 -> 0.41087386 | Q30: =V30 -> 4.6786042 | R30: =K30*SIN(RADIANS(Q30)) -> 6.3492397 | S30: =(N30/1000)/(R30*3600) -> 0.014370304 | T30: 9 | U30: =0.5*G$26*C$5*C$3*(X30-C$6)*K30^2+N30/K30*SIN(X30-C$1)-C$12*(C$14+G$29*(K$36-K30)/(K$36-K$22))*COS(W30) -> -5.2681935e-07 | V30: =DEGREES(W30) -> 4.6786042 | W30: 0.081657047 | X30: 0.0071711017 | Y30: =DEGREES(X30) -> 0.41087386 | Z30: =-0.5*G$26*C$5*K30^2*(C$8+(C$3^2)*(X30-C$6)^2/(PI()*C$7))+N30/K30*COS(X30-C$1)-C$12*(C$14+G$29*(K$36-K30)/(K$36-K$22))*SIN(W30) -> 1.9949766e-09 | AB30: =T30 -> 9
F31: v | G31: =(K36-G32)/T35 -> 5.359762 | H31: m/s | K31: =G$32+T30*G$31 -> 83.20119 | L31: =K31/C$9/C$2 -> 1.0535424 | M31: =0.1881*L31^3-0.9979*L31^2+1.6359*L31 -> 0.83582989 | N31: =G$27*M31 -> 333553.01 | O31: =N31/K31 -> 4008.9933 | P31: =Y31 -> -0.050208675 | Q31: =V31 -> 3.9397931 | R31: =K31*SIN(RADIANS(Q31)) -> 5.7166029 | S31: =(N31/1000)/(R31*3600) -> 0.01620781 | T31: 10 | U31: =0.5*G$26*C$5*C$3*(X31-C$6)*K31^2+N31/K31*SIN(X31-C$1)-C$12*(C$14+G$29*(K$36-K31)/(K$36-K$22))*COS(W31) -> -3.1534e-08 | V31: =DEGREES(W31) -> 3.9397931 | W31: 0.068762362 | X31: -0.00087630669 | Y31: =DEGREES(X31) -> -0.050208675 | Z31: =-0.5*G$26*C$5*K31^2*(C$8+(C$3^2)*(X31-C$6)^2/(PI()*C$7))+N31/K31*COS(X31-C$1)-C$12*(C$14+G$29*(K$36-K31)/(K$36-K$22))*SIN(W31) -> 1.2434612e-08 | AB31: =T31 -> 10
G32: =SQRT(2*(C$14)*C$12/C$5/C$15/G26) -> 34.963331 | K32: =G$32+T31*G$31 -> 88.560952 | L32: =K32/C$9/C$2 -> 1.1214108 | M32: =0.1881*L32^3-0.9979*L32^2+1.6359*L32 -> 0.84486149 | N32: =G$27*M32 -> 337157.23 | O32: =N32/K32 -> 3807.0642 | P32: =Y32 -> -0.42901446 | Q32: =V32 -> 3.1323059 | R32: =K32*SIN(RADIANS(Q32)) -> 4.8391319 | S32: =(N32/1000)/(R32*3600) -> 0.019353634 | T32: 11 | U32: =0.5*G$26*C$5*C$3*(X32-C$6)*K32^2+N32/K32*SIN(X32-C$1)-C$12*(C$14+G$29*(K$36-K32)/(K$36-K$22))*COS(W32) -> -5.9508966e-07 | V32: =DEGREES(W32) -> 3.1323059 | W32: 0.054669051 | X32: -0.0074877148 | Y32: =DEGREES(X32) -> -0.42901446 | Z32: =-0.5*G$26*C$5*K32^2*(C$8+(C$3^2)*(X32-C$6)^2/(PI()*C$7))+N32/K32*COS(X32-C$1)-C$12*(C$14+G$29*(K$36-K32)/(K$36-K$22))*SIN(W32) -> -9.5792529e-09 | AB32: =T32 -> 11
K33: =G$32+T32*G$31 -> 93.920714 | L33: =K33/C$9/C$2 -> 1.1892793 | M33: =0.1881*L33^3-0.9979*L33^2+1.6359*L33 -> 0.8505298 | N33: =G$27*M33 -> 339419.28 | O33: =N33/K33 -> 3613.8916 | P33: =Y33 -> -0.74381317 | Q33: =V33 -> 2.2600336 | R33: =K33*SIN(RADIANS(Q33)) -> 3.7037445 | S33: =(N33/1000)/(R33*3600) -> 0.025456165 | T33: 12 | U33: =0.5*G$26*C$5*C$3*(X33-C$6)*K33^2+N33/K33*SIN(X33-C$1)-C$12*(C$14+G$29*(K$36-K33)/(K$36-K$22))*COS(W33) -> -6.5404311e-07 | V33: =DEGREES(W33) -> 2.2600336 | W33: 0.039445028 | X33: -0.012981989 | Y33: =DEGREES(X33) -> -0.74381317 | Z33: =-0.5*G$26*C$5*K33^2*(C$8+(C$3^2)*(X33-C$6)^2/(PI()*C$7))+N33/K33*COS(X33-C$1)-C$12*(C$14+G$29*(K$36-K33)/(K$36-K$22))*SIN(W33) -> -1.2906412e-08 | AB33: =T33 -> 12
K34: =G$32+T33*G$31 -> 99.280476 | L34: =K34/C$9/C$2 -> 1.2571477 | M34: =0.1881*L34^3-0.9979*L34^2+1.6359*L34 -> 0.85318765 | N34: =G$27*M34 -> 340479.94 | O34: =N34/K34 -> 3429.4753 | P34: =Y34 -> -1.0081137 | Q34: =V34 -> 1.3250734 | R34: =K34*SIN(RADIANS(Q34)) -> 2.2958443 | S34: =(N34/1000)/(R34*3600) -> 0.041195198 | T34: 13 | U34: =0.5*G$26*C$5*C$3*(X34-C$6)*K34^2+N34/K34*SIN(X34-C$1)-C$12*(C$14+G$29*(K$36-K34)/(K$36-K$22))*COS(W34) -> -4.0907616e-07 | V34: =DEGREES(W34) -> 1.3250734 | W34: 0.023126893 | X34: -0.017594903 | Y34: =DEGREES(X34) -> -1.0081137 | Z34: =-0.5*G$26*C$5*K34^2*(C$8+(C$3^2)*(X34-C$6)^2/(PI()*C$7))+N34/K34*COS(X34-C$1)-C$12*(C$14+G$29*(K$36-K34)/(K$36-K$22))*SIN(W34) -> -7.4803665e-09 | AB34: =T34 -> 13
K35: =G$32+T34*G$31 -> 104.64024 | L35: =K35/C$9/C$2 -> 1.3250162 | M35: =0.1881*L35^3-0.9979*L35^2+1.6359*L35 -> 0.85318783 | N35: =G$27*M35 -> 340480.01 | O35: =N35/K35 -> 3253.8153 | P35: =Y35 -> -1.2320721 | Q35: =V35 -> 0.32818283 | R35: =K35*SIN(RADIANS(Q35)) -> 0.5993625 | S35: =(N35/1000)/(R35*3600) -> 0.15779729 | T35: 14 | U35: =0.5*G$26*C$5*C$3*(X35-C$6)*K35^2+N35/K35*SIN(X35-C$1)-C$12*(C$14+G$29*(K$36-K35)/(K$36-K$22))*COS(W35) -> -6.9048838e-08 | V35: =DEGREES(W35) -> 0.32818283 | W35: 0.0057278709 | X35: -0.021503715 | Y35: =DEGREES(X35) -> -1.2320721 | Z35: =-0.5*G$26*C$5*K35^2*(C$8+(C$3^2)*(X35-C$6)^2/(PI()*C$7))+N35/K35*COS(X35-C$1)-C$12*(C$14+G$29*(K$36-K35)/(K$36-K$22))*SIN(W35) -> -1.1209238e-09 | AB35: =T35 -> 14
K36: =K18 -> 110 | L36: =K36/C$9/C$2 -> 1.3928846 | M36: =0.1881*L36^3-0.9979*L36^2+1.6359*L36 -> 0.85088317 | N36: =G$27*M36 -> 339560.29 | O36: =N36/K36 -> 3086.9118 | P36: =Y36 -> -1.4234386 | Q36: =V36 -> -0.73092949 | R36: =K36*SIN(RADIANS(Q36)) -> -1.4032458 | S36: =(N36/1000)/(R36*3600) -> -0.067217235 | T36: 15 | U36: =0.5*G$26*C$5*C$3*(X36-C$6)*K36^2+N36/K36*SIN(X36-C$1)-C$12*(C$14+G$29*(K$36-K36)/(K$36-K$22))*COS(W36) -> 1.0955093e-05 | V36: =DEGREES(W36) -> -0.73092949 | W36: -0.012757126 | X36: -0.02484369 | Y36: =DEGREES(X36) -> -1.4234386 | Z36: =-0.5*G$26*C$5*K36^2*(C$8+(C$3^2)*(X36-C$6)^2/(PI()*C$7))+N36/K36*COS(X36-C$1)-C$12*(C$14+G$29*(K$36-K36)/(K$36-K$22))*SIN(W36) -> -1.6267628e-06 | AB36: =T36 -> 15
K38: Metoda ciągu, zmienna masa, h=2000m
K39: V [m/s] | L39: J | M39: ηs | N39: Nr [W] | O39: Ps [N] | P39: α [°] | Q39: γ [°] | R39: w [m/s] | S39: Nr/w | U39: γ | V39: [°] | W39: [rad] | X39: [rad] | Y39: [°] | Z39: α
K40: =SQRT(2*(C$14+G47)*C$12/C$5/C$15/G44) -> 40.680125 | L40: =K40/C$9/C$2 -> 0.51511565 | M40: =0.1906*L40^3-1.0151*L40^2+1.6538*L40 -> 0.60859919 | N40: =G$45*M40 -> 216378.69 | O40: =N40/K40 -> 5319.0272 | P40: =Y40 -> 11.680623 | Q40: =V40 -> 4.9044249 | R40: =K40*SIN(RADIANS(Q40)) -> 3.4779013 | S40: =(N40/1000)/(R40*3600) -> 0.017282029 | T40: 1 | U40: =0.5*G$44*C$5*C$3*(X40-C$6)*K40^2+N40/K40*SIN(X40-C$1)-C$12*(C$14+G$47*(K$54-K40)/(K$54-K$40))*COS(W40) -> -2.2046152e-08 | V40: =DEGREES(W40) -> 4.9044249 | W40: 0.085598362 | X40: 0.20386532 | Y40: =DEGREES(X40) -> 11.680623 | Z40: =-0.5*G$44*C$5*K40^2*(C$8+(C$3^2)*(X40-C$6)^2/(PI()*C$7))+N40/K40*COS(X40-C$1)-C$12*(C$14+G$47*(K$54-K40)/(K$54-K$40))*SIN(W40) -> -2.3464963e-10 | AB40: =T40 -> 1
K41: =G$50+T40*G$49 -> 41.978168 | L41: =K41/C$9/C$2 -> 0.53155222 | M41: =0.1906*L41^3-1.0151*L41^2+1.6538*L41 -> 0.62089283 | N41: =G$45*M41 -> 220749.52 | O41: =N41/K41 -> 5258.6744 | P41: =Y41 -> 10.78151 | Q41: =V41 -> 5.0729668 | R41: =K41*SIN(RADIANS(Q41)) -> 3.7118916 | S41: =(N41/1000)/(R41*3600) -> 0.016519693 | T41: 2 | U41: =0.5*G$44*C$5*C$3*(X41-C$6)*K41^2+N41/K41*SIN(X41-C$1)-C$12*(C$14+G$47*(K$54-K41)/(K$54-K$40))*COS(W41) -> 5.2768155e-07 | V41: =DEGREES(W41) -> 5.0729668 | W41: 0.088539974 | X41: 0.18817285 | Y41: =DEGREES(X41) -> 10.78151 | Z41: =-0.5*G$44*C$5*K41^2*(C$8+(C$3^2)*(X41-C$6)^2/(PI()*C$7))+N41/K41*COS(X41-C$1)-C$12*(C$14+G$47*(K$54-K41)/(K$54-K$40))*SIN(W41) -> -1.7688831e-06 | AB41: =T41 -> 2
K42: =G$50+T41*G$49 -> 47.210616 | L42: =K42/C$9/C$2 -> 0.59780856 | M42: =0.1906*L42^3-1.0151*L42^2+1.6538*L42 -> 0.6666045 | N42: =G$45*M42 -> 237001.64 | O42: =N42/K42 -> 5020.0921 | P42: =Y42 -> 7.853359 | Q42: =V42 -> 5.4906505 | R42: =K42*SIN(RADIANS(Q42)) -> 4.5172686 | S42: =(N42/1000)/(R42*3600) -> 0.014573805 | T42: 3 | U42: =0.5*G$44*C$5*C$3*(X42-C$6)*K42^2+N42/K42*SIN(X42-C$1)-C$12*(C$14+G$47*(K$54-K42)/(K$54-K$40))*COS(W42) -> 1.9154686e-07 | V42: =DEGREES(W42) -> 5.4906505 | W42: 0.095829929 | X42: 0.13706697 | Y42: =DEGREES(X42) -> 7.853359 | Z42: =-0.5*G$44*C$5*K42^2*(C$8+(C$3^2)*(X42-C$6)^2/(PI()*C$7))+N42/K42*COS(X42-C$1)-C$12*(C$14+G$47*(K$54-K42)/(K$54-K$40))*SIN(W42) -> -8.0025393e-07 | AB42: =T42 -> 3
...

Sheet h=0m
A1: wysokość lotu | B1: h | C1: 0 | D1: m | G1: Metoda ciągu, m=mśr, h=0m
A2: Maksymalny ciężar | B2: Qmax | C2: =Podsumowanie!B31 -> 28993.455 | D2: N | G2: V [m/s] | H2: J | I2: ηs | J2: Nr [W] | K2: Ps [N] | L2: α [°] | M2: γ [°] | N2: w [m/s]
A3: kąt pochylenia osi silnika fi | B3: φ | C3: =Podsumowanie!B29 -> 0.017453293 | D3: rad | G3: =SQRT(2*C$15/C$7/C$16/C17) -> 35.157432 | H3: =G3/C$12/C$4 -> 0.44518406 | I3: =0.185*H3^3-0.9822*H3^2+1.6209*H3 -> 0.54326041 | J3: =C$18*I3 -> 242294.14 | K3: =J3/G3 -> 6891.6905 | L3: =OFFSET(D27,A27-2,0,1,1) -> 11.327448 | M3: =OFFSET(D26,A27-2,0,1,1) -> 9.5841953 | N3: =G3*SIN(RADIANS(M3)) -> 5.8535985
A4: średnica śmigła | B4: D | C4: =Podsumowanie!B12 -> 1.84 | D4: m | G4: 45 | H4: =G4/C$12/C$4 -> 0.56981644 | I4: =0.185*H4^3-0.9822*H4^2+1.6209*H4 -> 0.63893181 | J4: =C$18*I4 -> 284963.59 | K4: =J4/G4 -> 6332.5241 | L4: =OFFSET(D28,A28-2,0,1,1) -> 5.9971158 | M4: =OFFSET(D27,A28-2,0,1,1) -> 9.6448957 | N4: =G4*SIN(RADIANS(M4)) -> 7.5393585
A5: Współczynnik kierunkowy prostej Cz(a) | B5: a∞ | C5: =Podsumowanie!B16 -> 6.134 | D5: 1/rad | G5: 52 | H5: =G5/C$12/C$4 -> 0.65845456 | I5: =0.185*H5^3-0.9822*H5^2+1.6209*H5 -> 0.69425801 | J5: =C$18*I5 -> 309639.07 | K5: =J5/G5 -> 5954.5975 | L5: =OFFSET(D29,A29-2,0,1,1) -> 3.8246266 | M5: =OFFSET(D28,A29-2,0,1,1) -> 9.0931619 | N5: =G5*SIN(RADIANS(M5)) -> 8.2180915
A6: Moc silnika | B6: Nmax | C6: =Podsumowanie!B9 -> 446000 | D6: W | G6: 59 | H6: =G6/C$12/C$4 -> 0.74709267 | I6: =0.185*H6^3-0.9822*H6^2+1.6209*H6 -> 0.73989283 | J6: =C$18*I6 -> 329992.2 | K6: =J6/G6 -> 5593.0882 | L6: =OFFSET(D30,A30-2,0,1,1) -> 2.3527363 | M6: =OFFSET(D29,A30-2,0,1,1) -> 8.281519 | N6: =G6*SIN(RADIANS(M6)) -> 8.498184
A7: Powierzchnia nośna | B7: S | C7: =Podsumowanie!B3 -> 21.3 | D7: m2 | G7: 67 | H7: =G7/C$12/C$4 -> 0.84839337 | I7: =0.185*H7^3-0.9822*H7^2+1.6209*H7 -> 0.78117154 | J7: =C$18*I7 -> 348402.51 | K7: =J7/G7 -> 5200.0374 | L7: =OFFSET(D31,A31-2,0,1,1) -> 1.1869397 | M7: =OFFSET(D30,A31-2,0,1,1) -> 7.1547475 | N7: =G7*SIN(RADIANS(M7)) -> 8.3448243
A8: Kąt zerowej siły nośnej | B8: α0 | C8: =Podsumowanie!B30 -> -0.051836279 | D8: rad | G8: 74 | H8: =G8/C$12/C$4 -> 0.93703148 | I8: =0.185*H8^3-0.9822*H8^2+1.6209*H8 -> 0.80864211 | J8: =C$18*I8 -> 360654.38 | K8: =J8/G8 -> 4873.7078 | L8: =OFFSET(D32,A32-2,0,1,1) -> 0.45359557 | M8: =OFFSET(D31,A32-2,0,1,1) -> 6.0505477 | N8: =G8*SIN(RADIANS(M8)) -> 7.8000302
A9: masa samolotu | B9: m | C9: =Podsumowanie!B7 -> 2405.5 | D9: kg | G9: 81 | H9: =G9/C$12/C$4 -> 1.0256696 | I9: =0.185*H9^3-0.9822*H9^2+1.6209*H9 -> 0.82885075 | J9: =C$18*I9 -> 369667.44 | K9: =J9/G9 -> 4563.7955 | L9: =OFFSET(D33,A33-2,0,1,1) -> -0.10241885 | M9: =OFFSET(D32,A33-2,0,1,1) -> 4.8658269 | N9: =G9*SIN(RADIANS(M9)) -> 6.8706351
A10: wydłużenie Oswalda | B10: Λe | C10: =Podsumowanie!B13 -> 5.884 | D10: - | G10: 89 | H10: =G10/C$12/C$4 -> 1.1269703 | I10: =0.185*H10^3-0.9822*H10^2+1.6209*H10 -> 0.84404582 | J10: =C$18*I10 -> 376444.43 | K10: =J10/G10 -> 4229.7127 | L10: =OFFSET(D34,A34-2,0,1,1) -> -0.58781925 | M10: =OFFSET(D33,A34-2,0,1,1) -> 3.4348398 | N10: =G10*SIN(RADIANS(M10)) -> 5.3322891
A11: Minimalny współczynnik Cx z danych | B11: (Cx)min | C11: =Podsumowanie!B14 -> 0.02214 | D11: - | G11: 96 | H11: =G11/C$12/C$4 -> 1.2156084 | I11: =0.185*H11^3-0.9822*H11^2+1.6209*H11 -> 0.85129619 | J11: =C$18*I11 -> 379678.1 | K11: =J11/G11 -> 3954.9802 | L11: =OFFSET(D35,A35-2,0,1,1) -> -0.91910979 | M11: =OFFSET(D34,A35-2,0,1,1) -> 2.1270789 | N11: =G11*SIN(RADIANS(M11)) -> 3.5631363
A12: Obroty silnika | B12: ns | C12: =Podsumowanie!B11 -> 42.92 | D12: 1/s | G12: 103 | H12: =G12/C$12/C$4 -> 1.3042465 | I12: =0.185*H12^3-0.9822*H12^2+1.6209*H12 -> 0.8537141 | J12: =C$18*I12 -> 380756.49 | K12: =J12/G12 -> 3696.6649 | L12: =OFFSET(D36,A36-2,0,1,1) -> -1.1867582 | M12: =OFFSET(D35,A36-2,0,1,1) -> 0.77433371 | N12: =G12*SIN(RADIANS(M12)) -> 1.3919689
A13: współczynnik korekcyjny | B13: k | C13: =Podsumowanie!B17 -> 0.12 | D13: - | G13: 111 | H13: =G13/C$12/C$4 -> 1.4055472 | I13: =0.185*H13^3-0.9822*H13^2+1.6209*H13 -> 0.85155173 | J13: =C$18*I13 -> 379792.07 | K13: =J13/G13 -> 3421.5502 | L13: =OFFSET(D37,A37-2,0,1,1) -> -1.4343085 | M13: =OFFSET(D36,A37-2,0,1,1) -> -0.82143482 | N13: =G13*SIN(RADIANS(M13)) -> -1.5913239
A14: gęstość powietrza przy ziemii | B14: ρ | C14: =Podsumowanie!B2 -> 1.2255 | D14: kg/m3 | G14: 118 | H14: =G14/C$12/C$4 -> 1.4941853 | I14: =0.185*H14^3-0.9822*H14^2+1.6209*H14 -> 0.84621734 | J14: =C$18*I14 -> 377412.93 | K14: =J14/G14 -> 3198.4147 | L14: =OFFSET(D38,A38-2,0,1,1) -> -1.6119936 | M14: =OFFSET(D37,A38-2,0,1,1) -> -2.2583952 | N14: =G14*SIN(RADIANS(M14)) -> -4.6499347
A15: Ciężar samolotu | B15: Q | C15: =Podsumowanie!B8 -> 26295.705 | D15: N | G15: 125 | H15: =G15/C$12/C$4 -> 1.5828235 | I15: =0.185*H15^3-0.9822*H15^2+1.6209*H15 -> 0.83847994 | J15: =C$18*I15 -> 373962.05 | K15: =J15/G15 -> 2991.6964 | L15: =OFFSET(D39,A39-2,0,1,1) -> -1.7615241 | M15: =OFFSET(D38,A39-2,0,1,1) -> -3.7317614 | N15: =G15*SIN(RADIANS(M15)) -> -8.1356855
A16: Maksymalne Cz | B16: Czmax | C16: =Podsumowanie!B15 -> 1.63 | D16: - | G16: 132 | H16: =G16/C$12/C$4 -> 1.6714616 | I16: =0.185*H16^3-0.9822*H16^2+1.6209*H16 -> 0.82911254 | J16: =C$18*I16 -> 369784.19 | K16: =J16/G16 -> 2801.3954 | L16: =OFFSET(D40,A40-2,0,1,1) -> -1.8886441 | M16: =OFFSET(D39,A40-2,0,1,1) -> -5.240845 | N16: =G16*SIN(RADIANS(M16)) -> -12.05721
A17: gęstość powietrza na wysokości h | B17: ρh | C17: =C14*(1-C1/44300)^4.256 -> 1.2255 | D17: kg/m3 | G17: 140 | H17: =G17/C$12/C$4 -> 1.7727623 | I17: =0.185*H17^3-0.9822*H17^2+1.6209*H17 -> 0.81740264 | J17: =C$18*I17 -> 364561.58 | K17: =J17/G17 -> 2604.0113 | L17: =OFFSET(D41,A41-2,0,1,1) -> -2.012017 | M17: =OFFSET(D40,A41-2,0,1,1) -> -7.009137 | N17: =G17*SIN(RADIANS(M17)) -> -17.083867
A18: Moc na wysokości przelotowej | B18: Nh | C18: =C6*((C17/C14)-C13)/(1-C13) -> 446000 | D18: W
A19: Współczynnik mocy | B19: CN | C19: =C18/C17/C12^3/C4^5 -> 0.21824952 | D19: -
A20: Maksymalny ciężar samolotu | B20: Qmax | C20: =Podsumowanie!B31 -> 28993.455 | D20: N | F20: Metoda mocy, m=mśr, h=0m
F21: Cz | G21: E | H21: V [m/s] | I21: J | J21: ηs | K21: Nn [W] | L21: Nr [W] | M21: ΔN [W] | N21: w [m/s] | O21: γ [°] | P21: α [°]
F22: 1.63 | G22: 156.18 | H22: =SQRT((2*C$15)/(C$7*C$17*F22)) -> 35.157432 | I22: =H22/C$12/C$4 -> 0.44518406 | J22: =0.185*I22^3-0.9822*I22^2+1.6209*I22 -> 0.54326041 | K22: =C$15*SQRT((2*C$15)/(C$17*C$7*G22)) -> 94445.889 | L22: =C$18*J22 -> 242294.14 | M22: =(L22-K22) -> 147848.25 | N22: =M22/C$15 -> 5.6225247 | O22: =DEGREES(ASIN(N22/H22)) -> 9.2024975 | P22: 15.277
F23: 1.571 | G23: 158.85 | H23: =SQRT((2*C$15)/(C$7*C$17*F23)) -> 35.811528 | I23: =H23/C$12/C$4 -> 0.45346661 | J23: =0.185*I23^3-0.9822*I23^2+1.6209*I23 -> 0.55030305 | K23: =C$15*SQRT((2*C$15)/(C$17*C$7*G23)) -> 93648.787 | L23: =C$18*J23 -> 245435.16 | M23: =(L23-K23) -> 151786.37 | N23: =M23/C$15 -> 5.7722877 | O23: =DEGREES(ASIN(N23/H23)) -> 9.2756951 | P23: 12.123
F24: 1.474 | G24: 163.07 | H24: =SQRT((2*C$15)/(C$7*C$17*F24)) -> 36.971086 | I24: =H24/C$12/C$4 -> 0.46814961 | J24: =0.185*I24^3-0.9822*I24^2+1.6209*I24 -> 0.56254206 | K24: =C$15*SQRT((2*C$15)/(C$17*C$7*G24)) -> 92429.101 | L24: =C$18*J24 -> 250893.76 | M24: =(L24-K24) -> 158464.66 | N24: =M24/C$15 -> 6.0262563 | O24: =DEGREES(ASIN(N24/H24)) -> 9.3810218 | P24: 11.015
B25: Równania | C25: Kąty [rad] | D25: Kąty [deg] | F25: 1.379 | G25: 167.61 | H25: =SQRT((2*C$15)/(C$7*C$17*F25)) -> 38.223356 | I25: =H25/C$12/C$4 -> 0.48400659 | J25: =0.185*I25^3-0.9822*I25^2+1.6209*I25 -> 0.57540992 | K25: =C$15*SQRT((2*C$15)/(C$17*C$7*G25)) -> 91168.709 | L25: =C$18*J25 -> 256632.82 | M25: =(L25-K25) -> 165464.11 | N25: =M25/C$15 -> 6.2924388 | O25: =DEGREES(ASIN(N25/H25)) -> 9.4753272 | P25: 9.578
A26: 1 | B26: =-K3*COS(C26+C27-C$3)+0.5*C$17*C$7*C$5*(C27-C$8)*G3^2*SIN(C26)+0.5*C$17*C$7*(C$11+1/PI()/C$10*C$5^2*(C27-C$8)^2)*G3^2*COS(C26) -> 0.00025508661 | C26: 0.16727576 | D26: =DEGREES(C26) -> 9.5841953 | F26: 1.272 | G26: 169.65 | H26: =SQRT((2*C$15)/(C$7*C$17*F26)) -> 39.798563 | I26: =H26/C$12/C$4 -> 0.50395279 | J26: =0.185*I26^3-0.9822*I26^2+1.6209*I26 -> 0.5910871 | K26: =C$15*SQRT((2*C$15)/(C$17*C$7*G26)) -> 90618.91 | L26: =C$18*J26 -> 263624.85 | M26: =(L26-K26) -> 173005.94 | N26: =M26/C$15 -> 6.5792469 | O26: =DEGREES(ASIN(N26/H26)) -> 9.5154573 | P26: 8.472
A27: 2 | B27: =K3*SIN(C26+C27-C$3)+0.5*C$17*C$7*C$5*(C27-C$8)*G3^2*COS(C26)-0.5*C$17*C$7*(C$11+1/PI()/C$10*C$5^2*(C27-C$8)^2)*G3^2*SIN(C26)-C$15 -> -2.8058639e-07 | C27: 0.19770126 | D27: =DEGREES(C27) -> 11.327448 | F27: 1.178 | G27: 170.58 | H27: =SQRT((2*C$15)/(C$7*C$17*F27)) -> 41.355979 | I27: =H27/C$12/C$4 -> 0.5236737 | J27: =0.185*I27^3-0.9822*I27^2+1.6209*I27 -> 0.60603763 | K27: =C$15*SQRT((2*C$15)/(C$17*C$7*G27)) -> 90371.546 | L27: =C$18*J27 -> 270292.78 | M27: =(L27-K27) -> 179921.24 | N27: =M27/C$15 -> 6.8422291 | O27: =DEGREES(ASIN(N27/H27)) -> 9.5232117 | P27: 7.694
A28: 3 | B28: =-K4*COS(C28+C29-C$3)+0.5*C$17*C$7*C$5*(C29-C$8)*G4^2*SIN(C28)+0.5*C$17*C$7*(C$11+1/PI()/C$10*C$5^2*(C29-C$8)^2)*G4^2*COS(C28) -> -0.00034872542 | C28: 0.16833519 | D28: =DEGREES(C28) -> 9.6448957 | F28: 1.08 | G28: 169.97 | H28: =SQRT((2*C$15)/(C$7*C$17*F28)) -> 43.191578 | I28: =H28/C$12/C$4 -> 0.54691714 | J28: =0.185*I28^3-0.9822*I28^2+1.6209*I28 -> 0.62296864 | K28: =C$15*SQRT((2*C$15)/(C$17*C$7*G28)) -> 90533.567 | L28: =C$18*J28 -> 277844.01 | M28: =(L28-K28) -> 187310.45 | N28: =M28/C$15 -> 7.1232335 | O28: =DEGREES(ASIN(N28/H28)) -> 9.4926926 | P28: 7.048
A29: 4 | B29: =K4*SIN(C28+C29-C$3)+0.5*C$17*C$7*C$5*(C29-C$8)*G4^2*COS(C28)-0.5*C$17*C$7*(C$11+1/PI()/C$10*C$5^2*(C29-C$8)^2)*G4^2*SIN(C28)-C$15 -> 0.00017152022 | C29: 0.10466942 | D29: =DEGREES(C29) -> 5.9971158 | F29: 0.969 | G29: 164.23 | H29: =SQRT((2*C$15)/(C$7*C$17*F29)) -> 45.598343 | I29: =H29/C$12/C$4 -> 0.57739301 | J29: =0.185*I29^3-0.9822*I29^2+1.6209*I29 -> 0.64405903 | K29: =C$15*SQRT((2*C$15)/(C$17*C$7*G29)) -> 92102.097 | L29: =C$18*J29 -> 287250.33 | M29: =(L29-K29) -> 195148.23 | N29: =M29/C$15 -> 7.4212967 | O29: =DEGREES(ASIN(N29/H29)) -> 9.3667642 | P29: 6.074
A30: 5 | B30: =-K5*COS(C30+C31-C$3)+0.5*C$17*C$7*C$5*(C31-C$8)*G5^2*SIN(C30)+0.5*C$17*C$7*(C$11+1/PI()/C$10*C$5^2*(C31-C$8)^2)*G5^2*COS(C30) -> -0.00041453414 | C30: 0.15870561 | D30: =DEGREES(C30) -> 9.0931619 | F30: 0.868 | G30: 160.73 | H30: =SQRT((2*C$15)/(C$7*C$17*F30)) -> 48.178257 | I30: =H30/C$12/C$4 -> 0.6100614 | J30: =0.185*I30^3-0.9822*I30^2+1.6209*I30 -> 0.66530249 | K30: =C$15*SQRT((2*C$15)/(C$17*C$7*G30)) -> 93099.488 | L30: =C$18*J30 -> 296724.91 | M30: =(L30-K30) -> 203625.42 | N30: =M30/C$15 -> 7.7436761 | O30: =DEGREES(ASIN(N30/H30)) -> 9.2492523 | P30: 5.099
