Workbook
Name g_v__dane: Podsumowanie!#REF!
Name g_v__dane_1: Podsumowanie!$V$1:$V$11
Name h_0: 'h=0m'!$I$40:$J$54
Name h_0: 'h=1000m'!$I$39:$J$53
Name h_0: 'h=1500m'!$I$39:$J$53
Name h_0: 'h=2000m'!$I$39:$J$52
Name h_0: 'h=2500m'!$I$39:$J$52
Name h_0: 'h=3000m'!$I$38:$J$52
Name h_0: 'h=3500m'!$I$38:$J$52
Name h_0: 'h=4000m'!$I$38:$J$52
Name h_0: 'h=4500m'!$I$38:$J$52
Name h_0: 'h=500m'!$I$39:$J$53
Name h_0: 'Nr(V)'!$B$2:$B$373
Name h_1: 'h=1000m'!$I$39:$J$53
Name h_1: 'h=1500m'!$I$39:$J$53
Name h_1: 'h=2000m'!$I$39:$J$52
Name h_1: 'h=2500m'!$I$39:$J$52
Name h_1: 'h=3000m'!$I$38:$J$52
Name h_1: 'h=3500m'!$I$38:$J$52
Name h_1: 'h=4000m'!$I$38:$J$52
Name h_1: 'h=4500m'!$I$38:$J$52
Name h_1: 'h=500m'!$I$39:$J$53
Name h_1000: 'Nr(V)'!$D$2:$D$112
Name h_1500: 'Nr(V)'!$E$2:$E$94
Name h_2000: 'Nr(V)'!$F$2:$F$280
Name h_2500: 'Nr(V)'!$G$2:$G$281
Name h_3000: 'Nr(V)'!$H$2:$H$372
Name h_3500: 'Nr(V)'!$I$2:$I$288
Name h_4000: 'Nr(V)'!$J$2:$J$288
Name h_4500: 'Nr(V)'!$K$2:$K$369
Name h_500: 'Nr(V)'!$C$2:$C$378
Name h_5000: 'Nr(V)'!#REF!
Name h_5011: 'Nr(V)'!$A$2:$A$510
Name PWS_Vmin: Podsumowanie!#REF!
Name PWS_Vmin_1: Podsumowanie!#REF!
Name V_minmax: Podsumowanie!#REF!
Name V_PWS: Podsumowanie!$AC$3:$AD$106
Name V_PWS_1: Podsumowanie!#REF!
Name V2_PWS: Podsumowanie!$AI$50:$AJ$150
Name w_V__dane: Podsumowanie!#REF!

Sheet Podsumowanie
A1: Ja w | B1: 9.81 | C1: m/s2 | AC1: ciągu | AD1: m zmienna | AE1: ciągu | AF1: mśr | AG1: mocy | AH1: mśr | AI1: ciągu | AJ1: mmax | AK1: mocy | AL1: mmax
A2: ρ0 | B2: 1.2255 | C2: kg/m3 | M2: h [m] | N2: Vmin [m/s] | O2: Vmin [km/h] | P2: Vmax [m/s] | Q2: Vmax [km/h] | R2: wmax [m/s] | S2: 10·wmax [m/s] | T2: Vw [m/s] | U2: Vw [km/h] | V2: γmax [°] | W2: 10·γmax [°] | X2: Vγ [m/s] | Y2: Vγ [km/h] | Z2: ht [m] | AA2: th [min] | AC2: Vmin
A3: S | B3: 18 | C3: m2 | M3: 0 | N3: =AC3 -> 20.474251 | O3: =N3*3.6 -> 73.707305 | P3: =AC13 -> 41.994755 | Q3: =P3*3.6 -> 151.18112 | R3: =AD23 -> 2.3164557 | S3: =10*R3 -> 23.164557 | T3: =AC23 -> 29.326946 | U3: =T3*3.6 -> 105.57701 | V3: =AD33 -> 4.8934426 | W3: =10*V3 -> 48.934426 | X3: =AC33 -> 25.677419 | Y3: =X3*3.6 -> 92.43871 | Z3: =AC46 -> 4240 | AA3: =Z3/R$3*LN(1/(1-M3/Z3))/60 -> 0 | AC3: 20.474251 | AD3: 1.6540084 | AE3: 19.907244 | AF3: 1.8847294 | AG3: 19.907244 | AH3: 1.728524 | AI3: 20.474251 | AJ3: 1.6540084 | AK3: 20.474251 | AL3: 1.5105485
A4: mmax | B4: 720 | C4: kg | M4: 500 | N4: =AC4 -> 20.97485 | O4: =N4*3.6 -> 75.509461 | P4: =AC14 -> 41.811788 | Q4: =P4*3.6 -> 150.52244 | R4: =AD24 -> 2.0379747 | S4: =10*R4 -> 20.379747 | T4: =AC24 -> 29.748503 | U4: =T4*3.6 -> 107.09461 | V4: =AD34 -> 4.147541 | W4: =10*V4 -> 41.47541 | X4: =AC34 -> 26.860215 | Y4: =X4*3.6 -> 96.696774 | Z4: =Z3 -> 4240 | AA4: =Z4/R$3*LN(1/(1-M4/Z4))/60 -> 3.8278685 | AC4: 20.97485 | AD4: 1.4008439 | AE4: 20.392191 | AF4: 1.6876131 | AG4: 20.365249 | AH4: 1.3566064 | AI4: 21.001198 | AJ4: 1.3966245 | AK4: 20.97485 | AL4: 1.2531646
A5: mpal | B5: 90 | C5: kg | M5: 1000 | N5: =AC5 -> 21.475449 | O5: =N5*3.6 -> 77.311617 | P5: =AC15 -> 41.674562 | Q5: =P5*3.6 -> 150.02842 | R5: =AD25 -> 1.742616 | S5: =10*R5 -> 17.42616 | T5: =AC25 -> 30.45988 | U5: =T5*3.6 -> 109.65557 | V5: =AD35 -> 3.4918033 | W5: =10*V5 -> 34.918033 | X5: =AC35 -> 27.596177 | Y5: =X5*3.6 -> 99.346237 | Z5: =Z4 -> 4240 | AA5: =Z5/R$3*LN(1/(1-M5/Z5))/60 -> 8.205908 | AC5: 21.475449 | AD5: 1.1350211 | AE5: 20.877138 | AF5: 1.3789215 | AG5: 20.90408 | AH5: 1.1037025 | AI5: 21.501796 | AJ5: 1.1223629 | AK5: 21.501796 | AL5: 0.99156118
A6: mk | B6: 520 | C6: kg | M6: 1500 | N6: =AC6 -> 22.002395 | O6: =N6*3.6 -> 79.208623 | P6: =AC16 -> 41.476347 | Q6: =P6*3.6 -> 149.31485 | R6: =AD26 -> 1.4303797 | S6: =10*R6 -> 14.303797 | T6: =AC26 -> 30.960479 | U6: =T6*3.6 -> 111.45772 | V6: =AD36 -> 2.9098361 | W6: =10*V6 -> 29.098361 | X6: =AC36 -> 28.227001 | Y6: =X6*3.6 -> 101.6172 | Z6: =Z5 -> 4240 | AA6: =Z6/R$3*LN(1/(1-M6/Z6))/60 -> 13.319247 | AC6: 22.002395 | AD6: 0.8649789 | AE6: 21.415968 | AF6: 1.1297367 | AG6: 21.415968 | AH6: 0.87683281 | AI6: 22.028743 | AJ6: 0.84810127 | AK6: 22.028743 | AL6: 0.72151899
A7: mobl | B7: =(B4+B6)/2 -> 620 | C7: kg | M7: 2000 | N7: =AC7 -> 22.555689 | O7: =N7*3.6 -> 81.200479 | P7: =AC17 -> 41.003682 | Q7: =P7*3.6 -> 147.61325 | R7: =AD27 -> 1.1265823 | S7: =10*R7 -> 11.265823 | T7: =AC27 -> 31.671856 | U7: =T7*3.6 -> 114.01868 | V7: =AD37 -> 2.204918 | W7: =10*V7 -> 22.04918 | X7: =AC37 -> 29.0681 | Y7: =X7*3.6 -> 104.64516 | Z7: =Z6 -> 4240 | AA7: =Z7/R$3*LN(1/(1-M7/Z7))/60 -> 19.465734 | AC7: 22.555689 | AD7: 0.5907173 | AE7: 21.98174 | AF7: 0.83592188 | AG7: 21.98174 | AH7: 0.60161382 | AI7: 22.608383 | AJ7: 0.56540084 | AK7: 22.608383 | AL7: 0.43881857
A8: Q | B8: =(B7+B4)/2*B1 -> 6572.7 | C8: N | M8: 2500 | N8: =AC8 -> 23.108982 | O8: =N8*3.6 -> 83.192335 | P8: =AC18 -> 40.759725 | Q8: =P8*3.6 -> 146.73501 | R8: =AD28 -> 0.86075949 | S8: =10*R8 -> 8.6075949 | T8: =AC28 -> 32.22515 | U8: =T8*3.6 -> 116.01054 | V8: =AD38 -> 1.6639344 | W8: =10*V8 -> 16.639344 | X8: =AC38 -> 29.961768 | Y8: =X8*3.6 -> 107.86237 | Z8: =Z7 -> 4240 | AA8: =Z8/R$3*LN(1/(1-M8/Z8))/60 -> 27.171362 | AC8: 23.108982 | AD8: 0.3164557 | AE8: 22.52057 | AF8: 0.56814125 | AG8: 22.493629 | AH8: 0.38218247 | AI8: 23.188024 | AJ8: 0.28691983 | AK8: 23.161677 | AL8: 0.16455696
A9: Qmax | B9: =(B7+B5)*B1 -> 6965.1 | C9: N | M9: 3000 | N9: =AC9 -> 23.688623 | O9: =N9*3.6 -> 85.279042 | P9: =AC19 -> 40.104092 | Q9: =P9*3.6 -> 144.37473 | R9: =AD29 -> 0.58649789 | S9: =10*R9 -> 5.8649789 | T9: =AC29 -> 32.778443 | U9: =T9*3.6 -> 118.0024 | V9: =AD39 -> 1.0983607 | W9: =10*V9 -> 10.983607 | X9: =AC39 -> 30.960573 | Y9: =X9*3.6 -> 111.45806 | Z9: =Z8 -> 4240 | AA9: =Z9/R$3*LN(1/(1-M9/Z9))/60 -> 37.506121 | AC9: 23.688623 | AD9: 0.13080169 | AE9: 23.086342 | AF9: 0.30407979 | AG9: 23.086342 | AH9: 0.14043607 | AI9: 23.767665 | AJ9: 0.071729958 | AK9: 24.031138 | AL9: -0.0042194093
A10: Nmax | B10: 59000 | C10: W | M10: 3500 | N10: =AC10 -> 25.48024 | O10: =N10*3.6 -> 91.728862 | P10: =AC20 -> 38.350654 | Q10: =P10*3.6 -> 138.06236 | R10: =AD30 -> 0.38396624 | S10: =10*R10 -> 3.8396624 | T10: =AC30 -> 33.173653 | U10: =T10*3.6 -> 119.42515 | V10: =AD40 -> 0.70491803 | W10: =10*V10 -> 7.0491803 | X10: =AC40 -> 31.880526 | Y10: =X10*3.6 -> 114.76989 | Z10: =Z9 -> 4240 | AA10: =Z10/R$3*LN(1/(1-M10/Z10))/60 -> 53.254014 | AC10: 25.48024 | AD10: -0.0042194093 | AE10: 23.732938 | AF10: 0.040018328 | AG10: 24.945307 | AH10: 0.0028265734 | AI10: 26.955689 | AJ10: -0.0042194093 | AK10: 28.088623 | AL10: -0.0042194093
A11: Nnom | B11: 59000 | C11: W | M11: 4000 | N11: =AC11 -> 28.536527 | O11: =N11*3.6 -> 102.7315 | P11: =AC21 -> 36.002573 | Q11: =P11*3.6 -> 129.60926 | R11: =AD31 -> 0.13080169 | S11: =10*R11 -> 1.3080169 | T11: =AC31 -> 33.700599 | U11: =T11*3.6 -> 121.32216 | V11: =AD41 -> 0.24590164 | W11: =10*V11 -> 2.4590164 | X11: =AC41 -> 33.326165 | Y11: =X11*3.6 -> 119.97419 | Z11: =Z10 -> 4240 | AA11: =Z11/R$3*LN(1/(1-M11/Z11))/60 -> 87.604536 | AC11: 28.536527 | AD11: -0.0042194093 | AE11: 27.235335 | AF11: 0.0028265734
A12: ns | B12: 36.667 | C12: 1/s | M12: =Z3 -> 4240 | O12: 122 | Q12: =O12 -> 122 | S12: 0 | U12: =Q12 -> 122 | W12: =S12 -> 0 | Y12: =U12 -> 122 | AA12: 160 | AC12: Vmax
A13: D | B13: 1.8 | C13: m | AC13: 41.994755 | AD13: -0.0039654634 | AE13: 41.756811 | AF13: 0.0028265734 | AG13: 41.595162 | AH13: 0.0028265734 | AI13: 41.522089 | AJ13: -0.0039654634 | AK13: 40.851209 | AL13: -0.0015236756
A14: Λe | B14: 4.587 | C14: - | M14: h [m] | N14: Vmin [m/s] | O14: Vmin [km/h] | P14: Vmax [m/s] | Q14: Vmax [km/h] | R14: wmax [m/s] | S14: 10·wmax [m/s] | T14: Vw [m/s] | U14: Vw [km/h] | V14: γmax [°] | W14: 10·γmax [°] | X14: Vγ [m/s] | Y14: Vγ [km/h] | Z14: ht [m] | AA14: th [min] | AC14: 41.811788 | AD14: -0.0039654634 | AE14: 41.541279 | AF14: 0.0028265734 | AG14: 41.217981 | AH14: 0.0028265734 | AI14: 41.247638 | AJ14: -0.0039654634 | AK14: 40.39379 | AL14: -0.0015236756
A15: (Cx)min | B15: 0.04478 | C15: - | M15: 0 | N15: =AE3 -> 19.907244 | O15: =N15*3.6 -> 71.666077 | P15: =AE13 -> 41.756811 | Q15: =P15*3.6 -> 150.32452 | R15: =AF23 -> 2.3830989 | S15: =10*R15 -> 23.830989 | T15: =AE23 -> 27.585575 | U15: =T15*3.6 -> 99.30807 | V15: =AF33 -> 5.4991119 | W15: =10*V15 -> 54.991119 | X15: =AE33 -> 21.753181 | Y15: =X15*3.6 -> 78.31145 | Z15: =AE46 -> 4070 | AA15: =Z15/R$15*LN(1/(1-M15/Z15))/60 -> 0 | AC15: 41.674562 | AD15: -0.0039654634 | AE15: 41.325747 | AF15: 0.0028265734 | AG15: 40.463618 | AH15: -0.00089260211 | AI15: 40.942692 | AJ15: -0.0015236756 | AK15: 39.905877 | AL15: -0.0015236756
A16: Czmax | B16: 1.507 | C16: - | M16: 500 | N16: =AE4 -> 20.392191 | O16: =N16*3.6 -> 73.411887 | P16: =AE14 -> 41.541279 | Q16: =P16*3.6 -> 149.5486 | R16: =AF24 -> 2.0781265 | S16: =10*R16 -> 20.781265 | T16: =AE24 -> 27.908873 | U16: =T16*3.6 -> 100.47194 | V16: =AF34 -> 4.7424512 | W16: =10*V16 -> 47.424512 | X16: =AE34 -> 22.13486 | Y16: =X16*3.6 -> 79.685496 | Z16: =Z15 -> 4070 | AA16: =Z16/R$15*LN(1/(1-M16/Z16))/60 -> 3.7310316 | AC16: 41.476347 | AD16: -0.0039654634 | AE16: 40.948565 | AF16: 0.0028265734 | AG16: 39.870905 | AH16: 0.0028265734 | AI16: 40.515768 | AJ16: -0.0039654634 | AK16: 39.55519 | AL16: -0.0015236756
A17: a∞ | B17: 5.832 | C17: 1/rad | M17: 1000 | N17: =AE5 -> 20.877138 | O17: =N17*3.6 -> 75.157697 | P17: =AE15 -> 41.325747 | Q17: =P17*3.6 -> 148.77269 | R17: =AF25 -> 1.814065 | S17: =10*R17 -> 18.14065 | T17: =AE25 -> 28.232171 | U17: =T17*3.6 -> 101.63582 | V17: =AF35 -> 3.8685613 | W17: =10*V17 -> 38.685613 | X17: =AE35 -> 22.898219 | Y17: =X17*3.6 -> 82.433588 | Z17: =Z16 -> 4070 | AA17: =Z17/R$15*LN(1/(1-M17/Z17))/60 -> 8.0259597 | AC17: 41.003682 | AD17: -0.0039654634 | AE17: 40.382794 | AF17: 0.0028265734 | AG17: 39.008776 | AH17: -0.00089260211 | AI17: 39.783899 | AJ17: -0.0064072511 | AK17: 38.975793 | AL17: -0.0064072511
A18: k | B18: 0.14 | C18: - | M18: 1500 | N18: =AE6 -> 21.415968 | O18: =N18*3.6 -> 77.097486 | P18: =AE16 -> 40.948565 | Q18: =P18*3.6 -> 147.41484 | R18: =AF26 -> 1.4867776 | S18: =10*R18 -> 14.867776 | T18: =AE26 -> 28.663235 | U18: =T18*3.6 -> 103.18765 | V18: =AF36 -> 3.1119005 | W18: =10*V18 -> 31.119005 | X18: =AE36 -> 23.788804 | Y18: =X18*3.6 -> 85.639695 | Z18: =Z17 -> 4070 | AA18: =Z18/R$15*LN(1/(1-M18/Z18))/60 -> 13.086112 | AC18: 40.759725 | AD18: -0.0039654634 | AE18: 39.924788 | AF18: -0.00089260211 | AG18: 38.389122 | AH18: -0.00089260211 | AI18: 39.143513 | AJ18: -0.0039654634 | AK18: 37.954225 | AL18: -0.0064072511
A19: φ | B19: 1 | C19: ° | M19: 2000 | N19: =AE7 -> 21.98174 | O19: =N19*3.6 -> 79.134264 | P19: =AE17 -> 40.382794 | Q19: =P19*3.6 -> 145.37806 | R19: =AF27 -> 1.1743668 | S19: =10*R19 -> 11.743668 | T19: =AE27 -> 29.067358 | U19: =T19*3.6 -> 104.64249 | V19: =AF37 -> 2.4404973 | W19: =10*V19 -> 24.404973 | X19: =AE37 -> 24.583969 | Y19: =X19*3.6 -> 88.50229 | Z19: =Z18 -> 4070 | AA19: =Z19/R$15*LN(1/(1-M19/Z19))/60 -> 19.24458 | AC19: 40.104092 | AD19: -0.0015236756 | AE19: 38.954893 | AF19: 0.0028265734 | AG19: 36.179918 | AH19: 0.0028265734 | AI19: 37.161366 | AJ19: -0.0064072511 | AK19: 35.255456 | AL19: -0.0015236756
A20: α0 | B20: -3.816 | C20: ° | M20: 2500 | N20: =AE8 -> 22.52057 | O20: =N20*3.6 -> 81.074053 | P20: =AE18 -> 39.924788 | Q20: =P20*3.6 -> 143.72924 | R20: =AF28 -> 0.90286704 | S20: =10*R20 -> 9.0286704 | T20: =AE28 -> 29.444539 | U20: =T20*3.6 -> 106.00034 | V20: =AF38 -> 1.8436945 | W20: =10*V20 -> 18.436945 | X20: =AE38 -> 25.506361 | Y20: =X20*3.6 -> 91.822901 | Z20: =Z19 -> 4070 | AA20: =Z20/R$15*LN(1/(1-M20/Z20))/60 -> 27.1142 | AC20: 38.350654 | AD20: -0.0039654634 | AE20: 36.610982 | AF20: -0.00089260211 | AG20: 34.347895 | AH20: -0.00089260211 | AI20: 33.913695 | AJ20: -0.0064072511 | AK20: 32.846385 | AL20: -0.0039654634
A21: ηś | B21: 0.791 | C21: - | M21: 3000 | N21: =AE9 -> 23.086342 | O21: =N21*3.6 -> 83.110832 | P21: =AE19 -> 38.954893 | Q21: =P21*3.6 -> 140.23762 | R21: =AF29 -> 0.59789465 | S21: =10*R21 -> 5.9789465 | T21: =AE29 -> 29.98337 | U21: =T21*3.6 -> 107.94013 | V21: =AF39 -> 1.2149201 | W21: =10*V21 -> 12.149201 | X21: =AE39 -> 26.492366 | Y21: =X21*3.6 -> 95.372519 | Z21: =Z20 -> 4070 | AA21: =Z21/R$15*LN(1/(1-M21/Z21))/60 -> 38.027911 | AC21: 36.002573 | AD21: -0.0015236756 | AE21: 32.48893 | AF21: 0.0028265734
A22: qN | B22: =B4/(B10/1000) -> 12.20339 | M22: 3500 | N22: =AE10 -> 23.732938 | O22: =N22*3.6 -> 85.438579 | P22: =AE20 -> 36.610982 | Q22: =P22*3.6 -> 131.79953 | R22: =AF30 -> 0.33011402 | S22: =10*R22 -> 3.3011402 | T22: =AE30 -> 30.549141 | U22: =T22*3.6 -> 109.97691 | V22: =AF40 -> 0.61811723 | W22: =10*V22 -> 6.1811723 | X22: =AE40 -> 27.828244 | Y22: =X22*3.6 -> 100.18168 | Z22: =Z21 -> 4070 | AA22: =Z22/R$15*LN(1/(1-M22/Z22))/60 -> 55.954113 | AC22: Vw
A23: qt | B23: =0.022*B25 -> 18.48 | M23: 4000 | N23: =AE11 -> 27.235335 | O23: =N23*3.6 -> 98.047207 | P23: =AE21 -> 32.48893 | Q23: =P23*3.6 -> 116.96015 | R23: =AF31 -> 0.040018328 | S23: =10*R23 -> 0.40018328 | T23: =AE31 -> 31.195738 | U23: =T23*3.6 -> 112.30466 | V23: =AF41 -> 0.11722913 | W23: =10*V23 -> 1.1722913 | X23: =AE41 -> 28.973282 | Y23: =X23*3.6 -> 104.30382 | Z23: =Z22 -> 4070 | AA23: =Z23/R$15*LN(1/(1-M23/Z23))/60 -> 115.64785 | AC23: 29.326946 | AD23: 2.3164557 | AE23: 27.585575 | AF23: 2.3830989 | AG23: 25.780493 | AH23: 2.2343319 | AI23: 28.273054 | AJ23: 2.0759494 | AK23: 27.42994 | AL23: 2.0506329
A24: qe | B24: =B23/B11 -> 0.00031322034 | M24: =Z15 -> 4070 | O24: 108 | Q24: =O24 -> 108 | S24: =S12 -> 0 | U24: =Q24 -> 108 | W24: =S24 -> 0 | Y24: =U24 -> 108 | AA24: =AA12 -> 160 | AC24: 29.748503 | AD24: 2.0379747 | AE24: 27.908873 | AF24: 2.0781265 | AG24: 26.265441 | AH24: 1.9516745 | AI24: 28.773653 | AJ24: 1.7848101 | AK24: 27.667066 | AL24: 1.7637131
A25: ρpal | B25: 840 | C25: kg/m3 | AC25: 30.45988 | AD25: 1.742616 | AE25: 28.232171 | AF25: 1.814065 | AG25: 26.696505 | AH25: 1.665298 | AI25: 29.116168 | AJ25: 1.5316456 | AK25: 27.877844 | AL25: 1.4978903
A26: thp | B26: 45.4 | C26: min | M26: h [m] | N26: Vmin [m/s] | O26: Vmin [km/h] | P26: Vmax [m/s] | Q26: Vmax [km/h] | R26: wmax [m/s] | S26: 10·wmax [m/s] | T26: Vw [m/s] | U26: Vw [km/h] | V26: γmax [°] | W26: 10·γmax [°] | X26: Vγ [m/s] | Y26: Vγ [km/h] | Z26: ht [m] | AA26: th [min] | AC26: 30.960479 | AD26: 1.4303797 | AE26: 28.663235 | AF26: 1.4867776 | AG26: 27.046745 | AH26: 1.3566064 | AI26: 29.590419 | AJ26: 1.2278481 | AK26: 28.299401 | AL26: 1.1814346
A27: Δt | B27: 1.25 | C27: h | M27: 0 | N27: =AG3 -> 19.907244 | O27: =N27*3.6 -> 71.666077 | P27: =AG13 -> 41.595162 | Q27: =P27*3.6 -> 149.74258 | R27: =AH23 -> 2.2343319 | S27: =10*R27 -> 22.343319 | T27: =AG23 -> 25.780493 | U27: =T27*3.6 -> 92.809777 | V27: =AH33 -> 5.2220249 | W27: =10*V27 -> 52.220249 | X27: =AG33 -> 21.117048 | Y27: =X27*3.6 -> 76.021374 | Z27: =AG46 -> 3900 | AA27: =Z27/R$27*LN(1/(1-M27/Z27))/60 -> 0 | AC27: 31.671856 | AD27: 1.1265823 | AE27: 29.067358 | AF27: 1.1743668 | AG27: 27.585575 | AH27: 1.0665108 | AI27: 30.064671 | AJ27: 0.89451477 | AK27: 28.615569 | AL27: 0.907173
A28: ht | B28: 4550 | C28: m | M28: 500 | N28: =AG4 -> 20.365249 | O28: =N28*3.6 -> 73.314898 | P28: =AG14 -> 41.217981 | Q28: =P28*3.6 -> 148.38473 | R28: =AH24 -> 1.9516745 | S28: =10*R28 -> 19.516745 | T28: =AG24 -> 26.265441 | U28: =T28*3.6 -> 94.555587 | V28: =AH34 -> 4.2841918 | W28: =10*V28 -> 42.841918 | X28: =AG34 -> 22.03944 | Y28: =X28*3.6 -> 79.341985 | Z28: =Z27 -> 3900 | AA28: =Z28/R$27*LN(1/(1-M28/Z28))/60 -> 3.9913824 | AC28: 32.22515 | AD28: 0.86075949 | AE28: 29.444539 | AF28: 0.90286704 | AG28: 28.097464 | AH28: 0.79129177 | AI28: 30.538922 | AJ28: 0.62869198 | AK28: 29.063473 | AL28: 0.62025316
A29: hp | B29: 3700 | C29: m | M29: 1000 | N29: =AG5 -> 20.90408 | O29: =N29*3.6 -> 75.254687 | P29: =AG15 -> 40.463618 | Q29: =P29*3.6 -> 145.66903 | R29: =AH25 -> 1.665298 | S29: =10*R29 -> 16.65298 | T29: =AG25 -> 26.696505 | U29: =T29*3.6 -> 96.107418 | V29: =AH35 -> 3.5914742 | W29: =10*V29 -> 35.914742 | X29: =AG35 -> 22.739186 | Y29: =X29*3.6 -> 81.861069 | Z29: =Z28 -> 3900 | AA29: =Z29/R$27*LN(1/(1-M29/Z29))/60 -> 8.6188083 | AC29: 32.778443 | AD29: 0.58649789 | AE29: 29.98337 | AF29: 0.59789465 | AG29: 28.690177 | AH29: 0.52351114 | AI29: 30.960479 | AJ29: 0.32911392 | AK29: 29.590419 | AL29: 0.35021097
A30: φ | B30: =RADIANS(B19) -> 0.017453293 | C30: rad | M30: 1500 | N30: =AG6 -> 21.415968 | O30: =N30*3.6 -> 77.097486 | P30: =AG16 -> 39.870905 | Q30: =P30*3.6 -> 143.53526 | R30: =AH26 -> 1.3566064 | S30: =10*R30 -> 13.566064 | T30: =AG26 -> 27.046745 | U30: =T30*3.6 -> 97.368281 | V30: =AH36 -> 2.8028419 | W30: =10*V30 -> 28.028419 | X30: =AG36 -> 23.629771 | Y30: =X30*3.6 -> 85.067176 | Z30: =Z29 -> 3900 | AA30: =Z30/R$27*LN(1/(1-M30/Z30))/60 -> 14.124136 | AC30: 33.173653 | AD30: 0.38396624 | AE30: 30.549141 | AF30: 0.33011402 | AG30: 29.444539 | AH30: 0.22969628 | AI30: 31.382036 | AJ30: 0.080168776 | AK30: 30.328144 | AL30: 0.080168776
A31: α0 | B31: =RADIANS(B20) -> -0.066601764 | C31: rad | M31: 2000 | N31: =AG7 -> 21.98174 | O31: =N31*3.6 -> 79.134264 | P31: =AG17 -> 39.008776 | Q31: =P31*3.6 -> 140.4316 | R31: =AH27 -> 1.0665108 | S31: =10*R31 -> 10.665108 | T31: =AG27 -> 27.585575 | U31: =T31*3.6 -> 99.30807 | V31: =AH37 -> 2.1527531 | W31: =10*V31 -> 21.527531 | X31: =AG37 -> 24.424936 | Y31: =X31*3.6 -> 87.929771 | Z31: =Z30 -> 3900 | AA31: =Z31/R$27*LN(1/(1-M31/Z31))/60 -> 20.920336 | AC31: 33.700599 | AD31: 0.13080169 | AE31: 31.195738 | AF31: 0.040018328
A32: qe | B32: 0.31322 | C32: kg/kWh | M32: 2500 | N32: =AG8 -> 22.493629 | O32: =N32*3.6 -> 80.977064 | P32: =AG18 -> 38.389122 | Q32: =P32*3.6 -> 138.20084 | R32: =AH28 -> 0.79129177 | S32: =10*R32 -> 7.9129177 | T32: =AG28 -> 28.097464 | U32: =T32*3.6 -> 101.15087 | V32: =AH38 -> 1.4920071 | W32: =10*V32 -> 14.920071 | X32: =AG38 -> 25.888041 | Y32: =X32*3.6 -> 93.196947 | Z32: =Z31 -> 3900 | AA32: =Z32/R$27*LN(1/(1-M32/Z32))/60 -> 29.804337 | AC32: Vy
M33: 3000 | N33: =AG9 -> 23.086342 | O33: =N33*3.6 -> 83.110832 | P33: =AG19 -> 36.179918 | Q33: =P33*3.6 -> 130.2477 | R33: =AH29 -> 0.52351114 | S33: =10*R33 -> 5.2351114 | T33: =AG29 -> 28.690177 | U33: =T33*3.6 -> 103.28464 | V33: =AH39 -> 0.95914742 | W33: =10*V33 -> 9.5914742 | X33: =AG39 -> 27.160305 | Y33: =X33*3.6 -> 97.777099 | Z33: =Z32 -> 3900 | AA33: =Z33/R$27*LN(1/(1-M33/Z33))/60 -> 42.657902 | AC33: 25.677419 | AD33: 4.8934426 | AE33: 21.753181 | AF33: 5.4991119 | AG33: 21.117048 | AH33: 5.2220249 | AI33: 22.339307 | AJ33: 4.6147541 | AK33: 24.100358 | AL33: 4.442623
M34: 3500 | N34: =AG10 -> 24.945307 | O34: =N34*3.6 -> 89.803104 | P34: =AG20 -> 34.347895 | Q34: =P34*3.6 -> 123.65242 | R34: =AH30 -> 0.22969628 | S34: =10*R34 -> 2.2969628 | T34: =AG30 -> 29.444539 | U34: =T34*3.6 -> 106.00034 | V34: =AH40 -> 0.40497336 | W34: =10*V34 -> 4.0497336 | X34: =AG40 -> 29.005089 | Y34: =X34*3.6 -> 104.41832 | Z34: =Z33 -> 3900 | AA34: =Z34/R$27*LN(1/(1-M34/Z34))/60 -> 66.249055 | AC34: 26.860215 | AD34: 4.147541 | AE34: 22.13486 | AF34: 4.7424512 | AG34: 22.03944 | AH34: 4.2841918 | AI34: 23.048984 | AJ34: 3.8606557 | AK34: 25.388292 | AL34: 3.7786885
M35: =Z27 -> 3900 | O35: 110 | Q35: =O35 -> 110 | S35: =S24 -> 0 | U35: =Q35 -> 110 | W35: =S35 -> 0 | Y35: =U35 -> 110 | AA35: =AA12 -> 160 | AC35: 27.596177 | AD35: 3.4918033 | AE35: 22.898219 | AF35: 3.8685613 | AG35: 22.739186 | AH35: 3.5914742 | AI35: 24.310633 | AJ35: 3.1311475 | AK35: 26.623656 | AL35: 3.1229508
AC36: 28.227001 | AD36: 2.9098361 | AE36: 23.788804 | AF36: 3.1119005 | AG36: 23.629771 | AH36: 2.8028419 | AI36: 25.44086 | AJ36: 2.4918033 | AK36: 27.569892 | AL36: 2.4508197
M37: h [m] | N37: Vmin [m/s] | O37: Vmin [km/h] | P37: Vmax [m/s] | Q37: Vmax [km/h] | R37: wmax [m/s] | S37: 10·wmax [m/s] | T37: Vw [m/s] | U37: Vw [km/h] | V37: γmax [°] | W37: 10·γmax [°] | X37: Vγ [m/s] | Y37: Vγ [km/h] | Z37: ht [m] | AA37: th [min] | AC37: 29.0681 | AD37: 2.204918 | AE37: 24.583969 | AF37: 2.4404973 | AG37: 24.424936 | AH37: 2.1527531 | AI37: 26.544803 | AJ37: 1.8606557 | AK37: 28.332139 | AL37: 1.8442623
M38: 0 | N38: =AI3 -> 20.474251 | O38: =N38*3.6 -> 73.707305 | P38: =AI13 -> 41.522089 | Q38: =P38*3.6 -> 149.47952 | R38: =AJ23 -> 2.0759494 | S38: =10*R38 -> 20.759494 | T38: =AI23 -> 28.273054 | U38: =T38*3.6 -> 101.78299 | V38: =AJ33 -> 4.6147541 | W38: =10*V38 -> 46.147541 | X38: =AI33 -> 22.339307 | Y38: =X38*3.6 -> 80.421505 | Z38: =M46 -> 3640 | AA38: =Z38/R$38*LN(1/(1-M38/Z38))/60 -> 0 | AC38: 29.961768 | AD38: 1.6639344 | AE38: 25.506361 | AF38: 1.8436945 | AG38: 25.888041 | AH38: 1.4920071 | AI38: 27.701314 | AJ38: 1.352459 | AK38: 29.436081 | AL38: 1.2295082
M39: 500 | N39: =AI4 -> 21.001198 | O39: =N39*3.6 -> 75.604311 | P39: =AI14 -> 41.247638 | Q39: =P39*3.6 -> 148.4915 | R39: =AJ24 -> 1.7848101 | S39: =10*R39 -> 17.848101 | T39: =AI24 -> 28.773653 | U39: =T39*3.6 -> 103.58515 | V39: =AJ34 -> 3.8606557 | W39: =10*V39 -> 38.606557 | X39: =AI34 -> 23.048984 | Y39: =X39*3.6 -> 82.976344 | Z39: =Z38 -> 3640 | AA39: =Z39/R$38*LN(1/(1-M39/Z39))/60 -> 4.3181015 | AC39: 30.960573 | AD39: 1.0983607 | AE39: 26.492366 | AF39: 1.2149201 | AG39: 27.160305 | AH39: 0.95914742 | AI39: 28.673835 | AJ39: 0.73770492 | AK39: 30.145759 | AL39: 0.69672131
M40: 1000 | N40: =AI5 -> 21.501796 | O40: =N40*3.6 -> 77.406467 | P40: =AI15 -> 40.942692 | Q40: =P40*3.6 -> 147.39369 | R40: =AJ25 -> 1.5316456 | S40: =10*R40 -> 15.316456 | T40: =AI25 -> 29.116168 | U40: =T40*3.6 -> 104.8182 | V40: =AJ35 -> 3.1311475 | W40: =10*V40 -> 31.311475 | X40: =AI35 -> 24.310633 | Y40: =X40*3.6 -> 87.51828 | Z40: =Z39 -> 3640 | AA40: =Z40/R$38*LN(1/(1-M40/Z40))/60 -> 9.3867522 | AC40: 31.880526 | AD40: 0.70491803 | AE40: 27.828244 | AF40: 0.61811723 | AG40: 29.005089 | AH40: 0.40497336 | AI40: 30.250896 | AJ40: 0.18032787 | AK40: 30.934289 | AL40: 0.14754098
...

Sheet Metoda Ciągu, zmienna masa
A1: kąt pochylenia osi silnika fi | B1: φ | C1: =Podsumowanie!B30 -> 0.017453293 | D1: rad
A2: średnica śmigła | B2: D | C2: =Podsumowanie!B13 -> 1.8 | D2: m | J2: Metoda ciągu, zmienna masa, h=0m
A3: Współczynnik kierunkowy prostej Cz(a) | B3: a∞ | C3: =Podsumowanie!B17 -> 5.832 | D3: 1/rad | J3: V [m/s] | K3: Nr [W] | L3: Ps [N] | M3: α [°] | N3: γ [°] | O3: w [m/s] | P3: Nr/w | R3: γ | S3: [°] | T3: [rad] | U3: [rad] | V3: [°] | W3: α
A4: Moc silnika | B4: Nmax | C4: =Podsumowanie!B10 -> 59000 | D4: W | J4: =SQRT(2*(C$14+G11)*C$12/C$5/C$15/G8) -> 20.470532 | K4: ='Nr(V)'!B43 -> 29979.747 | L4: =K4/J4 -> 1464.5319 | M4: =V4 -> 10.430745 | N4: =S4 -> 4.6389383 | O4: =J4*SIN(RADIANS(N4)) -> 1.6555813 | P4: =(K4/1000)/(O4*3600) -> 0.0050300807 | Q4: 1 | R4: =0.5*G$8*C$5*C$3*(U4-C$6)*J4^2+K4/J4*SIN(U4-C$1)-C$12*(C$14+G$11*(J$18-J4)/(J$18-J$4))*COS(T4) -> 6.2471581e-06 | S4: =DEGREES(T4) -> 4.6389383 | T4: 0.080964747 | U4: 0.18205085 | V4: =DEGREES(U4) -> 10.430745 | W4: =-0.5*G$8*C$5*J4^2*(C$8+(C$3^2)*(U4-C$6)^2/(PI()*C$7))+K4/J4*COS(U4-C$1)-C$12*(C$14+G$11*(J$18-J4)/(J$18-J$4))*SIN(T4) -> -1.4850214e-05 | X4: =Q4 -> 1
A5: Powierzchnia nośna | B5: S | C5: =Podsumowanie!B3 -> 18 | D5: m2 | J5: =J$4+Q4*G$13 -> 22.07978 | K5: ='Nr(V)'!B46 -> 30919.618 | L5: =K5/J5 -> 1400.359 | M5: =V5 -> 8.4212486 | N5: =S5 -> 4.728102 | O5: =J5*SIN(RADIANS(N5)) -> 1.8199772 | P5: =(K5/1000)/(O5*3600) -> 0.0047191707 | Q5: 2 | R5: =0.5*G$8*C$5*C$3*(U5-C$6)*J5^2+K5/J5*SIN(U5-C$1)-C$12*(C$14+G$11*(J$18-J5)/(J$18-J$4))*COS(T5) -> 7.7291108e-05 | S5: =DEGREES(T5) -> 4.728102 | T5: 0.082520948 | U5: 0.14697852 | V5: =DEGREES(U5) -> 8.4212486 | W5: =-0.5*G$8*C$5*J5^2*(C$8+(C$3^2)*(U5-C$6)^2/(PI()*C$7))+K5/J5*COS(U5-C$1)-C$12*(C$14+G$11*(J$18-J5)/(J$18-J$4))*SIN(T5) -> 1.3867341e-05 | X5: =Q5 -> 2
A6: Kąt zerowej siły nośnej | B6: α0 | C6: =Podsumowanie!B31 -> -0.066601764 | D6: rad | J6: =J$4+Q5*G$13 -> 23.689028 | K6: ='Nr(V)'!B50 -> 32329.313 | L6: =K6/J6 -> 1364.7378 | M6: =V6 -> 6.7819428 | N6: =S6 -> 4.8719059 | O6: =J6*SIN(RADIANS(N6)) -> 2.0118705 | P6: =(K6/1000)/(O6*3600) -> 0.0044636891 | Q6: 3 | R6: =0.5*G$8*C$5*C$3*(U6-C$6)*J6^2+K6/J6*SIN(U6-C$1)-C$12*(C$14+G$11*(J$18-J6)/(J$18-J$4))*COS(T6) -> -3.8726284e-09 | S6: =DEGREES(T6) -> 4.8719059 | T6: 0.085030799 | U6: 0.11836723 | V6: =DEGREES(U6) -> 6.7819428 | W6: =-0.5*G$8*C$5*J6^2*(C$8+(C$3^2)*(U6-C$6)^2/(PI()*C$7))+K6/J6*COS(U6-C$1)-C$12*(C$14+G$11*(J$18-J6)/(J$18-J$4))*SIN(T6) -> -5.1386451e-11 | X6: =Q6 -> 3
A7: wydłużenie Oswalda | B7: Λe | C7: =Podsumowanie!B14 -> 4.587 | D7: - | F7: h | G7: 0 | H7: m | J7: =J$4+Q6*G$13 -> 25.298276 | K7: ='Nr(V)'!B53 -> 33621.99 | L7: =K7/J7 -> 1329.023 | M7: =V7 -> 5.4374494 | N7: =S7 -> 4.8626386 | O7: =J7*SIN(RADIANS(N7)) -> 2.1444642 | P7: =(K7/1000)/(O7*3600) -> 0.0043551399 | Q7: 4 | R7: =0.5*G$8*C$5*C$3*(U7-C$6)*J7^2+K7/J7*SIN(U7-C$1)-C$12*(C$14+G$11*(J$18-J7)/(J$18-J$4))*COS(T7) -> 1.7014183e-05 | S7: =DEGREES(T7) -> 4.8626386 | T7: 0.084869054 | U7: 0.094901395 | V7: =DEGREES(U7) -> 5.4374494 | W7: =-0.5*G$8*C$5*J7^2*(C$8+(C$3^2)*(U7-C$6)^2/(PI()*C$7))+K7/J7*COS(U7-C$1)-C$12*(C$14+G$11*(J$18-J7)/(J$18-J$4))*SIN(T7) -> 2.362561e-06 | X7: =Q7 -> 4
A8: Minimalny współczynnik Cx z danych | B8: (Cx)min | C8: =Podsumowanie!B15 -> 0.04478 | D8: - | F8: ρh | G8: =C$11*(1-G7/44300)^4.256 -> 1.2255 | H8: kg/m3 | J8: =J$4+Q7*G$13 -> 26.907523 | K8: ='Nr(V)'!B56 -> 35149.962 | L8: =K8/J8 -> 1306.3247 | M8: =V8 -> 4.3201011 | N8: =S8 -> 4.8408461 | O8: =J8*SIN(RADIANS(N8)) -> 2.270678 | P8: =(K8/1000)/(O8*3600) -> 0.0042999836 | Q8: 5 | R8: =0.5*G$8*C$5*C$3*(U8-C$6)*J8^2+K8/J8*SIN(U8-C$1)-C$12*(C$14+G$11*(J$18-J8)/(J$18-J$4))*COS(T8) -> 0.00018341632 | S8: =DEGREES(T8) -> 4.8408461 | T8: 0.084488703 | U8: 0.075399988 | V8: =DEGREES(U8) -> 4.3201011 | W8: =-0.5*G$8*C$5*J8^2*(C$8+(C$3^2)*(U8-C$6)^2/(PI()*C$7))+K8/J8*COS(U8-C$1)-C$12*(C$14+G$11*(J$18-J8)/(J$18-J$4))*SIN(T8) -> 2.2190786e-05 | X8: =Q8 -> 5
A9: Obroty silnika | B9: ns | C9: =Podsumowanie!B12 -> 36.667 | D9: 1/s | F9: Nh | G9: =C$4*((G8/C$11)-C$10)/(1-C$10) -> 59000 | H9: W | J9: =J$4+Q8*G$13 -> 28.516771 | K9: ='Nr(V)'!B59 -> 36324.992 | L9: =K9/J9 -> 1273.8116 | M9: =V9 -> 3.3859258 | N9: =S9 -> 4.6283772 | O9: =J9*SIN(RADIANS(N9)) -> 2.3010922 | P9: =(K9/1000)/(O9*3600) -> 0.004384994 | Q9: 6 | R9: =0.5*G$8*C$5*C$3*(U9-C$6)*J9^2+K9/J9*SIN(U9-C$1)-C$12*(C$14+G$11*(J$18-J9)/(J$18-J$4))*COS(T9) -> 9.5606437e-05 | S9: =DEGREES(T9) -> 4.6283772 | T9: 0.080780421 | U9: 0.059095554 | V9: =DEGREES(U9) -> 3.3859258 | W9: =-0.5*G$8*C$5*J9^2*(C$8+(C$3^2)*(U9-C$6)^2/(PI()*C$7))+K9/J9*COS(U9-C$1)-C$12*(C$14+G$11*(J$18-J9)/(J$18-J$4))*SIN(T9) -> 1.0381259e-05 | X9: =Q9 -> 6
A10: współczynnik korekcyjny | B10: k | C10: =Podsumowanie!B18 -> 0.14 | D10: - | F10: CN | G10: =G9/G8/C$9^3/C$2^5 -> 0.051683276 | H10: - | J10: =J$4+Q9*G$13 -> 30.126019 | K10: ='Nr(V)'!B62 -> 37500.113 | L10: =K10/J10 -> 1244.7749 | M10: =V10 -> 2.5958092 | N10: =S10 -> 4.3549428 | O10: =J10*SIN(RADIANS(N10)) -> 2.287617 | P10: =(K10/1000)/(O10*3600) -> 0.0045535149 | Q10: 7 | R10: =0.5*G$8*C$5*C$3*(U10-C$6)*J10^2+K10/J10*SIN(U10-C$1)-C$12*(C$14+G$11*(J$18-J10)/(J$18-J$4))*COS(T10) -> 2.6192611e-05 | S10: =DEGREES(T10) -> 4.3549428 | T10: 0.07600809 | U10: 0.045305417 | V10: =DEGREES(U10) -> 2.5958092 | W10: =-0.5*G$8*C$5*J10^2*(C$8+(C$3^2)*(U10-C$6)^2/(PI()*C$7))+K10/J10*COS(U10-C$1)-C$12*(C$14+G$11*(J$18-J10)/(J$18-J$4))*SIN(T10) -> 2.5815343e-06 | X10: =Q10 -> 7
A11: gęstość powietrza przy ziemii | B11: ρ | C11: =Podsumowanie!B2 -> 1.2255 | D11: kg/m3 | F11: mp | G11: =C13 -> 90 | H11: kg | J11: =J$4+Q10*G$13 -> 31.735266 | K11: ='Nr(V)'!B66 -> 38850.938 | L11: =K11/J11 -> 1224.2197 | M11: =V11 -> 1.92172 | N11: =S11 -> 4.076156 | O11: =J11*SIN(RADIANS(N11)) -> 2.2558172 | P11: =(K11/1000)/(O11*3600) -> 0.0047840433 | Q11: 8 | R11: =0.5*G$8*C$5*C$3*(U11-C$6)*J11^2+K11/J11*SIN(U11-C$1)-C$12*(C$14+G$11*(J$18-J11)/(J$18-J$4))*COS(T11) -> -3.4106051e-10 | S11: =DEGREES(T11) -> 4.076156 | T11: 0.071142344 | U11: 0.033540341 | V11: =DEGREES(U11) -> 1.92172 | W11: =-0.5*G$8*C$5*J11^2*(C$8+(C$3^2)*(U11-C$6)^2/(PI()*C$7))+K11/J11*COS(U11-C$1)-C$12*(C$14+G$11*(J$18-J11)/(J$18-J$4))*SIN(T11) -> -6.5369932e-12 | X11: =Q11 -> 8
A12: Przyspieszenie grawitacyjne | B12: g | C12: =Podsumowanie!B1 -> 9.81 | D12: m/s2 | F12: dmp | G12: {=C$16*(G25-G7)*MIN(IF(P4:P18>0,P4:P18))} -> 0.67342044 | H12: kg | J12: =J$4+Q11*G$13 -> 33.344514 | K12: ='Nr(V)'!B69 -> 39967.235 | L12: =K12/J12 -> 1198.615 | M12: =V12 -> 1.3433093 | N12: =S12 -> 3.6807826 | O12: =J12*SIN(RADIANS(N12)) -> 2.1406376 | P12: =(K12/1000)/(O12*3600) -> 0.0051863097 | Q12: 9 | R12: =0.5*G$8*C$5*C$3*(U12-C$6)*J12^2+K12/J12*SIN(U12-C$1)-C$12*(C$14+G$11*(J$18-J12)/(J$18-J$4))*COS(T12) -> 4.5642519e-06 | S12: =DEGREES(T12) -> 3.6807826 | T12: 0.064241775 | U12: 0.023445171 | V12: =DEGREES(U12) -> 1.3433093 | W12: =-0.5*G$8*C$5*J12^2*(C$8+(C$3^2)*(U12-C$6)^2/(PI()*C$7))+K12/J12*COS(U12-C$1)-C$12*(C$14+G$11*(J$18-J12)/(J$18-J$4))*SIN(T12) -> 5.5568643e-07 | X12: =Q12 -> 9
A13: Masa paliwa | B13: mp | C13: =Podsumowanie!B5 -> 90 | D13: kg | F13: v | G13: =(J18-J4)/Q17 -> 1.6092477 | H13: m/s | J13: =J$4+Q12*G$13 -> 34.953762 | K13: ='Nr(V)'!B72 -> 41318.556 | L13: =K13/J13 -> 1182.0918 | M13: =V13 -> 0.84278363 | N13: =S13 -> 3.3009703 | O13: =J13*SIN(RADIANS(N13)) -> 2.0126702 | P13: =(K13/1000)/(O13*3600) -> 0.0057025619 | Q13: 10 | R13: =0.5*G$8*C$5*C$3*(U13-C$6)*J13^2+K13/J13*SIN(U13-C$1)-C$12*(C$14+G$11*(J$18-J13)/(J$18-J$4))*COS(T13) -> 2.9588837e-06 | S13: =DEGREES(T13) -> 3.3009703 | T13: 0.057612801 | U13: 0.014709349 | V13: =DEGREES(U13) -> 0.84278363 | W13: =-0.5*G$8*C$5*J13^2*(C$8+(C$3^2)*(U13-C$6)^2/(PI()*C$7))+K13/J13*COS(U13-C$1)-C$12*(C$14+G$11*(J$18-J13)/(J$18-J$4))*SIN(T13) -> 4.2920408e-07 | X13: =Q13 -> 10
A14: Miminalna masa samolotu | B14: mmin | C14: =Podsumowanie!B7 -> 620 | D14: kg | J14: =J$4+Q13*G$13 -> 36.563009 | K14: ='Nr(V)'!B75 -> 42611.279 | L14: =K14/J14 -> 1165.4204 | M14: =V14 -> 0.40738283 | N14: =S14 -> 2.8593773 | O14: =J14*SIN(RADIANS(N14)) -> 1.8239397 | P14: =(K14/1000)/(O14*3600) -> 0.0064895052 | Q14: 11 | R14: =0.5*G$8*C$5*C$3*(U14-C$6)*J14^2+K14/J14*SIN(U14-C$1)-C$12*(C$14+G$11*(J$18-J14)/(J$18-J$4))*COS(T14) -> 7.1600507e-06 | S14: =DEGREES(T14) -> 2.8593773 | T14: 0.049905549 | U14: 0.0071101717 | V14: =DEGREES(U14) -> 0.40738283 | W14: =-0.5*G$8*C$5*J14^2*(C$8+(C$3^2)*(U14-C$6)^2/(PI()*C$7))+K14/J14*COS(U14-C$1)-C$12*(C$14+G$11*(J$18-J14)/(J$18-J$4))*SIN(T14) -> 5.7546333e-07 | X14: =Q14 -> 11
A15: maksymalny współczynnik siły nośnej | B15: Czmax | C15: =Podsumowanie!B16 -> 1.507 | D15: - | J15: =J$4+Q14*G$13 -> 38.172257 | K15: ='Nr(V)'!B78 -> 43786.264 | L15: =K15/J15 -> 1147.0703 | M15: =V15 -> 0.026398948 | N15: =S15 -> 2.3452915 | O15: =J15*SIN(RADIANS(N15)) -> 1.5620709 | P15: =(K15/1000)/(O15*3600) -> 0.0077863628 | Q15: 12 | R15: =0.5*G$8*C$5*C$3*(U15-C$6)*J15^2+K15/J15*SIN(U15-C$1)-C$12*(C$14+G$11*(J$18-J15)/(J$18-J$4))*COS(T15) -> 2.2783788e-06 | S15: =DEGREES(T15) -> 2.3452915 | T15: 0.040933059 | U15: 0.00046074857 | V15: =DEGREES(U15) -> 0.026398948 | W15: =-0.5*G$8*C$5*J15^2*(C$8+(C$3^2)*(U15-C$6)^2/(PI()*C$7))+K15/J15*COS(U15-C$1)-C$12*(C$14+G$11*(J$18-J15)/(J$18-J$4))*SIN(T15) -> 2.0034514e-07 | X15: =Q15 -> 12
A16: Jednostkowe zużycie paliwa | B16: qe | C16: =Podsumowanie!B32 -> 0.31322 | D16: kg/kWh | J16: =J$4+Q15*G$13 -> 39.781505 | K16: ='Nr(V)'!B82 -> 44078.491 | L16: =K16/J16 -> 1108.0147 | M16: =V16 -> -0.30878163 | N16: =S16 -> 1.5850411 | O16: =J16*SIN(RADIANS(N16)) -> 1.1003826 | P16: =(K16/1000)/(O16*3600) -> 0.011127062 | Q16: 13 | R16: =0.5*G$8*C$5*C$3*(U16-C$6)*J16^2+K16/J16*SIN(U16-C$1)-C$12*(C$14+G$11*(J$18-J16)/(J$18-J$4))*COS(T16) -> 8.7362423e-08 | S16: =DEGREES(T16) -> 1.5850411 | T16: 0.027664186 | U16: -0.0053892561 | V16: =DEGREES(U16) -> -0.30878163 | W16: =-0.5*G$8*C$5*J16^2*(C$8+(C$3^2)*(U16-C$6)^2/(PI()*C$7))+K16/J16*COS(U16-C$1)-C$12*(C$14+G$11*(J$18-J16)/(J$18-J$4))*SIN(T16) -> 1.3235052e-08 | X16: =Q16 -> 13
J17: =J$4+Q16*G$13 -> 41.390752 | K17: ='Nr(V)'!B85 -> 42900.491 | L17: =K17/J17 -> 1036.4753 | M17: =V17 -> -0.60591224 | N17: =S17 -> 0.46549685 | O17: =J17*SIN(RADIANS(N17)) -> 0.33627351 | P17: =(K17/1000)/(O17*3600) -> 0.035437828 | Q17: 14 | R17: =0.5*G$8*C$5*C$3*(U17-C$6)*J17^2+K17/J17*SIN(U17-C$1)-C$12*(C$14+G$11*(J$18-J17)/(J$18-J$4))*COS(T17) -> -2.4155281e-05 | S17: =DEGREES(T17) -> 0.46549685 | T17: 0.0081244527 | U17: -0.010575164 | V17: =DEGREES(U17) -> -0.60591224 | W17: =-0.5*G$8*C$5*J17^2*(C$8+(C$3^2)*(U17-C$6)^2/(PI()*C$7))+K17/J17*COS(U17-C$1)-C$12*(C$14+G$11*(J$18-J17)/(J$18-J$4))*SIN(T17) -> 6.7705725e-06 | X17: =Q17 -> 14
J18: 43 | K18: ='Nr(V)'!B88 -> 41193.123 | L18: =K18/J18 -> 957.9796 | M18: =V18 -> -0.87116654 | N18: =S18 -> -0.78102628 | O18: =J18*SIN(RADIANS(N18)) -> -0.58613549 | P18: =(K18/1000)/(O18*3600) -> -0.019521995 | Q18: 15 | R18: =0.5*G$8*C$5*C$3*(U18-C$6)*J18^2+K18/J18*SIN(U18-C$1)-C$12*(C$14+G$11*(J$18-J18)/(J$18-J$4))*COS(T18) -> -5.566964e-05 | S18: =DEGREES(T18) -> -0.78102628 | T18: -0.01363148 | U18: -0.015204724 | V18: =DEGREES(U18) -> -0.87116654 | W18: =-0.5*G$8*C$5*J18^2*(C$8+(C$3^2)*(U18-C$6)^2/(PI()*C$7))+K18/J18*COS(U18-C$1)-C$12*(C$14+G$11*(J$18-J18)/(J$18-J$4))*SIN(T18) -> 2.4851379e-06 | X18: =Q18 -> 15
J20: Metoda ciągu, zmienna masa, h=500m,
J21: V [m/s] | K21: Nr [W] | L21: Ps [N] | M21: α [°] | N21: γ [°] | O21: w [m/s] | P21: Nr/w | R21: γ | S21: [°] | T21: [rad] | U21: [rad] | V21: [°] | W21: α
J22: =SQRT(2*(C$14+G29)*C$12/C$5/C$15/G26) -> 20.961063 | K22: ='Nr(V)'!C44 -> 28685.224 | L22: =K22/J22 -> 1368.5005 | M22: =V22 -> 10.476854 | N22: =S22 -> 3.8305175 | O22: =J22*SIN(RADIANS(N22)) -> 1.4003112 | P22: =(K22/1000)/(O22*3600) -> 0.005690248 | Q22: 1 | R22: =0.5*G$26*C$5*C$3*(U22-C$6)*J22^2+K22/J22*SIN(U22-C$1)-C$12*(C$14+G$29*(J$36-J22)/(J$36-J$22))*COS(T22) -> 3.9652159e-06 | S22: =DEGREES(T22) -> 3.8305175 | T22: 0.066855143 | U22: 0.1828556 | V22: =DEGREES(U22) -> 10.476854 | W22: =-0.5*G$26*C$5*J22^2*(C$8+(C$3^2)*(U22-C$6)^2/(PI()*C$7))+K22/J22*COS(U22-C$1)-C$12*(C$14+G$29*(J$36-J22)/(J$36-J$22))*SIN(T22) -> -9.527157e-06 | X22: =Q22 -> 1
J23: =J$22+Q22*G$31 -> 22.535273 | K23: ='Nr(V)'!C47 -> 29624.916 | L23: =K23/J23 -> 1314.602 | M23: =V23 -> 8.5300715 | N23: =S23 -> 3.9862945 | O23: =J23*SIN(RADIANS(N23)) -> 1.5666037 | P23: =(K23/1000)/(O23*3600) -> 0.0052528558 | Q23: 2 | R23: =0.5*G$26*C$5*C$3*(U23-C$6)*J23^2+K23/J23*SIN(U23-C$1)-C$12*(C$14+G$29*(J$36-J23)/(J$36-J$22))*COS(T23) -> 5.4117014e-05 | S23: =DEGREES(T23) -> 3.9862945 | T23: 0.069573964 | U23: 0.14887783 | V23: =DEGREES(U23) -> 8.5300715 | W23: =-0.5*G$26*C$5*J23^2*(C$8+(C$3^2)*(U23-C$6)^2/(PI()*C$7))+K23/J23*COS(U23-C$1)-C$12*(C$14+G$29*(J$36-J23)/(J$36-J$22))*SIN(T23) -> 1.0079528e-05 | X23: =Q23 -> 2
J24: =J$22+Q23*G$31 -> 24.109483 | K24: ='Nr(V)'!C50 -> 30505.918 | L24: =K24/J24 -> 1265.3079 | M24: =V24 -> 6.9363877 | N24: =S24 -> 4.0044537 | O24: =J24*SIN(RADIANS(N24)) -> 1.683662 | P24: =(K24/1000)/(O24*3600) -> 0.0050329972 | Q24: 3 | R24: =0.5*G$26*C$5*C$3*(U24-C$6)*J24^2+K24/J24*SIN(U24-C$1)-C$12*(C$14+G$29*(J$36-J24)/(J$36-J$22))*COS(T24) -> 4.3592627e-07 | S24: =DEGREES(T24) -> 4.0044537 | T24: 0.069890902 | U24: 0.1210628 | V24: =DEGREES(U24) -> 6.9363877 | W24: =-0.5*G$26*C$5*J24^2*(C$8+(C$3^2)*(U24-C$6)^2/(PI()*C$7))+K24/J24*COS(U24-C$1)-C$12*(C$14+G$29*(J$36-J24)/(J$36-J$22))*SIN(T24) -> 7.3345063e-09 | X24: =Q24 -> 3
F25: h | G25: 500 | H25: m | J25: =J$22+Q24*G$31 -> 25.683692 | K25: ='Nr(V)'!C53 -> 31857.284 | L25: =K25/J25 -> 1240.3701 | M25: =V25 -> 5.6132989 | N25: =S25 -> 4.0886767 | O25: =J25*SIN(RADIANS(N25)) -> 1.8312555 | P25: =(K25/1000)/(O25*3600) -> 0.0048323381 | Q25: 4 | R25: =0.5*G$26*C$5*C$3*(U25-C$6)*J25^2+K25/J25*SIN(U25-C$1)-C$12*(C$14+G$29*(J$36-J25)/(J$36-J$22))*COS(T25) -> 1.2485543e-08 | S25: =DEGREES(T25) -> 4.0886767 | T25: 0.07136087 | U25: 0.097970548 | V25: =DEGREES(U25) -> 5.6132989 | W25: =-0.5*G$26*C$5*J25^2*(C$8+(C$3^2)*(U25-C$6)^2/(PI()*C$7))+K25/J25*COS(U25-C$1)-C$12*(C$14+G$29*(J$36-J25)/(J$36-J$22))*SIN(T25) -> -4.0756731e-11 | X25: =Q25 -> 4
F26: ρh | G26: =C$11*(1-G25/44300)^4.256 -> 1.1677043 | H26: kg/m3 | J26: =J$22+Q25*G$31 -> 27.257902 | K26: ='Nr(V)'!C57 -> 33384.851 | L26: =K26/J26 -> 1224.777 | M26: =V26 -> 4.5077994 | N26: =S26 -> 4.1363193 | O26: =J26*SIN(RADIANS(N26)) -> 1.9661043 | P26: =(K26/1000)/(O26*3600) -> 0.0047167232 | Q26: 5 | R26: =0.5*G$26*C$5*C$3*(U26-C$6)*J26^2+K26/J26*SIN(U26-C$1)-C$12*(C$14+G$29*(J$36-J26)/(J$36-J$22))*COS(T26) -> 9.2899424e-05 | S26: =DEGREES(T26) -> 4.1363193 | T26: 0.072192391 | U26: 0.078675941 | V26: =DEGREES(U26) -> 4.5077994 | W26: =-0.5*G$26*C$5*J26^2*(C$8+(C$3^2)*(U26-C$6)^2/(PI()*C$7))+K26/J26*COS(U26-C$1)-C$12*(C$14+G$29*(J$36-J26)/(J$36-J$22))*SIN(T26) -> 1.1234613e-05 | X26: =Q26 -> 5
F27: Nh | G27: =C$4*((G26/C$11)-C$10)/(1-C$10) -> 55764.541 | H27: W | J27: =J$22+Q26*G$31 -> 28.832112 | K27: ='Nr(V)'!C60 -> 34736.352 | L27: =K27/J27 -> 1204.78 | M27: =V27 -> 3.5776357 | N27: =S27 -> 4.0468047 | O27: =J27*SIN(RADIANS(N27)) -> 2.0347213 | P27: =(K27/1000)/(O27*3600) -> 0.0047421663 | Q27: 6 | R27: =0.5*G$26*C$5*C$3*(U27-C$6)*J27^2+K27/J27*SIN(U27-C$1)-C$12*(C$14+G$29*(J$36-J27)/(J$36-J$22))*COS(T27) -> -7.8307494e-10 | S27: =DEGREES(T27) -> 4.0468047 | T27: 0.070630067 | U27: 0.062441523 | V27: =DEGREES(U27) -> 3.5776357 | W27: =-0.5*G$26*C$5*J27^2*(C$8+(C$3^2)*(U27-C$6)^2/(PI()*C$7))+K27/J27*COS(U27-C$1)-C$12*(C$14+G$29*(J$36-J27)/(J$36-J$22))*SIN(T27) -> -1.1425527e-11 | X27: =Q27 -> 6
F28: CN | G28: =G27/G26/C$9^3/C$2^5 -> 0.051266846 | H28: - | J28: =J$22+Q27*G$31 -> 30.406322 | K28: ='Nr(V)'!C63 -> 35676.043 | L28: =K28/J28 -> 1173.3101 | M28: =V28 -> 2.7886917 | N28: =S28 -> 3.7706061 | O28: =J28*SIN(RADIANS(N28)) -> 1.9995805 | P28: =(K28/1000)/(O28*3600) -> 0.0049560456 | Q28: 7 | R28: =0.5*G$26*C$5*C$3*(U28-C$6)*J28^2+K28/J28*SIN(U28-C$1)-C$12*(C$14+G$29*(J$36-J28)/(J$36-J$22))*COS(T28) -> 2.9514556e-05 | S28: =DEGREES(T28) -> 3.7706061 | T28: 0.06580949 | U28: 0.048671852 | V28: =DEGREES(U28) -> 2.7886917 | W28: =-0.5*G$26*C$5*J28^2*(C$8+(C$3^2)*(U28-C$6)^2/(PI()*C$7))+K28/J28*COS(U28-C$1)-C$12*(C$14+G$29*(J$36-J28)/(J$36-J$22))*SIN(T28) -> 2.9668087e-06 | X28: =Q28 -> 7
F29: mp | G29: =G11-G12 -> 89.32658 | H29: kg | J29: =J$22+Q28*G$31 -> 31.980532 | K29: ='Nr(V)'!C66 -> 36674.603 | L29: =K29/J29 -> 1146.779 | M29: =V29 -> 2.1125423 | N29: =S29 -> 3.4610325 | O29: =J29*SIN(RADIANS(N29)) -> 1.9306545 | P29: =(K29/1000)/(O29*3600) -> 0.0052766507 | Q29: 8 | R29: =0.5*G$26*C$5*C$3*(U29-C$6)*J29^2+K29/J29*SIN(U29-C$1)-C$12*(C$14+G$29*(J$36-J29)/(J$36-J$22))*COS(T29) -> 3.588284e-06 | S29: =DEGREES(T29) -> 3.4610325 | T29: 0.060406412 | U29: 0.036870819 | V29: =DEGREES(U29) -> 2.1125423 | W29: =-0.5*G$26*C$5*J29^2*(C$8+(C$3^2)*(U29-C$6)^2/(PI()*C$7))+K29/J29*COS(U29-C$1)-C$12*(C$14+G$29*(J$36-J29)/(J$36-J$22))*SIN(T29) -> 3.665362e-07 | X29: =Q29 -> 8
F30: dmp | G30: {=C$16*(G43-G25)*MIN(IF(P22:P36>0,P22:P36))} -> 0.73868602 | H30: kg | J30: =J$22+Q29*G$31 -> 33.554741 | K30: ='Nr(V)'!C69 -> 37614.384 | L30: =K30/J30 -> 1120.9857 | M30: =V30 -> 1.529323 | N30: =S30 -> 3.0890406 | O30: =J30*SIN(RADIANS(N30)) -> 1.8081917 | P30: =(K30/1000)/(O30*3600) -> 0.0057783918 | Q30: 9 | R30: =0.5*G$26*C$5*C$3*(U30-C$6)*J30^2+K30/J30*SIN(U30-C$1)-C$12*(C$14+G$29*(J$36-J30)/(J$36-J$22))*COS(T30) -> 1.1177699e-05 | S30: =DEGREES(T30) -> 3.0890406 | T30: 0.053913929 | U30: 0.026691722 | V30: =DEGREES(U30) -> 1.529323 | W30: =-0.5*G$26*C$5*J30^2*(C$8+(C$3^2)*(U30-C$6)^2/(PI()*C$7))+K30/J30*COS(U30-C$1)-C$12*(C$14+G$29*(J$36-J30)/(J$36-J$22))*SIN(T30) -> 1.0097273e-06 | X30: =Q30 -> 9
F31: v | G31: =(J36-J22)/Q35 -> 1.5742098 | H31: m/s | J31: =J$22+Q30*G$31 -> 35.128951 | K31: ='Nr(V)'!C72 -> 38906.972 | L31: =K31/J31 -> 1107.5472 | M31: =V31 -> 1.0225517 | N31: =S31 -> 2.7649921 | O31: =J31*SIN(RADIANS(N31)) -> 1.6946026 | P31: =(K31/1000)/(O31*3600) -> 0.0063775967 | Q31: 10 | R31: =0.5*G$26*C$5*C$3*(U31-C$6)*J31^2+K31/J31*SIN(U31-C$1)-C$12*(C$14+G$29*(J$36-J31)/(J$36-J$22))*COS(T31) -> 2.3515304e-06 | S31: =DEGREES(T31) -> 2.7649921 | T31: 0.048258217 | U31: 0.017846894 | V31: =DEGREES(U31) -> 1.0225517 | W31: =-0.5*G$26*C$5*J31^2*(C$8+(C$3^2)*(U31-C$6)^2/(PI()*C$7))+K31/J31*COS(U31-C$1)-C$12*(C$14+G$29*(J$36-J31)/(J$36-J$22))*SIN(T31) -> 3.2073478e-07 | X31: =Q31 -> 10
J32: =J$22+Q31*G$31 -> 36.703161 | K32: ='Nr(V)'!C75 -> 40199.469 | L32: =K32/J32 -> 1095.259 | M32: =V32 -> 0.58016523 | N32: =S32 -> 2.3942559 | O32: =J32*SIN(RADIANS(N32)) -> 1.5332925 | P32: =(K32/1000)/(O32*3600) -> 0.0072827066 | Q32: 11 | R32: =0.5*G$26*C$5*C$3*(U32-C$6)*J32^2+K32/J32*SIN(U32-C$1)-C$12*(C$14+G$29*(J$36-J32)/(J$36-J$22))*COS(T32) -> 7.3431056e-07 | S32: =DEGREES(T32) -> 2.3942559 | T32: 0.041787649 | U32: 0.010125794 | V32: =DEGREES(U32) -> 0.58016523 | W32: =-0.5*G$26*C$5*J32^2*(C$8+(C$3^2)*(U32-C$6)^2/(PI()*C$7))+K32/J32*COS(U32-C$1)-C$12*(C$14+G$29*(J$36-J32)/(J$36-J$22))*SIN(T32) -> 1.1933651e-07 | X32: =Q32 -> 11
J33: =J$22+Q32*G$31 -> 38.277371 | K33: ='Nr(V)'!C79 -> 41609.433 | L33: =K33/J33 -> 1087.0505 | M33: =V33 -> 0.19180301 | N33: =S33 -> 2.0071978 | O33: =J33*SIN(RADIANS(N33)) -> 1.3406666 | P33: =(K33/1000)/(O33*3600) -> 0.0086212157 | Q33: 12 | R33: =0.5*G$26*C$5*C$3*(U33-C$6)*J33^2+K33/J33*SIN(U33-C$1)-C$12*(C$14+G$29*(J$36-J33)/(J$36-J$22))*COS(T33) -> 1.7159537e-06 | S33: =DEGREES(T33) -> 2.0071978 | T33: 0.035032209 | U33: 0.0033475941 | V33: =DEGREES(U33) -> 0.19180301 | W33: =-0.5*G$26*C$5*J33^2*(C$8+(C$3^2)*(U33-C$6)^2/(PI()*C$7))+K33/J33*COS(U33-C$1)-C$12*(C$14+G$29*(J$36-J33)/(J$36-J$22))*SIN(T33) -> 1.7124557e-07 | X33: =Q33 -> 12
J34: =J$22+Q33*G$31 -> 39.85158 | K34: ='Nr(V)'!C82 -> 41607.813 | L34: =K34/J34 -> 1044.0693 | M34: =V34 -> -0.15070426 | N34: =S34 -> 1.2485077 | O34: =J34*SIN(RADIANS(N34)) -> 0.86831996 | P34: =(K34/1000)/(O34*3600) -> 0.013310446 | Q34: 13 | R34: =0.5*G$26*C$5*C$3*(U34-C$6)*J34^2+K34/J34*SIN(U34-C$1)-C$12*(C$14+G$29*(J$36-J34)/(J$36-J$22))*COS(T34) -> 6.2448453e-07 | S34: =DEGREES(T34) -> 1.2485077 | T34: 0.021790571 | U34: -0.0026302855 | V34: =DEGREES(U34) -> -0.15070426 | W34: =-0.5*G$26*C$5*J34^2*(C$8+(C$3^2)*(U34-C$6)^2/(PI()*C$7))+K34/J34*COS(U34-C$1)-C$12*(C$14+G$29*(J$36-J34)/(J$36-J$22))*SIN(T34) -> 5.8993606e-08 | X34: =Q34 -> 13
J35: =J$22+Q34*G$31 -> 41.42579 | K35: ='Nr(V)'!C85 -> 40724.11 | L35: =K35/J35 -> 983.06175 | M35: =V35 -> -0.45513211 | N35: =S35 -> 0.26734524 | O35: =J35*SIN(RADIANS(N35)) -> 0.1932943 | P35: =(K35/1000)/(O35*3600) -> 0.058523467 | Q35: 14 | R35: =0.5*G$26*C$5*C$3*(U35-C$6)*J35^2+K35/J35*SIN(U35-C$1)-C$12*(C$14+G$29*(J$36-J35)/(J$36-J$22))*COS(T35) -> 4.5274646e-09 | S35: =DEGREES(T35) -> 0.26734524 | T35: 0.0046660548 | U35: -0.0079435538 | V35: =DEGREES(U35) -> -0.45513211 | W35: =-0.5*G$26*C$5*J35^2*(C$8+(C$3^2)*(U35-C$6)^2/(PI()*C$7))+K35/J35*COS(U35-C$1)-C$12*(C$14+G$29*(J$36-J35)/(J$36-J$22))*SIN(T35) -> -2.3138824e-11 | X35: =Q35 -> 14
J36: =J18 -> 43 | K36: ='Nr(V)'!C88 -> 39369.594 | L36: =K36/J36 -> 915.57194 | M36: =V36 -> -0.72731147 | N36: =S36 -> -0.83165417 | O36: =J36*SIN(RADIANS(N36)) -> -0.62412754 | P36: =(K36/1000)/(O36*3600) -> -0.017522057 | Q36: 15 | R36: =0.5*G$26*C$5*C$3*(U36-C$6)*J36^2+K36/J36*SIN(U36-C$1)-C$12*(C$14+G$29*(J$36-J36)/(J$36-J$22))*COS(T36) -> -4.7646417e-05 | S36: =DEGREES(T36) -> -0.83165417 | T36: -0.014515104 | U36: -0.01269398 | V36: =DEGREES(U36) -> -0.72731147 | W36: =-0.5*G$26*C$5*J36^2*(C$8+(C$3^2)*(U36-C$6)^2/(PI()*C$7))+K36/J36*COS(U36-C$1)-C$12*(C$14+G$29*(J$36-J36)/(J$36-J$22))*SIN(T36) -> 1.3814785e-06 | X36: =Q36 -> 15
J38: Metoda ciągu, zmienna masa, h=1000m
J39: V [m/s] | K39: Nr [W] | L39: Ps [N] | M39: α [°] | N39: γ [°] | O39: w [m/s] | P39: Nr/w | R39: γ | S39: [°] | T39: [rad] | U39: [rad] | V39: [°] | W39: α
J40: =SQRT(2*(C$14+G47)*C$12/C$5/C$15/G44) -> 21.468303 | K40: ='Nr(V)'!D45 -> 27331.788 | L40: =K40/J40 -> 1273.1229 | M40: =V40 -> 10.520158 | N40: =S40 -> 3.030043 | O40: =J40*SIN(RADIANS(N40)) -> 1.1348055 | P40: =(K40/1000)/(O40*3600) -> 0.0066902773 | Q40: 1 | R40: =0.5*G$44*C$5*C$3*(U40-C$6)*J40^2+K40/J40*SIN(U40-C$1)-C$12*(C$14+G$47*(J$54-J40)/(J$54-J$40))*COS(T40) -> 0.00057037086 | S40: =DEGREES(T40) -> 3.030043 | T40: 0.052884227 | U40: 0.18361139 | V40: =DEGREES(U40) -> 10.520158 | W40: =-0.5*G$44*C$5*J40^2*(C$8+(C$3^2)*(U40-C$6)^2/(PI()*C$7))+K40/J40*COS(U40-C$1)-C$12*(C$14+G$47*(J$54-J40)/(J$54-J$40))*SIN(T40) -> 0.00012328854 | X40: =Q40 -> 1
J41: =J$40+Q40*G$49 -> 23.006281 | K41: ='Nr(V)'!D48 -> 28212.656 | L41: =K41/J41 -> 1226.3023 | M41: =V41 -> 8.6383635 | N41: =S41 -> 3.2241706 | O41: =J41*SIN(RADIANS(N41)) -> 1.2939354 | P41: =(K41/1000)/(O41*3600) -> 0.0060566 | Q41: 2 | R41: =0.5*G$44*C$5*C$3*(U41-C$6)*J41^2+K41/J41*SIN(U41-C$1)-C$12*(C$14+G$47*(J$54-J41)/(J$54-J$40))*COS(T41) -> 3.904926e-05 | S41: =DEGREES(T41) -> 3.2241706 | T41: 0.056272393 | U41: 0.15076789 | V41: =DEGREES(U41) -> 8.6383635 | W41: =-0.5*G$44*C$5*J41^2*(C$8+(C$3^2)*(U41-C$6)^2/(PI()*C$7))+K41/J41*COS(U41-C$1)-C$12*(C$14+G$47*(J$54-J41)/(J$54-J$40))*SIN(T41) -> 9.2026027e-06 | X41: =Q41 -> 2
J42: =J$40+Q41*G$49 -> 24.54426 | K42: ='Nr(V)'!D51 -> 29328.818 | L42: =K42/J42 -> 1194.9359 | M42: =V42 -> 7.0829124 | N42: =S42 -> 3.3867457 | O42: =J42*SIN(RADIANS(N42)) -> 1.4499631 | P42: =(K42/1000)/(O42*3600) -> 0.0056186903 | Q42: 3 | R42: =0.5*G$44*C$5*C$3*(U42-C$6)*J42^2+K42/J42*SIN(U42-C$1)-C$12*(C$14+G$47*(J$54-J42)/(J$54-J$40))*COS(T42) -> 8.1380001e-05 | S42: =DEGREES(T42) -> 3.3867457 | T42: 0.059109863 | U42: 0.12362014 | V42: =DEGREES(U42) -> 7.0829124 | W42: =-0.5*G$44*C$5*J42^2*(C$8+(C$3^2)*(U42-C$6)^2/(PI()*C$7))+K42/J42*COS(U42-C$1)-C$12*(C$14+G$47*(J$54-J42)/(J$54-J$40))*SIN(T42) -> 1.3725068e-05 | X42: =Q42 -> 3
...

Sheet Nr(V)
A1: h | B1: 0 | C1: 500 | D1: 1000 | E1: 1500 | F1: 2000 | G1: 2500 | H1: 3000 | I1: 3500 | J1: 4000 | K1: 4500
A2: 0 | B2: 0 | C2: 0 | D2: 0 | E2: 0 | F2: 0 | G2: 0 | H2: 0 | I2: 0 | J2: 0 | K2: 0
A3: 0.5 | B3: 587.78523 | C3: 822.98933 | D3: 764.25582 | E3: 646.60876 | F3: 528.87169 | G3: 470.18318 | H3: 705.34227 | I3: 587.78523 | J3: 293.71259 | K3: 705.29727 | M3: V | N3: mmax | O3: mśr | P3: zmien | Q3: zmien, h | R3: mmin
A4: 1 | B4: 1469.6431 | C4: 1646.0687 | D4: 1351.951 | E4: 1410.8196 | F4: 1057.8784 | G4: 1351.951 | H4: 1351.951 | I4: 1116.7019 | J4: 940.18633 | K4: 1116.7019 | M4: 0 | N4: 100 | O4: 50 | P4: 100 | Q4: 90 | R4: 0
A5: 1.5 | B5: 2527.9265 | C5: 2410.1895 | D5: 2116.1618 | E5: 2116.1618 | F5: 1822.0442 | G5: 1998.5598 | H5: 1998.3348 | I5: 1645.6186 | J5: 1527.9265 | K5: 1469.238 | M5: 100 | N5: 100 | O5: 50 | P5: 0 | Q5: 0 | R5: 0
A6: 2 | B6: 3233.3588 | C6: 3056.8432 | D6: 2821.5941 | E6: 2586.3 | F6: 2409.7844 | G6: 2527.4315 | H6: 2409.7394 | I6: 1998.0197 | J6: 1997.9747 | K6: 2056.8432
A7: 2.5 | B7: 4115.2167 | C7: 3879.8326 | D7: 3762.1855 | E7: 3291.5973 | F7: 3291.5973 | G7: 3173.9952 | H7: 2821.0991 | I7: 2468.0679 | J7: 2350.4658 | K7: 2526.9814
A8: 3 | B8: 4879.4275 | C8: 4350.0158 | D8: 4408.7493 | E8: 3820.604 | F8: 3702.9119 | G8: 3761.6904 | H8: 3291.1922 | I8: 2997.0296 | J8: 2702.9569 | K8: 2938.161
A9: 3.5 | B9: 5702.3718 | C9: 5290.6972 | D9: 5290.6521 | E9: 4408.3892 | F9: 4408.2992 | G9: 4290.6521 | H9: 3878.8874 | I9: 3643.6833 | J9: 3173.0501 | K9: 3290.7422
A10: 4 | B10: 6407.8041 | C10: 6231.2885 | D10: 6113.6865 | E10: 5466.5827 | F10: 4878.3924 | G10: 4878.4824 | H10: 4290.2471 | I10: 4113.7765 | J10: 3701.8768 | K10: 3819.6589
A11: 4.5 | B11: 6995.6794 | C11: 6936.7208 | D11: 6819.0738 | E11: 6054.4129 | F11: 5583.8697 | G11: 5466.1326 | H11: 5054.3679 | I11: 4642.6032 | J11: 4113.2814 | K11: 4230.8835
A12: 5 | B12: 7936.2708 | C12: 7524.5511 | D12: 7406.904 | E12: 6759.8002 | F12: 6348.0355 | G12: 5936.3608 | H12: 5465.6825 | I12: 4995.1393 | J12: 4700.9766 | K12: 4583.3296
A13: 5.5 | B13: 8759.2601 | C13: 8347.4504 | D13: 8112.2463 | E13: 7465.1424 | F13: 6876.9972 | G13: 6582.7895 | H13: 5935.8207 | I13: 5465.2325 | J13: 5171.0698 | K13: 4876.9072
A14: 6 | B14: 9288.2668 | C14: 9052.9727 | D14: 8582.3844 | E14: 7935.3256 | F14: 7464.6924 | G14: 7111.7062 | H14: 6582.3394 | I14: 5994.1041 | J14: 5876.4121 | K14: 5170.6647
A15: 6.5 | B15: 10052.433 | C15: 9817.1385 | D15: 9228.8582 | E15: 8640.6229 | F15: 7993.6991 | G15: 7699.4914 | H15: 7111.2111 | I15: 6758.2699 | J15: 6346.5052 | K15: 5640.6229
A16: 7 | B16: 11287.187 | C16: 10404.879 | D16: 10051.983 | E16: 9228.4531 | F16: 8816.5984 | G16: 8404.8337 | H16: 7581.3943 | I16: 7287.2316 | J16: 6934.2005 | K16: 6404.9237
A17: 7.5 | B17: 12169.135 | C17: 11110.311 | D17: 10874.927 | E17: 10227.868 | F17: 9463.2522 | G17: 8933.8404 | H17: 8345.6051 | I17: 7933.7504 | J17: 7404.4736 | K17: 6816.2384
... A114: 56 | B114: 14297.988 | C114: 13533.282 | D114: 12650.974 | E114: 12180.386 | F114: 11474.504 | G114: 10827.445 | H114: 10356.857 | I114: 9945.092 | J114: 9180.3411 | K114: 8650.9744

Sheet h=0m
A1: wysokość lotu | B1: h | C1: 0 | D1: m | I1: Metoda ciągu, m=mśr, h=0m | P1: ='Nr(V)'!A1 -> h | Q1: ='Nr(V)'!B1 -> 0
A2: Ciężar maksymalny samolotu | B2: Qmax | C2: =Podsumowanie!B9 -> 6965.1 | D2: N | I2: V [m/s] | J2: Nr [W] | K2: Ps [N] | L2: α [°] | M2: γ [°] | N2: w [m/s] | P2: ='Nr(V)'!A2 -> 0 | Q2: ='Nr(V)'!B2 -> 0
A3: kąt pochylenia osi silnika fi | B3: φ | C3: =Podsumowanie!B30 -> 0.017453293 | D3: rad | I3: =SQRT(2*C$15/C$7/C$16/C17) -> 19.885539 | J3: =Q42 -> 29215.581 | K3: =J3/I3 -> 1469.1873 | L3: =OFFSET(D23,A23-2,0,1,1) -> 10.383333 | M3: =OFFSET(D22,A23-2,0,1,1) -> 5.4301575 | N3: =I3*SIN(RADIANS(M3)) -> 1.8818145 | P3: ='Nr(V)'!A3 -> 0.5 | Q3: ='Nr(V)'!B3 -> 587.78523
A4: średnica śmigła | B4: D | C4: =Podsumowanie!B13 -> 1.8 | D4: m | I4: 22 | J4: =Q46 -> 30919.618 | K4: =J4/I4 -> 1405.4372 | L4: =OFFSET(D24,A24-2,0,1,1) -> 7.9134634 | M4: =OFFSET(D23,A24-2,0,1,1) -> 5.4839101 | N4: =I4*SIN(RADIANS(M4)) -> 2.1024568 | P4: ='Nr(V)'!A4 -> 1 | Q4: ='Nr(V)'!B4 -> 1469.6431
A5: Współczynnik kierunkowy Cz(a) | B5: a∞ | C5: =Podsumowanie!B17 -> 5.832 | D5: 1/rad | I5: 24 | J5: =Q50 -> 32329.313 | K5: =J5/I5 -> 1347.0547 | L5: =OFFSET(D25,A25-2,0,1,1) -> 6.1189324 | M5: =OFFSET(D24,A25-2,0,1,1) -> 5.2932964 | N5: =I5*SIN(RADIANS(M5)) -> 2.2140981 | P5: ='Nr(V)'!A5 -> 1.5 | Q5: ='Nr(V)'!B5 -> 2527.9265
A6: Moc silnika | B6: Nmax | C6: =Podsumowanie!B10 -> 59000 | D6: W | I6: 26 | J6: =Q54 -> 34268.689 | K6: =J6/I6 -> 1318.0265 | L6: =OFFSET(D26,A26-2,0,1,1) -> 4.6972699 | M6: =OFFSET(D25,A26-2,0,1,1) -> 5.1754179 | N6: =I6*SIN(RADIANS(M6)) -> 2.3453378 | P6: ='Nr(V)'!A6 -> 2 | Q6: ='Nr(V)'!B6 -> 3233.3588
A7: Powierzchnia nośna | B7: S | C7: =Podsumowanie!B3 -> 18 | D7: m2 | I7: 28 | J7: =Q58 -> 35972.546 | K7: =J7/I7 -> 1284.7338 | L7: =OFFSET(D27,A27-2,0,1,1) -> 3.5593866 | M7: =OFFSET(D26,A27-2,0,1,1) -> 4.870519 | N7: =I7*SIN(RADIANS(M7)) -> 2.3773191 | P7: ='Nr(V)'!A7 -> 2.5 | Q7: ='Nr(V)'!B7 -> 4115.2167
A8: Kąt zerowej siły nośnej | B8: α0 | C8: =Podsumowanie!B31 -> -0.066601764 | D8: rad | I8: 30 | J8: =Q62 -> 37500.113 | K8: =J8/I8 -> 1250.0038 | L8: =OFFSET(D28,A28-2,0,1,1) -> 2.6343041 | M8: =OFFSET(D27,A28-2,0,1,1) -> 4.4331578 | N8: =I8*SIN(RADIANS(M8)) -> 2.3188807 | P8: ='Nr(V)'!A8 -> 3 | Q8: ='Nr(V)'!B8 -> 4879.4275
A9: masa samolotu | B9: m | C9: =Podsumowanie!B7 -> 620 | D9: kg | I9: 33 | J9: =Q68 -> 39673.613 | K9: =J9/I9 -> 1202.2307 | L9: =OFFSET(D29,A29-2,0,1,1) -> 1.5399967 | M9: =OFFSET(D28,A29-2,0,1,1) -> 3.6339571 | N9: =I9*SIN(RADIANS(M9)) -> 2.0916061 | P9: ='Nr(V)'!A9 -> 3.5 | Q9: ='Nr(V)'!B9 -> 5702.3718
A10: wydłużenie Oswalda | B10: Λe | C10: =Podsumowanie!B14 -> 4.587 | D10: - | I10: 36 | J10: =Q74 -> 42141.23 | K10: =J10/I10 -> 1170.5897 | L10: =OFFSET(D30,A30-2,0,1,1) -> 0.7002188 | M10: =OFFSET(D29,A30-2,0,1,1) -> 2.7981526 | N10: =I10*SIN(RADIANS(M10)) -> 1.7574324 | P10: ='Nr(V)'!A10 -> 4 | Q10: ='Nr(V)'!B10 -> 6407.8041
A11: Minimalny Cx z danych | B11: (Cx)min | C11: =Podsumowanie!B15 -> 0.04478 | D11: - | I11: 39 | J11: =Q80 -> 44197.039 | K11: =J11/I11 -> 1133.2574 | L11: =OFFSET(D31,A31-2,0,1,1) -> 0.04240908 | M11: =OFFSET(D30,A31-2,0,1,1) -> 1.763901 | N11: =I11*SIN(RADIANS(M11)) -> 1.2004597 | P11: ='Nr(V)'!A11 -> 4.5 | Q11: ='Nr(V)'!B11 -> 6995.6794
A12: Obroty silnika | B12: ns | C12: =Podsumowanie!B12 -> 36.667 | D12: 1/s | I12: 42 | J12: =Q86 -> 42370.629 | K12: =J12/I12 -> 1008.8245 | L12: =OFFSET(D32,A32-2,0,1,1) -> -0.483918 | M12: =OFFSET(D31,A32-2,0,1,1) -> -0.15747115 | N12: =I12*SIN(RADIANS(M12)) -> -0.11543224 | P12: ='Nr(V)'!A12 -> 5 | Q12: ='Nr(V)'!B12 -> 7936.2708
A13: współczynnik korekcyjny | B13: k | C13: =Podsumowanie!B18 -> 0.14 | D13: - | I13: 44 | J13: =Q90 -> 40192.268 | K13: =J13/I13 -> 913.46063 | L13: =OFFSET(D33,A33-2,0,1,1) -> -0.78009709 | M13: =OFFSET(D32,A33-2,0,1,1) -> -1.6100224 | N13: =I13*SIN(RADIANS(M13)) -> -1.2362457 | P13: ='Nr(V)'!A13 -> 5.5 | Q13: ='Nr(V)'!B13 -> 8759.2601
A14: gęstość powietrza przy ziemii | B14: ρ | C14: =Podsumowanie!B2 -> 1.2255 | D14: kg/m3 | I14: 46 | J14: =Q94 -> 37307.89 | K14: =J14/I14 -> 811.04108 | L14: =OFFSET(D34,A34-2,0,1,1) -> -1.0412817 | M14: =OFFSET(D33,A34-2,0,1,1) -> -3.1725646 | N14: =I14*SIN(RADIANS(M14)) -> -2.5457967 | P14: ='Nr(V)'!A14 -> 6 | Q14: ='Nr(V)'!B14 -> 9288.2668
A15: Ciężar samolotu | B15: Q | C15: =Podsumowanie!B8 -> 6572.7 | D15: N | I15: 48 | J15: =Q98 -> 34070.525 | K15: =J15/I15 -> 709.80261 | L15: =OFFSET(D35,A35-2,0,1,1) -> -1.2728928 | M15: =OFFSET(D34,A35-2,0,1,1) -> -4.7726776 | N15: =I15*SIN(RADIANS(M15)) -> -3.9937268 | P15: ='Nr(V)'!A15 -> 6.5 | Q15: ='Nr(V)'!B15 -> 10052.433
A16: maksymalny współczynnik siły nośnej | B16: Czmax | C16: =Podsumowanie!B16 -> 1.507 | D16: - | I16: 50 | J16: =Q102 -> 29715.694 | K16: =J16/I16 -> 594.31388 | L16: =OFFSET(D36,A36-2,0,1,1) -> -1.4802799 | M16: =OFFSET(D35,A36-2,0,1,1) -> -6.5447488 | N16: =I16*SIN(RADIANS(M16)) -> -5.6989586 | P16: ='Nr(V)'!A16 -> 7 | Q16: ='Nr(V)'!B16 -> 11287.187
A17: gęstość powietrza na wysokości h | B17: ρh | C17: =C14*(1-C1/44300)^4.256 -> 1.2255 | D17: kg/m3 | I17: 52 | J17: =Q106 -> 24772.492 | K17: =J17/I17 -> 476.39408 | L17: =OFFSET(D37,A37-2,0,1,1) -> -1.6667116 | M17: =OFFSET(D36,A37-2,0,1,1) -> -8.3869781 | N17: =I17*SIN(RADIANS(M17)) -> -7.5846258 | P17: ='Nr(V)'!A17 -> 7.5 | Q17: ='Nr(V)'!B17 -> 12169.135
A18: Moc na wysokości przelotowej | B18: Nh | C18: =C6*((C17/C14)-C13)/(1-C13) -> 59000 | D18: W | P18: ='Nr(V)'!A18 -> 8 | Q18: ='Nr(V)'!B18 -> 13168.594
A19: Współczynnik mocy | B19: CN | C19: =C18/C17/C12^3/C4^5 -> 0.051683276 | D19: - | P19: ='Nr(V)'!A19 -> 8.5 | Q19: ='Nr(V)'!B19 -> 14050.452
F20: Metoda mocy, m=mśr, h=0m | P20: ='Nr(V)'!A20 -> 9 | Q20: ='Nr(V)'!B20 -> 14638.238
B21: Równania | C21: Kąty [rad] | D21: Kąty [deg] | F21: Cz | G21: E | H21: V [m/s] | I21: Nn [W] | J21: Nr [W] | K21: ΔN [W] | L21: w [m/s] | M21: γ [°] | N21: α [°] | P21: ='Nr(V)'!A21 -> 9.5 | Q21: ='Nr(V)'!B21 -> 15461.227
A22: 1 | B22: =-K3*COS(C22+C23-C$3)+0.5*C$17*C$7*C$5*(C23-C$8)*I3^2*SIN(C22)+0.5*C$17*C$7*(C$11+1/PI()/C$10*C$5^2*(C23-C$8)^2)*I3^2*COS(C22) -> -1.3506076e-06 | C22: 0.094774126 | D22: =DEGREES(C22) -> 5.4301575 | F22: 1.507 | G22: 80.83 | H22: =SQRT((2*C$15)/(C$7*C$17*F22)) -> 19.885539 | I22: =C$15*SQRT((2*C$15)/(C$17*C$7*G22)) -> 17846.437 | J22: =Q42 -> 29215.581 | K22: =(J22-I22) -> 11369.145 | L22: =K22/C$15 -> 1.7297526 | M22: =DEGREES(ASIN(L22/H22)) -> 4.9902058 | N22: 13.202 | P22: ='Nr(V)'!A22 -> 10 | Q22: ='Nr(V)'!B22 -> 16049.057
A23: 2 | B23: =K3*SIN(C22+C23-C$3)+0.5*C$17*C$7*C$5*(C23-C$8)*I3^2*COS(C22)-0.5*C$17*C$7*(C$11+1/PI()/C$10*C$5^2*(C23-C$8)^2)*I3^2*SIN(C22)-C$15 -> 4.03179e-09 | C23: 0.18122335 | D23: =DEGREES(C23) -> 10.383333 | F23: 1.4 | G23: 82.93 | H23: =SQRT((2*C$15)/(C$7*C$17*F23)) -> 20.631461 | I23: =C$15*SQRT((2*C$15)/(C$17*C$7*G23)) -> 17619.029 | J23: =Q43 -> 29979.747 | K23: =(J23-I23) -> 12360.718 | L23: =K23/C$15 -> 1.880615 | M23: =DEGREES(ASIN(L23/H23)) -> 5.2299291 | N23: 11.19 | P23: ='Nr(V)'!A23 -> 10.5 | Q23: ='Nr(V)'!B23 -> 16872.046
A24: 3 | B24: =-K4*COS(C24+C25-C$3)+0.5*C$17*C$7*C$5*(C25-C$8)*I4^2*SIN(C24)+0.5*C$17*C$7*(C$11+1/PI()/C$10*C$5^2*(C25-C$8)^2)*I4^2*COS(C24) -> 1.124879e-07 | C24: 0.095712287 | D24: =DEGREES(C24) -> 5.4839101 | F24: 1.2976295 | G24: 83.61 | H24: =SQRT((2*C$15)/(C$7*C$17*F24)) -> 21.429826 | I24: =C$15*SQRT((2*C$15)/(C$17*C$7*G24)) -> 17547.235 | J24: =Q44 -> 30332.373 | K24: =(J24-I24) -> 12785.138 | L24: =K24/C$15 -> 1.9451882 | M24: =DEGREES(ASIN(L24/H24)) -> 5.2079139 | N24: 9.623 | P24: ='Nr(V)'!A24 -> 11 | Q24: ='Nr(V)'!B24 -> 17577.479
A25: 4 | B25: =K4*SIN(C24+C25-C$3)+0.5*C$17*C$7*C$5*(C25-C$8)*I4^2*COS(C24)-0.5*C$17*C$7*(C$11+1/PI()/C$10*C$5^2*(C25-C$8)^2)*I4^2*SIN(C24)-C$15 -> 0 | C25: 0.13811599 | D25: =DEGREES(C25) -> 7.9134634 | F25: 1.197 | G25: 82.42 | H25: =SQRT((2*C$15)/(C$7*C$17*F25)) -> 22.312432 | I25: =C$15*SQRT((2*C$15)/(C$17*C$7*G25)) -> 17673.457 | J25: =Q46 -> 30919.618 | K25: =(J25-I25) -> 13246.162 | L25: =K25/C$15 -> 2.0153303 | M25: =DEGREES(ASIN(L25/H25)) -> 5.182201 | N25: 8.057 | P25: ='Nr(V)'!A25 -> 11.5 | Q25: ='Nr(V)'!B25 -> 18518.07
A26: 5 | B26: =-K5*COS(C26+C27-C$3)+0.5*C$17*C$7*C$5*(C27-C$8)*I5^2*SIN(C26)+0.5*C$17*C$7*(C$11+1/PI()/C$10*C$5^2*(C27-C$8)^2)*I5^2*COS(C26) -> 1.5305773e-07 | C26: 0.09238545 | D26: =DEGREES(C26) -> 5.2932964 | F26: 0.992 | G26: 77.64 | H26: =SQRT((2*C$15)/(C$7*C$17*F26)) -> 24.509709 | I26: =C$15*SQRT((2*C$15)/(C$17*C$7*G26)) -> 18209.375 | J26: =Q51 -> 32564.202 | K26: =(J26-I26) -> 14354.827 | L26: =K26/C$15 -> 2.1840076 | M26: =DEGREES(ASIN(L26/H26)) -> 5.1122848 | N26: 6.187 | P26: ='Nr(V)'!A26 -> 12 | Q26: ='Nr(V)'!B26 -> 19223.502
A27: 6 | B27: =K5*SIN(C26+C27-C$3)+0.5*C$17*C$7*C$5*(C27-C$8)*I5^2*COS(C26)-0.5*C$17*C$7*(C$11+1/PI()/C$10*C$5^2*(C27-C$8)^2)*I5^2*SIN(C26)-C$15 -> 0 | C27: 0.10679552 | D27: =DEGREES(C27) -> 6.1189324 | F27: 0.89051119 | G27: 71.59 | H27: =SQRT((2*C$15)/(C$7*C$17*F27)) -> 25.868682 | I27: =C$15*SQRT((2*C$15)/(C$17*C$7*G27)) -> 18963.2 | J27: =Q53 -> 33621.99 | K27: =(J27-I27) -> 14658.79 | L27: =K27/C$15 -> 2.230254 | M27: =DEGREES(ASIN(L27/H27)) -> 4.9458637 | N27: 5.346 | P27: ='Nr(V)'!A27 -> 12.5 | Q27: ='Nr(V)'!B27 -> 19928.935
A28: 7 | B28: =-K6*COS(C28+C29-C$3)+0.5*C$17*C$7*C$5*(C29-C$8)*I6^2*SIN(C28)+0.5*C$17*C$7*(C$11+1/PI()/C$10*C$5^2*(C29-C$8)^2)*I6^2*COS(C28) -> 1.7766581e-07 | C28: 0.090328082 | D28: =DEGREES(C28) -> 5.1754179 | F28: 0.78877734 | G28: 62.64 | H28: =SQRT((2*C$15)/(C$7*C$17*F28)) -> 27.486331 | I28: =C$15*SQRT((2*C$15)/(C$17*C$7*G28)) -> 20272.716 | J28: =Q55 -> 34797.471 | K28: =(J28-I28) -> 14524.755 | L28: =K28/C$15 -> 2.2098612 | M28: =DEGREES(ASIN(L28/H28)) -> 4.6114749 | N28: 4.154 | P28: ='Nr(V)'!A28 -> 13 | Q28: ='Nr(V)'!B28 -> 20281.471
A29: 8 | B29: =K6*SIN(C28+C29-C$3)+0.5*C$17*C$7*C$5*(C29-C$8)*I6^2*COS(C28)-0.5*C$17*C$7*(C$11+1/PI()/C$10*C$5^2*(C29-C$8)^2)*I6^2*SIN(C28)-C$15 -> 0 | C29: 0.081982826 | D29: =DEGREES(C29) -> 4.6972699 | F29: 0.68820194 | G29: 51.95 | H29: =SQRT((2*C$15)/(C$7*C$17*F29)) -> 29.426326 | I29: =C$15*SQRT((2*C$15)/(C$17*C$7*G29)) -> 22261.018 | J29: =Q59 -> 36324.992 | K29: =(J29-I29) -> 14063.974 | L29: =K29/C$15 -> 2.1397559 | M29: =DEGREES(ASIN(L29/H29)) -> 4.1699831 | N29: 3.079 | P29: ='Nr(V)'!A29 -> 13.5 | Q29: ='Nr(V)'!B29 -> 20751.429
A30: 9 | B30: =-K7*COS(C30+C31-C$3)+0.5*C$17*C$7*C$5*(C31-C$8)*I7^2*SIN(C30)+0.5*C$17*C$7*(C$11+1/PI()/C$10*C$5^2*(C31-C$8)^2)*I7^2*COS(C30) -> 1.7587683e-07 | C30: 0.085006594 | D30: =DEGREES(C30) -> 4.870519 | F30: 0.58038845 | G30: 39.37 | H30: =SQRT((2*C$15)/(C$7*C$17*F30)) -> 32.043106 | I30: =C$15*SQRT((2*C$15)/(C$17*C$7*G30)) -> 25571.435 | J30: =Q64 -> 38322.517 | K30: =(J30-I30) -> 12751.082 | L30: =K30/C$15 -> 1.9400067 | M30: =DEGREES(ASIN(L30/H30)) -> 3.4710185 | N30: 2.073 | P30: ='Nr(V)'!A30 -> 14 | Q30: ='Nr(V)'!B30 -> 21221.657
