Workbook
Name CdodJ: 'projekt 5'!$W$15:$X$49
Name cx: 'projekty 2 i 3'!$C$3:$C$376
Name Cx_Cz: 'projekty 2 i 3'!$E$2:$F$123
Name cz: 'projekty 2 i 3'!$A$3:$B$348
Name Cz_a: 'projekty 2 i 3'!$A$4:$B$237
Name Cz_a_1: 'projekty 2 i 3'!$F$3:$G$237

Sheet Arkusz1
A1: Dana | B1: Symbol | C1: Wartość | D1: Jednostka
A2: Rozpiętość płata | B2: b | C2: 10.8 | D2: m
A3: Wysokość samolotu | B3: hs | C3: 2.25 | D3: m
A4: Długość kadłuba | B4: lk | C4: 7.75 | D4: m
A5: Powierzchnia nośna | B5: S | C5: 18 | D5: m2
A6: Masa pustego samolotu | B6: m0 | C6: 440 | D6: kg
A7: Masa maksymalna samolotu | B7: mk | C7: 720 | D7: kg
A8: Masa paliwa | B8: mp | C8: 90 | D8: kg
A9: Moc silnika | B9: N | C9: 59000 | D9: W
A10: Obroty silnika | B10: ns | C10: 2200 | D10: 1/min
A11: Zużycie paliwa | B11: q | C11: 0.022 | D11: m3/h
A12: Prędkość maksymalna | B12: Vmax | C12: 43 | D12: m/s
A13: Maksymalna prędkość wznoszenia | B13: wmax | C13: 2.2 | D13: m/s
... A18: kąt skosu krawędzi natarcia płata | B18: Vx0 | C18: 0 | D18: °
A19: zbieżność płata | B19: λ | C19: =C17/C16 -> 1 | D19: -
A20: wydłużenie geometryczne płata | B20: Λ | C20: =C2*C2/C5 -> 6.48 | D20: -
A21: średnia cięciwa aerodynamiczna | B21: ca | C21: =2*C16*(1+C19+C19^2)/(3+3*C19) -> 1.8 | D21: m
A22: położenie noska ca względem początku cięciwy przykadłubowej | B22: xN | C22: =C2*TAN(RADIANS(C18))*(1+2*C19)/(6+6*C19) -> 0 | D22: m
A23: gęstość powietrza przy ziemii | B23: ρ | C23: 1.225 | D23: kg/m3
A24: Liczba Reynoldsa 3M | B24: Re3M | C24: 3000000 | D24: -
A25: Czmax dla Reynoldsa 3M | B25: Czmax re | C25: 1.526 | D25: -
A26: lepkość kinematyczna powietrzna na poziomie morza | B26: ν | C26: =1.4607*10^-5 -> 1.4607e-05 | D26: m2/s
A27: Prędkość przeciągnięcia | B27: VS1 | C27: =SQRT(2*C7*C14/C23/C5/C25) -> 20.489633 | D27: m/s
A28: Obliczona liczba Reynoldsa | B28: Re | C28: =C27*C21/C26 -> 2524908.6 | D28: -
A29: środek aerodynamiczny na x | B29: xsa kreska | C29: 0.245 | D29: -
A30: środek aerodynamiczny na z | B30: zsa kreska | C30: -0.088 | D30: -
A31: Współczynnik momentu podłużnego względem środka aerodynamicznego | B31: Cmsa | C31: -0.096 | D31: -
A32: Współczynnik kierunkowy prostej Cz(a) | B32: a∞ | C32: 5.8316 | D32: 1/rad
A33: minimalna wartość Cx | B33: Cx∞ min1 | C33: =MIN('projekty 2 i 3'!C3:C50) -> 0.0056379595 | D33: -
A34: Cz odpowiadające minimalnej wartości Cx | B34: Cz∞1 | C34: ='projekty 2 i 3'!B27 -> 0.31724078 | D34: -
A35: Korekta dottycząca liczby reynoldsa | B35: Cx∞ min2 | C35: =C33*(C28/10^7)^0.11 -> 0.0048458389 | D35: -
A36: maksymalny współczynnik Cz | B36: Czmax | C36: =MAX('projekty 2 i 3'!B4:B5) -> -0.51634528 | D36: -
A37: Minimalny współczynnik Cx' | B37: Cx'∞ min | C37: =MIN('projekty 2 i 3'!J3:J44) -> 0.0051735104 | D37: -
A38: korekta technologiczna współczynnika oporu | B38: ΔCxtech | C38: =0.5*C37 -> 0.0025867552 | D38: -
A39: Kąt skosu lini utworzonej z 1/4 cięciwy płata | B39: β25 | C39: =DEGREES(ATAN(TAN(RADIANS(C18))+C16/2/C2*(C19-1))) -> 0 | D39: °
A40: Współczynnik do wyznaczenia tau 1 | B40: τ1 | C40: =0.023*(C20/C32)^3-0.103*(C20/C32)^2+0.25*(C20/C32) -> 0.18217545 | D40: -
A41: Współczynnik do wyznaczenia tau 2 | B41: τ2 | C41: =-0.18*C19^5+1.52*C19^4-3.51*C19^3+3.5*C19^2-1.33*C19+0.17 -> 0.17 | D41: -
A42: Współczynnik do wyznaczenia delta 1 | B42: δ1 | C42: =0.0537*C20/C32-0.005 -> 0.054670759 | D42: -
A43: Współczynnik do wyznaczenia delta 2 | B43: δ2 | C43: =-0.43*C19^5+1.83*C19^4-3.06*C19^3+2.56*C19^2-C19+0.148 -> 0.048 | D43: -
A44: Współczynnik do wyznaczenia delta 3 | B44: δ3 | C44: =1+C39^3*(-2.2*(10^(-7))*C20^3+(10^(-7))*C20^2+1.6*(10^(-5))) -> 1 | D44: -
...

Sheet projekty 2 i 3
A1: a deg | B1: Cz | C1: Cx | D1: a rad | E1: dCxRe | G1: profil | K1: płat | O1: samolot
G2: Cz | H2: Cx | I2: α [°] | J2: Cx' | K2: αi [°] | L2: αp [°] | M2: Cxi | N2: C'xp | O2: CzH | P2: CxH | Q2: Cx'szk | R2: Cx | S2: ΔCzH | T2: Cz' | U2: K | V2: E | W2: alfa | X2: Cz'2 | Y2: K/10 | Z2: E/100
A3: -10.472953 | B3: -0.67901252 | C3: 0.010836724 | D3: =RADIANS(A3) -> -0.18278752 | E3: =(Arkusz1!C$35-Arkusz1!C$33)*(1-ABS('projekty 2 i 3'!G3/Arkusz1!C$36)) -> 0.00024954634 | F3: =RADIANS(L3) -> -0.22221825 | G3: =B3 -> -0.67901252 | H3: =C3 -> 0.010836724 | I3: =A3 -> -10.472953 | J3: =H3+E3 -> 0.01108627 | K3: =DEGREES(G3*(1+Arkusz1!C$46)/Arkusz1!C$20/PI()) -> -2.2592145 | L3: =I3+K3 -> -12.732168 | M3: =G3^2*(1+Arkusz1!C$45)/Arkusz1!C$20/PI() -> 0.023886229 | N3: =J3+M3+Arkusz1!C$38 -> 0.037559254 | O3: =Arkusz1!C$31/Arkusz1!C$63+(Arkusz1!C$54-Arkusz1!C$29)/Arkusz1!C$63*'projekty 2 i 3'!G3 -> -0.3397088 | P3: =Arkusz1!C$58+Arkusz1!C$59+1/PI()/Arkusz1!C$62*'projekty 2 i 3'!O3^2 -> 0.029503045 | Q3: =Arkusz1!C$90*(1+1/Arkusz1!C$91*ABS('projekty 2 i 3'!G3)) -> 0.035938074 | R3: =(N3+Q3+P3*Arkusz1!C$53/Arkusz1!C$5)*(1+Arkusz1!C$92) -> 0.082928259 | S3: =O3*Arkusz1!C$53/Arkusz1!C$5 -> -0.054542135 | T3: =G3+S3 -> -0.73355466 | U3: =T3/R3 -> -8.8456537 | V3: =T3^3/R3^2 -> -57.397417 | W3: =I3 -> -10.472953 | X3: =T3^2 -> 0.53810244 | Y3: =U3/10 -> -0.88456537 | Z3: =V3/100 -> -0.57397417 | AA3: =Arkusz1!C$32*('projekty 2 i 3'!D3-'projekty 2 i 3'!D$18) -> -0.70163457
A4: -9.7579514 | B4: -0.62011487 | C4: 0.010107105 | D4: =RADIANS(A4) -> -0.17030838 | E4: =(Arkusz1!C$35-Arkusz1!C$33)*(1-ABS('projekty 2 i 3'!G4/Arkusz1!C$36)) -> 0.00015919199 | F4: =RADIANS(L4) -> -0.20631888 | G4: =B4 -> -0.62011487 | H4: =C4 -> 0.010107105 | I4: =A4 -> -9.7579514 | J4: =H4+E4 -> 0.010266297 | K4: =DEGREES(G4*(1+Arkusz1!C$46)/Arkusz1!C$20/PI()) -> -2.0632499 | L4: =I4+K4 -> -11.821201 | M4: =G4^2*(1+Arkusz1!C$45)/Arkusz1!C$20/PI() -> 0.019922155 | N4: =J4+M4+Arkusz1!C$38 -> 0.032775208 | O4: =Arkusz1!C$31/Arkusz1!C$63+(Arkusz1!C$54-Arkusz1!C$29)/Arkusz1!C$63*'projekty 2 i 3'!G4 -> -0.33386169 | P4: =Arkusz1!C$58+Arkusz1!C$59+1/PI()/Arkusz1!C$62*'projekty 2 i 3'!O4^2 -> 0.028881812 | Q4: =Arkusz1!C$90*(1+1/Arkusz1!C$91*ABS('projekty 2 i 3'!G4)) -> 0.035485699 | R4: =(N4+Q4+P4*Arkusz1!C$53/Arkusz1!C$5)*(1+Arkusz1!C$92) -> 0.077271925 | S4: =O4*Arkusz1!C$53/Arkusz1!C$5 -> -0.053603349 | T4: =G4+S4 -> -0.67371822 | U4: =T4/R4 -> -8.718797 | V4: =T4^3/R4^2 -> -51.214322 | W4: =I4 -> -9.7579514 | X4: =T4^2 -> 0.45389624 | Y4: =U4/10 -> -0.8718797 | Z4: =V4/100 -> -0.51214322 | AA4: =Arkusz1!C$32*('projekty 2 i 3'!D4-'projekty 2 i 3'!D$18) -> -0.62886122
A5: -8.7991285 | B5: -0.51634528 | C5: 0.0091110296 | D5: =RADIANS(A5) -> -0.15357376 | E5: =(Arkusz1!C$35-Arkusz1!C$33)*(1-ABS('projekty 2 i 3'!G5/Arkusz1!C$36)) -> 0 | F5: =RADIANS(L5) -> -0.1835583 | G5: =B5 -> -0.51634528 | H5: =C5 -> 0.0091110296 | I5: =A5 -> -8.7991285 | J5: =H5+E5 -> 0.0091110296 | K5: =DEGREES(G5*(1+Arkusz1!C$46)/Arkusz1!C$20/PI()) -> -1.7179871 | L5: =I5+K5 -> -10.517116 | M5: =G5^2*(1+Arkusz1!C$45)/Arkusz1!C$20/PI() -> 0.013812505 | N5: =J5+M5+Arkusz1!C$38 -> 0.02551029 | O5: =Arkusz1!C$31/Arkusz1!C$63+(Arkusz1!C$54-Arkusz1!C$29)/Arkusz1!C$63*'projekty 2 i 3'!G5 -> -0.32355988 | P5: =Arkusz1!C$58+Arkusz1!C$59+1/PI()/Arkusz1!C$62*'projekty 2 i 3'!O5^2 -> 0.027813525 | Q5: =Arkusz1!C$90*(1+1/Arkusz1!C$91*ABS('projekty 2 i 3'!G5)) -> 0.034688676 | R5: =(N5+Q5+P5*Arkusz1!C$53/Arkusz1!C$5)*(1+Arkusz1!C$92) -> 0.068544457 | S5: =O5*Arkusz1!C$53/Arkusz1!C$5 -> -0.051949336 | T5: =G5+S5 -> -0.56829461 | U5: =T5/R5 -> -8.2908909 | V5: =T5^3/R5^2 -> -39.063931 | W5: =I5 -> -8.7991285 | X5: =T5^2 -> 0.32295877 | Y5: =U5/10 -> -0.82908909 | Z5: =V5/100 -> -0.39063931 | AA5: =Arkusz1!C$32*('projekty 2 i 3'!D5-'projekty 2 i 3'!D$18) -> -0.53127163
A6: -7.864482 | B6: -0.4161164 | C6: 0.0080691656 | D6: =RADIANS(A6) -> -0.1372611 | E6: =(Arkusz1!C$35-Arkusz1!C$33)*(1-ABS('projekty 2 i 3'!G6/Arkusz1!C$36)) -> -0.00015376021 | F6: =RADIANS(L6) -> -0.16142527 | G6: =B6 -> -0.4161164 | H6: =C6 -> 0.0080691656 | I6: =A6 -> -7.864482 | J6: =H6+E6 -> 0.0079154054 | K6: =DEGREES(G6*(1+Arkusz1!C$46)/Arkusz1!C$20/PI()) -> -1.384505 | L6: =I6+K6 -> -9.248987 | M6: =G6^2*(1+Arkusz1!C$45)/Arkusz1!C$20/PI() -> 0.0089706039 | N6: =J6+M6+Arkusz1!C$38 -> 0.019472765 | O6: =Arkusz1!C$31/Arkusz1!C$63+(Arkusz1!C$54-Arkusz1!C$29)/Arkusz1!C$63*'projekty 2 i 3'!G6 -> -0.31360958 | P6: =Arkusz1!C$58+Arkusz1!C$59+1/PI()/Arkusz1!C$62*'projekty 2 i 3'!O6^2 -> 0.026813475 | Q6: =Arkusz1!C$90*(1+1/Arkusz1!C$91*ABS('projekty 2 i 3'!G6)) -> 0.033918849 | R6: =(N6+Q6+P6*Arkusz1!C$53/Arkusz1!C$5)*(1+Arkusz1!C$92) -> 0.061158466 | S6: =O6*Arkusz1!C$53/Arkusz1!C$5 -> -0.05035176 | T6: =G6+S6 -> -0.46646816 | U6: =T6/R6 -> -7.627205 | V6: =T6^3/R6^2 -> -27.136438 | W6: =I6 -> -7.864482 | X6: =T6^2 -> 0.21759254 | Y6: =U6/10 -> -0.7627205 | Z6: =V6/100 -> -0.27136438 | AA6: =Arkusz1!C$32*('projekty 2 i 3'!D6-'projekty 2 i 3'!D$18) -> -0.43614273
A7: -6.9313786 | B7: -0.3229861 | C7: 0.0074271298 | D7: =RADIANS(A7) -> -0.12097538 | E7: =(Arkusz1!C$35-Arkusz1!C$33)*(1-ABS('projekty 2 i 3'!G7/Arkusz1!C$36)) -> -0.00029663055 | F7: =RADIANS(L7) -> -0.13973141 | G7: =B7 -> -0.3229861 | H7: =C7 -> 0.0074271298 | I7: =A7 -> -6.9313786 | J7: =H7+E7 -> 0.0071304992 | K7: =DEGREES(G7*(1+Arkusz1!C$46)/Arkusz1!C$20/PI()) -> -1.0746413 | L7: =I7+K7 -> -8.0060199 | M7: =G7^2*(1+Arkusz1!C$45)/Arkusz1!C$20/PI() -> 0.0054045518 | N7: =J7+M7+Arkusz1!C$38 -> 0.015121806 | O7: =Arkusz1!C$31/Arkusz1!C$63+(Arkusz1!C$54-Arkusz1!C$29)/Arkusz1!C$63*'projekty 2 i 3'!G7 -> -0.304364 | P7: =Arkusz1!C$58+Arkusz1!C$59+1/PI()/Arkusz1!C$62*'projekty 2 i 3'!O7^2 -> 0.025912247 | Q7: =Arkusz1!C$90*(1+1/Arkusz1!C$91*ABS('projekty 2 i 3'!G7)) -> 0.033203543 | R7: =(N7+Q7+P7*Arkusz1!C$53/Arkusz1!C$5)*(1+Arkusz1!C$92) -> 0.055634847 | S7: =O7*Arkusz1!C$53/Arkusz1!C$5 -> -0.048867331 | T7: =G7+S7 -> -0.37185343 | U7: =T7/R7 -> -6.6838222 | V7: =T7^3/R7^2 -> -16.611986 | W7: =I7 -> -6.9313786 | X7: =T7^2 -> 0.13827497 | Y7: =U7/10 -> -0.66838222 | Z7: =V7/100 -> -0.16611986 | AA7: =Arkusz1!C$32*('projekty 2 i 3'!D7-'projekty 2 i 3'!D$18) -> -0.34117089
A8: -6.4524816 | B8: -0.27346749 | C8: 0.0071138859 | D8: =RADIANS(A8) -> -0.11261705 | E8: =(Arkusz1!C$35-Arkusz1!C$33)*(1-ABS('projekty 2 i 3'!G8/Arkusz1!C$36)) -> -0.00037259659 | F8: =RADIANS(L8) -> -0.1284975 | G8: =B8 -> -0.27346749 | H8: =C8 -> 0.0071138859 | I8: =A8 -> -6.4524816 | J8: =H8+E8 -> 0.0067412893 | K8: =DEGREES(G8*(1+Arkusz1!C$46)/Arkusz1!C$20/PI()) -> -0.90988268 | L8: =I8+K8 -> -7.3623643 | M8: =G8^2*(1+Arkusz1!C$45)/Arkusz1!C$20/PI() -> 0.0038743909 | N8: =J8+M8+Arkusz1!C$38 -> 0.013202435 | O8: =Arkusz1!C$31/Arkusz1!C$63+(Arkusz1!C$54-Arkusz1!C$29)/Arkusz1!C$63*'projekty 2 i 3'!G8 -> -0.299448 | P8: =Arkusz1!C$58+Arkusz1!C$59+1/PI()/Arkusz1!C$62*'projekty 2 i 3'!O8^2 -> 0.025444034 | Q8: =Arkusz1!C$90*(1+1/Arkusz1!C$91*ABS('projekty 2 i 3'!G8)) -> 0.032823206 | R8: =(N8+Q8+P8*Arkusz1!C$53/Arkusz1!C$5)*(1+Arkusz1!C$92) -> 0.053117471 | S8: =O8*Arkusz1!C$53/Arkusz1!C$5 -> -0.04807804 | T8: =G8+S8 -> -0.32154553 | U8: =T8/R8 -> -6.0534796 | V8: =T8^3/R8^2 -> -11.782912 | W8: =I8 -> -6.4524816 | X8: =T8^2 -> 0.10339153 | Y8: =U8/10 -> -0.60534796 | Z8: =V8/100 -> -0.11782912 | AA8: =Arkusz1!C$32*('projekty 2 i 3'!D8-'projekty 2 i 3'!D$18) -> -0.29242845
A9: -5.8784224 | B9: -0.2168846 | C9: 0.0069243134 | D9: =RADIANS(A9) -> -0.10259783 | E9: =(Arkusz1!C$35-Arkusz1!C$33)*(1-ABS('projekty 2 i 3'!G9/Arkusz1!C$36)) -> -0.00045939989 | F9: =RADIANS(L9) -> -0.11519247 | G9: =B9 -> -0.2168846 | H9: =C9 -> 0.0069243134 | I9: =A9 -> -5.8784224 | J9: =H9+E9 -> 0.0064649135 | K9: =DEGREES(G9*(1+Arkusz1!C$46)/Arkusz1!C$20/PI()) -> -0.72161973 | L9: =I9+K9 -> -6.6000421 | M9: =G9^2*(1+Arkusz1!C$45)/Arkusz1!C$20/PI() -> 0.0024369659 | N9: =J9+M9+Arkusz1!C$38 -> 0.011488635 | O9: =Arkusz1!C$31/Arkusz1!C$63+(Arkusz1!C$54-Arkusz1!C$29)/Arkusz1!C$63*'projekty 2 i 3'!G9 -> -0.29383069 | P9: =Arkusz1!C$58+Arkusz1!C$59+1/PI()/Arkusz1!C$62*'projekty 2 i 3'!O9^2 -> 0.024918358 | Q9: =Arkusz1!C$90*(1+1/Arkusz1!C$91*ABS('projekty 2 i 3'!G9)) -> 0.03238861 | R9: =(N9+Q9+P9*Arkusz1!C$53/Arkusz1!C$5)*(1+Arkusz1!C$92) -> 0.050750707 | S9: =O9*Arkusz1!C$53/Arkusz1!C$5 -> -0.047176149 | T9: =G9+S9 -> -0.26406075 | U9: =T9/R9 -> -5.2030949 | V9: =T9^3/R9^2 -> -7.1487045 | W9: =I9 -> -5.8784224 | X9: =T9^2 -> 0.069728077 | Y9: =U9/10 -> -0.52030949 | Z9: =V9/100 -> -0.071487045 | AA9: =Arkusz1!C$32*('projekty 2 i 3'!D9-'projekty 2 i 3'!D$18) -> -0.23400035
A10: -5.4710256 | B10: -0.17325576 | C10: 0.0066734045 | D10: =RADIANS(A10) -> -0.09548741 | E10: =(Arkusz1!C$35-Arkusz1!C$33)*(1-ABS('projekty 2 i 3'!G10/Arkusz1!C$36)) -> -0.00052633049 | F10: =RADIANS(L10) -> -0.10554849 | G10: =B10 -> -0.17325576 | H10: =C10 -> 0.0066734045 | I10: =A10 -> -5.4710256 | J10: =H10+E10 -> 0.006147074 | K10: =DEGREES(G10*(1+Arkusz1!C$46)/Arkusz1!C$20/PI()) -> -0.57645759 | L10: =I10+K10 -> -6.0474832 | M10: =G10^2*(1+Arkusz1!C$45)/Arkusz1!C$20/PI() -> 0.0015551324 | N10: =J10+M10+Arkusz1!C$38 -> 0.010288962 | O10: =Arkusz1!C$31/Arkusz1!C$63+(Arkusz1!C$54-Arkusz1!C$29)/Arkusz1!C$63*'projekty 2 i 3'!G10 -> -0.2894994 | P10: =Arkusz1!C$58+Arkusz1!C$59+1/PI()/Arkusz1!C$62*'projekty 2 i 3'!O10^2 -> 0.024519828 | Q10: =Arkusz1!C$90*(1+1/Arkusz1!C$91*ABS('projekty 2 i 3'!G10)) -> 0.03205351 | R10: =(N10+Q10+P10*Arkusz1!C$53/Arkusz1!C$5)*(1+Arkusz1!C$92) -> 0.049056022 | S10: =O10*Arkusz1!C$53/Arkusz1!C$5 -> -0.046480737 | T10: =G10+S10 -> -0.21973649 | U10: =T10/R10 -> -4.479297 | V10: =T10^3/R10^2 -> -4.4088154 | W10: =I10 -> -5.4710256 | X10: =T10^2 -> 0.048284126 | Y10: =U10/10 -> -0.4479297 | Z10: =V10/100 -> -0.044088154 | AA10: =Arkusz1!C$32*('projekty 2 i 3'!D10-'projekty 2 i 3'!D$18) -> -0.19253525
A11: -5.0157905 | B11: -0.12491167 | C11: 0.0063748529 | D11: =RADIANS(A11) -> -0.087542058 | E11: =(Arkusz1!C$35-Arkusz1!C$33)*(1-ABS('projekty 2 i 3'!G11/Arkusz1!C$36)) -> -0.00060049471 | F11: =RADIANS(L11) -> -0.094795767 | G11: =B11 -> -0.12491167 | H11: =C11 -> 0.0063748529 | I11: =A11 -> -5.0157905 | J11: =H11+E11 -> 0.0057743581 | K11: =DEGREES(G11*(1+Arkusz1!C$46)/Arkusz1!C$20/PI()) -> -0.41560687 | L11: =I11+K11 -> -5.4313974 | M11: =G11^2*(1+Arkusz1!C$45)/Arkusz1!C$20/PI() -> 0.00080834748 | N11: =J11+M11+Arkusz1!C$38 -> 0.0091694608 | O11: =Arkusz1!C$31/Arkusz1!C$63+(Arkusz1!C$54-Arkusz1!C$29)/Arkusz1!C$63*'projekty 2 i 3'!G11 -> -0.2847 | P11: =Arkusz1!C$58+Arkusz1!C$59+1/PI()/Arkusz1!C$62*'projekty 2 i 3'!O11^2 -> 0.024085137 | Q11: =Arkusz1!C$90*(1+1/Arkusz1!C$91*ABS('projekty 2 i 3'!G11)) -> 0.031682194 | R11: =(N11+Q11+P11*Arkusz1!C$53/Arkusz1!C$5)*(1+Arkusz1!C$92) -> 0.047401777 | S11: =O11*Arkusz1!C$53/Arkusz1!C$5 -> -0.045710167 | T11: =G11+S11 -> -0.17062184 | U11: =T11/R11 -> -3.599482 | V11: =T11^3/R11^2 -> -2.2106228 | W11: =I11 -> -5.0157905 | X11: =T11^2 -> 0.029111813 | Y11: =U11/10 -> -0.3599482 | Z11: =V11/100 -> -0.022106228 | AA11: =Arkusz1!C$32*('projekty 2 i 3'!D11-'projekty 2 i 3'!D$18) -> -0.14620114
A12: -4.8241802 | B12: -0.10486761 | C12: 0.0063110915 | D12: =RADIANS(A12) -> -0.084197829 | E12: =(Arkusz1!C$35-Arkusz1!C$33)*(1-ABS('projekty 2 i 3'!G12/Arkusz1!C$36)) -> -0.00063124412 | F12: =RADIANS(L12) -> -0.090287564 | G12: =B12 -> -0.10486761 | H12: =C12 -> 0.0063110915 | I12: =A12 -> -4.8241802 | J12: =H12+E12 -> 0.0056798473 | K12: =DEGREES(G12*(1+Arkusz1!C$46)/Arkusz1!C$20/PI()) -> -0.34891615 | L12: =I12+K12 -> -5.1730964 | M12: =G12^2*(1+Arkusz1!C$45)/Arkusz1!C$20/PI() -> 0.00056973748 | N12: =J12+M12+Arkusz1!C$38 -> 0.00883634 | O12: =Arkusz1!C$31/Arkusz1!C$63+(Arkusz1!C$54-Arkusz1!C$29)/Arkusz1!C$63*'projekty 2 i 3'!G12 -> -0.28271011 | P12: =Arkusz1!C$58+Arkusz1!C$59+1/PI()/Arkusz1!C$62*'projekty 2 i 3'!O12^2 -> 0.02390704 | Q12: =Arkusz1!C$90*(1+1/Arkusz1!C$91*ABS('projekty 2 i 3'!G12)) -> 0.031528241 | R12: =(N12+Q12+P12*Arkusz1!C$53/Arkusz1!C$5)*(1+Arkusz1!C$92) -> 0.046855169 | S12: =O12*Arkusz1!C$53/Arkusz1!C$5 -> -0.045390679 | T12: =G12+S12 -> -0.15025829 | U12: =T12/R12 -> -3.2068669 | V12: =T12^3/R12^2 -> -1.5452556 | W12: =I12 -> -4.8241802 | X12: =T12^2 -> 0.022577554 | Y12: =U12/10 -> -0.32068669 | Z12: =V12/100 -> -0.015452556 | AA12: =Arkusz1!C$32*('projekty 2 i 3'!D12-'projekty 2 i 3'!D$18) -> -0.12669893
A13: -4.5849889 | B13: -0.081291407 | C13: 0.006294117 | D13: =RADIANS(A13) -> -0.080023152 | E13: =(Arkusz1!C$35-Arkusz1!C$33)*(1-ABS('projekty 2 i 3'!G13/Arkusz1!C$36)) -> -0.00066741216 | F13: =RADIANS(L13) -> -0.084743801 | G13: =B13 -> -0.081291407 | H13: =C13 -> 0.006294117 | I13: =A13 -> -4.5849889 | J13: =H13+E13 -> 0.0056267048 | K13: =DEGREES(G13*(1+Arkusz1!C$46)/Arkusz1!C$20/PI()) -> -0.27047326 | L13: =I13+K13 -> -4.8554622 | M13: =G13^2*(1+Arkusz1!C$45)/Arkusz1!C$20/PI() -> 0.00034235865 | N13: =J13+M13+Arkusz1!C$38 -> 0.0085558187 | O13: =Arkusz1!C$31/Arkusz1!C$63+(Arkusz1!C$54-Arkusz1!C$29)/Arkusz1!C$63*'projekty 2 i 3'!G13 -> -0.28036957 | P13: =Arkusz1!C$58+Arkusz1!C$59+1/PI()/Arkusz1!C$62*'projekty 2 i 3'!O13^2 -> 0.023699158 | Q13: =Arkusz1!C$90*(1+1/Arkusz1!C$91*ABS('projekty 2 i 3'!G13)) -> 0.03134716 | R13: =(N13+Q13+P13*Arkusz1!C$53/Arkusz1!C$5)*(1+Arkusz1!C$92) -> 0.04633049 | S13: =O13*Arkusz1!C$53/Arkusz1!C$5 -> -0.045014891 | T13: =G13+S13 -> -0.1263063 | U13: =T13/R13 -> -2.7262025 | V13: =T13^3/R13^2 -> -0.93873115 | W13: =I13 -> -4.5849889 | X13: =T13^2 -> 0.015953281 | Y13: =U13/10 -> -0.27262025 | Z13: =V13/100 -> -0.0093873115 | AA13: =Arkusz1!C$32*('projekty 2 i 3'!D13-'projekty 2 i 3'!D$18) -> -0.10235388
A14: -4.3926071 | B14: -0.057698055 | C14: 0.0062153781 | D14: =RADIANS(A14) -> -0.076665456 | E14: =(Arkusz1!C$35-Arkusz1!C$33)*(1-ABS('projekty 2 i 3'!G14/Arkusz1!C$36)) -> -0.00070360651 | F14: =RADIANS(L14) -> -0.080016022 | G14: =B14 -> -0.057698055 | H14: =C14 -> 0.0062153781 | I14: =A14 -> -4.3926071 | J14: =H14+E14 -> 0.0055117715 | K14: =DEGREES(G14*(1+Arkusz1!C$46)/Arkusz1!C$20/PI()) -> -0.19197331 | L14: =I14+K14 -> -4.5845804 | M14: =G14^2*(1+Arkusz1!C$45)/Arkusz1!C$20/PI() -> 0.00017247032 | N14: =J14+M14+Arkusz1!C$38 -> 0.0082709971 | O14: =Arkusz1!C$31/Arkusz1!C$63+(Arkusz1!C$54-Arkusz1!C$29)/Arkusz1!C$63*'projekty 2 i 3'!G14 -> -0.27802732 | P14: =Arkusz1!C$58+Arkusz1!C$59+1/PI()/Arkusz1!C$62*'projekty 2 i 3'!O14^2 -> 0.023492855 | Q14: =Arkusz1!C$90*(1+1/Arkusz1!C$91*ABS('projekty 2 i 3'!G14)) -> 0.031165946 | R14: =(N14+Q14+P14*Arkusz1!C$53/Arkusz1!C$5)*(1+Arkusz1!C$92) -> 0.045801383 | S14: =O14*Arkusz1!C$53/Arkusz1!C$5 -> -0.04463883 | T14: =G14+S14 -> -0.10233689 | U14: =T14/R14 -> -2.2343624 | V14: =T14^3/R14^2 -> -0.51090412 | W14: =I14 -> -4.3926071 | X14: =T14^2 -> 0.010472838 | Y14: =U14/10 -> -0.22343624 | Z14: =V14/100 -> -0.0051090412 | AA14: =Arkusz1!C$32*('projekty 2 i 3'!D14-'projekty 2 i 3'!D$18) -> -0.082773141
... A38: 11.190065 | B38: 1.4214988 | C38: 0.019133265 | D38: =RADIANS(A38) -> 0.19530347 | E38: =(Arkusz1!C$35-Arkusz1!C$33)*(1-ABS('projekty 2 i 3'!G38/Arkusz1!C$36)) -> 0.0013885878 | F38: =RADIANS(L38) -> 0.2778509 | G38: =B38 -> 1.4214988 | H38: =C38 -> 0.019133265 | I38: =A38 -> 11.190065 | J38: =H38+E38 -> 0.020521852 | K38: =DEGREES(G38*(1+Arkusz1!C$46)/Arkusz1!C$20/PI()) -> 4.7296194 | L38: =I38+K38 -> 15.919684 | M38: =G38^2*(1+Arkusz1!C$45)/Arkusz1!C$20/PI() -> 0.10468514 | N38: =J38+M38+Arkusz1!C$38 -> 0.12779375 | O38: =Arkusz1!C$31/Arkusz1!C$63+(Arkusz1!C$54-Arkusz1!C$29)/Arkusz1!C$63*'projekty 2 i 3'!G38 -> -0.13117889 | P38: =Arkusz1!C$58+Arkusz1!C$59+1/PI()/Arkusz1!C$62*'projekty 2 i 3'!O38^2 -> 0.014014303 | Q38: =Arkusz1!C$90*(1+1/Arkusz1!C$91*ABS('projekty 2 i 3'!G38)) -> 0.041640886 | R38: =(N38+Q38+P38*Arkusz1!C$53/Arkusz1!C$5)*(1+Arkusz1!C$92) -> 0.18198579 | S38: =O38*Arkusz1!C$53/Arkusz1!C$5 -> -0.021061499 | T38: =G38+S38 -> 1.4004373 | U38: =T38/R38 -> 7.6953114 | V38: =T38^3/R38^2 -> 82.930842 | W38: =I38 -> 11.190065 | X38: =T38^2 -> 1.9612247 | Y38: =U38/10 -> 0.76953114 | Z38: =V38/100 -> 0.82930842 | AA38: =Arkusz1!C$32*('projekty 2 i 3'!D38-'projekty 2 i 3'!D$18) -> 1.5032409
A39: 11.950076 | B39: 1.4720976 | C39: =0.0058*B39^4-0.004*B39^3+0.002*B39^2-0.0022*B39+0.0061 -> 0.021672918 | D39: =RADIANS(A39) -> 0.20856817 | E39: =(Arkusz1!C$35-Arkusz1!C$33)*(1-ABS('projekty 2 i 3'!G39/Arkusz1!C$36)) -> 0.001466211 | F39: =RADIANS(L39) -> 0.29405391 | G39: =B39 -> 1.4720976 | H39: =C39 -> 0.021672918 | I39: =A39 -> 11.950076 | J39: =H39+E39 -> 0.023139129 | K39: =DEGREES(G39*(1+Arkusz1!C$46)/Arkusz1!C$20/PI()) -> 4.8979721 | L39: =I39+K39 -> 16.848048 | M39: =G39^2*(1+Arkusz1!C$45)/Arkusz1!C$20/PI() -> 0.1122704 | N39: =J39+M39+Arkusz1!C$38 -> 0.13799628 | O39: =Arkusz1!C$31/Arkusz1!C$63+(Arkusz1!C$54-Arkusz1!C$29)/Arkusz1!C$63*'projekty 2 i 3'!G39 -> -0.12615565 | P39: =Arkusz1!C$58+Arkusz1!C$59+1/PI()/Arkusz1!C$62*'projekty 2 i 3'!O39^2 -> 0.013810405 | Q39: =Arkusz1!C$90*(1+1/Arkusz1!C$91*ABS('projekty 2 i 3'!G39)) -> 0.04202952 | R39: =(N39+Q39+P39*Arkusz1!C$53/Arkusz1!C$5)*(1+Arkusz1!C$92) -> 0.19317773 | S39: =O39*Arkusz1!C$53/Arkusz1!C$5 -> -0.02025499 | T39: =G39+S39 -> 1.4518427 | U39: =T39/R39 -> 7.51558 | V39: =T39^3/R39^2 -> 82.005796 | W39: =I39 -> 11.950076 | X39: =T39^2 -> 2.1078471 | Y39: =U39/10 -> 0.751558 | Z39: =V39/100 -> 0.82005796 | AA39: =Arkusz1!C$32*('projekty 2 i 3'!D39-'projekty 2 i 3'!D$18) -> 1.5805953
A40: 13.202358 | B40: 1.5260657 | C40: =0.0058*B40^4-0.004*B40^3+0.002*B40^2-0.0022*B40+0.0061 -> 0.024641597 | D40: =RADIANS(A40) -> 0.23042462 | E40: =(Arkusz1!C$35-Arkusz1!C$33)*(1-ABS('projekty 2 i 3'!G40/Arkusz1!C$36)) -> 0.0015490029 | F40: =RADIANS(L40) -> 0.31904432 | G40: =B40 -> 1.5260657 | H40: =C40 -> 0.024641597 | I40: =A40 -> 13.202358 | J40: =H40+E40 -> 0.0261906 | K40: =DEGREES(G40*(1+Arkusz1!C$46)/Arkusz1!C$20/PI()) -> 5.077535 | L40: =I40+K40 -> 18.279893 | M40: =G40^2*(1+Arkusz1!C$45)/Arkusz1!C$20/PI() -> 0.1206531 | N40: =J40+M40+Arkusz1!C$38 -> 0.14943046 | O40: =Arkusz1!C$31/Arkusz1!C$63+(Arkusz1!C$54-Arkusz1!C$29)/Arkusz1!C$63*'projekty 2 i 3'!G40 -> -0.12079792 | P40: =Arkusz1!C$58+Arkusz1!C$59+1/PI()/Arkusz1!C$62*'projekty 2 i 3'!O40^2 -> 0.013601704 | Q40: =Arkusz1!C$90*(1+1/Arkusz1!C$91*ABS('projekty 2 i 3'!G40)) -> 0.042444032 | R40: =(N40+Q40+P40*Arkusz1!C$53/Arkusz1!C$5)*(1+Arkusz1!C$92) -> 0.20570182 | S40: =O40*Arkusz1!C$53/Arkusz1!C$5 -> -0.019394778 | T40: =G40+S40 -> 1.5066709 | U40: =T40/R40 -> 7.3245387 | V40: =T40^3/R40^2 -> 80.831189 | W40: =I40 -> 13.202358 | X40: =T40^2 -> 2.2700573 | Y40: =U40/10 -> 0.73245387 | Z40: =V40/100 -> 0.80831189 | AA40: =Arkusz1!C$32*('projekty 2 i 3'!D40-'projekty 2 i 3'!D$18) -> 1.7080533
A41: 15.038987 | B41: 1.4685998 | C41: =0.0058*B41^4-0.004*B41^3+0.002*B41^2-0.0022*B41+0.0061 -> 0.021492827 | D41: =RADIANS(A41) -> 0.26247985 | E41: =(Arkusz1!C$35-Arkusz1!C$33)*(1-ABS('projekty 2 i 3'!G41/Arkusz1!C$36)) -> #VALUE! | F41: =RADIANS(L41) -> 0 | G41: Tabela 3.3 Charakterystyki aerodynamiczne samolotu PWS-51
A42: 15.918851 | B42: 1.4244994 | C42: =0.0058*B42^4-0.004*B42^3+0.002*B42^2-0.0022*B42+0.0061 -> 0.019344482 | D42: =RADIANS(A42) -> 0.27783637 | E42: =(Arkusz1!C$35-Arkusz1!C$33)*(1-ABS('projekty 2 i 3'!G42/Arkusz1!C$36)) -> -0.00079212056 | F42: =RADIANS(L42) -> 0
A43: 18.657721 | B43: 1.3181922 | C43: =0.0058*B43^4-0.004*B43^3+0.002*B43^2-0.0022*B43+0.0061 -> 0.015025403 | D43: =RADIANS(A43) -> 0.32563866 | E43: =(Arkusz1!C$35-Arkusz1!C$33)*(1-ABS('projekty 2 i 3'!G43/Arkusz1!C$36)) -> -0.00079212056 | F43: =RADIANS(L43) -> 0
A44: 20.40356 | B44: 1.2737746 | C44: =0.0058*B44^4-0.004*B44^3+0.002*B44^2-0.0022*B44+0.0061 -> 0.013544462 | D44: =RADIANS(A44) -> 0.35610931 | E44: =(Arkusz1!C$35-Arkusz1!C$33)*(1-ABS('projekty 2 i 3'!G44/Arkusz1!C$36)) -> -0.00079212056 | F44: =RADIANS(L44) -> 0

Sheet projekt 4
H1: mmin | I1: =Arkusz1!C99 -> 520 | J1: mśr | K1: =Arkusz1!C100 -> 620 | L1: mmax | M1: =Arkusz1!C7 -> 720
B2: Cz | C2: Cx | D2: K | E2: A | F2: B | G2: γ [°] | H2: V [m/s] | I2: w [m/s] | J2: V [m/s] | K2: w [m/s] | L2: V [m/s] | M2: w [m/s]
A3: 1 | B3: =OFFSET('projekty 2 i 3'!$T$40,-A3+1,0,1,1) -> 1.5066709 | C3: =OFFSET('projekty 2 i 3'!$R$40,-A3+1,0,1,1) -> 0.20570182 | D3: =OFFSET('projekty 2 i 3'!$U$40,-A3+1,0,1,1) -> 7.3245387 | E3: =SQRT(1/SQRT(B3^2+C3^2)) -> 0.81093425 | F3: =SQRT(C3^2/(C3^2+B3^2)^(3/2)) -> 0.10969708 | G3: =DEGREES(ATAN(1/D3)) -> 7.7743758 | H3: ='projekt 4'!$E3*SQRT(2*Arkusz1!$C$14/Arkusz1!$C$5/Arkusz1!$C$102*'projekt 4'!I$1) -> 17.869925 | I3: ='projekt 4'!$F3*SQRT(2*Arkusz1!$C$14/Arkusz1!$C$5/Arkusz1!$C$102*'projekt 4'!I$1) -> 2.4173089 | J3: ='projekt 4'!$E3*SQRT(2*Arkusz1!$C$14/Arkusz1!$C$5/Arkusz1!$C$102*'projekt 4'!K$1) -> 19.51268 | K3: ='projekt 4'!$F3*SQRT(2*Arkusz1!$C$14/Arkusz1!$C$5/Arkusz1!$C$102*'projekt 4'!K$1) -> 2.6395284 | L3: ='projekt 4'!$E3*SQRT(2*Arkusz1!$C$14/Arkusz1!$C$5/Arkusz1!$C$102*'projekt 4'!M$1) -> 21.027484 | M3: ='projekt 4'!$F3*SQRT(2*Arkusz1!$C$14/Arkusz1!$C$5/Arkusz1!$C$102*'projekt 4'!M$1) -> 2.8444397 | O3: 0 | P3: 0
A4: 2 | B4: =OFFSET('projekty 2 i 3'!$T$40,-A4+1,0,1,1) -> 1.4518427 | C4: =OFFSET('projekty 2 i 3'!$R$40,-A4+1,0,1,1) -> 0.19317773 | D4: =OFFSET('projekty 2 i 3'!$U$40,-A4+1,0,1,1) -> 7.51558 | E4: =SQRT(1/SQRT(B4^2+C4^2)) -> 0.82629446 | F4: =SQRT(C4^2/(C4^2+B4^2)^(3/2)) -> 0.1089837 | G4: =DEGREES(ATAN(1/D4)) -> 7.5790827 | H4: ='projekt 4'!$E4*SQRT(2*Arkusz1!$C$14/Arkusz1!$C$5/Arkusz1!$C$102*'projekt 4'!I$1) -> 18.208406 | I4: ='projekt 4'!$F4*SQRT(2*Arkusz1!$C$14/Arkusz1!$C$5/Arkusz1!$C$102*'projekt 4'!I$1) -> 2.4015889 | J4: ='projekt 4'!$E4*SQRT(2*Arkusz1!$C$14/Arkusz1!$C$5/Arkusz1!$C$102*'projekt 4'!K$1) -> 19.882277 | K4: ='projekt 4'!$F4*SQRT(2*Arkusz1!$C$14/Arkusz1!$C$5/Arkusz1!$C$102*'projekt 4'!K$1) -> 2.6223632 | L4: ='projekt 4'!$E4*SQRT(2*Arkusz1!$C$14/Arkusz1!$C$5/Arkusz1!$C$102*'projekt 4'!M$1) -> 21.425774 | M4: ='projekt 4'!$F4*SQRT(2*Arkusz1!$C$14/Arkusz1!$C$5/Arkusz1!$C$102*'projekt 4'!M$1) -> 2.825942 | O4: 140 | P4: =O4*TAN(RADIANS(Arkusz1!C104)) -> 15.614842
A5: 3 | B5: =OFFSET('projekty 2 i 3'!$T$40,-A5+1,0,1,1) -> 1.4004373 | C5: =OFFSET('projekty 2 i 3'!$R$40,-A5+1,0,1,1) -> 0.18198579 | D5: =OFFSET('projekty 2 i 3'!$U$40,-A5+1,0,1,1) -> 7.6953114 | E5: =SQRT(1/SQRT(B5^2+C5^2)) -> 0.84149203 | F5: =SQRT(C5^2/(C5^2+B5^2)^(3/2)) -> 0.1084395 | G5: =DEGREES(ATAN(1/D5)) -> 7.404053 | H5: ='projekt 4'!$E5*SQRT(2*Arkusz1!$C$14/Arkusz1!$C$5/Arkusz1!$C$102*'projekt 4'!I$1) -> 18.543304 | I5: ='projekt 4'!$F5*SQRT(2*Arkusz1!$C$14/Arkusz1!$C$5/Arkusz1!$C$102*'projekt 4'!I$1) -> 2.3895966 | J5: ='projekt 4'!$E5*SQRT(2*Arkusz1!$C$14/Arkusz1!$C$5/Arkusz1!$C$102*'projekt 4'!K$1) -> 20.24796 | K5: ='projekt 4'!$F5*SQRT(2*Arkusz1!$C$14/Arkusz1!$C$5/Arkusz1!$C$102*'projekt 4'!K$1) -> 2.6092685 | L5: ='projekt 4'!$E5*SQRT(2*Arkusz1!$C$14/Arkusz1!$C$5/Arkusz1!$C$102*'projekt 4'!M$1) -> 21.819846 | M5: ='projekt 4'!$F5*SQRT(2*Arkusz1!$C$14/Arkusz1!$C$5/Arkusz1!$C$102*'projekt 4'!M$1) -> 2.8118308
A6: 4 | B6: =OFFSET('projekty 2 i 3'!$T$40,-A6+1,0,1,1) -> 1.2976441 | C6: =OFFSET('projekty 2 i 3'!$R$40,-A6+1,0,1,1) -> 0.16166598 | D6: =OFFSET('projekty 2 i 3'!$U$40,-A6+1,0,1,1) -> 8.0266985 | E6: =SQRT(1/SQRT(B6^2+C6^2)) -> 0.87448015 | F6: =SQRT(C6^2/(C6^2+B6^2)^(3/2)) -> 0.10811066 | G6: =DEGREES(ATAN(1/D6)) -> 7.1015594 | H6: ='projekt 4'!$E6*SQRT(2*Arkusz1!$C$14/Arkusz1!$C$5/Arkusz1!$C$102*'projekt 4'!I$1) -> 19.270237 | I6: ='projekt 4'!$F6*SQRT(2*Arkusz1!$C$14/Arkusz1!$C$5/Arkusz1!$C$102*'projekt 4'!I$1) -> 2.3823502 | J6: ='projekt 4'!$E6*SQRT(2*Arkusz1!$C$14/Arkusz1!$C$5/Arkusz1!$C$102*'projekt 4'!K$1) -> 21.041719 | K6: ='projekt 4'!$F6*SQRT(2*Arkusz1!$C$14/Arkusz1!$C$5/Arkusz1!$C$102*'projekt 4'!K$1) -> 2.6013559 | L6: ='projekt 4'!$E6*SQRT(2*Arkusz1!$C$14/Arkusz1!$C$5/Arkusz1!$C$102*'projekt 4'!M$1) -> 22.675226 | M6: ='projekt 4'!$F6*SQRT(2*Arkusz1!$C$14/Arkusz1!$C$5/Arkusz1!$C$102*'projekt 4'!M$1) -> 2.8033039
A7: 5 | B7: =OFFSET('projekty 2 i 3'!$T$40,-A7+1,0,1,1) -> 1.1972547 | C7: =OFFSET('projekty 2 i 3'!$R$40,-A7+1,0,1,1) -> 0.1443005 | D7: =OFFSET('projekty 2 i 3'!$U$40,-A7+1,0,1,1) -> 8.2969551 | E7: =SQRT(1/SQRT(B7^2+C7^2)) -> 0.91062772 | F7: =SQRT(C7^2/(C7^2+B7^2)^(3/2)) -> 0.10896585 | G7: =DEGREES(ATAN(1/D7)) -> 6.8724894 | H7: ='projekt 4'!$E7*SQRT(2*Arkusz1!$C$14/Arkusz1!$C$5/Arkusz1!$C$102*'projekt 4'!I$1) -> 20.066793 | I7: ='projekt 4'!$F7*SQRT(2*Arkusz1!$C$14/Arkusz1!$C$5/Arkusz1!$C$102*'projekt 4'!I$1) -> 2.4011955 | J7: ='projekt 4'!$E7*SQRT(2*Arkusz1!$C$14/Arkusz1!$C$5/Arkusz1!$C$102*'projekt 4'!K$1) -> 21.911501 | K7: ='projekt 4'!$F7*SQRT(2*Arkusz1!$C$14/Arkusz1!$C$5/Arkusz1!$C$102*'projekt 4'!K$1) -> 2.6219336 | L7: ='projekt 4'!$E7*SQRT(2*Arkusz1!$C$14/Arkusz1!$C$5/Arkusz1!$C$102*'projekt 4'!M$1) -> 23.612531 | M7: ='projekt 4'!$F7*SQRT(2*Arkusz1!$C$14/Arkusz1!$C$5/Arkusz1!$C$102*'projekt 4'!M$1) -> 2.825479
A8: 6 | B8: =OFFSET('projekty 2 i 3'!$T$40,-A8+1,0,1,1) -> 0.99239987 | C8: =OFFSET('projekty 2 i 3'!$R$40,-A8+1,0,1,1) -> 0.1122017 | D8: =OFFSET('projekty 2 i 3'!$U$40,-A8+1,0,1,1) -> 8.8447844 | E8: =SQRT(1/SQRT(B8^2+C8^2)) -> 1.0006393 | F8: =SQRT(C8^2/(C8^2+B8^2)^(3/2)) -> 0.11241705 | G8: =DEGREES(ATAN(1/D8)) -> 6.4505248 | H8: ='projekt 4'!$E8*SQRT(2*Arkusz1!$C$14/Arkusz1!$C$5/Arkusz1!$C$102*'projekt 4'!I$1) -> 22.050309 | I8: ='projekt 4'!$F8*SQRT(2*Arkusz1!$C$14/Arkusz1!$C$5/Arkusz1!$C$102*'projekt 4'!I$1) -> 2.4772467 | J8: ='projekt 4'!$E8*SQRT(2*Arkusz1!$C$14/Arkusz1!$C$5/Arkusz1!$C$102*'projekt 4'!K$1) -> 24.077359 | K8: ='projekt 4'!$F8*SQRT(2*Arkusz1!$C$14/Arkusz1!$C$5/Arkusz1!$C$102*'projekt 4'!K$1) -> 2.7049761 | L8: ='projekt 4'!$E8*SQRT(2*Arkusz1!$C$14/Arkusz1!$C$5/Arkusz1!$C$102*'projekt 4'!M$1) -> 25.946528 | M8: ='projekt 4'!$F8*SQRT(2*Arkusz1!$C$14/Arkusz1!$C$5/Arkusz1!$C$102*'projekt 4'!M$1) -> 2.9149683
A9: 7 | B9: =OFFSET('projekty 2 i 3'!$T$40,-A9+1,0,1,1) -> 0.89053857 | C9: =OFFSET('projekty 2 i 3'!$R$40,-A9+1,0,1,1) -> 0.09932585 | D9: =OFFSET('projekty 2 i 3'!$U$40,-A9+1,0,1,1) -> 8.9658288 | E9: =SQRT(1/SQRT(B9^2+C9^2)) -> 1.0564071 | F9: =SQRT(C9^2/(C9^2+B9^2)^(3/2)) -> 0.11709982 | G9: =DEGREES(ATAN(1/D9)) -> 6.364158 | H9: ='projekt 4'!$E9*SQRT(2*Arkusz1!$C$14/Arkusz1!$C$5/Arkusz1!$C$102*'projekt 4'!I$1) -> 23.279219 | I9: ='projekt 4'!$F9*SQRT(2*Arkusz1!$C$14/Arkusz1!$C$5/Arkusz1!$C$102*'projekt 4'!I$1) -> 2.5804374 | J9: ='projekt 4'!$E9*SQRT(2*Arkusz1!$C$14/Arkusz1!$C$5/Arkusz1!$C$102*'projekt 4'!K$1) -> 25.419241 | K9: ='projekt 4'!$F9*SQRT(2*Arkusz1!$C$14/Arkusz1!$C$5/Arkusz1!$C$102*'projekt 4'!K$1) -> 2.817653 | L9: ='projekt 4'!$E9*SQRT(2*Arkusz1!$C$14/Arkusz1!$C$5/Arkusz1!$C$102*'projekt 4'!M$1) -> 27.392583 | M9: ='projekt 4'!$F9*SQRT(2*Arkusz1!$C$14/Arkusz1!$C$5/Arkusz1!$C$102*'projekt 4'!M$1) -> 3.0363925
A10: 8 | B10: =OFFSET('projekty 2 i 3'!$T$40,-A10+1,0,1,1) -> 0.78880792 | C10: =OFFSET('projekty 2 i 3'!$R$40,-A10+1,0,1,1) -> 0.088517737 | D10: =OFFSET('projekty 2 i 3'!$U$40,-A10+1,0,1,1) -> 8.9112979 | E10: =SQRT(1/SQRT(B10^2+C10^2)) -> 1.1224207 | F10: =SQRT(C10^2/(C10^2+B10^2)^(3/2)) -> 0.12516916 | G10: =DEGREES(ATAN(1/D10)) -> 6.4027798 | H10: ='projekt 4'!$E10*SQRT(2*Arkusz1!$C$14/Arkusz1!$C$5/Arkusz1!$C$102*'projekt 4'!I$1) -> 24.73391 | I10: ='projekt 4'!$F10*SQRT(2*Arkusz1!$C$14/Arkusz1!$C$5/Arkusz1!$C$102*'projekt 4'!I$1) -> 2.758255 | J10: ='projekt 4'!$E10*SQRT(2*Arkusz1!$C$14/Arkusz1!$C$5/Arkusz1!$C$102*'projekt 4'!K$1) -> 27.007659 | K10: ='projekt 4'!$F10*SQRT(2*Arkusz1!$C$14/Arkusz1!$C$5/Arkusz1!$C$102*'projekt 4'!K$1) -> 3.0118171 | L10: ='projekt 4'!$E10*SQRT(2*Arkusz1!$C$14/Arkusz1!$C$5/Arkusz1!$C$102*'projekt 4'!M$1) -> 29.104313 | M10: ='projekt 4'!$F10*SQRT(2*Arkusz1!$C$14/Arkusz1!$C$5/Arkusz1!$C$102*'projekt 4'!M$1) -> 3.2456299
A11: 9 | B11: =OFFSET('projekty 2 i 3'!$T$40,-A11+1,0,1,1) -> 0.68823568 | C11: =OFFSET('projekty 2 i 3'!$R$40,-A11+1,0,1,1) -> 0.07921233 | D11: =OFFSET('projekty 2 i 3'!$U$40,-A11+1,0,1,1) -> 8.6884918 | E11: =SQRT(1/SQRT(B11^2+C11^2)) -> 1.2014414 | F11: =SQRT(C11^2/(C11^2+B11^2)^(3/2)) -> 0.13737275 | G11: =DEGREES(ATAN(1/D11)) -> 6.5655556 | H11: ='projekt 4'!$E11*SQRT(2*Arkusz1!$C$14/Arkusz1!$C$5/Arkusz1!$C$102*'projekt 4'!I$1) -> 26.475227 | I11: ='projekt 4'!$F11*SQRT(2*Arkusz1!$C$14/Arkusz1!$C$5/Arkusz1!$C$102*'projekt 4'!I$1) -> 3.0271761 | J11: ='projekt 4'!$E11*SQRT(2*Arkusz1!$C$14/Arkusz1!$C$5/Arkusz1!$C$102*'projekt 4'!K$1) -> 28.909053 | K11: ='projekt 4'!$F11*SQRT(2*Arkusz1!$C$14/Arkusz1!$C$5/Arkusz1!$C$102*'projekt 4'!K$1) -> 3.3054596 | L11: ='projekt 4'!$E11*SQRT(2*Arkusz1!$C$14/Arkusz1!$C$5/Arkusz1!$C$102*'projekt 4'!M$1) -> 31.153315 | M11: ='projekt 4'!$F11*SQRT(2*Arkusz1!$C$14/Arkusz1!$C$5/Arkusz1!$C$102*'projekt 4'!M$1) -> 3.5620684
A12: 10 | B12: =OFFSET('projekty 2 i 3'!$T$40,-A12+1,0,1,1) -> 0.58042558 | C12: =OFFSET('projekty 2 i 3'!$R$40,-A12+1,0,1,1) -> 0.070474666 | D12: =OFFSET('projekty 2 i 3'!$U$40,-A12+1,0,1,1) -> 8.2359465 | E12: =SQRT(1/SQRT(B12^2+C12^2)) -> 1.3077892 | F12: =SQRT(C12^2/(C12^2+B12^2)^(3/2)) -> 0.1576327 | G12: =DEGREES(ATAN(1/D12)) -> 6.9229058 | H12: ='projekt 4'!$E12*SQRT(2*Arkusz1!$C$14/Arkusz1!$C$5/Arkusz1!$C$102*'projekt 4'!I$1) -> 28.818731 | I12: ='projekt 4'!$F12*SQRT(2*Arkusz1!$C$14/Arkusz1!$C$5/Arkusz1!$C$102*'projekt 4'!I$1) -> 3.4736288 | J12: ='projekt 4'!$E12*SQRT(2*Arkusz1!$C$14/Arkusz1!$C$5/Arkusz1!$C$102*'projekt 4'!K$1) -> 31.467992 | K12: ='projekt 4'!$F12*SQRT(2*Arkusz1!$C$14/Arkusz1!$C$5/Arkusz1!$C$102*'projekt 4'!K$1) -> 3.792954 | L12: ='projekt 4'!$E12*SQRT(2*Arkusz1!$C$14/Arkusz1!$C$5/Arkusz1!$C$102*'projekt 4'!M$1) -> 33.910909 | M12: ='projekt 4'!$F12*SQRT(2*Arkusz1!$C$14/Arkusz1!$C$5/Arkusz1!$C$102*'projekt 4'!M$1) -> 4.0874079
A13: 11 | B13: =OFFSET('projekty 2 i 3'!$T$40,-A13+1,0,1,1) -> 0.4833721 | C13: =OFFSET('projekty 2 i 3'!$R$40,-A13+1,0,1,1) -> 0.063619965 | D13: =OFFSET('projekty 2 i 3'!$U$40,-A13+1,0,1,1) -> 7.5978052 | E13: =SQRT(1/SQRT(B13^2+C13^2)) -> 1.4321697 | F13: =SQRT(C13^2/(C13^2+B13^2)^(3/2)) -> 0.18688606 | G13: =DEGREES(ATAN(1/D13)) -> 7.4979984 | H13: ='projekt 4'!$E13*SQRT(2*Arkusz1!$C$14/Arkusz1!$C$5/Arkusz1!$C$102*'projekt 4'!I$1) -> 31.559607 | I13: ='projekt 4'!$F13*SQRT(2*Arkusz1!$C$14/Arkusz1!$C$5/Arkusz1!$C$102*'projekt 4'!I$1) -> 4.1182623 | J13: ='projekt 4'!$E13*SQRT(2*Arkusz1!$C$14/Arkusz1!$C$5/Arkusz1!$C$102*'projekt 4'!K$1) -> 34.460832 | K13: ='projekt 4'!$F13*SQRT(2*Arkusz1!$C$14/Arkusz1!$C$5/Arkusz1!$C$102*'projekt 4'!K$1) -> 4.4968476 | L13: ='projekt 4'!$E13*SQRT(2*Arkusz1!$C$14/Arkusz1!$C$5/Arkusz1!$C$102*'projekt 4'!M$1) -> 37.136089 | M13: ='projekt 4'!$F13*SQRT(2*Arkusz1!$C$14/Arkusz1!$C$5/Arkusz1!$C$102*'projekt 4'!M$1) -> 4.8459461
A14: 12 | B14: =OFFSET('projekty 2 i 3'!$T$40,-A14+1,0,1,1) -> 0.38030885 | C14: =OFFSET('projekty 2 i 3'!$R$40,-A14+1,0,1,1) -> 0.057545445 | D14: =OFFSET('projekty 2 i 3'!$U$40,-A14+1,0,1,1) -> 6.6088436 | E14: =SQRT(1/SQRT(B14^2+C14^2)) -> 1.6124044 | F14: =SQRT(C14^2/(C14^2+B14^2)^(3/2)) -> 0.24123087 | G14: =DEGREES(ATAN(1/D14)) -> 8.6042918 | H14: ='projekt 4'!$E14*SQRT(2*Arkusz1!$C$14/Arkusz1!$C$5/Arkusz1!$C$102*'projekt 4'!I$1) -> 35.531298 | I14: ='projekt 4'!$F14*SQRT(2*Arkusz1!$C$14/Arkusz1!$C$5/Arkusz1!$C$102*'projekt 4'!I$1) -> 5.3158164 | J14: ='projekt 4'!$E14*SQRT(2*Arkusz1!$C$14/Arkusz1!$C$5/Arkusz1!$C$102*'projekt 4'!K$1) -> 38.797634 | K14: ='projekt 4'!$F14*SQRT(2*Arkusz1!$C$14/Arkusz1!$C$5/Arkusz1!$C$102*'projekt 4'!K$1) -> 5.8044911 | L14: ='projekt 4'!$E14*SQRT(2*Arkusz1!$C$14/Arkusz1!$C$5/Arkusz1!$C$102*'projekt 4'!M$1) -> 41.809565 | M14: ='projekt 4'!$F14*SQRT(2*Arkusz1!$C$14/Arkusz1!$C$5/Arkusz1!$C$102*'projekt 4'!M$1) -> 6.2551042
A15: 13 | B15: =OFFSET('projekty 2 i 3'!$T$40,-A15+1,0,1,1) -> 0.33362424 | C15: =OFFSET('projekty 2 i 3'!$R$40,-A15+1,0,1,1) -> 0.055070935 | D15: =OFFSET('projekty 2 i 3'!$U$40,-A15+1,0,1,1) -> 6.0580819 | E15: =SQRT(1/SQRT(B15^2+C15^2)) -> 1.7196989 | F15: =SQRT(C15^2/(C15^2+B15^2)^(3/2)) -> 0.28007844 | G15: =DEGREES(ATAN(1/D15)) -> 9.3732196 | H15: ='projekt 4'!$E15*SQRT(2*Arkusz1!$C$14/Arkusz1!$C$5/Arkusz1!$C$102*'projekt 4'!I$1) -> 37.895663 | I15: ='projekt 4'!$F15*SQRT(2*Arkusz1!$C$14/Arkusz1!$C$5/Arkusz1!$C$102*'projekt 4'!I$1) -> 6.1718701 | J15: ='projekt 4'!$E15*SQRT(2*Arkusz1!$C$14/Arkusz1!$C$5/Arkusz1!$C$102*'projekt 4'!K$1) -> 41.379352 | K15: ='projekt 4'!$F15*SQRT(2*Arkusz1!$C$14/Arkusz1!$C$5/Arkusz1!$C$102*'projekt 4'!K$1) -> 6.7392405 | L15: ='projekt 4'!$E15*SQRT(2*Arkusz1!$C$14/Arkusz1!$C$5/Arkusz1!$C$102*'projekt 4'!M$1) -> 44.591706 | M15: ='projekt 4'!$F15*SQRT(2*Arkusz1!$C$14/Arkusz1!$C$5/Arkusz1!$C$102*'projekt 4'!M$1) -> 7.2624199
A16: 14 | B16: =OFFSET('projekty 2 i 3'!$T$40,-A16+1,0,1,1) -> 0.2785782 | C16: =OFFSET('projekty 2 i 3'!$R$40,-A16+1,0,1,1) -> 0.052550024 | D16: =OFFSET('projekty 2 i 3'!$U$40,-A16+1,0,1,1) -> 5.3012002 | E16: =SQRT(1/SQRT(B16^2+C16^2)) -> 1.8781494 | F16: =SQRT(C16^2/(C16^2+B16^2)^(3/2)) -> 0.34814752 | G16: =DEGREES(ATAN(1/D16)) -> 10.682549 | H16: ='projekt 4'!$E16*SQRT(2*Arkusz1!$C$14/Arkusz1!$C$5/Arkusz1!$C$102*'projekt 4'!I$1) -> 41.387313 | I16: ='projekt 4'!$F16*SQRT(2*Arkusz1!$C$14/Arkusz1!$C$5/Arkusz1!$C$102*'projekt 4'!I$1) -> 7.6718554 | J16: ='projekt 4'!$E16*SQRT(2*Arkusz1!$C$14/Arkusz1!$C$5/Arkusz1!$C$102*'projekt 4'!K$1) -> 45.191983 | K16: ='projekt 4'!$F16*SQRT(2*Arkusz1!$C$14/Arkusz1!$C$5/Arkusz1!$C$102*'projekt 4'!K$1) -> 8.377117 | L16: ='projekt 4'!$E16*SQRT(2*Arkusz1!$C$14/Arkusz1!$C$5/Arkusz1!$C$102*'projekt 4'!M$1) -> 48.700319 | M16: ='projekt 4'!$F16*SQRT(2*Arkusz1!$C$14/Arkusz1!$C$5/Arkusz1!$C$102*'projekt 4'!M$1) -> 9.0274478
... A18: 16 | B18: =OFFSET('projekty 2 i 3'!$T$40,-A18+1,0,1,1) -> 0.17679529 | C18: =OFFSET('projekty 2 i 3'!$R$40,-A18+1,0,1,1) -> 0.048838546 | D18: =OFFSET('projekty 2 i 3'!$U$40,-A18+1,0,1,1) -> 3.619995 | E18: =SQRT(1/SQRT(B18^2+C18^2)) -> 2.3349644 | F18: =SQRT(C18^2/(C18^2+B18^2)^(3/2)) -> 0.62173242 | G18: =DEGREES(ATAN(1/D18)) -> 15.442467 | H18: ='projekt 4'!$E18*SQRT(2*Arkusz1!$C$14/Arkusz1!$C$5/Arkusz1!$C$102*'projekt 4'!I$1) -> 51.453789 | I18: ='projekt 4'!$F18*SQRT(2*Arkusz1!$C$14/Arkusz1!$C$5/Arkusz1!$C$102*'projekt 4'!I$1) -> 13.700632 | J18: ='projekt 4'!$E18*SQRT(2*Arkusz1!$C$14/Arkusz1!$C$5/Arkusz1!$C$102*'projekt 4'!K$1) -> 56.183855 | K18: ='projekt 4'!$F18*SQRT(2*Arkusz1!$C$14/Arkusz1!$C$5/Arkusz1!$C$102*'projekt 4'!K$1) -> 14.96011 | L18: ='projekt 4'!$E18*SQRT(2*Arkusz1!$C$14/Arkusz1!$C$5/Arkusz1!$C$102*'projekt 4'!M$1) -> 60.545509 | M18: ='projekt 4'!$F18*SQRT(2*Arkusz1!$C$14/Arkusz1!$C$5/Arkusz1!$C$102*'projekt 4'!M$1) -> 16.12149
C40: mmin | D40: =I1 -> 520 | F40: mśr | G40: =K1 -> 620 | I40: mmax | J40: =M1 -> 720
C41: obliczone [m/s] | D41: z wykresu | E41: błąd | F41: obliczone | G41: z wykresu | H41: błąd | I41: obliczone | J41: z wykresu | K41: błąd
B42: Vopt | C42: =SQRT(2*Arkusz1!$C$14/Arkusz1!$C$5/Arkusz1!$C$102/SQRT(Arkusz1!$C$95*PI()*Arkusz1!$C$93)*'projekt 4'!D$40) -> 24.448972 | D42: 24.5 | E42: =100*ABS(C42-D42)/MAX(C42:D42) -> 0.20827901 | F42: =SQRT(2*Arkusz1!$C$14/Arkusz1!$C$5/Arkusz1!$C$102/SQRT(Arkusz1!$C$95*PI()*Arkusz1!$C$93)*'projekt 4'!G$40) -> 26.696527 | G42: 26.7 | H42: =100*ABS(F42-G42)/MAX(F42:G42) -> 0.013006833 | I42: =SQRT(2*Arkusz1!$C$14/Arkusz1!$C$5/Arkusz1!$C$102/SQRT(Arkusz1!$C$95*PI()*Arkusz1!$C$93)*'projekt 4'!J$40) -> 28.769027 | J42: 28.8 | K42: =100*ABS(I42-J42)/MAX(I42:J42) -> 0.10754528
B43: Vek | C43: =C42/(3^(1/4)) -> 18.577201 | D43: 18.6 | E43: =100*ABS(C43-D43)/MAX(C43:D43) -> 0.12257457 | F43: =F42/(3^(1/4)) -> 20.284974 | G43: 20.3 | H43: =100*ABS(F43-G43)/MAX(F43:G43) -> 0.074019552 | I43: =I42/(3^(1/4)) -> 21.859733 | J43: 21.9 | K43: =100*ABS(I43-J43)/MAX(I43:J43) -> 0.1838661
B44: wopt | C44: =SQRT(8*SQRT(Arkusz1!$C$93)*Arkusz1!$C$14/Arkusz1!$C$5/Arkusz1!$C$102/((Arkusz1!$C$95*PI())^(3/2))*'projekt 4'!D$40) -> 2.7567861 | D44: 2.8 | E44: =100*ABS(C44-D44)/MAX(C44:D44) -> 1.5433544 | F44: =SQRT(8*SQRT(Arkusz1!$C$93)*Arkusz1!$C$14/Arkusz1!$C$5/Arkusz1!$C$102/((Arkusz1!$C$95*PI())^(3/2))*'projekt 4'!G$40) -> 3.0102131 | G44: 3 | H44: =100*ABS(F44-G44)/MAX(F44:G44) -> 0.33928122 | I44: =SQRT(8*SQRT(Arkusz1!$C$93)*Arkusz1!$C$14/Arkusz1!$C$5/Arkusz1!$C$102/((Arkusz1!$C$95*PI())^(3/2))*'projekt 4'!J$40) -> 3.2439014 | J44: 3.2 | K44: =100*ABS(I44-J44)/MAX(I44:J44) -> 1.3533514
B45: wek | C45: =C44*2/(3^(3/4)) -> 2.4187563 | D45: 2.4 | E45: =100*ABS(C45-D45)/MAX(C45:D45) -> 0.77545402 | F45: =F44*2/(3^(3/4)) -> 2.6411088 | G45: 2.6 | H45: =100*ABS(F45-G45)/MAX(F45:G45) -> 1.5564982 | I45: =I44*2/(3^(3/4)) -> 2.8461429 | J45: 2.8 | K45: =100*ABS(I45-J45)/MAX(I45:J45) -> 1.6212424

Sheet projekt 5
A1: Nmax | B1: =Arkusz1!C9 -> 59000 | C1: W | F1: h | G1: ρ | H1: N | I1: N/ns | J1: Cngran
A2: nsmax | B2: =Arkusz1!C10/60 -> 36.666667 | C2: obr/s | F2: 0 | G2: =Arkusz1!C$23*(1-'projekt 5'!F2/44300)^4.256 -> 1.225 | H2: =Arkusz1!C$9*('projekt 5'!G2/G$2-Arkusz1!C$105)/(1-Arkusz1!C$105) -> 59000 | I2: =H2/B$2 -> 1609.0909 | J2: =H2/B$2^3/G2/B$3^5 -> 0.051107341
A3: D | B3: =Arkusz1!C109 -> 1.8041958 | C3: m | F3: 500 | G3: =Arkusz1!C$23*(1-'projekt 5'!F3/44300)^4.256 -> 1.1672279 | H3: =Arkusz1!C$9*('projekt 5'!G3/G$2-Arkusz1!C$105)/(1-Arkusz1!C$105) -> 55764.541 | I3: =H3/B$2 -> 1520.8511 | J3: =H3/B$2^3/G3/B$3^5 -> 0.050695551
F4: 1000 | G4: =Arkusz1!C$23*(1-'projekt 5'!F4/44300)^4.256 -> 1.1115636 | H4: =Arkusz1!C$9*('projekt 5'!G4/G$2-Arkusz1!C$105)/(1-Arkusz1!C$105) -> 52647.131 | I4: =H4/B$2 -> 1435.8308 | J4: =H4/B$2^3/G4/B$3^5 -> 0.050258296
F5: 1500 | G5: =Arkusz1!C$23*(1-'projekt 5'!F5/44300)^4.256 -> 1.0579533 | H5: =Arkusz1!C$9*('projekt 5'!G5/G$2-Arkusz1!C$105)/(1-Arkusz1!C$105) -> 49644.752 | I5: =H5/B$2 -> 1353.9478 | J5: =H5/B$2^3/G5/B$3^5 -> 0.049793678
F6: 2000 | G6: =Arkusz1!C$23*(1-'projekt 5'!F6/44300)^4.256 -> 1.0063439 | H6: =Arkusz1!C$9*('projekt 5'!G6/G$2-Arkusz1!C$105)/(1-Arkusz1!C$105) -> 46754.43 | I6: =H6/B$2 -> 1275.1208 | J6: =H6/B$2^3/G6/B$3^5 -> 0.049299635
F7: 2500 | G7: =Arkusz1!C$23*(1-'projekt 5'!F7/44300)^4.256 -> 0.95668306 | H7: =Arkusz1!C$9*('projekt 5'!G7/G$2-Arkusz1!C$105)/(1-Arkusz1!C$105) -> 43973.233 | I7: =H7/B$2 -> 1199.27 | J7: =H7/B$2^3/G7/B$3^5 -> 0.048773922
F8: 3000 | G8: =Arkusz1!C$23*(1-'projekt 5'!F8/44300)^4.256 -> 0.90891914 | H8: =Arkusz1!C$9*('projekt 5'!G8/G$2-Arkusz1!C$105)/(1-Arkusz1!C$105) -> 41298.272 | I8: =H8/B$2 -> 1126.3165 | J8: =H8/B$2^3/G8/B$3^5 -> 0.048214092
F9: 3500 | G9: =Arkusz1!C$23*(1-'projekt 5'!F9/44300)^4.256 -> 0.86300137 | H9: =Arkusz1!C$9*('projekt 5'!G9/G$2-Arkusz1!C$105)/(1-Arkusz1!C$105) -> 38726.702 | I9: =H9/B$2 -> 1056.1828 | J9: =H9/B$2^3/G9/B$3^5 -> 0.047617479
F10: 4000 | G10: =Arkusz1!C$23*(1-'projekt 5'!F10/44300)^4.256 -> 0.8188797 | H10: =Arkusz1!C$9*('projekt 5'!G10/G$2-Arkusz1!C$105)/(1-Arkusz1!C$105) -> 36255.721 | I10: =H10/B$2 -> 988.7924 | J10: =H10/B$2^3/G10/B$3^5 -> 0.046981168
F11: 4500 | G11: =Arkusz1!C$23*(1-'projekt 5'!F11/44300)^4.256 -> 0.77650487 | H11: =Arkusz1!C$9*('projekt 5'!G11/G$2-Arkusz1!C$105)/(1-Arkusz1!C$105) -> 33882.57 | I11: =H11/B$2 -> 924.07009 | J11: =H11/B$2^3/G11/B$3^5 -> 0.046301976
F12: 5000 | G12: =Arkusz1!C$23*(1-'projekt 5'!F12/44300)^4.256 -> 0.73582836 | H12: =Arkusz1!C$9*('projekt 5'!G12/G$2-Arkusz1!C$105)/(1-Arkusz1!C$105) -> 31604.531 | I12: =H12/B$2 -> 861.94176 | J12: =H12/B$2^3/G12/B$3^5 -> 0.045576418
A14: h=0m | J14: h=500m | S14: h=1000m
A15: LP | B15: J | C15: CN | D15: ηs | E15: ns [1/s] | F15: V [m/s] | G15: N [W] | H15: Nr [W] | J15: LP | K15: J | L15: CN | M15: ηs | N15: ns [1/s] | O15: V [m/s] | P15: N [W] | Q15: Nr [W] | S15: LP | T15: J | U15: CN | V15: ηs | W15: ns [1/s] | X15: V [m/s] | Y15: N [W] | Z15: Nr [W]
A16: 1 | B16: 0 | C16: 0.073277583 | D16: 0 | E16: =SQRT($I$2/$G$2/$B$3^5/C16) -> 30.621574 | F16: =B16*E16*$B$3 -> 0 | G16: =$I$2*E16 -> 49272.896 | H16: =G16*D16 -> 0 | J16: 1 | K16: 0 | L16: 0.073277583 | M16: 0 | N16: =SQRT($I$3/$G$3/$B$3^5/L16) -> 30.49796 | O16: =K16*N16*$B$3 -> 0 | P16: =$I$3*N16 -> 46382.856 | Q16: =P16*M16 -> 0 | S16: 1 | T16: 0 | U16: 0.073277583 | V16: 0 | W16: =SQRT($I$4/$G$4/$B$3^5/U16) -> 30.366151 | X16: =T16*W16*$B$3 -> 0 | Y16: =$I$4*W16 -> 43600.655 | Z16: =Y16*V16 -> 0
A17: 2 | B17: 0.022604318 | C17: 0.073328782 | D17: 0.043340858 | E17: =SQRT($I$2/$G$2/$B$3^5/C17) -> 30.610882 | F17: =B17*E17*$B$3 -> 1.2483918 | G17: =$I$2*E17 -> 49255.691 | H17: =G17*D17 -> 2134.7839 | J17: 2 | K17: 0.022604318 | L17: 0.073328782 | M17: 0.043340858 | N17: =SQRT($I$3/$G$3/$B$3^5/L17) -> 30.487311 | O17: =K17*N17*$B$3 -> 1.2433523 | P17: =$I$3*N17 -> 46366.661 | Q17: =P17*M17 -> 2009.5708 | S17: 2 | T17: 0.022604318 | U17: 0.073328782 | V17: 0.043340858 | W17: =SQRT($I$4/$G$4/$B$3^5/U17) -> 30.355548 | X17: =T17*W17*$B$3 -> 1.2379786 | Y17: =$I$4*W17 -> 43585.432 | Z17: =Y17*V17 -> 1889.03
A18: 3 | B18: 0.083744347 | C18: 0.072704156 | D18: 0.14988713 | E18: =SQRT($I$2/$G$2/$B$3^5/C18) -> 30.742095 | F18: =B18*E18*$B$3 -> 4.64486 | G18: =$I$2*E18 -> 49466.825 | H18: =G18*D18 -> 7414.4406 | J18: 3 | K18: 0.083744347 | L18: 0.072704156 | M18: 0.14988713 | N18: =SQRT($I$3/$G$3/$B$3^5/L18) -> 30.617994 | O18: =K18*N18*$B$3 -> 4.6261095 | P18: =$I$3*N18 -> 46565.411 | Q18: =P18*M18 -> 6979.5559 | S18: 3 | T18: 0.083744347 | U18: 0.072704156 | V18: 0.14988713 | W18: =SQRT($I$4/$G$4/$B$3^5/U18) -> 30.485666 | X18: =T18*W18*$B$3 -> 4.6061159 | Y18: =$I$4*W18 -> 43772.26 | Z18: =Y18*V18 -> 6560.8986
A19: 4 | B19: 0.11710897 | C19: 0.07202833 | D19: 0.20586907 | E19: =SQRT($I$2/$G$2/$B$3^5/C19) -> 30.885981 | F19: =B19*E19*$B$3 -> 6.525822 | G19: =$I$2*E19 -> 49698.351 | H19: =G19*D19 -> 10231.354 | J19: 4 | K19: 0.11710897 | L19: 0.07202833 | M19: 0.20586907 | N19: =SQRT($I$3/$G$3/$B$3^5/L19) -> 30.7613 | O19: =K19*N19*$B$3 -> 6.4994784 | P19: =$I$3*N19 -> 46783.357 | Q19: =P19*M19 -> 9631.2464 | S19: 4 | T19: 0.11710897 | U19: 0.07202833 | V19: 0.20586907 | W19: =SQRT($I$4/$G$4/$B$3^5/U19) -> 30.628352 | X19: =T19*W19*$B$3 -> 6.4713883 | Y19: =$I$4*W19 -> 43977.133 | Z19: =Y19*V19 -> 9053.5317
A20: 5 | B20: 0.15047359 | C20: 0.071352504 | D20: 0.2744921 | E20: =SQRT($I$2/$G$2/$B$3^5/C20) -> 31.031907 | F20: =B20*E20*$B$3 -> 8.4246606 | G20: =$I$2*E20 -> 49933.159 | H20: =G20*D20 -> 13706.258 | J20: 5 | K20: 0.15047359 | L20: 0.071352504 | M20: 0.2744921 | N20: =SQRT($I$3/$G$3/$B$3^5/L20) -> 30.906637 | O20: =K20*N20*$B$3 -> 8.3906517 | P20: =$I$3*N20 -> 47004.393 | Q20: =P20*M20 -> 12902.334 | S20: 5 | T20: 0.15047359 | U20: 0.071352504 | V20: 0.2744921 | W20: =SQRT($I$4/$G$4/$B$3^5/U20) -> 30.773061 | X20: =T20*W20*$B$3 -> 8.3543882 | Y20: =$I$4*W20 -> 44184.91 | Z20: =Y20*V20 -> 12128.409
A21: 6 | B21: 0.21535114 | C21: 0.06999744 | D21: 0.38645598 | E21: =SQRT($I$2/$G$2/$B$3^5/C21) -> 31.330837 | F21: =B21*E21*$B$3 -> 12.173146 | G21: =$I$2*E21 -> 50414.165 | H21: =G21*D21 -> 19482.856 | J21: 6 | K21: 0.21535114 | L21: 0.06999744 | M21: 0.38645598 | N21: =SQRT($I$3/$G$3/$B$3^5/L21) -> 31.20436 | O21: =K21*N21*$B$3 -> 12.124005 | P21: =$I$3*N21 -> 47457.185 | Q21: =P21*M21 -> 18340.113 | S21: 6 | T21: 0.21535114 | U21: 0.06999744 | V21: 0.38645598 | W21: =SQRT($I$4/$G$4/$B$3^5/U21) -> 31.069498 | X21: =T21*W21*$B$3 -> 12.071607 | Y21: =$I$4*W21 -> 44610.543 | Z21: =Y21*V21 -> 17240.011
A22: 7 | B22: 0.25982592 | C22: 0.069342094 | D22: 0.43702032 | E22: =SQRT($I$2/$G$2/$B$3^5/C22) -> 31.478541 | F22: =B22*E22*$B$3 -> 14.756411 | G22: =$I$2*E22 -> 50651.835 | H22: =G22*D22 -> 22135.881 | J22: 7 | K22: 0.25982592 | L22: 0.069342094 | M22: 0.43702032 | N22: =SQRT($I$3/$G$3/$B$3^5/L22) -> 31.351468 | O22: =K22*N22*$B$3 -> 14.696842 | P22: =$I$3*N22 -> 47680.915 | Q22: =P22*M22 -> 20837.528 | S22: 7 | T22: 0.25982592 | U22: 0.069342094 | V22: 0.43702032 | W22: =SQRT($I$4/$G$4/$B$3^5/U22) -> 31.21597 | X22: =T22*W22*$B$3 -> 14.633324 | Y22: =$I$4*W22 -> 44820.852 | Z22: =Y22*V22 -> 19587.623
A23: 8 | B23: 0.35625053 | C23: 0.066570526 | D23: 0.58148984 | E23: =SQRT($I$2/$G$2/$B$3^5/C23) -> 32.127141 | F23: =B23*E23*$B$3 -> 20.649582 | G23: =$I$2*E23 -> 51695.49 | H23: =G23*D23 -> 30060.403 | J23: 8 | K23: 0.35625053 | L23: 0.066570526 | M23: 0.58148984 | N23: =SQRT($I$3/$G$3/$B$3^5/L23) -> 31.997449 | O23: =K23*N23*$B$3 -> 20.566224 | P23: =$I$3*N23 -> 48663.356 | Q23: =P23*M23 -> 28297.247 | S23: 8 | T23: 0.35625053 | U23: 0.066570526 | V23: 0.58148984 | W23: =SQRT($I$4/$G$4/$B$3^5/U23) -> 31.859159 | X23: =T23*W23*$B$3 -> 20.477338 | Y23: =$I$4*W23 -> 45744.364 | Z23: =Y23*V23 -> 26599.883
A24: 9 | B24: 0.40075945 | C24: 0.065177916 | D24: 0.60857788 | E24: =SQRT($I$2/$G$2/$B$3^5/C24) -> 32.468546 | F24: =B24*E24*$B$3 -> 23.476334 | G24: =$I$2*E24 -> 52244.842 | H24: =G24*D24 -> 31795.055 | J24: 9 | K24: 0.40075945 | L24: 0.065177916 | M24: 0.60857788 | N24: =SQRT($I$3/$G$3/$B$3^5/L24) -> 32.337476 | O24: =K24*N24*$B$3 -> 23.381564 | P24: =$I$3*N24 -> 49180.486 | Q24: =P24*M24 -> 29930.156 | S24: 9 | T24: 0.40075945 | U24: 0.065177916 | V24: 0.60857788 | W24: =SQRT($I$4/$G$4/$B$3^5/U24) -> 32.197717 | X24: =T24*W24*$B$3 -> 23.280511 | Y24: =$I$4*W24 -> 46230.475 | Z24: =Y24*V24 -> 28134.844
A25: 10 | B25: 0.46578206 | C25: 0.060689479 | D25: 0.66997743 | E25: =SQRT($I$2/$G$2/$B$3^5/C25) -> 33.647777 | F25: =B25*E25*$B$3 -> 28.276314 | G25: =$I$2*E25 -> 54142.331 | H25: =G25*D25 -> 36274.14 | J25: 10 | K25: 0.46578206 | L25: 0.060689479 | M25: 0.66997743 | N25: =SQRT($I$3/$G$3/$B$3^5/L25) -> 33.511946 | O25: =K25*N25*$B$3 -> 28.162168 | P25: =$I$3*N25 -> 50966.681 | Q25: =P25*M25 -> 34146.526 | S25: 10 | T25: 0.46578206 | U25: 0.060689479 | V25: 0.66997743 | W25: =SQRT($I$4/$G$4/$B$3^5/U25) -> 33.367111 | X25: =T25*W25*$B$3 -> 28.040454 | Y25: =$I$4*W25 -> 47909.527 | Z25: =Y25*V25 -> 32098.302
A26: 11 | B26: 0.52707569 | C26: 0.056747163 | D26: 0.70790068 | E26: =SQRT($I$2/$G$2/$B$3^5/C26) -> 34.796936 | F26: =B26*E26*$B$3 -> 33.090067 | G26: =$I$2*E26 -> 55991.433 | H26: =G26*D26 -> 39636.373 | J26: 11 | K26: 0.52707569 | L26: 0.056747163 | M26: 0.70790068 | N26: =SQRT($I$3/$G$3/$B$3^5/L26) -> 34.656466 | O26: =K26*N26*$B$3 -> 32.956489 | P26: =$I$3*N26 -> 52707.325 | Q26: =P26*M26 -> 37311.551 | S26: 11 | T26: 0.52707569 | U26: 0.056747163 | V26: 0.70790068 | W26: =SQRT($I$4/$G$4/$B$3^5/U26) -> 34.506685 | X26: =T26*W26*$B$3 -> 32.814054 | Y26: =$I$4*W26 -> 49545.762 | Z26: =Y26*V26 -> 35073.478
A27: 12 | B27: 0.58472566 | C27: 0.051507808 | D27: 0.75124153 | E27: =SQRT($I$2/$G$2/$B$3^5/C27) -> 36.523849 | F27: =B27*E27*$B$3 -> 38.531185 | G27: =$I$2*E27 -> 58770.194 | H27: =G27*D27 -> 44150.611 | J27: 12 | K27: 0.58472566 | L27: 0.051507808 | M27: 0.75124153 | N27: =SQRT($I$3/$G$3/$B$3^5/L27) -> 36.376409 | O27: =K27*N27*$B$3 -> 38.375641 | P27: =$I$3*N27 -> 55323.102 | Q27: =P27*M27 -> 41561.012 | S27: 12 | T27: 0.58472566 | U27: 0.051507808 | V27: 0.75124153 | W27: =SQRT($I$4/$G$4/$B$3^5/U27) -> 36.219194 | X27: =T27*W27*$B$3 -> 38.209785 | Y27: =$I$4*W27 -> 52004.635 | Z27: =Y27*V27 -> 39068.042
A28: 13 | B28: 0.62189607 | C28: 0.048627016 | D28: 0.76749436 | E28: =$B$2 -> 36.666667 | F28: =B28*E28*$B$3 -> 41.140817 | G28: =C28*$G$2*E28^3*$B$3^5 -> 56136.631 | H28: =G28*D28 -> 43084.547 | J28: 13 | K28: 0.62189607 | L28: 0.048627016 | M28: 0.76749436 | N28: =$B$2 -> 36.666667 | O28: =K28*N28*$B$3 -> 41.140817 | P28: =L28*$G$3*N28^3*$B$3^5 -> 53489.175 | Q28: =P28*M28 -> 41052.64 | S28: 13 | T28: 0.62189607 | U28: 0.048627016 | V28: 0.76749436 | W28: =$B$2 -> 36.666667 | X28: =T28*W28*$B$3 -> 41.140817 | Y28: =U28*$G$4*W28^3*$B$3^5 -> 50938.314 | Z28: =Y28*V28 -> 39094.869
A29: 14 | B29: 0.67399095 | C29: 0.043377421 | D29: 0.78735892 | E29: =$B$2 -> 36.666667 | F29: =B29*E29*$B$3 -> 44.587094 | G29: =C29*$G$2*E29^3*$B$3^5 -> 50076.325 | H29: =G29*D29 -> 39428.041 | J29: 14 | K29: 0.67399095 | L29: 0.043377421 | M29: 0.78735892 | N29: =$B$2 -> 36.666667 | O29: =K29*N29*$B$3 -> 44.587094 | P29: =L29*$G$3*N29^3*$B$3^5 -> 47714.679 | Q29: =P29*M29 -> 37568.578 | S29: 14 | T29: 0.67399095 | U29: 0.043377421 | V29: 0.78735892 | W29: =$B$2 -> 36.666667 | X29: =T29*W29*$B$3 -> 44.587094 | Y29: =U29*$G$4*W29^3*$B$3^5 -> 45439.2 | Z29: =Y29*V29 -> 35776.96
A30: 15 | B30: 0.72612851 | C30: 0.037206246 | D30: 0.79097065 | E30: =$B$2 -> 36.666667 | F30: =B30*E30*$B$3 -> 48.036194 | G30: =C30*$G$2*E30^3*$B$3^5 -> 42952.117 | H30: =G30*D30 -> 33973.864 | J30: 15 | K30: 0.72612851 | L30: 0.037206246 | M30: 0.79097065 | N30: =$B$2 -> 36.666667 | O30: =K30*N30*$B$3 -> 48.036194 | P30: =L30*$G$3*N30^3*$B$3^5 -> 40926.456 | Q30: =P30*M30 -> 32371.625 | S30: 15 | T30: 0.72612851 | U30: 0.037206246 | V30: 0.79097065 | W30: =$B$2 -> 36.666667 | X30: =T30*W30*$B$3 -> 48.036194 | Y30: =U30*$G$4*W30^3*$B$3^5 -> 38974.702 | Z30: =Y30*V30 -> 30827.846
A31: 16 | B31: 0.7877208 | C31: 0.026812868 | D31: 0.77832957 | E31: =$B$2 -> 36.666667 | F31: =B31*E31*$B$3 -> 52.11076 | G31: =C31*$G$2*E31^3*$B$3^5 -> 30953.659 | H31: =G31*D31 -> 24092.148 | J31: 16 | K31: 0.7877208 | L31: 0.026812868 | M31: 0.77832957 | N31: =$B$2 -> 36.666667 | O31: =K31*N31*$B$3 -> 52.11076 | P31: =L31*$G$3*N31^3*$B$3^5 -> 29493.855 | Q31: =P31*M31 -> 22955.94 | S31: 16 | T31: 0.7877208 | U31: 0.026812868 | V31: 0.77832957 | W31: =$B$2 -> 36.666667 | X31: =T31*W31*$B$3 -> 52.11076 | Y31: =U31*$G$4*W31^3*$B$3^5 -> 28087.315 | Z31: =Y31*V31 -> 21861.188
A32: 17 | B32: 0.81755269 | C32: 0.022443895 | D32: 0.76027088 | E32: =$B$2 -> 36.666667 | F32: =B32*E32*$B$3 -> 54.084255 | G32: =C32*$G$2*E32^3*$B$3^5 -> 25909.972 | H32: =G32*D32 -> 19698.597 | J32: 17 | K32: 0.81755269 | L32: 0.022443895 | M32: 0.76027088 | N32: =$B$2 -> 36.666667 | O32: =K32*N32*$B$3 -> 54.084255 | P32: =L32*$G$3*N32^3*$B$3^5 -> 24688.033 | Q32: =P32*M32 -> 18769.593 | S32: 17 | T32: 0.81755269 | U32: 0.022443895 | V32: 0.76027088 | W32: =$B$2 -> 36.666667 | X32: =T32*W32*$B$3 -> 54.084255 | Y32: =U32*$G$4*W32^3*$B$3^5 -> 23510.679 | Z32: =Y32*V32 -> 17874.485
A33: 18 | B33: 0.83622323 | C33: 0.019160338 | D33: 0.72776524 | E33: =$B$2 -> 36.666667 | F33: =B33*E33*$B$3 -> 55.319383 | G33: =C33*$G$2*E33^3*$B$3^5 -> 22119.326 | H33: =G33*D33 -> 16097.676 | J33: 18 | K33: 0.83622323 | L33: 0.019160338 | M33: 0.72776524 | N33: =$B$2 -> 36.666667 | O33: =K33*N33*$B$3 -> 55.319383 | P33: =L33*$G$3*N33^3*$B$3^5 -> 21076.158 | Q33: =P33*M33 -> 15338.495 | S33: 18 | T33: 0.83622323 | U33: 0.019160338 | V33: 0.72776524 | W33: =$B$2 -> 36.666667 | X33: =T33*W33*$B$3 -> 55.319383 | Y33: =U33*$G$4*W33^3*$B$3^5 -> 20071.051 | Z33: =Y33*V33 -> 14607.013
A34: 19 | B34: 0.88853144 | C34: 0.0093028415 | D34: 0.53092551 | E34: =$B$2 -> 36.666667 | F34: =B34*E34*$B$3 -> 58.779772 | G34: =C34*$G$2*E34^3*$B$3^5 -> 10739.507 | H34: =G34*D34 -> 5701.8782 | J34: 19 | K34: 0.88853144 | L34: 0.0093028415 | M34: 0.53092551 | N34: =$B$2 -> 36.666667 | O34: =K34*N34*$B$3 -> 58.779772 | P34: =L34*$G$3*N34^3*$B$3^5 -> 10233.022 | Q34: =P34*M34 -> 5432.9723 | S34: 19 | T34: 0.88853144 | U34: 0.0093028415 | V34: 0.53092551 | W34: =$B$2 -> 36.666667 | X34: =T34*W34*$B$3 -> 58.779772 | Y34: =U34*$G$4*W34^3*$B$3^5 -> 9745.0164 | Z34: =Y34*V34 -> 5173.8778
A35: 20 | B35: 0.90536735 | C35: 0.0056472395 | D35: 0.48216704 | E35: =$B$2 -> 36.666667 | F35: =B35*E35*$B$3 -> 59.893533 | G35: =C35*$G$2*E35^3*$B$3^5 -> 6519.3595 | H35: =G35*D35 -> 3143.4203 | J35: 20 | K35: 0.90536735 | L35: 0.0056472395 | M35: 0.48216704 | N35: =$B$2 -> 36.666667 | O35: =K35*N35*$B$3 -> 59.893533 | P35: =L35*$G$3*N35^3*$B$3^5 -> 6211.9004 | Q35: =P35*M35 -> 2995.1737 | S35: 20 | T35: 0.90536735 | U35: 0.0056472395 | V35: 0.48216704 | W35: =$B$2 -> 36.666667 | X35: =T35*W35*$B$3 -> 59.893533 | Y35: =U35*$G$4*W35^3*$B$3^5 -> 5915.6594 | Z35: =Y35*V35 -> 2852.336
A37: h=1500m | J37: h=2000m | S37: h=2500m
A38: LP | B38: J | C38: CN | D38: ηs | E38: ns [1/s] | F38: V [m/s] | G38: N [W] | H38: Nr [W] | J38: LP | K38: J | L38: CN | M38: ηs | N38: ns [1/s] | O38: V [m/s] | P38: N [W] | Q38: Nr [W] | S38: LP | T38: J | U38: CN | V38: ηs | W38: ns [1/s] | X38: V [m/s] | Y38: N [W] | Z38: Nr [W]
A39: 1 | B39: 0 | C39: 0.073277583 | D39: 0 | E39: =SQRT($I$5/$G$5/$B$3^5/C39) -> 30.225463 | F39: =B39*E39*$B$3 -> 0 | G39: =$I$5*E39 -> 40923.699 | H39: =G39*D39 -> 0 | J39: 1 | K39: 0 | L39: 0.073277583 | M39: 0 | N39: =SQRT($I$6/$G$6/$B$3^5/L39) -> 30.075144 | O39: =K39*N39*$B$3 -> 0 | P39: =$I$6*N39 -> 38349.442 | Q39: =P39*M39 -> 0 | S39: 1 | T39: 0 | U39: 0.073277583 | V39: 0 | W39: =SQRT($I$7/$G$7/$B$3^5/U39) -> 29.914359 | X39: =T39*W39*$B$3 -> 0 | Y39: =$I$7*W39 -> 35875.393 | Z39: =Y39*V39 -> 0
A40: 2 | B40: 0.022604318 | C40: 0.073328782 | D40: 0.043340858 | E40: =SQRT($I$5/$G$5/$B$3^5/C40) -> 30.214909 | F40: =B40*E40*$B$3 -> 1.232243 | G40: =$I$5*E40 -> 40909.41 | H40: =G40*D40 -> 1773.0489 | J40: 2 | K40: 0.022604318 | L40: 0.073328782 | M40: 0.043340858 | N40: =SQRT($I$6/$G$6/$B$3^5/L40) -> 30.064643 | O40: =K40*N40*$B$3 -> 1.2261147 | P40: =$I$6*N40 -> 38336.052 | Q40: =P40*M40 -> 1661.5174 | S40: 2 | T40: 0.022604318 | U40: 0.073328782 | V40: 0.043340858 | W40: =SQRT($I$7/$G$7/$B$3^5/U40) -> 29.903914 | X40: =T40*W40*$B$3 -> 1.2195598 | Y40: =$I$7*W40 -> 35862.866 | Z40: =Y40*V40 -> 1554.3274
A41: 3 | B41: 0.083744347 | C41: 0.072704156 | D41: 0.14988713 | E41: =SQRT($I$5/$G$5/$B$3^5/C41) -> 30.344425 | F41: =B41*E41*$B$3 -> 4.5847756 | G41: =$I$5*E41 -> 41084.767 | H41: =G41*D41 -> 6158.078 | J41: 3 | K41: 0.083744347 | L41: 0.072704156 | M41: 0.14988713 | N41: =SQRT($I$6/$G$6/$B$3^5/L41) -> 30.193514 | O41: =K41*N41*$B$3 -> 4.5619743 | P41: =$I$6*N41 -> 38500.379 | Q41: =P41*M41 -> 5770.7114 | S41: 3 | T41: 0.083744347 | U41: 0.072704156 | V41: 0.14988713 | W41: =SQRT($I$7/$G$7/$B$3^5/U41) -> 30.032096 | X41: =T41*W41*$B$3 -> 4.5375855 | Y41: =$I$7*W41 -> 36016.592 | Z41: =Y41*V41 -> 5398.4237
A42: 4 | B42: 0.11710897 | C42: 0.07202833 | D42: 0.20586907 | E42: =SQRT($I$5/$G$5/$B$3^5/C42) -> 30.48645 | F42: =B42*E42*$B$3 -> 6.4414061 | G42: =$I$5*E42 -> 41277.062 | H42: =G42*D42 -> 8497.6705 | J42: 4 | K42: 0.11710897 | L42: 0.07202833 | M42: 0.20586907 | N42: =SQRT($I$6/$G$6/$B$3^5/L42) -> 30.334833 | O42: =K42*N42*$B$3 -> 6.4093713 | P42: =$I$6*N42 -> 38680.577 | Q42: =P42*M42 -> 7963.1346 | S42: 4 | T42: 0.11710897 | U42: 0.07202833 | V42: 0.20586907 | W42: =SQRT($I$7/$G$7/$B$3^5/U42) -> 30.17266 | X42: =T42*W42*$B$3 -> 6.3751061 | Y42: =$I$7*W42 -> 36185.165 | Z42: =Y42*V42 -> 7449.4065
...
